Workbook
Name Food_Type: "Baseline"
Name Methane_LHV: '[1]Global params'!$E$21

Sheet LCI
A2: Process | B2: Flow direction | C2: Flow type | D2: Flow name | E2: Value | F2: Unit
A3: Pretreatment | B3: input | C3: Technosphere flow | D3: Waste | E3: 1 | F3: t
B4: input | C4: Technosphere flow | D4: Electricity | E4: =E3*Parameters!C3 -> 19 | F4: kWh
B5: input | C5: Technosphere flow | D5: Water
B6: output | C6: Intermediate flow | D6: Pretreated biowaste | E6: =E3*Parameters!C5 -> 1 | F6: t
A7: Incineration | B7: input | C7: Intermediate flow | D7: discarded biowaste | E7: =E3*(1-Parameters!C5)*1000 -> 0 | F7: kg
A9: AD | B9: input | C9: Intermediate flow | D9: Pretreated waste | E9: =E6 -> 1 | F9: t
B10: input | D10: Electricity | E10: =Parameters!C13*LCI!E9 -> 29 | F10: kWh
D11: Heat | E11: =E9*Parameters!C14 -> 295 | F11: MJ
B12: output | C12: Elementary flow | D12: Methane | E12: =Parameters!C8*(Parameters!C6*(1-Waste_characteristics!B4))*LCI!E9*Parameters!C10*0.001 -> 2.15424 | F12: kg
B13: output | C13: Intermediate flow | D13: Biogas | E13: =(((Parameters!C6*(1-Waste_characteristics!B4))/Parameters!C9)*0.001)-((E12/Parameters!C10)*(1/Parameters!C9)) -> 244.34667 | F13: m3
A14: CHP | B14: input | C14: Intermediate flow | D14: Biogas | E14: =E13 -> 244.34667 | F14: m3
B15: output | C15: Elementary flow | D15: Nitrogen Oxides (NOx) | E15: =E14*Parameters!C23 -> 0.040098397 | F15: kg
B16: output | C16: Elementary flow | D16: Volatile Organic Compounds (VOCs) | E16: =E14*Parameters!C24 -> 0.38647217 | F16: kg
B17: output | C17: Elementary flow | D17: Sulfur Dioxide (SO2) | E17: =E14*Parameters!C25 -> 0.0034370055 | F17: kg
B18: output | C18: Elementary flow | D18: Particulate Matter (PM) | E18: =LCI!E14*Parameters!C26 -> 0.0084015689 | F18: kg
B19: output | C19: Elementary flow | D19: Carbon Monoxide (CO) | E19: =E14*Parameters!C27 -> 0.26102147 | F19: kg
B20: output | C20: Elementary flow | D20: Ammonia (NH3) | E20: =E14*Parameters!C28 -> 0.015657469 | F20: kg
B21: output | C21: Elementary flow | D21: Methane (CH4) | E21: =E14*Parameters!C29 -> 1.0515246 | F21: kg
B22: output | C22: Elementary flow | D22: Nitrous Oxide (N2O) | E22: =LCI!E14*Parameters!C30 -> 0.0250363 | F22: kg
B23: output | C23: Technosphere flow | D23: Electricity | E23: =E14*Parameters!C9*Parameters!C19*Parameters!C18/3.6 -> 555.88867 | F23: kWh
B24: output | C24: Technosphere flow | D24: Heat | E24: =E14*Parameters!C9*Parameters!C19*Parameters!C17 -> 2360.3888 | F24: MJ
A27: Biogas boiler | B27: input | C27: Intermediate flow | D27: Biogas | E27: =E13 -> 244.34667 | F27: m3
B28: output | C28: Elementary flow | D28: CO2 | E28: =$E$27*Parameters!C33 -> 491.05958 | F28: kg
B29: output | C29: Elementary flow | D29: CH4 | E29: =$E$27*Parameters!C34 -> 0.0062605205 | F29: kg
B30: output | C30: Elementary flow | D30: N2O | E30: =$E$27*Parameters!C35 -> 0.0062605205 | F30: kg
B31: output | C31: Elementary flow | D31: Sox | E31: =$E$27*Parameters!C36 -> 0.043432361 | F31: kg
B32: output | C32: Elementary flow | D32: PM10 | E32: =$E$27*Parameters!C37 -> 0.031850398 | F32: kg
B33: output | C33: Elementary flow | D33: PM2.5 | E33: =$E$27*Parameters!C38 -> 0.031850398 | F33: kg
B34: output | C34: Elementary flow | D34: Nox | E34: =$E$27*Parameters!C39 -> 0.41867231 | F34: kg
B35: output | C35: Elementary flow | D35: NH3 | E35: =$E$27*Parameters!C40 -> 0.01322535 | F35: kg
B36: output | C36: Elementary flow | D36: CO | E36: =$E$27*Parameters!C41 -> 0.35215428 | F36: kg
B37: output | C37: Elementary flow | D37: VOC | E37: =$E$27*Parameters!C42 -> 0.021051 | F37: kg
B38: input | C38: Technosphere flow | D38: Electricity | E38: =Parameters!C43*LCI!E27 -> 0.66462293 | F38: kWh
B39: output | C39: Technosphere flow | D39: Heat | E39: =E27*Parameters!C9*Parameters!C19*Parameters!C32 -> 4233.306 | F39: MJ
A42: Biogas upgrading | B42: input | C42: Technosphere flow | D42: Biogas | E42: =E13 -> 244.34667 | F42: m3
B43: output | C43: Elementary flow | D43: CO2 | E43: =E42*(1-Parameters!C9)*Parameters!C46*Parameters!C11 -> 190.61972 | F43: kg
B44: output | C44: Elementary flow | D44: CH4 | E44: =E42*Parameters!C9*Parameters!C47*Parameters!C10 -> 1.9000397 | F44: kg
B45: output | C45: Elementary flow | D45: H2S | E45: =Parameters!C48*LCI!E42 -> 0.00146608 | F45: kg
B46: output | C46: Elementary flow | D46: Sox | E46: =E42*Parameters!C49 -> 0.001612688 | F46: kg
...

Sheet Parameters
B1: Pretreatment
A2: Process | B2: Parameter | C2: Value | D2: Unit | F2: Source
A3: Pretreatment | B3: Electricity requirement | C3: 19 | D3: kWh/t
B4: Sorting efficiency for impurities | C4: 1 | D4: % of impurities sorted
B5: Sorting efficiency for biowaste | C5: 1 | D5: % of biowaste retained
A6: AD | B6: Methane production | C6: =374*1000 -> 374000 | D6: L/dry-t | F6: https://catalog.data.gov/dataset/food-waste-management-life-cycle-inventory-tool-v1-0-0
B7: VS conversion | C7: 0.86 | D7: %VS initial
B8: Fugitive methane loss | C8: 0.02 | F8: https://catalog.data.gov/dataset/food-waste-management-life-cycle-inventory-tool-v1-0-1
B9: Methane volume share in biogas | C9: 0.6 | F9: https://catalog.data.gov/dataset/food-waste-management-life-cycle-inventory-tool-v1-0-2
B10: Methane density | C10: 0.72 | D10: kg/m3 | F10: https://catalog.data.gov/dataset/food-waste-management-life-cycle-inventory-tool-v1-0-3
B11: CO2 density | C11: 1.98 | D11: kg/m3
B12: biogas density | C12: =(C9*C10)+((1-C9)*C11) -> 1.224 | D12: kg/m3
B13: Electricity requirement | C13: 29 | D13: kWh/t | F13: https://catalog.data.gov/dataset/food-waste-management-life-cycle-inventory-tool-v1-0-4
B14: Heat requirement | C14: 295 | D14: MJ/t | F14: https://catalog.data.gov/dataset/food-waste-management-life-cycle-inventory-tool-v1-0-5
B15: Water requriement | C15: 0 | D15: %of total waste
A16: CHP | B16: Efficiency | F16: https://catalog.data.gov/dataset/food-waste-management-life-cycle-inventory-tool-v1-0-6
B17: Thermal | C17: 0.46 | F17: https://catalog.data.gov/dataset/food-waste-management-life-cycle-inventory-tool-v1-0-7
B18: Electric | C18: 0.39 | F18: https://catalog.data.gov/dataset/food-waste-management-life-cycle-inventory-tool-v1-0-8
B19: Methane_lhv | C19: 35 | D19: MJ/m3 | F19: https://catalog.data.gov/dataset/food-waste-management-life-cycle-inventory-tool-v1-0-9
B20: Electricity requirement | F20: https://www.sciencedirect.com/science/article/pii/S0013935122009598?casa_token=b-5UAciDODcAAAAA:iPTgJGz224xsnoQdrEctjVyXjbgpRksrTp6NPBa96VQZoPJqxyo5SRxUSGA4QFvLo7qp_-bQrQ
B21: Lubricating oil | C21: 1.54 | D21: g/m3 of biogas | F21: https://www.sciencedirect.com/science/article/pii/S0013935122009598?casa_token=b-5UAciDODcAAAAA:iPTgJGz224xsnoQdrEctjVyXjbgpRksrTp6NPBa96VQZoPJqxyo5SRxUSGA4QFvLo7qp_-bQrQ
B22: Emissions
B23: Nitrogen Oxides (NOx) | C23: 0.00016410454 | D23: kg/m3 biogas combusted | F23: https://catalog.data.gov/dataset/food-waste-management-life-cycle-inventory-tool-v1-0-0
B24: Volatile Organic Compounds (VOCs) | C24: 0.0015816552 | D24: kg/m3 biogas combusted | F24: https://catalog.data.gov/dataset/food-waste-management-life-cycle-inventory-tool-v1-0-1
B25: Sulfur Dioxide (SO2) | C25: 1.4066103e-05 | D25: kg/m3 biogas combusted | F25: https://catalog.data.gov/dataset/food-waste-management-life-cycle-inventory-tool-v1-0-2
B26: Particulate Matter (PM2.5) | C26: 3.4383808e-05 | D26: kg/m3 biogas combusted | F26: https://catalog.data.gov/dataset/food-waste-management-life-cycle-inventory-tool-v1-0-3
B27: Carbon Monoxide (CO) | C27: 0.0010682424 | D27: kg/m3 biogas combusted | F27: https://catalog.data.gov/dataset/food-waste-management-life-cycle-inventory-tool-v1-0-4
B28: Ammonia (NH3) | C28: 6.4078915e-05 | D28: kg/m3 biogas combusted | F28: https://catalog.data.gov/dataset/food-waste-management-life-cycle-inventory-tool-v1-0-5
B29: Methane (CH4) | C29: 0.0043034128 | D29: kg/m3 biogas combusted | F29: https://catalog.data.gov/dataset/food-waste-management-life-cycle-inventory-tool-v1-0-6
B30: Nitrous Oxide (N2O) | C30: 0.00010246221 | D30: kg/m3 biogas combusted | F30: https://catalog.data.gov/dataset/food-waste-management-life-cycle-inventory-tool-v1-0-7
A31: Biogas boiler
B32: Efficiency | C32: 0.825 | F32: https://pureadmin.qub.ac.uk/ws/files/135497181/Document2.pdf
B33: CO2 | C33: =L36*L$47 -> 2.009684 | D33: kg/m3 of biogas | E33: Labutong, 2012
B34: CH4 | C34: =L37*L$47 -> 2.5621469e-05 | D34: kg/m3 of biogas | E34: Labutong, 2012
B35: N2O | C35: =L38*L$47 -> 2.5621469e-05 | D35: kg/m3 of biogas | E35: Labutong, 2012
B36: Sox | C36: =L39*L$47 -> 0.00017774894 | D36: kg/m3 of biogas | E36: Labutong, 2012 | K36: CO2 | L36: =39.1+86.4 -> 125.5
B37: PM10 | C37: =L40*L$47 -> 0.00013034922 | D37: kg/m3 of biogas | E37: Labutong, 2012 | K37: CH4 | L37: 0.0016
B38: PM2.5 | C38: =L41*L$47 -> 0.00013034922 | D38: kg/m3 of biogas | E38: Labutong, 2012 | K38: N2O | L38: 0.0016
B39: Nox | C39: =L42*L$47 -> 0.0017134357 | D39: kg/m3 of biogas | E39: Labutong, 2012 | K39: Sox | L39: 0.0111
B40: NH3 | C40: =L43*L$47 -> 5.4125353e-05 | D40: kg/m3 of biogas | E40: Labutong, 2012 | K40: PM10 | L40: 0.00814
...

Sheet Waste_characteristics
C1: Unit
A2: Mass | B2: 1 | C2: t
A3: FW | B3: =B2-B7 -> 1 | C3: t
A4: Moisture content, FW | B4: 0.6 | C4: %FW | D4: 0.72
A5: VS, FW | B5: 0.96 | C5: %TS
A6: VS, FW | B6: =B3*(1-B4)*B5 -> 0.384 | C6: t
A7: impurities | B7: 0 | C7: t
A8: Nitrogen content, FW | B8: 0.038 | C8: % of dry mass of FW
A9: Carbon content, FW | B9: 0.5 | C9: % of dry mass of FW
A10: Phosphorus content, FW | B10: 0.0051 | C10: % of dry mass of FW
A11: Potassium content, FW | B11: 0.01 | C11: % of dry mass of FW
J35: https://journals.sagepub.com/doi/full/10.1177/0734242X14545374#bibr26-0734242X14545374

Sheet AD_a_end
A1: Process | C1: ecosystem quality - acidification: terrestrial | D1: ecosystem quality - climate change: freshwater ecosystems | E1: ecosystem quality - climate change: terrestrial ecosystems | F1: ecosystem quality - ecotoxicity: freshwater | G1: ecosystem quality - ecotoxicity: marine | H1: ecosystem quality - ecotoxicity: terrestrial | I1: ecosystem quality - eutrophication: freshwater | J1: ecosystem quality - eutrophication: marine | K1: ecosystem quality - land use | L1: ecosystem quality - photochemical oxidant formation: terrestrial ecosystems | M1: ecosystem quality - water use: aquatic ecosystems | N1: ecosystem quality - water use: terrestrial ecosystems | O1: human health - climate change: human health | P1: human health - human toxicity: carcinogenic | Q1: human health - human toxicity: non-carcinogenic | R1: human health - ionising radiation | S1: human health - ozone depletion | T1: human health - particulate matter formation | U1: human health - photochemical oxidant formation: human health | V1: human health - water use: human health | W1: natural resources - energy resources: non-renewable, fossil | X1: natural resources - material resources: metals/minerals | Y1: total: ecosystem quality - ecosystem quality | Z1: total: human health - human health | AA1: total: natural resources - natural resources
A2: Pretreatment
B3: Electricity consumption | C3: =LCI!$E4*impact_process_end!C2 -> 3.6450434e-10 | D3: =LCI!$E4*impact_process_end!D2 -> 1.15404e-13 | E3: =LCI!$E4*impact_process_end!E2 -> 4.2251524e-09 | F3: =LCI!$E4*impact_process_end!F2 -> 8.1552881e-11 | G3: =LCI!$E4*impact_process_end!G2 -> 1.5682593e-11 | H3: =LCI!$E4*impact_process_end!H2 -> 1.2308702e-10 | I3: =LCI!$E4*impact_process_end!I2 -> 1.9524541e-10 | J3: =LCI!$E4*impact_process_end!J2 -> 3.734404e-13 | ... AA3: =LCI!$E4*impact_process_end!AA2 -> 0.16322532
B4: Water consumption | C4: =LCI!$E5*impact_process_end!C3 -> 0 | D4: =LCI!$E5*impact_process_end!D3 -> 0 | E4: =LCI!$E5*impact_process_end!E3 -> 0 | F4: =LCI!$E5*impact_process_end!F3 -> 0 | G4: =LCI!$E5*impact_process_end!G3 -> 0 | H4: =LCI!$E5*impact_process_end!H3 -> 0 | I4: =LCI!$E5*impact_process_end!I3 -> 0 | J4: =LCI!$E5*impact_process_end!J3 -> 0 | ... AA4: =LCI!$E5*impact_process_end!AA3 -> 0
A5: Incineration
B6: Incineration | C6: =LCI!$E7*impact_process_end!C4 -> 0 | D6: =LCI!$E7*impact_process_end!D4 -> 0 | E6: =LCI!$E7*impact_process_end!E4 -> 0 | F6: =LCI!$E7*impact_process_end!F4 -> 0 | G6: =LCI!$E7*impact_process_end!G4 -> 0 | H6: =LCI!$E7*impact_process_end!H4 -> 0 | I6: =LCI!$E7*impact_process_end!I4 -> 0 | J6: =LCI!$E7*impact_process_end!J4 -> 0 | ... AA6: =LCI!$E7*impact_process_end!AA4 -> 0
A7: AD
B8: Electricity consumption | C8: =LCI!$E10*impact_process_end!C2 -> 5.5634872e-10 | D8: =LCI!$E10*impact_process_end!D2 -> 1.7614295e-13 | E8: =LCI!$E10*impact_process_end!E2 -> 6.4489168e-09 | F8: =LCI!$E10*impact_process_end!F2 -> 1.2447545e-10 | G8: =LCI!$E10*impact_process_end!G2 -> 2.393659e-11 | H8: =LCI!$E10*impact_process_end!H2 -> 1.8786966e-10 | I8: =LCI!$E10*impact_process_end!I2 -> 2.9800616e-10 | J8: =LCI!$E10*impact_process_end!J2 -> 5.6998798e-13 | ... AA8: =LCI!$E10*impact_process_end!AA2 -> 0.24913338
B9: Heat consumption | C9: =LCI!$E11*impact_process_end!C10 -> 4.4309908e-09 | D9: =LCI!$E11*impact_process_end!D10 -> 9.8281617e-13 | E9: =LCI!$E11*impact_process_end!E10 -> 3.5988137e-08 | F9: =LCI!$E11*impact_process_end!F10 -> 1.1525021e-10 | G9: =LCI!$E11*impact_process_end!G10 -> 2.3982393e-11 | H9: =LCI!$E11*impact_process_end!H10 -> 2.6827041e-10 | I9: =LCI!$E11*impact_process_end!I10 -> 7.098951e-10 | J9: =LCI!$E11*impact_process_end!J10 -> 1.9156217e-13 | ... AA9: =LCI!$E11*impact_process_end!AA10 -> 1.4361398
B10: Fugitive methane | C10: =LCI!$E12*impact_process_end!C11 -> 0 | D10: =LCI!$E12*impact_process_end!D11 -> 5.601024e-12 | E10: =LCI!$E12*impact_process_end!E11 -> 2.0508365e-07 | F10: =LCI!$E12*impact_process_end!F11 -> 0 | G10: =LCI!$E12*impact_process_end!G11 -> 0 | H10: =LCI!$E12*impact_process_end!H11 -> 0 | I10: =LCI!$E12*impact_process_end!I11 -> 0 | J10: =LCI!$E12*impact_process_end!J11 -> 0 | ... AA10: =LCI!$E12*impact_process_end!AA11 -> 0
A11: CHP
B12: Nitrogen oxides | C12: =LCI!$E15*impact_process_end!C12 -> 3.0595077e-09 | D12: =LCI!$E15*impact_process_end!D12 -> 0 | E12: =LCI!$E15*impact_process_end!E12 -> 0 | F12: =LCI!$E15*impact_process_end!F12 -> 0 | G12: =LCI!$E15*impact_process_end!G12 -> 0 | H12: =LCI!$E15*impact_process_end!H12 -> 0 | I12: =LCI!$E15*impact_process_end!I12 -> 0 | J12: =LCI!$E15*impact_process_end!J12 -> 0 | ... AA12: =LCI!$E15*impact_process_end!AA12 -> 0
B13: Volatile organic compounds | C13: =LCI!$E16*impact_process_end!C13 -> 0 | D13: =LCI!$E16*impact_process_end!D13 -> 0 | E13: =LCI!$E16*impact_process_end!E13 -> 0 | F13: =LCI!$E16*impact_process_end!F13 -> 0 | G13: =LCI!$E16*impact_process_end!G13 -> 0 | H13: =LCI!$E16*impact_process_end!H13 -> 0 | I13: =LCI!$E16*impact_process_end!I13 -> 0 | J13: =LCI!$E16*impact_process_end!J13 -> 0 | ... AA13: =LCI!$E16*impact_process_end!AA13 -> 0
B14: Sulfur dioxide | C14: =LCI!$E17*impact_process_end!C14 -> 7.2864516e-10 | D14: =LCI!$E17*impact_process_end!D14 -> 0 | E14: =LCI!$E17*impact_process_end!E14 -> 0 | F14: =LCI!$E17*impact_process_end!F14 -> 0 | G14: =LCI!$E17*impact_process_end!G14 -> 0 | H14: =LCI!$E17*impact_process_end!H14 -> 0 | I14: =LCI!$E17*impact_process_end!I14 -> 0 | J14: =LCI!$E17*impact_process_end!J14 -> 0 | ... AA14: =LCI!$E17*impact_process_end!AA14 -> 0
B15: Particulate matter | C15: =LCI!$E18*impact_process_end!C21 -> 0 | D15: =LCI!$E18*impact_process_end!D21 -> 0 | E15: =LCI!$E18*impact_process_end!E21 -> 0 | F15: =LCI!$E18*impact_process_end!F21 -> 0 | G15: =LCI!$E18*impact_process_end!G21 -> 0 | H15: =LCI!$E18*impact_process_end!H21 -> 0 | I15: =LCI!$E18*impact_process_end!I21 -> 0 | J15: =LCI!$E18*impact_process_end!J21 -> 0 | ... AA15: =LCI!$E18*impact_process_end!AA21 -> 0
B16: Carbon monoxide | C16: =LCI!$E19*impact_process_end!C16 -> 0 | D16: =LCI!$E19*impact_process_end!D16 -> 0 | E16: =LCI!$E19*impact_process_end!E16 -> 0 | F16: =LCI!$E19*impact_process_end!F16 -> 0 | G16: =LCI!$E19*impact_process_end!G16 -> 0 | H16: =LCI!$E19*impact_process_end!H16 -> 0 | I16: =LCI!$E19*impact_process_end!I16 -> 0 | J16: =LCI!$E19*impact_process_end!J16 -> 0 | ... AA16: =LCI!$E19*impact_process_end!AA16 -> 0
B17: Ammonia | C17: =LCI!$E20*impact_process_end!C17 -> 6.5135072e-09 | D17: =LCI!$E20*impact_process_end!D17 -> 0 | E17: =LCI!$E20*impact_process_end!E17 -> 0 | F17: =LCI!$E20*impact_process_end!F17 -> 0 | G17: =LCI!$E20*impact_process_end!G17 -> 0 | H17: =LCI!$E20*impact_process_end!H17 -> 0 | I17: =LCI!$E20*impact_process_end!I17 -> 0 | J17: =LCI!$E20*impact_process_end!J17 -> 0 | ... AA17: =LCI!$E20*impact_process_end!AA17 -> 0
B18: Methane | C18: =LCI!$E21*impact_process_end!C11 -> 0 | D18: =LCI!$E21*impact_process_end!D11 -> 2.7339639e-12 | E18: =LCI!$E21*impact_process_end!E11 -> 1.0010514e-07 | F18: =LCI!$E21*impact_process_end!F11 -> 0 | G18: =LCI!$E21*impact_process_end!G11 -> 0 | H18: =LCI!$E21*impact_process_end!H11 -> 0 | I18: =LCI!$E21*impact_process_end!I11 -> 0 | J18: =LCI!$E21*impact_process_end!J11 -> 0 | ... AA18: =LCI!$E21*impact_process_end!AA11 -> 0
B19: Nitrous oxide | C19: =LCI!$E22*impact_process_end!C19 -> 0 | D19: =LCI!$E22*impact_process_end!D19 -> 5.7082763e-13 | E19: =LCI!$E22*impact_process_end!E19 -> 2.0880274e-08 | F19: =LCI!$E22*impact_process_end!F19 -> 0 | G19: =LCI!$E22*impact_process_end!G19 -> 0 | H19: =LCI!$E22*impact_process_end!H19 -> 0 | I19: =LCI!$E22*impact_process_end!I19 -> 0 | J19: =LCI!$E22*impact_process_end!J19 -> 0 | ... AA19: =LCI!$E22*impact_process_end!AA19 -> 0
A20: Total AD-a
B21: Total AD-a | C21: =SUM(C3:C4,C6,C8:C10,C12:C19) -> 1.5653504e-08 | D21: =SUM(D3:D4,D6,D8:D10,D12:D19) -> 1.0180179e-11 | E21: =SUM(E3:E4,E6,E8:E10,E12:E19) -> 3.7273127e-07 | F21: =SUM(F3:F4,F6,F8:F10,F12:F19) -> 3.2127854e-10 | G21: =SUM(G3:G4,G6,G8:G10,G12:G19) -> 6.3601576e-11 | H21: =SUM(H3:H4,H6,H8:H10,H12:H19) -> 5.7922708e-10 | I21: =SUM(I3:I4,I6,I8:I10,I12:I19) -> 1.2031467e-09 | J21: =SUM(J3:J4,J6,J8:J10,J12:J19) -> 1.1349905e-12 | ... AA21: =SUM(AA3:AA4,AA6,AA8:AA10,AA12:AA19) -> 1.8484985
A23: Biogas boiler
B24: CO2
B25: CH4 | C25: =LCI!$E29*impact_process_end!C11 -> 0 | D25: =LCI!$E29*impact_process_end!D11 -> 1.6277353e-14 | E25: =LCI!$E29*impact_process_end!E11 -> 5.9600155e-10 | F25: =LCI!$E29*impact_process_end!F11 -> 0 | G25: =LCI!$E29*impact_process_end!G11 -> 0 | H25: =LCI!$E29*impact_process_end!H11 -> 0 | I25: =LCI!$E29*impact_process_end!I11 -> 0 | J25: =LCI!$E29*impact_process_end!J11 -> 0 | ... AA25: =LCI!$E29*impact_process_end!AA11 -> 0
B26: N2O | C26: =LCI!$E30*impact_process_end!C19 -> 0 | D26: =LCI!$E30*impact_process_end!D19 -> 1.4273987e-13 | E26: =LCI!$E30*impact_process_end!E19 -> 5.2212741e-09 | F26: =LCI!$E30*impact_process_end!F19 -> 0 | G26: =LCI!$E30*impact_process_end!G19 -> 0 | H26: =LCI!$E30*impact_process_end!H19 -> 0 | I26: =LCI!$E30*impact_process_end!I19 -> 0 | J26: =LCI!$E30*impact_process_end!J19 -> 0 | ... AA26: =LCI!$E30*impact_process_end!AA19 -> 0
B27: Sox | C27: =LCI!$E31*impact_process_end!C18 -> 9.2076606e-09 | D27: =LCI!$E31*impact_process_end!D18 -> 0 | E27: =LCI!$E31*impact_process_end!E18 -> 0 | F27: =LCI!$E31*impact_process_end!F18 -> 0 | G27: =LCI!$E31*impact_process_end!G18 -> 0 | H27: =LCI!$E31*impact_process_end!H18 -> 0 | I27: =LCI!$E31*impact_process_end!I18 -> 0 | J27: =LCI!$E31*impact_process_end!J18 -> 0 | ... AA27: =LCI!$E31*impact_process_end!AA18 -> 0
B28: PM10 | C28: =LCI!$E32*impact_process_end!C15 -> 0 | D28: =LCI!$E32*impact_process_end!D15 -> 0 | E28: =LCI!$E32*impact_process_end!E15 -> 0 | F28: =LCI!$E32*impact_process_end!F15 -> 0 | G28: =LCI!$E32*impact_process_end!G15 -> 0 | H28: =LCI!$E32*impact_process_end!H15 -> 0 | I28: =LCI!$E32*impact_process_end!I15 -> 0 | J28: =LCI!$E32*impact_process_end!J15 -> 0 | ... AA28: =LCI!$E32*impact_process_end!AA15 -> 0
B29: PM2.5 | C29: =LCI!$E33*impact_process_end!C21 -> 0 | D29: =LCI!$E33*impact_process_end!D21 -> 0 | E29: =LCI!$E33*impact_process_end!E21 -> 0 | F29: =LCI!$E33*impact_process_end!F21 -> 0 | G29: =LCI!$E33*impact_process_end!G21 -> 0 | H29: =LCI!$E33*impact_process_end!H21 -> 0 | I29: =LCI!$E33*impact_process_end!I21 -> 0 | J29: =LCI!$E33*impact_process_end!J21 -> 0 | ... AA29: =LCI!$E33*impact_process_end!AA21 -> 0
B30: Nox | C30: =LCI!$E34*impact_process_end!C12 -> 3.1944697e-08 | D30: =LCI!$E34*impact_process_end!D12 -> 0 | E30: =LCI!$E34*impact_process_end!E12 -> 0 | F30: =LCI!$E34*impact_process_end!F12 -> 0 | G30: =LCI!$E34*impact_process_end!G12 -> 0 | H30: =LCI!$E34*impact_process_end!H12 -> 0 | I30: =LCI!$E34*impact_process_end!I12 -> 0 | J30: =LCI!$E34*impact_process_end!J12 -> 0 | ... AA30: =LCI!$E34*impact_process_end!AA12 -> 0
B31: NH3 | C31: =LCI!$E35*impact_process_end!C17 -> 5.5017454e-09 | D31: =LCI!$E35*impact_process_end!D17 -> 0 | E31: =LCI!$E35*impact_process_end!E17 -> 0 | F31: =LCI!$E35*impact_process_end!F17 -> 0 | G31: =LCI!$E35*impact_process_end!G17 -> 0 | H31: =LCI!$E35*impact_process_end!H17 -> 0 | I31: =LCI!$E35*impact_process_end!I17 -> 0 | J31: =LCI!$E35*impact_process_end!J17 -> 0 | ... AA31: =LCI!$E35*impact_process_end!AA17 -> 0
B32: CO | C32: =LCI!$E36*impact_process_end!C16 -> 0 | D32: =LCI!$E36*impact_process_end!D16 -> 0 | E32: =LCI!$E36*impact_process_end!E16 -> 0 | F32: =LCI!$E36*impact_process_end!F16 -> 0 | G32: =LCI!$E36*impact_process_end!G16 -> 0 | H32: =LCI!$E36*impact_process_end!H16 -> 0 | I32: =LCI!$E36*impact_process_end!I16 -> 0 | J32: =LCI!$E36*impact_process_end!J16 -> 0 | ... AA32: =LCI!$E36*impact_process_end!AA16 -> 0
B33: VOC | C33: =LCI!$E37*impact_process_end!C13 -> 0 | D33: =LCI!$E37*impact_process_end!D13 -> 0 | E33: =LCI!$E37*impact_process_end!E13 -> 0 | F33: =LCI!$E37*impact_process_end!F13 -> 0 | G33: =LCI!$E37*impact_process_end!G13 -> 0 | H33: =LCI!$E37*impact_process_end!H13 -> 0 | I33: =LCI!$E37*impact_process_end!I13 -> 0 | J33: =LCI!$E37*impact_process_end!J13 -> 0 | ... AA33: =LCI!$E37*impact_process_end!AA13 -> 0
B34: Electricity consumption | C34: =LCI!$E38*impact_process_end!C2 -> 1.2750418e-11 | D34: =LCI!$E38*impact_process_end!D2 -> 4.0368497e-15 | E34: =LCI!$E38*impact_process_end!E2 -> 1.4779648e-10 | F34: =LCI!$E38*impact_process_end!F2 -> 2.8527324e-12 | G34: =LCI!$E38*impact_process_end!G2 -> 5.4857954e-13 | H34: =LCI!$E38*impact_process_end!H2 -> 4.3056029e-12 | I34: =LCI!$E38*impact_process_end!I2 -> 6.8297147e-12 | J34: =LCI!$E38*impact_process_end!J2 -> 1.3063003e-14 | ... AA34: =LCI!$E38*impact_process_end!AA2 -> 0.0057096469
A36: Upgrading
B37: CO2
B38: CH4 | C38: =LCI!$E44*impact_process_end!C11 -> 0 | D38: =LCI!$E44*impact_process_end!D11 -> 4.9401032e-12 | E38: =LCI!$E44*impact_process_end!E11 -> 1.8088378e-07 | F38: =LCI!$E44*impact_process_end!F11 -> 0 | G38: =LCI!$E44*impact_process_end!G11 -> 0 | H38: =LCI!$E44*impact_process_end!H11 -> 0 | I38: =LCI!$E44*impact_process_end!I11 -> 0 | J38: =LCI!$E44*impact_process_end!J11 -> 0 | ... AA38: =LCI!$E44*impact_process_end!AA11 -> 0
B39: H2S | C39: =LCI!$E45*impact_process_end!C23 -> 0 | D39: =LCI!$E45*impact_process_end!D23 -> 0 | E39: =LCI!$E45*impact_process_end!E23 -> 0 | F39: =LCI!$E45*impact_process_end!F23 -> 0 | G39: =LCI!$E45*impact_process_end!G23 -> 0 | H39: =LCI!$E45*impact_process_end!H23 -> 0 | I39: =LCI!$E45*impact_process_end!I23 -> 0 | J39: =LCI!$E45*impact_process_end!J23 -> 0 | ... AA39: =LCI!$E45*impact_process_end!AA23 -> 0
B40: Sox | C40: =LCI!$E46*impact_process_end!C18 -> 3.4188986e-10 | D40: =LCI!$E46*impact_process_end!D18 -> 0 | E40: =LCI!$E46*impact_process_end!E18 -> 0 | F40: =LCI!$E46*impact_process_end!F18 -> 0 | G40: =LCI!$E46*impact_process_end!G18 -> 0 | H40: =LCI!$E46*impact_process_end!H18 -> 0 | I40: =LCI!$E46*impact_process_end!I18 -> 0 | J40: =LCI!$E46*impact_process_end!J18 -> 0 | ... AA40: =LCI!$E46*impact_process_end!AA18 -> 0
B41: Electricity | C41: =LCI!$E47*impact_process_end!C2 -> 1.5938022e-09 | D41: =LCI!$E47*impact_process_end!D2 -> 5.0460622e-13 | E41: =LCI!$E47*impact_process_end!E2 -> 1.847456e-08 | F41: =LCI!$E47*impact_process_end!F2 -> 3.5659155e-10 | G41: =LCI!$E47*impact_process_end!G2 -> 6.8572442e-11 | H41: =LCI!$E47*impact_process_end!H2 -> 5.3820036e-10 | I41: =LCI!$E47*impact_process_end!I2 -> 8.5371434e-10 | J41: =LCI!$E47*impact_process_end!J2 -> 1.6328753e-12 | ... AA41: =LCI!$E47*impact_process_end!AA2 -> 0.71370587
B42: Activated carbon | C42: =LCI!$E48*impact_process_end!C29 -> 7.1949017e-10 | D42: =LCI!$E48*impact_process_end!D29 -> 5.6552935e-14 | E42: =LCI!$E48*impact_process_end!E29 -> 2.0707302e-09 | F42: =LCI!$E48*impact_process_end!F29 -> 8.3298761e-12 | G42: =LCI!$E48*impact_process_end!G29 -> 1.7515105e-12 | H42: =LCI!$E48*impact_process_end!H29 -> 9.4189028e-12 | I42: =LCI!$E48*impact_process_end!I29 -> 1.9682028e-10 | J42: =LCI!$E48*impact_process_end!J29 -> 3.3824241e-14 | ... AA42: =LCI!$E48*impact_process_end!AA29 -> 0.031556119
...

Sheet AD_a_mid
A1: Process | C1: acidification: terrestrial - terrestrial acidification potential (TAP) | D1: climate change - global warming potential (GWP100) | E1: ecotoxicity: freshwater - freshwater ecotoxicity potential (FETP) | F1: ecotoxicity: marine - marine ecotoxicity potential (METP) | G1: ecotoxicity: terrestrial - terrestrial ecotoxicity potential (TETP) | H1: energy resources: non-renewable, fossil - fossil fuel potential (FFP) | I1: eutrophication: freshwater - freshwater eutrophication potential (FEP) | J1: eutrophication: marine - marine eutrophication potential (MEP) | K1: human toxicity: carcinogenic - human toxicity potential (HTPc) | L1: human toxicity: non-carcinogenic - human toxicity potential (HTPnc) | M1: ionising radiation - ionising radiation potential (IRP) | N1: land use - agricultural land occupation (LOP) | O1: material resources: metals/minerals - surplus ore potential (SOP) | P1: ozone depletion - ozone depletion potential (ODPinfinite) | Q1: particulate matter formation - particulate matter formation potential (PMFP) | R1: photochemical oxidant formation: human health - photochemical oxidant formation potential: humans (HOFP) | S1: photochemical oxidant formation: terrestrial ecosystems - photochemical oxidant formation potential: ecosystems (EOFP) | T1: water use - water consumption potential (WCP)
A2: Pretreatment
B3: Electricity consumption | C3: =LCI!$E4*impact_process_mid!C2 -> 0.0017193824 | D3: =LCI!$E4*impact_process_mid!D2 -> 1.5087176 | E3: =LCI!$E4*impact_process_mid!E2 -> 0.11786519 | F3: =LCI!$E4*impact_process_mid!F2 -> 0.14915508 | G3: =LCI!$E4*impact_process_mid!G2 -> 10.779995 | H3: =LCI!$E4*impact_process_mid!H2 -> 0.46313814 | I3: =LCI!$E4*impact_process_mid!I2 -> 0.00029153876 | J3: =LCI!$E4*impact_process_mid!J2 -> 0.00021976564 | ... T3: =LCI!$E4*impact_process_mid!T2 -> 0.059569474
B4: Water consumption | C4: =LCI!$E5*impact_process_mid!C3 -> 0 | D4: =LCI!$E5*impact_process_mid!D3 -> 0 | E4: =LCI!$E5*impact_process_mid!E3 -> 0 | F4: =LCI!$E5*impact_process_mid!F3 -> 0 | G4: =LCI!$E5*impact_process_mid!G3 -> 0 | H4: =LCI!$E5*impact_process_mid!H3 -> 0 | I4: =LCI!$E5*impact_process_mid!I3 -> 0 | J4: =LCI!$E5*impact_process_mid!J3 -> 0 | ... T4: =LCI!$E5*impact_process_mid!T3 -> 0
A5: Incineration
B6: Incineration | C6: =LCI!$E7*impact_process_mid!C4 -> 0 | D6: =LCI!$E7*impact_process_mid!D4 -> 0 | E6: =LCI!$E7*impact_process_mid!E4 -> 0 | F6: =LCI!$E7*impact_process_mid!F4 -> 0 | G6: =LCI!$E7*impact_process_mid!G4 -> 0 | H6: =LCI!$E7*impact_process_mid!H4 -> 0 | I6: =LCI!$E7*impact_process_mid!I4 -> 0 | J6: =LCI!$E7*impact_process_mid!J4 -> 0 | ... T6: =LCI!$E7*impact_process_mid!T4 -> 0
A7: AD
B8: Electricity consumption | C8: =LCI!$E10*impact_process_mid!C2 -> 0.0026243205 | D8: =LCI!$E10*impact_process_mid!D2 -> 2.3027795 | E8: =LCI!$E10*impact_process_mid!E2 -> 0.1798995 | F8: =LCI!$E10*impact_process_mid!F2 -> 0.22765776 | G8: =LCI!$E10*impact_process_mid!G2 -> 16.453677 | H8: =LCI!$E10*impact_process_mid!H2 -> 0.70689505 | I8: =LCI!$E10*impact_process_mid!I2 -> 0.00044498021 | J8: =LCI!$E10*impact_process_mid!J2 -> 0.00033543177 | ... T8: =LCI!$E10*impact_process_mid!T2 -> 0.090921828
B9: Heat consumption | C9: =LCI!$E11*impact_process_mid!C10 -> 0.02090364 | D9: =LCI!$E11*impact_process_mid!D10 -> 12.849496 | E9: =LCI!$E11*impact_process_mid!E10 -> 0.16649727 | F9: =LCI!$E11*impact_process_mid!F10 -> 0.22814841 | G9: =LCI!$E11*impact_process_mid!G10 -> 23.518362 | H9: =LCI!$E11*impact_process_mid!H10 -> 4.1413318 | I9: =LCI!$E11*impact_process_mid!I10 -> 0.0010598955 | J9: =LCI!$E11*impact_process_mid!J10 -> 0.00011268951 | ... T9: =LCI!$E11*impact_process_mid!T10 -> 0.045958936
B10: Fugitive methane | C10: =LCI!$E12*impact_process_mid!C11 -> 0 | D10: =LCI!$E12*impact_process_mid!D11 -> 73.24416 | E10: =LCI!$E12*impact_process_mid!E11 -> 0 | F10: =LCI!$E12*impact_process_mid!F11 -> 0 | G10: =LCI!$E12*impact_process_mid!G11 -> 0 | H10: =LCI!$E12*impact_process_mid!H11 -> 0 | I10: =LCI!$E12*impact_process_mid!I11 -> 0 | J10: =LCI!$E12*impact_process_mid!J11 -> 0 | ... T10: =LCI!$E12*impact_process_mid!T11 -> 0
A11: CHP
B12: Nitrogen oxides | C12: =LCI!$E15*impact_process_mid!C12 -> 0.014435423 | D12: =LCI!$E15*impact_process_mid!D12 -> 0 | E12: =LCI!$E15*impact_process_mid!E12 -> 0 | F12: =LCI!$E15*impact_process_mid!F12 -> 0 | G12: =LCI!$E15*impact_process_mid!G12 -> 0 | H12: =LCI!$E15*impact_process_mid!H12 -> 0 | I12: =LCI!$E15*impact_process_mid!I12 -> 0 | J12: =LCI!$E15*impact_process_mid!J12 -> 0 | ... T12: =LCI!$E15*impact_process_mid!T12 -> 0
B13: Volatile organic compounds | C13: =LCI!$E16*impact_process_mid!C13 -> 0 | D13: =LCI!$E16*impact_process_mid!D13 -> 0 | E13: =LCI!$E16*impact_process_mid!E13 -> 0 | F13: =LCI!$E16*impact_process_mid!F13 -> 0 | G13: =LCI!$E16*impact_process_mid!G13 -> 0 | H13: =LCI!$E16*impact_process_mid!H13 -> 0 | I13: =LCI!$E16*impact_process_mid!I13 -> 0 | J13: =LCI!$E16*impact_process_mid!J13 -> 0 | ... T13: =LCI!$E16*impact_process_mid!T13 -> 0
B14: Sulfur dioxide | C14: =LCI!$E17*impact_process_mid!C14 -> 0.0034370055 | D14: =LCI!$E17*impact_process_mid!D14 -> 0 | E14: =LCI!$E17*impact_process_mid!E14 -> 0 | F14: =LCI!$E17*impact_process_mid!F14 -> 0 | G14: =LCI!$E17*impact_process_mid!G14 -> 0 | H14: =LCI!$E17*impact_process_mid!H14 -> 0 | I14: =LCI!$E17*impact_process_mid!I14 -> 0 | J14: =LCI!$E17*impact_process_mid!J14 -> 0 | ... T14: =LCI!$E17*impact_process_mid!T14 -> 0
B15: Particulate matter | C15: =LCI!$E18*impact_process_mid!C21 -> 0 | D15: =LCI!$E18*impact_process_mid!D21 -> 0 | E15: =LCI!$E18*impact_process_mid!E21 -> 0 | F15: =LCI!$E18*impact_process_mid!F21 -> 0 | G15: =LCI!$E18*impact_process_mid!G21 -> 0 | H15: =LCI!$E18*impact_process_mid!H21 -> 0 | I15: =LCI!$E18*impact_process_mid!I21 -> 0 | J15: =LCI!$E18*impact_process_mid!J21 -> 0 | ... T15: =LCI!$E18*impact_process_mid!T21 -> 0
B16: Carbon monoxide | C16: =LCI!$E19*impact_process_mid!C16 -> 0 | D16: =LCI!$E19*impact_process_mid!D16 -> 0 | E16: =LCI!$E19*impact_process_mid!E16 -> 0 | F16: =LCI!$E19*impact_process_mid!F16 -> 0 | G16: =LCI!$E19*impact_process_mid!G16 -> 0 | H16: =LCI!$E19*impact_process_mid!H16 -> 0 | I16: =LCI!$E19*impact_process_mid!I16 -> 0 | J16: =LCI!$E19*impact_process_mid!J16 -> 0 | ... T16: =LCI!$E19*impact_process_mid!T16 -> 0
B17: Ammonia | C17: =LCI!$E20*impact_process_mid!C17 -> 0.03068864 | D17: =LCI!$E20*impact_process_mid!D17 -> 0 | E17: =LCI!$E20*impact_process_mid!E17 -> 0 | F17: =LCI!$E20*impact_process_mid!F17 -> 0 | G17: =LCI!$E20*impact_process_mid!G17 -> 0 | H17: =LCI!$E20*impact_process_mid!H17 -> 0 | I17: =LCI!$E20*impact_process_mid!I17 -> 0 | J17: =LCI!$E20*impact_process_mid!J17 -> 0 | ... T17: =LCI!$E20*impact_process_mid!T17 -> 0
B18: Methane | C18: =LCI!$E21*impact_process_mid!C11 -> 0 | D18: =LCI!$E21*impact_process_mid!D11 -> 35.751836 | E18: =LCI!$E21*impact_process_mid!E11 -> 0 | F18: =LCI!$E21*impact_process_mid!F11 -> 0 | G18: =LCI!$E21*impact_process_mid!G11 -> 0 | H18: =LCI!$E21*impact_process_mid!H11 -> 0 | I18: =LCI!$E21*impact_process_mid!I11 -> 0 | J18: =LCI!$E21*impact_process_mid!J11 -> 0 | ... T18: =LCI!$E21*impact_process_mid!T11 -> 0
B19: Nitrous oxide | C19: =LCI!$E22*impact_process_mid!C19 -> 0 | D19: =LCI!$E22*impact_process_mid!D19 -> 7.4608173 | E19: =LCI!$E22*impact_process_mid!E19 -> 0 | F19: =LCI!$E22*impact_process_mid!F19 -> 0 | G19: =LCI!$E22*impact_process_mid!G19 -> 0 | H19: =LCI!$E22*impact_process_mid!H19 -> 0 | I19: =LCI!$E22*impact_process_mid!I19 -> 0 | J19: =LCI!$E22*impact_process_mid!J19 -> 0 | ... T19: =LCI!$E22*impact_process_mid!T19 -> 0
A20: Total AD-a
B21: Total AD-a | C21: =SUM(C3:C4,C6,C8:C10,C12:C19) -> 0.073808411 | D21: =SUM(D3:D4,D6,D8:D10,D12:D19) -> 133.11781 | E21: =SUM(E3:E4,E6,E8:E10,E12:E19) -> 0.46426197 | F21: =SUM(F3:F4,F6,F8:F10,F12:F19) -> 0.60496126 | G21: =SUM(G3:G4,G6,G8:G10,G12:G19) -> 50.752035 | H21: =SUM(H3:H4,H6,H8:H10,H12:H19) -> 5.311365 | I21: =SUM(I3:I4,I6,I8:I10,I12:I19) -> 0.0017964145 | J21: =SUM(J3:J4,J6,J8:J10,J12:J19) -> 0.00066788692 | ... T21: =SUM(T3:T4,T6,T8:T10,T12:T19) -> 0.19645024
A23: Biogas boiler
B24: CO2
B25: CH4 | C25: =LCI!$E29*impact_process_mid!C11 -> 0 | D25: =LCI!$E29*impact_process_mid!D11 -> 0.2128577 | E25: =LCI!$E29*impact_process_mid!E11 -> 0 | F25: =LCI!$E29*impact_process_mid!F11 -> 0 | G25: =LCI!$E29*impact_process_mid!G11 -> 0 | H25: =LCI!$E29*impact_process_mid!H11 -> 0 | I25: =LCI!$E29*impact_process_mid!I11 -> 0 | J25: =LCI!$E29*impact_process_mid!J11 -> 0 | ... T25: =LCI!$E29*impact_process_mid!T11 -> 0
B26: N2O | C26: =LCI!$E30*impact_process_mid!C19 -> 0 | D26: =LCI!$E30*impact_process_mid!D19 -> 1.8656351 | E26: =LCI!$E30*impact_process_mid!E19 -> 0 | F26: =LCI!$E30*impact_process_mid!F19 -> 0 | G26: =LCI!$E30*impact_process_mid!G19 -> 0 | H26: =LCI!$E30*impact_process_mid!H19 -> 0 | I26: =LCI!$E30*impact_process_mid!I19 -> 0 | J26: =LCI!$E30*impact_process_mid!J19 -> 0 | ... T26: =LCI!$E30*impact_process_mid!T19 -> 0
B27: Sox | C27: =LCI!$E31*impact_process_mid!C18 -> 0.043432361 | D27: =LCI!$E31*impact_process_mid!D18 -> 0 | E27: =LCI!$E31*impact_process_mid!E18 -> 0 | F27: =LCI!$E31*impact_process_mid!F18 -> 0 | G27: =LCI!$E31*impact_process_mid!G18 -> 0 | H27: =LCI!$E31*impact_process_mid!H18 -> 0 | I27: =LCI!$E31*impact_process_mid!I18 -> 0 | J27: =LCI!$E31*impact_process_mid!J18 -> 0 | ... T27: =LCI!$E31*impact_process_mid!T18 -> 0
B28: PM10 | C28: =LCI!$E32*impact_process_mid!C15 -> 0 | D28: =LCI!$E32*impact_process_mid!D15 -> 0 | E28: =LCI!$E32*impact_process_mid!E15 -> 0 | F28: =LCI!$E32*impact_process_mid!F15 -> 0 | G28: =LCI!$E32*impact_process_mid!G15 -> 0 | H28: =LCI!$E32*impact_process_mid!H15 -> 0 | I28: =LCI!$E32*impact_process_mid!I15 -> 0 | J28: =LCI!$E32*impact_process_mid!J15 -> 0 | ... T28: =LCI!$E32*impact_process_mid!T15 -> 0
B29: PM2.5 | C29: =LCI!$E33*impact_process_mid!C21 -> 0 | D29: =LCI!$E33*impact_process_mid!D21 -> 0 | E29: =LCI!$E33*impact_process_mid!E21 -> 0 | F29: =LCI!$E33*impact_process_mid!F21 -> 0 | G29: =LCI!$E33*impact_process_mid!G21 -> 0 | H29: =LCI!$E33*impact_process_mid!H21 -> 0 | I29: =LCI!$E33*impact_process_mid!I21 -> 0 | J29: =LCI!$E33*impact_process_mid!J21 -> 0 | ... T29: =LCI!$E33*impact_process_mid!T21 -> 0
B30: Nox | C30: =LCI!$E34*impact_process_mid!C12 -> 0.15072203 | D30: =LCI!$E34*impact_process_mid!D12 -> 0 | E30: =LCI!$E34*impact_process_mid!E12 -> 0 | F30: =LCI!$E34*impact_process_mid!F12 -> 0 | G30: =LCI!$E34*impact_process_mid!G12 -> 0 | H30: =LCI!$E34*impact_process_mid!H12 -> 0 | I30: =LCI!$E34*impact_process_mid!I12 -> 0 | J30: =LCI!$E34*impact_process_mid!J12 -> 0 | ... T30: =LCI!$E34*impact_process_mid!T12 -> 0
B31: NH3 | C31: =LCI!$E35*impact_process_mid!C17 -> 0.025921685 | D31: =LCI!$E35*impact_process_mid!D17 -> 0 | E31: =LCI!$E35*impact_process_mid!E17 -> 0 | F31: =LCI!$E35*impact_process_mid!F17 -> 0 | G31: =LCI!$E35*impact_process_mid!G17 -> 0 | H31: =LCI!$E35*impact_process_mid!H17 -> 0 | I31: =LCI!$E35*impact_process_mid!I17 -> 0 | J31: =LCI!$E35*impact_process_mid!J17 -> 0 | ... T31: =LCI!$E35*impact_process_mid!T17 -> 0
B32: CO | C32: =LCI!$E36*impact_process_mid!C16 -> 0 | D32: =LCI!$E36*impact_process_mid!D16 -> 0 | E32: =LCI!$E36*impact_process_mid!E16 -> 0 | F32: =LCI!$E36*impact_process_mid!F16 -> 0 | G32: =LCI!$E36*impact_process_mid!G16 -> 0 | H32: =LCI!$E36*impact_process_mid!H16 -> 0 | I32: =LCI!$E36*impact_process_mid!I16 -> 0 | J32: =LCI!$E36*impact_process_mid!J16 -> 0 | ... T32: =LCI!$E36*impact_process_mid!T16 -> 0
B33: VOC | C33: =LCI!$E37*impact_process_mid!C13 -> 0 | D33: =LCI!$E37*impact_process_mid!D13 -> 0 | E33: =LCI!$E37*impact_process_mid!E13 -> 0 | F33: =LCI!$E37*impact_process_mid!F13 -> 0 | G33: =LCI!$E37*impact_process_mid!G13 -> 0 | H33: =LCI!$E37*impact_process_mid!H13 -> 0 | I33: =LCI!$E37*impact_process_mid!I13 -> 0 | J33: =LCI!$E37*impact_process_mid!J13 -> 0 | ... T33: =LCI!$E37*impact_process_mid!T13 -> 0
B34: Electricity consumption | C34: =LCI!$E38*impact_process_mid!C2 -> 6.0144261e-05 | D34: =LCI!$E38*impact_process_mid!D2 -> 0.052775174 | E34: =LCI!$E38*impact_process_mid!E2 -> 0.0041229426 | F34: =LCI!$E38*impact_process_mid!F2 -> 0.0052174679 | G34: =LCI!$E38*impact_process_mid!G2 -> 0.37708591 | H34: =LCI!$E38*impact_process_mid!H2 -> 0.016200644 | I34: =LCI!$E38*impact_process_mid!I2 -> 1.0198071e-05 | J34: =LCI!$E38*impact_process_mid!J2 -> 7.6874361e-06 | ... T34: =LCI!$E38*impact_process_mid!T2 -> 0.0020837494
A36: Upgrading
B37: CO2
B38: CH4 | C38: =LCI!$E44*impact_process_mid!C11 -> 0 | D38: =LCI!$E44*impact_process_mid!D11 -> 64.601349 | E38: =LCI!$E44*impact_process_mid!E11 -> 0 | F38: =LCI!$E44*impact_process_mid!F11 -> 0 | G38: =LCI!$E44*impact_process_mid!G11 -> 0 | H38: =LCI!$E44*impact_process_mid!H11 -> 0 | I38: =LCI!$E44*impact_process_mid!I11 -> 0 | J38: =LCI!$E44*impact_process_mid!J11 -> 0 | ... T38: =LCI!$E44*impact_process_mid!T11 -> 0
B39: H2S | C39: =LCI!$E45*impact_process_mid!C23 -> 0 | D39: =LCI!$E45*impact_process_mid!D23 -> 0 | E39: =LCI!$E45*impact_process_mid!E23 -> 0 | F39: =LCI!$E45*impact_process_mid!F23 -> 0 | G39: =LCI!$E45*impact_process_mid!G23 -> 0 | H39: =LCI!$E45*impact_process_mid!H23 -> 0 | I39: =LCI!$E45*impact_process_mid!I23 -> 0 | J39: =LCI!$E45*impact_process_mid!J23 -> 0 | ... T39: =LCI!$E45*impact_process_mid!T23 -> 0
B40: Sox | C40: =LCI!$E46*impact_process_mid!C18 -> 0.001612688 | D40: =LCI!$E46*impact_process_mid!D18 -> 0 | E40: =LCI!$E46*impact_process_mid!E18 -> 0 | F40: =LCI!$E46*impact_process_mid!F18 -> 0 | G40: =LCI!$E46*impact_process_mid!G18 -> 0 | H40: =LCI!$E46*impact_process_mid!H18 -> 0 | I40: =LCI!$E46*impact_process_mid!I18 -> 0 | J40: =LCI!$E46*impact_process_mid!J18 -> 0 | ... T40: =LCI!$E46*impact_process_mid!T18 -> 0
B41: Electricity | C41: =LCI!$E47*impact_process_mid!C2 -> 0.0075180326 | D41: =LCI!$E47*impact_process_mid!D2 -> 6.5968967 | E41: =LCI!$E47*impact_process_mid!E2 -> 0.51536782 | F41: =LCI!$E47*impact_process_mid!F2 -> 0.65218349 | G41: =LCI!$E47*impact_process_mid!G2 -> 47.135738 | H41: =LCI!$E47*impact_process_mid!H2 -> 2.0250805 | I41: =LCI!$E47*impact_process_mid!I2 -> 0.0012747588 | J41: =LCI!$E47*impact_process_mid!J2 -> 0.00096092951 | ... T41: =LCI!$E47*impact_process_mid!T2 -> 0.26046867
B42: Activated carbon | C42: =LCI!$E48*impact_process_mid!C29 -> 0.0033939361 | D42: =LCI!$E48*impact_process_mid!D29 -> 0.73936068 | E42: =LCI!$E48*impact_process_mid!E29 -> 0.012025733 | F42: =LCI!$E48*impact_process_mid!F29 -> 0.01667039 | G42: =LCI!$E48*impact_process_mid!G29 -> 0.82597018 | H42: =LCI!$E48*impact_process_mid!H29 -> 0.18811165 | I42: =LCI!$E48*impact_process_mid!I29 -> 0.00029389414 | J42: =LCI!$E48*impact_process_mid!J29 -> 1.9906411e-05 | ... T42: =LCI!$E48*impact_process_mid!T29 -> 0.0019751897
...

Sheet impact_process_mid
A1: Process | B1: Reference unit | C1: acidification: terrestrial - terrestrial acidification potential (TAP) | D1: climate change - global warming potential (GWP100) | E1: ecotoxicity: freshwater - freshwater ecotoxicity potential (FETP) | F1: ecotoxicity: marine - marine ecotoxicity potential (METP) | G1: ecotoxicity: terrestrial - terrestrial ecotoxicity potential (TETP) | H1: energy resources: non-renewable, fossil - fossil fuel potential (FFP) | I1: eutrophication: freshwater - freshwater eutrophication potential (FEP) | J1: eutrophication: marine - marine eutrophication potential (MEP) | K1: human toxicity: carcinogenic - human toxicity potential (HTPc) | L1: human toxicity: non-carcinogenic - human toxicity potential (HTPnc) | M1: ionising radiation - ionising radiation potential (IRP) | N1: land use - agricultural land occupation (LOP) | O1: material resources: metals/minerals - surplus ore potential (SOP) | P1: ozone depletion - ozone depletion potential (ODPinfinite) | Q1: particulate matter formation - particulate matter formation potential (PMFP) | R1: photochemical oxidant formation: human health - photochemical oxidant formation potential: humans (HOFP) | S1: photochemical oxidant formation: terrestrial ecosystems - photochemical oxidant formation potential: ecosystems (EOFP) | T1: water use - water consumption potential (WCP) | V1: Information | W1: Geography
A2: Electricity | B2: kWh | C2: 9.049381e-05 | D2: 0.079406189 | E2: 0.0062034311 | F2: 0.0078502676 | G2: 0.56736818 | H2: 0.024375692 | I2: 1.5344145e-05 | J2: 1.1566613e-05 | K2: 0.0059147603 | L2: 0.12794399 | M2: 0.55006624 | N2: 0.0028505746 | O2: 0.0017727191 | P2: 8.6459139e-08 | Q2: 5.0191089e-05 | R2: 8.1690947e-05 | S2: 9.0198139e-05 | T2: 0.0031352355 | V2: market for electricity, medium voltage | electricity, medium voltage | Cutoff, U | W2: FR
A3: Water | B3: kg | C3: 6.934533e-07 | D3: 0.00031448718 | E3: 1.6344982e-05 | F3: 2.2483537e-05 | G3: 0.0011552651 | H3: 8.2797071e-05 | I3: 2.0365943e-07 | J3: 2.122186e-08 | K3: 0.0002599786 | L3: 0.00037706261 | M3: 0.00010820091 | N3: 8.2753463e-06 | O3: 3.4750839e-05 | P3: 1.2081554e-10 | Q3: 3.8763074e-07 | R3: 5.3875424e-07 | S3: 5.7339186e-07 | T3: 3.4526299e-06 | V3: market for tap water | tap water | Cutoff, U | W3: Europe without Switzerland
A4: Incineration | B4: kg | C4: 0.0001363856 | D4: 0.040980828 | E4: 0.0067876314 | F4: 0.0090687992 | G4: 0.093690771 | H4: 0.0057803422 | I4: 4.8682721e-05 | J4: 1.2084724e-05 | K4: 0.010550695 | L4: 0.30316586 | M4: 0.00038257425 | N4: 0.00079287043 | O4: 0.0011589877 | P4: 5.7786312e-07 | Q4: 5.4055787e-05 | R4: 0.00025789436 | S4: 0.00026089125 | T4: 0.0018198871
A5: Heat, natural gas | B5: MJ | C5: 2.7642789e-05 | D5: 0.078571532 | E5: 0.00056949792 | F5: 0.00075180929 | G5: 0.040860748 | H5: 0.026216279 | I5: 2.7368311e-06 | J5: 2.8430163e-07 | K5: 0.0015731326 | L5: 0.0088030327 | M5: 0.0010481272 | N5: 0.00015742974 | O5: 0.00052648906 | P5: 1.2286717e-08 | Q5: 1.190633e-05 | R5: 5.0216773e-05 | S5: 5.888624e-05 | T5: 6.1814732e-05
A6: Heat, fuel | B6: MJ | C6: 0.00012056148 | D6: 0.098206281 | E6: 0.00090128215 | F6: 0.0012533522 | G6: 0.10124155 | H6: 0.028615023 | I6: 3.3282226e-06 | J6: 2.3768029e-06 | K6: 0.0018046053 | L6: 0.016080339 | M6: 0.0012311628 | N6: 0.00026029536 | O6: 0.00063014235 | P6: 1.3890748e-08 | Q6: 4.1127784e-05 | R6: 9.0031824e-05 | S6: 0.00010559271 | T6: 6.3116088e-05
A7: Heat, coal | B7: MJ | C7: 0.00035729226 | D7: 0.062444666 | E7: 0.00083144411 | F7: 0.0011627961 | G7: 0.033957796 | H7: 0.012997135 | I7: 2.2782621e-05 | J7: 1.4545929e-06 | K7: 0.0023277124 | L7: 0.039289368 | M7: 0.000101304 | N7: 0.00063795047 | O7: 8.3398518e-05 | P7: 9.5950858e-09 | Q7: 0.00012951127 | R7: 0.00016308707 | S7: 0.00016365245 | T7: 5.3685901e-05
A8: Heat, wood chips | B8: MJ | C8: 0.00015807715 | D8: 0.017263471 | E8: 0.00081184821 | F8: 0.0011495494 | G8: 0.16689692 | H8: 0.0044475403 | I8: 6.2691844e-06 | J8: 6.6643957e-07 | K8: 0.0014328128 | L8: 0.042289363 | M8: 0.0011085274 | N8: 0.02819778 | O8: 0.0002250437 | P8: 4.5527191e-08 | Q8: 0.00018578324 | R8: 0.00032228755 | S8: 0.00032625557 | T8: 0.00035061659
A9: Heat, waste | B9: MJ | C9: 0 | D9: 0 | E9: 0 | F9: 0 | G9: 0 | H9: 0 | I9: 0 | J9: 0 | K9: 0 | L9: 0 | M9: 0 | N9: 0 | O9: 0 | P9: 0 | Q9: 0 | R9: 0 | S9: 0 | T9: 0
A10: Heat mix | B10: MJ | C10: =(C5*Parameters!$C103)+(impact_process_mid!C6*Parameters!$C105)+(impact_process_mid!C7*Parameters!$C104)+(impact_process_mid!C8*Parameters!$C106)+(impact_process_mid!C9*Parameters!$C107) -> 7.0859796e-05 | D10: =(D5*Parameters!$C103)+(impact_process_mid!D6*Parameters!$C105)+(impact_process_mid!D7*Parameters!$C104)+(impact_process_mid!D8*Parameters!$C106)+(impact_process_mid!D9*Parameters!$C107) -> 0.043557614 | E10: =(E5*Parameters!$C103)+(impact_process_mid!E6*Parameters!$C105)+(impact_process_mid!E7*Parameters!$C104)+(impact_process_mid!E8*Parameters!$C106)+(impact_process_mid!E9*Parameters!$C107) -> 0.00056439754 | F10: =(F5*Parameters!$C103)+(impact_process_mid!F6*Parameters!$C105)+(impact_process_mid!F7*Parameters!$C104)+(impact_process_mid!F8*Parameters!$C106)+(impact_process_mid!F9*Parameters!$C107) -> 0.00077338445 | G10: =(G5*Parameters!$C103)+(impact_process_mid!G6*Parameters!$C105)+(impact_process_mid!G7*Parameters!$C104)+(impact_process_mid!G8*Parameters!$C106)+(impact_process_mid!G9*Parameters!$C107) -> 0.079723263 | H10: =(H5*Parameters!$C103)+(impact_process_mid!H6*Parameters!$C105)+(impact_process_mid!H7*Parameters!$C104)+(impact_process_mid!H8*Parameters!$C106)+(impact_process_mid!H9*Parameters!$C107) -> 0.014038413 | I10: =(I5*Parameters!$C103)+(impact_process_mid!I6*Parameters!$C105)+(impact_process_mid!I7*Parameters!$C104)+(impact_process_mid!I8*Parameters!$C106)+(impact_process_mid!I9*Parameters!$C107) -> 3.5928661e-06 | J10: =(J5*Parameters!$C103)+(impact_process_mid!J6*Parameters!$C105)+(impact_process_mid!J7*Parameters!$C104)+(impact_process_mid!J8*Parameters!$C106)+(impact_process_mid!J9*Parameters!$C107) -> 3.8199834e-07 | ... T10: =(T5*Parameters!$C103)+(impact_process_mid!T6*Parameters!$C105)+(impact_process_mid!T7*Parameters!$C104)+(impact_process_mid!T8*Parameters!$C106)+(impact_process_mid!T9*Parameters!$C107) -> 0.000155793
A11: CH4 | B11: kg | D11: 34
A12: Nitrogen oxides | B12: kg | C12: 0.36 | Q12: 0.11 | R12: 1 | S12: 1
A13: Volatile organic compounds | B13: kg | R13: 0.18 | S13: 0.29
A14: Sulfur dioxide | B14: kg | C14: 1 | Q14: 0.29
A15: Particulate matter | B15: kg
A16: Carbon monoxide | B16: kg
A17: Ammonia | B17: kg | C17: 1.96 | Q17: 0.24
A18: sulfure oxides | B18: kg | C18: 1 | Q18: 0.29
A19: dinitrogen monoxide | B19: kg | D19: 298 | P19: 0.011
A20: Nitrate | B20: kg | J20: 0.0671
A21: PM2.5 | B21: kg | Q21: 1
A22: NMOVC | B22: kg | R22: 0.18 | S22: 0.29
A23: H2S | B23: kg
A24: Diesel | B24: kg | C24: 0.0023508892 | D24: 0.92876412 | E24: 0.0081038342 | F24: 0.01444995 | G24: 1.8555053 | H24: 1.2025197 | I24: 5.0584011e-05 | J24: 9.5059369e-05 | K24: 0.033196741 | L24: 0.23697936 | M24: 0.018590728 | N24: 0.0082089583 | O24: 0.017620037 | P24: 2.2557152e-07 | Q24: 0.00085162725 | R24: 0.0024420029 | S24: 0.0030960544 | T24: 0.0015799267
A25: N-fertilizer | B25: kg | C25: 0.0060823245 | D25: 1.6170842 | E25: 0.079410018 | F25: 0.10377325 | G25: 7.9107315 | H25: 0.46888006 | I25: 0.00020204942 | J25: 0.00018735552 | K25: 0.077351704 | L25: 1.2662508 | M25: 0.052863555 | N25: 0.018683906 | O25: 0.019675109 | P25: 5.6884222e-06 | Q25: 0.0013464194 | R25: 0.0021807021 | S25: 0.0023671436 | T25: 0.02479962
A26: K-fertilizer | B26: kg | C26: 0.0021572232 | D26: 0.67905932 | E26: 0.044678445 | F26: 0.060921909 | G26: 7.9126646 | H26: 0.22057815 | I26: 0.00013802493 | J26: 1.8609399e-05 | K26: 0.054389198 | L26: 0.82745426 | M26: 0.029626146 | N26: 0.041719554 | O26: 0.019310072 | P26: 2.0735443e-07 | Q26: 0.00084941695 | R26: 0.002363843 | S26: 0.0024814035 | T26: 0.006576871
A27: P-fertilizer | B27: kg | C27: 0.0051285758 | D27: 0.39573733 | E27: 0.052250247 | F27: 0.069366658 | G27: 5.9021895 | H27: 0.10401881 | I27: 0.00055371209 | J27: 3.0054435e-05 | K27: 0.047233399 | L27: 1.1333036 | M27: 0.10689344 | N27: 0.039263549 | O27: 0.024403218 | P27: 1.4437296e-07 | Q27: 0.001786324 | R27: 0.00094941113 | S27: 0.00099035079 | T27: 0.01104029
A28: Peat | B28: kg | C28: 2.929496e-05 | D28: 0.015818492 | E28: 0.00044732062 | F28: 0.00061066585 | G28: 0.076419092 | H28: 0.22209679 | I28: 1.7791631e-06 | J28: 2.9251738e-07 | K28: 0.00094263586 | L28: 0.0085991838 | M28: 0.0041513436 | N28: 0.0013068929 | O28: 0.00028716041 | P28: 4.1892753e-09 | Q28: 1.3340842e-05 | R28: 4.8063181e-05 | S28: 4.955178e-05 | T28: 0.00080994948
A29: Activated carbon | B29: kg | C29: 0.015606562 | D29: 3.3998513 | E29: 0.055298725 | F29: 0.07665656 | G29: 3.7981135 | H29: 0.86500627 | I29: 0.0013514329 | J29: 9.1536973e-05 | K29: 0.12258342 | L29: 2.3857778 | M29: 0.1218183 | N29: 0.039431024 | O29: 0.010279413 | P29: 6.3972763e-07 | Q29: 0.0059753148 | R29: 0.0077772246 | S29: 0.0079267587 | T29: 0.0090826458
A30: Zeolite | B30: kg | C30: 0.021429327 | D30: 5.3022918 | E30: 0.39564253 | F30: 0.5346072 | G30: 34.130497 | H30: 1.3570353 | I30: 0.0019913219 | J30: 0.00025459548 | K30: 1.7594109 | L30: 8.8018491 | M30: 0.28791329 | N30: 0.1224902 | O30: 0.35255185 | P30: 2.4165618e-06 | Q30: 0.0093199077 | R30: 0.014494237 | S30: 0.01494539 | T30: 0.074318769
A31: treatment of wastewater | B31: m3 | C31: 0.0014609826 | D31: 0.48416968 | E31: 0.028523336 | F31: 0.038469008 | G31: 1.7882989 | H31: 0.085296599 | I31: 0.0018098478 | J31: 0.0054775032 | K31: 0.033453794 | L31: 3.4352602 | M31: 0.019357563 | N31: 0.0085362147 | O31: 0.0066238358 | P31: 1.9560213e-06 | Q31: 0.00069311454 | R31: 0.0011080395 | S31: 0.0011355327 | T31: 0.0029936946

Sheet impact_process_end
A1: Process | B1: Reference unit | C1: ecosystem quality - acidification: terrestrial | D1: ecosystem quality - climate change: freshwater ecosystems | E1: ecosystem quality - climate change: terrestrial ecosystems | F1: ecosystem quality - ecotoxicity: freshwater | G1: ecosystem quality - ecotoxicity: marine | H1: ecosystem quality - ecotoxicity: terrestrial | I1: ecosystem quality - eutrophication: freshwater | J1: ecosystem quality - eutrophication: marine | K1: ecosystem quality - land use | L1: ecosystem quality - photochemical oxidant formation: terrestrial ecosystems | M1: ecosystem quality - water use: aquatic ecosystems | N1: ecosystem quality - water use: terrestrial ecosystems | O1: human health - climate change: human health | P1: human health - human toxicity: carcinogenic | Q1: human health - human toxicity: non-carcinogenic | R1: human health - ionising radiation | S1: human health - ozone depletion | T1: human health - particulate matter formation | U1: human health - photochemical oxidant formation: human health | V1: human health - water use: human health | W1: natural resources - energy resources: non-renewable, fossil | X1: natural resources - material resources: metals/minerals | Y1: total: ecosystem quality - ecosystem quality | Z1: total: human health - human health | AA1: total: natural resources - natural resources
A2: Electricity production | B2: kWh | C2: 1.9184439e-11 | D2: 6.0738947e-15 | E2: 2.2237644e-10 | F2: 4.2922569e-12 | G2: 8.2539965e-13 | H2: 6.4782641e-12 | I2: 1.0276074e-11 | J2: 1.9654758e-14 | K2: 2.5279937e-11 | L2: 1.1634952e-11 | M2: 1.8936822e-15 | N2: 4.2325679e-11 | O2: 7.3690334e-08 | P2: 1.9634188e-08 | Q2: 2.9153726e-08 | R2: 4.6663557e-09 | S2: 4.5900065e-11 | T2: 3.1545717e-08 | U2: 7.435363e-11 | V2: 6.9602227e-09 | W2: 0.0081807522 | X2: 0.00041005411 | Y2: 3.00375e-10 | Z2: 1.6577057e-07 | AA2: 0.0085908064
A3: Water production | B3: kg | C3: 1.4700901e-13 | D3: 2.4055506e-17 | E3: 8.8073441e-13 | F3: 1.1327354e-14 | G3: 2.3642653e-15 | H3: 1.3175558e-14 | I3: 1.3639079e-13 | J3: 3.6072826e-17 | K3: 7.3405021e-14 | L3: 7.3964669e-14 | M3: 2.0853885e-18 | N3: 4.6610504e-14 | O3: 2.918476e-10 | P3: 8.6309672e-10 | Q3: 8.5961448e-11 | R3: 9.1793575e-13 | S3: 6.4138568e-14 | T3: 2.436228e-10 | U3: 4.9032547e-13 | V3: 7.6648384e-12 | W3: 1.8110008e-05 | X3: 8.0391234e-06 | Y3: 1.3384276e-12 | Z3: 1.4936635e-09 | AA3: 2.6149132e-05
A4: Incineration | B4: kg | C4: 2.8909345e-11 | D4: 3.1349805e-15 | E4: 1.147388e-10 | F4: 4.6988185e-12 | G4: 9.5300873e-13 | H4: 1.0683495e-12 | I4: 3.2602719e-11 | J4: 2.0532137e-14 | K4: 7.036807e-12 | L4: 3.365474e-11 | M4: 1.0992118e-15 | N4: 2.4568476e-11 | O4: 3.8054145e-08 | P4: 3.5018038e-08 | Q4: 6.9092746e-08 | R4: 3.2457167e-12 | S4: 3.0679239e-10 | T4: 3.3986197e-08 | U4: 2.3468909e-10 | V4: 4.0401493e-09 | W4: 0.0019160164 | X4: 0.00026809773 | Y4: 2.2368682e-10 | Z4: 1.8073579e-07 | AA4: 0.0021841142
A5: Heat, natural gas | B5: MJ | C5: 5.8596788e-12 | D5: 6.0095664e-15 | E5: 2.2005785e-10 | F5: 3.9423616e-13 | G5: 7.9041745e-14 | H5: 4.6652181e-13 | I5: 1.83291e-12 | J5: 4.8327959e-16 | K5: 1.3967289e-12 | L5: 7.5957621e-12 | M5: 3.7336098e-17 | N5: 8.3449888e-13 | O5: 7.2912599e-08 | P5: 5.2224808e-09 | Q5: 2.006983e-09 | R5: 8.8919637e-12 | S5: 6.5205912e-12 | T5: 7.4836522e-09 | U5: 4.5712088e-11 | V5: 1.3722871e-10 | W5: 0.0092754795 | X5: 0.00012178732 | Y5: 2.3768934e-10 | Z5: 8.7823992e-08 | AA5: 0.0093972668
A6: Heat, fuel | B6: MJ | C6: 2.5557965e-11 | D6: 7.5116872e-15 | E6: 2.7503278e-10 | F6: 6.2377907e-13 | G6: 1.3175299e-13 | H6: 1.1552019e-12 | I6: 2.2289549e-12 | J6: 4.0447553e-15 | K6: 2.30984e-12 | L6: 1.362041e-11 | M6: 3.8122117e-17 | N6: 8.5206718e-13 | O6: 9.1133854e-08 | P6: 5.9911273e-09 | Q6: 3.6663062e-09 | R6: 1.0444772e-11 | S6: 7.3726802e-12 | T6: 2.5830515e-08 | U6: 8.1956371e-11 | V6: 1.4011771e-10 | W6: 0.012632578 | X6: 0.00014576258 | Y6: 3.2067246e-10 | Z6: 1.2686163e-07 | AA6: 0.012778341
A7: Heat, coal | B7: MJ | C7: 7.5743371e-11 | D7: 4.7762184e-15 | E7: 1.7488519e-10 | F7: 5.7629575e-13 | G7: 1.2216986e-13 | H7: 3.8727287e-13 | I7: 1.5257465e-11 | J7: 2.4714322e-15 | K7: 5.6606331e-12 | L7: 2.111112e-11 | M7: 3.2426284e-17 | N7: 7.2475967e-13 | O7: 5.79475e-08 | P7: 7.7270311e-09 | Q7: 8.9554148e-09 | R7: 8.5960471e-13 | S7: 5.0940978e-12 | T7: 8.1342807e-08 | U7: 1.4841023e-10 | V7: 1.191827e-10 | W7: 0.0012654872 | X7: 1.9291145e-05 | Y7: 2.9375096e-10 | Z7: 1.5624627e-07 | AA7: 0.0012847784
A8: Heat, wood chips | B8: MJ | C8: 3.3507688e-11 | D8: 1.3205747e-15 | E8: 4.8351767e-11 | F8: 5.6192731e-13 | G8: 1.2082046e-13 | H8: 1.9032052e-12 | I8: 4.1991827e-12 | J8: 1.1328756e-15 | K8: 2.5003582e-10 | L8: 4.2086659e-11 | M8: 2.1177242e-16 | N8: 4.7333239e-12 | O8: 1.6023833e-08 | P8: 4.7549023e-09 | Q8: 9.6440321e-09 | R8: 9.4046979e-12 | S8: 2.4170687e-11 | T8: 1.1684551e-07 | U8: 2.9328764e-10 | V8: 7.7836882e-10 | W8: 0.0010861877 | X8: 5.20553e-05 | Y8: 3.8076743e-10 | Z8: 1.4837273e-07 | AA8: 0.001138243
A9: Heat,waste | B9: MJ
A10: Heat, mix | B10: MJ | C10: =(C5*Parameters!$C103)+(C6*Parameters!$C105)+(C7*Parameters!$C104)+(C8*Parameters!$C106)+(C9*Parameters!$C107) -> 1.5020308e-11 | D10: =(D5*Parameters!$C103)+(D6*Parameters!$C105)+(D7*Parameters!$C104)+(D8*Parameters!$C106)+(D9*Parameters!$C107) -> 3.3315802e-15 | E10: =(E5*Parameters!$C103)+(E6*Parameters!$C105)+(E7*Parameters!$C104)+(E8*Parameters!$C106)+(E9*Parameters!$C107) -> 1.2199369e-10 | F10: =(F5*Parameters!$C103)+(F6*Parameters!$C105)+(F7*Parameters!$C104)+(F8*Parameters!$C106)+(F9*Parameters!$C107) -> 3.9067868e-13 | G10: =(G5*Parameters!$C103)+(G6*Parameters!$C105)+(G7*Parameters!$C104)+(G8*Parameters!$C106)+(G9*Parameters!$C107) -> 8.1296247e-14 | H10: =(H5*Parameters!$C103)+(H6*Parameters!$C105)+(H7*Parameters!$C104)+(H8*Parameters!$C106)+(H9*Parameters!$C107) -> 9.0939122e-13 | I10: =(I5*Parameters!$C103)+(I6*Parameters!$C105)+(I7*Parameters!$C104)+(I8*Parameters!$C106)+(I9*Parameters!$C107) -> 2.4064241e-12 | J10: =(J5*Parameters!$C103)+(J6*Parameters!$C105)+(J7*Parameters!$C104)+(J8*Parameters!$C106)+(J9*Parameters!$C107) -> 6.4936328e-16 | ... AA10: =(AA5*Parameters!$C103)+(AA6*Parameters!$C105)+(AA7*Parameters!$C104)+(AA8*Parameters!$C106)+(AA9*Parameters!$C107) -> 0.0048682706
A11: CH4 | B11: kg | C11: 0 | D11: 2.6e-12 | E11: 9.52e-08 | O11: 3.16e-05 | Y11: =SUM(D11:E11) -> 9.52026e-08 | Z11: 3.16e-05 | AA11: 0
A12: Nitrogen oxides | B12: kg | C12: 7.63e-08 | L12: 1.29e-07 | T12: 6.92e-05 | U12: 9.1e-07 | Y12: =SUM(C12:N12) -> 2.053e-07 | Z12: =SUM(O12:V12) -> 7.011e-05
A13: Volatile organic compounds | B13: kg | L13: 3.74e-08 | U13: 1.64e-07 | Y13: =SUM(C13:N13) -> 3.74e-08 | Z13: =SUM(O13:V13) -> 1.64e-07
A14: Sulfur dioxide | B14: kg | C14: 2.12e-07 | T14: 0.00018 | Y14: =SUM(C14:N14) -> 2.12e-07 | Z14: =SUM(O14:V14) -> 0.00018
A15: Particulate matter | B15: kg | Y15: =SUM(C15:N15) -> 0 | Z15: =SUM(O15:V15) -> 0
A16: Carbon monoxide | B16: kg | Y16: =SUM(C16:N16) -> 0 | Z16: =SUM(O16:V16) -> 0
A17: Ammonia | B17: kg | C17: 4.16e-07 | T17: 0.00015 | Y17: =SUM(C17:N17) -> 4.16e-07 | Z17: =SUM(O17:V17) -> 0.00015
A18: sulfure oxides | B18: kg | C18: 2.12e-07 | T18: 0.00018 | Y18: =SUM(C18:N18) -> 2.12e-07 | Z18: =SUM(O18:V18) -> 0.00018
A19: dinitrogen monoxide | B19: kg | D19: 2.28e-11 | E19: 8.34e-07 | O19: 0.00028 | S19: 5.84e-06 | Y19: =SUM(C19:N19) -> 8.340228e-07 | Z19: =SUM(O19:V19) -> 0.00028584
A20: Nitrate | B20: kg | J20: 1.14e-10 | Y20: =SUM(C20:N20) -> 1.14e-10 | Z20: =SUM(O20:V20) -> 0
A21: PM2.5 | B21: kg | T21: 0.00063 | Y21: =SUM(C21:N21) -> 0 | Z21: =SUM(O21:V21) -> 0.00063
A22: NMOVC | B22: kg | L22: 3.74 | U22: 1.64e-07 | Y22: =SUM(C22:N22) -> 3.74 | Z22: =SUM(O22:V22) -> 1.64e-07
A23: H2S | B23: kg
A24: Diesel | B24: kg | C24: 4.9836698e-10 | D24: 7.1004269e-14 | E24: 2.6028659e-09 | F24: 5.6154248e-12 | G24: 1.5182813e-12 | H24: 2.1147146e-11 | I24: 3.38776e-11 | J24: 1.6178475e-13 | K24: 7.2855538e-11 | L24: 3.993467e-10 | M24: 9.542757e-16 | N24: 2.132901e-11 | O24: 8.6181025e-07 | P24: 1.1021083e-07 | Q24: 5.4037915e-08 | R24: 1.5771865e-10 | S24: 1.1967107e-10 | T24: 5.3493628e-07 | U24: 2.2233799e-09 | V24: 3.5074372e-09 | W24: 0.53665358 | X24: 0.0040760871 | Y24: 3.6358265e-09 | Z24: 1.5670016e-06 | AA24: 0.54072967
A25: N-fertilizer | B25: kg | C25: 1.2903561e-09 | D25: 1.2369109e-13 | E25: 4.5285502e-09 | F25: 5.4939864e-11 | G25: 1.0909604e-11 | H25: 9.0318775e-11 | I25: 1.3531374e-10 | J25: 3.1878816e-13 | K25: 1.6575235e-10 | L25: 3.0534654e-10 | M25: 1.4978971e-14 | N25: 3.3479488e-10 | O25: 1.5008621e-06 | P25: 2.56804e-07 | Q25: 2.8870746e-07 | R25: 4.4847748e-10 | S25: 3.0200039e-09 | T25: 8.4635306e-07 | U25: 1.9847696e-09 | V25: 5.5055157e-08 | W25: 0.16256299 | X25: 0.0045505917 | Y25: 6.581939e-09 | Z25: 2.9532312e-06 | AA25: 0.16711358
A26: K-fertilizer | B26: kg | C26: 4.573135e-10 | D26: 5.1939994e-14 | E26: 1.9018072e-09 | F26: 3.0914423e-11 | G26: 6.4039124e-12 | H26: 9.0270489e-11 | I26: 9.2436064e-11 | J26: 3.165079e-14 | K26: 3.7025812e-10 | L26: 3.2009236e-10 | M26: 3.9724301e-15 | N26: 8.8787758e-11 | O26: 6.3016516e-07 | P26: 1.8056663e-07 | Q26: 1.8866753e-07 | R26: 2.5133909e-10 | S26: 1.1007192e-10 | T26: 5.3378601e-07 | U26: 2.1513032e-09 | V26: 1.4600654e-08 | W26: 0.082306566 | X26: 0.0044666042 | Y26: 3.2695772e-09 | Z26: 1.5502957e-06 | AA26: 0.08677317
A27: P-fertilizer | B27: kg | C27: 1.0872882e-09 | D27: 3.0276304e-14 | E27: 1.1084689e-09 | F27: 3.615153e-11 | G27: 7.2919005e-12 | H27: 6.7357211e-11 | I27: 3.7084478e-10 | J27: 5.1097205e-14 | K27: 3.4844916e-10 | L27: 1.2775224e-10 | M27: 6.6683349e-15 | N27: 1.4904391e-10 | O27: 3.6731738e-07 | P27: 1.5680443e-07 | Q27: 2.5835835e-07 | R27: 9.0684647e-10 | S27: 7.6643703e-11 | T27: 1.1217144e-06 | U27: 8.6403548e-10 | V27: 2.4509443e-08 | W27: 0.029816668 | X27: 0.0056418414 | Y27: 3.153583e-09 | Z27: 1.9305149e-06 | AA27: 0.035458509
