Workbook
Name Food_Type: "Baseline"
Name FW_mass: Waste_characteristics!$B$3
Name H2O_FW: Waste_characteristics!$B$4
Name Mass: Waste_characteristics!$B$2
Name mass_VS_FW: Waste_characteristics!$B$6
Name Methane_LHV: '[1]Global params'!$E$21
Name VS_FW: Waste_characteristics!$B$5

Sheet Waste_characteristics
C1: Unit
A2: Mass | B2: 1 | C2: t
A3: FW | B3: =B2-B7 -> 1 | C3: t
A4: Moisture content, FW | B4: =[2]mass_composition!$D$99/[2]mass_composition!$C$99 -> 0.63542863 | C4: %FW | D4: 0.72
A5: VS, FW | B5: =[2]mass_composition!$F$99/[2]mass_composition!$E$99 -> 0.96463821 | C5: %TS
A6: VS, FW | B6: =B3*(1-B4)*B5 -> 0.35167947 | C6: t
A7: impurities | B7: 0 | C7: t
A8: Nitrogen content, FW | B8: =[2]mass_composition!$R$99/[2]mass_composition!$E$99 -> 0.032826764 | C8: % of dry mass of FW
A9: Carbon content, FW | B9: =[2]mass_composition!$J$99/[2]mass_composition!$E$99 -> 0.46707763 | C9: % of dry mass of FW
A10: Phosphorus content, FW | B10: =[2]mass_composition!$U$99/[2]mass_composition!$E$99 -> 0.0040243826 | C10: % of dry mass of FW
A11: Potassium content, FW | B11: =[2]mass_composition!$Q$99/[2]mass_composition!$E$99 -> 0.0082642017 | C11: % of dry mass of FW
J35: https://journals.sagepub.com/doi/full/10.1177/0734242X14545374#bibr26-0734242X14545374

Sheet LCI
A2: Process | B2: Flow direction | C2: Flow type | D2: Flow name | E2: Value | F2: Unit | I2: UF | J2: Treatment of 1t of biowaste
A3: Pretreatment | B3: input | C3: Technosphere flow | D3: Waste | E3: 1 | F3: t
B4: input | C4: Technosphere flow | D4: Electricity | E4: =E3*Parameters!C3 -> 9.98 | F4: kWh
B5: input | C5: Technosphere flow | D5: Water
B6: output | C6: Intermediate flow | D6: Pretreated biowaste | E6: =E3*Parameters!C5 -> 0.77 | F6: t
A7: Incineration | B7: input | C7: Intermediate flow | D7: discarded biowaste | E7: =E3*(1-Parameters!C5)*1000 -> 230 | F7: kg
A9: AD | B9: input | C9: Intermediate flow | D9: Pretreated waste | E9: =E6 -> 0.77 | F9: t
B10: input | C10: Intermediate flow | D10: Electricity | E10: =Parameters!C14*LCI!E9 -> 22.33 | F10: kWh
B11: input | C11: Intermediate flow | D11: Heat | E11: =E9*Parameters!C15 -> 227.15 | F11: MJ
B12: output | C12: Elementary flow | D12: Methane | E12: =Parameters!C9*(Parameters!C7*(1-Waste_characteristics!B4))*LCI!E9*Parameters!C11*0.001 -> 1.5118454 | F12: kg
B13: output | C13: Intermediate flow | D13: Biogas | E13: =(((Parameters!C7*(1-Waste_characteristics!B4))/Parameters!C10)*0.001)-((E12/Parameters!C11)*(1/Parameters!C10)) -> 223.74985 | F13: m3
A14: CHP | B14: input | C14: Intermediate flow | D14: Biogas | E14: =E13 -> 223.74985 | F14: m3
B15: output | C15: Elementary flow | D15: Nitrogen Oxides (NOx) | E15: =E14*Parameters!C24 -> 0.036718365 | F15: kg
B16: output | C16: Elementary flow | D16: Volatile Organic Compounds (VOCs) | E16: =E14*Parameters!C25 -> 0.3538951 | F16: kg
B17: output | C17: Elementary flow | D17: Sulfur Dioxide (SO2) | E17: =E14*Parameters!C26 -> 0.0031472884 | F17: kg
B18: output | C18: Elementary flow | D18: Particulate Matter (PM) | E18: =LCI!E14*Parameters!C27 -> 0.0076933718 | F18: kg
B19: output | C19: Elementary flow | D19: Carbon Monoxide (CO) | E19: =E14*Parameters!C28 -> 0.23901907 | F19: kg
B20: output | C20: Elementary flow | D20: Ammonia (NH3) | E20: =E14*Parameters!C29 -> 0.014337647 | F20: kg
B21: output | C21: Elementary flow | D21: Methane (CH4) | E21: =E14*Parameters!C30 -> 0.96288796 | F21: kg
B22: output | C22: Elementary flow | D22: Nitrous Oxide (N2O) | E22: =LCI!E14*Parameters!C31 -> 0.022925904 | F22: kg
B23: output | C23: Technosphere flow | D23: Electricity | E23: =E14*Parameters!C10*Parameters!C20*Parameters!C19/3.6 -> 509.0309 | F23: kWh
B24: output | C24: Technosphere flow | D24: Heat | E24: =E14*Parameters!C10*Parameters!C20*Parameters!C18 -> 2161.4235 | F24: MJ
A27: Biogas boiler | B27: input | C27: Intermediate flow | D27: Biogas | E27: =E13 -> 223.74985 | F27: m3
B28: output | C28: Elementary flow | D28: CO2 | E28: =$E$27*Parameters!C34 -> 449.66648 | F28: kg
B29: output | C29: Elementary flow | D29: CH4 | E29: =$E$27*Parameters!C35 -> 0.0057327997 | F29: kg
B30: output | C30: Elementary flow | D30: N2O | E30: =$E$27*Parameters!C36 -> 0.0057327997 | F30: kg
B31: output | C31: Elementary flow | D31: Sox | E31: =$E$27*Parameters!C37 -> 0.039771298 | F31: kg
B32: output | C32: Elementary flow | D32: PM10 | E32: =$E$27*Parameters!C38 -> 0.029165619 | F32: kg
B33: output | C33: Elementary flow | D33: PM2.5 | E33: =$E$27*Parameters!C39 -> 0.029165619 | F33: kg
B34: output | C34: Elementary flow | D34: Nox | E34: =$E$27*Parameters!C40 -> 0.38338098 | F34: kg
B35: output | C35: Elementary flow | D35: NH3 | E35: =$E$27*Parameters!C41 -> 0.012110539 | F35: kg
B36: output | C36: Elementary flow | D36: CO | E36: =$E$27*Parameters!C42 -> 0.32246998 | F36: kg
B37: output | C37: Elementary flow | D37: VOC | E37: =$E$27*Parameters!C43 -> 0.019276539 | F37: kg
B38: input | C38: Technosphere flow | D38: Electricity | E38: =Parameters!C44*LCI!E27 -> 0.60859958 | F38: kWh
B39: output | C39: Technosphere flow | D39: Heat | E39: =E27*Parameters!C10*Parameters!C20*Parameters!C33 -> 3876.4661 | F39: MJ
A42: Biogas upgrading | B42: input | C42: Technosphere flow | D42: Biogas | E42: =E13 -> 223.74985 | F42: m3
B43: output | C43: Elementary flow | D43: CO2 | E43: =E42*(1-Parameters!C10)*Parameters!C47*Parameters!C12 -> 174.55173 | F43: kg
B44: output | C44: Elementary flow | D44: CH4 | E44: =E42*Parameters!C10*Parameters!C48*Parameters!C11 -> 1.7398788 | F44: kg
B45: output | C45: Elementary flow | D45: H2S | E45: =Parameters!C49*LCI!E42 -> 0.0013424991 | F45: kg
B46: output | C46: Elementary flow | D46: Sox | E46: =E42*Parameters!C50 -> 0.001476749 | F46: kg
...

Sheet LCI_AD-c
A1: AD+injection+Digestate
A2: Process | B2: Flow direction | C2: Flow type | D2: Flow name | E2: Value | F2: Unit
A3: Pretreatment | B3: input | C3: Technosphere flow | D3: Waste | E3: 1 | F3: t
B4: input | C4: Technosphere flow | D4: Electricity | E4: =E3*Parameters!C3 -> 9.98 | F4: kWh
B5: input | C5: Technosphere flow | D5: Water
B6: output | C6: Intermediate flow | D6: Pretreated biowaste | E6: =E3*Parameters!C5 -> 0.77 | F6: t
A7: Incineration | B7: input | C7: Intermediate flow | D7: discarded biowaste | E7: =E3*(1-Parameters!C5)*1000 -> 230 | F7: kg
A8: AD | B8: input | C8: Intermediate flow | D8: Pretreated waste | E8: =E6 -> 0.77 | F8: t
B9: input | C9: Intermediate flow | D9: Electricity | E9: =Parameters!C14*E8 -> 22.33 | F9: kWh
B10: input | C10: Intermediate flow | D10: Heat | E10: =E8*Parameters!C15 -> 227.15 | F10: MJ
B11: output | C11: Elementary flow | D11: Methane | E11: =Parameters!C9*(Parameters!C7*(1-Waste_characteristics!B4))*E8*Parameters!C11*0.001 -> 1.5118454 | F11: kg
B12: output | C12: Intermediate flow | D12: Biogas | E12: =(((Parameters!C7*(1-Waste_characteristics!B4))/Parameters!C10)*0.001)-((E11/Parameters!C11)*(1/Parameters!C10)) -> 223.74985 | F12: m3
B13: output | C13: Technosphere flow | D13: Digestate | E13: =Parameters!C66 -> 0.5558219 | F13: t
A14: Biogas upgrading | B14: input | C14: Technosphere flow | D14: Biogas | E14: =E12 -> 223.74985 | F14: m3
B15: output | C15: Elementary flow | D15: CO2 | E15: =E14*(1-Parameters!C10)*Parameters!C47*Parameters!C12 -> 174.55173 | F15: kg
B16: output | C16: Elementary flow | D16: CH4 | E16: =E14*Parameters!C10*Parameters!C48*Parameters!C11 -> 1.7398788 | F16: kg
B17: output | C17: Elementary flow | D17: H2S | E17: =Parameters!C49*E14 -> 0.0013424991 | F17: kg
B18: output | C18: Elementary flow | D18: Sox | E18: =E14*Parameters!C50 -> 0.001476749 | F18: kg
B19: input | C19: Technosphere flow | D19: Electricity requirement | E19: =E14*Parameters!C51 -> 76.074947 | F19: kWh
B20: input | C20: Technosphere flow | D20: Activated carbon | E20: =E14*Parameters!C52 -> 0.19913736 | F20: kg
B21: input | C21: Technosphere flow | D21: Zeolite | E21: =E14*Parameters!C53 -> 2.6626232 | F21: kg
B22: output | C22: Technosphere flow | D22: Biomethane | E22: =(E14*Parameters!C10*(1-Parameters!C48)) -> 131.83341 | F22: m3
A23: Storage | B23: input | C23: Technosphere flow | D23: Digestate | E23: =E13 -> 0.5558219 | F23: t
B24: output | C24: Elementary flow | D24: CH4 | E24: =Parameters!C74*1000 -> 1.7377103 | F24: kg
B25: output | C25: Technosphere flow | D25: Digestate after storage | E25: =E23-(E24*0.001) -> 0.55408419 | F25: t
A26: Land application of digestate | B26: input | C26: Technosphere flow | D26: Digestate after storage | E26: =E24-(E25*0.001) -> 1.7371563 | F26: t
B27: output | C27: Elementary flow | D27: N2O | E27: =Waste_characteristics!B3*Parameters!C5*(1-Waste_characteristics!B4)*Waste_characteristics!B8*Parameters!C78*(44/28)*1000 -> 0.18825189 | F27: kg
B28: output | C28: Elementary flow | D28: NH3 | E28: =Waste_characteristics!B3*Parameters!C5*(1-Waste_characteristics!B4)*Waste_characteristics!B8*Parameters!C79*(17/14)*1000 -> 4.4759191 | F28: kg
B29: output | C29: Elementary flow | D29: NO3 | E29: =Waste_characteristics!B3*Parameters!C5*(1-Waste_characteristics!B4)*Waste_characteristics!B8*Parameters!C80*(62/14)*1000 -> 6.1214777 | F29: kg

Sheet LCI_AD-d
A1: AD+injection+Composting of digestate
A2: Process | B2: Flow direction | C2: Flow type | D2: Flow name | E2: Value | F2: Unit
A3: Pretreatment | B3: input | C3: Technosphere flow | D3: Waste | E3: 1 | F3: t
B4: input | C4: Technosphere flow | D4: Electricity | E4: =E3*Parameters!C3 -> 9.98 | F4: kWh
B5: input | C5: Technosphere flow | D5: Water
B6: output | C6: Intermediate flow | D6: Pretreated biowaste | E6: =E3*Parameters!C5 -> 0.77 | F6: t
A7: Incineration | B7: input | C7: Intermediate flow | D7: discarded biowaste | E7: =E3*(1-Parameters!C5)*1000 -> 230 | F7: kg
A8: AD | B8: input | C8: Intermediate flow | D8: Pretreated waste | E8: =E6 -> 0.77 | F8: t
B9: input | C9: Intermediate flow | D9: Electricity | E9: =Parameters!C14*E8 -> 22.33 | F9: kWh
B10: input | C10: Intermediate flow | D10: Heat | E10: =E8*Parameters!C15 -> 227.15 | F10: MJ
B11: output | C11: Elementary flow | D11: Methane | E11: =Parameters!C9*(Parameters!C7*(1-Waste_characteristics!B4))*E8*Parameters!C11*0.001 -> 1.5118454 | F11: kg
B12: output | C12: Intermediate flow | D12: Biogas | E12: =(((Parameters!C7*(1-Waste_characteristics!B4))/Parameters!C10)*0.001)-((E11/Parameters!C11)*(1/Parameters!C10)) -> 223.74985 | F12: m3
B13: output | C13: Technosphere flow | D13: Digestate | E13: =Parameters!C66 -> 0.5558219 | F13: t
A14: Biogas upgrading | B14: input | C14: Technosphere flow | D14: Biogas | E14: =E12 -> 223.74985 | F14: m3
B15: output | C15: Elementary flow | D15: CO2 | E15: =E14*(1-Parameters!C10)*Parameters!C47*Parameters!C12 -> 174.55173 | F15: kg
B16: output | C16: Elementary flow | D16: CH4 | E16: =E14*Parameters!C10*Parameters!C48*Parameters!C11 -> 1.7398788 | F16: kg
B17: output | C17: Elementary flow | D17: H2S | E17: =Parameters!C49*E14 -> 0.0013424991 | F17: kg
B18: output | C18: Elementary flow | D18: Sox | E18: =E14*Parameters!C50 -> 0.001476749 | F18: kg
B19: input | C19: Technosphere flow | D19: Electricity requirement | E19: =E14*Parameters!C51 -> 76.074947 | F19: kWh
B20: input | C20: Technosphere flow | D20: Activated carbon | E20: =E14*Parameters!C52 -> 0.19913736 | F20: kg
B21: input | C21: Technosphere flow | D21: Zeolite | E21: =E14*Parameters!C53 -> 2.6626232 | F21: kg
B22: output | C22: Technosphere flow | D22: Biomethane | E22: =(E14*Parameters!C10*(1-Parameters!C48)) -> 131.83341 | F22: m3
A23: Dewatering | B23: input | C23: Technosphere flow | D23: Digestate | E23: =E13 -> 0.5558219 | F23: t
B24: input | C24: Technosphere flow | D24: electricity | E24: =E23*Parameters!C84*1000 -> 2.0184752 | F24: kWh
B25: output | C25: Technosphere flow | D25: dewatered digestate | E25: =Parameters!C68*Parameters!C82*(1/Parameters!C83) -> 0.2970039 | F25: t
B26: output | C26: Technosphere flow | D26: wastewater | E26: =(E23-E25)*1000/Parameters!C70 -> 0.25911227 | F26: m3
A27: Composting of digestate | B27: input | C27: Technosphere flow | D27: dewatered digestate | E27: =E25 -> 0.2970039 | F27: t
B28: output | C28: Elementary flow | D28: CH4 | E28: =(16/12)*Parameters!C91*(1-Parameters!C88)*((E6*1000*(1-Waste_characteristics!B4)*Waste_characteristics!B9)-((E12*(1-Parameters!C10)*Parameters!C12*(12/44)))-((E12*(Parameters!C10)*Parameters!C11*(12/16)))) -> 0.088228561 | F28: kg
B29: output | C29: Elementary flow | D29: N2O | E29: =(E6*1000*(1-Waste_characteristics!B4)*Waste_characteristics!B8)*(1-Parameters!C85)*Parameters!C92*(44/28) -> 0.062318617 | F29: kg
B30: output | C30: Elementary flow | D30: NH3 | E30: =(E6*1000*(1-Waste_characteristics!B4)*Waste_characteristics!B8)*(1-Parameters!C85)*Parameters!C93*(17/14) -> 0.20275914 | F30: kg
B31: output | C31: Elementary flow | D31: NMVOC | E31: =E27*Parameters!C94 -> 0.030888406 | F31: kg
B32: output | C32: Elementary flow | D32: CO | E32: =(44/12)*Parameters!C95*(1-Parameters!C88)*((E6*1000*(1-Waste_characteristics!B4)*Waste_characteristics!B9)-((E13*(1-Parameters!C10)*Parameters!C12*(12/44)))-((E13*(Parameters!C10)*Parameters!C11*(12/16)))) -> 0.12509677 | F32: kg
B33: output | C33: Technosphere flow | D33: compost | E33: =E27*(1-Parameters!C96) -> 0.15444203 | F33: t
B34: input | C34: Technosphere flow | D34: electricity | E34: =E27*Parameters!C97 -> 3.1254739 | F34: kWh
B35: input | C35: Technosphere flow | D35: diesel | E35: =E27*Parameters!C98*Parameters!C99 -> 0.44883056 | F35: kg
A36: Land application of compost

Sheet LCI_AD-b
A1: AD+CHP+Composting
A2: Process | B2: Flow direction | C2: Flow type | D2: Flow name | E2: Value | F2: Unit
A3: Pretreatment | B3: input | C3: Technosphere flow | D3: Waste | E3: 1 | F3: t
B4: input | C4: Technosphere flow | D4: Electricity | E4: =E3*Parameters!C3 -> 9.98 | F4: kWh
B5: input | C5: Technosphere flow | D5: Water
B6: output | C6: Intermediate flow | D6: Pretreated biowaste | E6: =E3*Parameters!C5 -> 0.77 | F6: t
A7: Incineration | B7: input | C7: Intermediate flow | D7: discarded biowaste | E7: =E3*(1-Parameters!C5)*1000 -> 230 | F7: kg
A8: AD | B8: input | C8: Intermediate flow | D8: Pretreated waste | E8: =E6 -> 0.77 | F8: t
B9: input | C9: Intermediate flow | D9: Electricity | E9: =Parameters!C14*E8 -> 22.33 | F9: kWh
B10: input | C10: Intermediate flow | D10: Heat | E10: =E8*Parameters!C15 -> 227.15 | F10: MJ
B11: output | C11: Elementary flow | D11: Methane | E11: =Parameters!C9*(Parameters!C7*(1-Waste_characteristics!B4))*E8*Parameters!C11*0.001 -> 1.5118454 | F11: kg
B12: output | C12: Intermediate flow | D12: Biogas | E12: =(((Parameters!C7*(1-Waste_characteristics!B4))/Parameters!C10)*0.001)-((E11/Parameters!C11)*(1/Parameters!C10)) -> 223.74985 | F12: m3
B13: output | C13: Technosphere flow | D13: Digestate | E13: =Parameters!C66 -> 0.5558219 | F13: t
A14: CHP | B14: input | C14: Intermediate flow | D14: Biogas | E14: =E12 -> 223.74985 | F14: m3
B15: output | C15: Elementary flow | D15: Nitrogen Oxides (NOx) | E15: =E14*Parameters!C24 -> 0.036718365 | F15: kg
B16: output | C16: Elementary flow | D16: Volatile Organic Compounds (VOCs) | E16: =E14*Parameters!C25 -> 0.3538951 | F16: kg
B17: output | C17: Elementary flow | D17: Sulfur Dioxide (SO2) | E17: =E14*Parameters!C26 -> 0.0031472884 | F17: kg
B18: output | C18: Elementary flow | D18: Particulate Matter (PM) | E18: =LCI!E14*Parameters!C27 -> 0.0076933718 | F18: kg
B19: output | C19: Elementary flow | D19: Carbon Monoxide (CO) | E19: =E14*Parameters!C28 -> 0.23901907 | F19: kg
B20: output | C20: Elementary flow | D20: Ammonia (NH3) | E20: =E14*Parameters!C29 -> 0.014337647 | F20: kg
B21: output | C21: Elementary flow | D21: Methane (CH4) | E21: =E14*Parameters!C30 -> 0.96288796 | F21: kg
B22: output | C22: Elementary flow | D22: Nitrous Oxide (N2O) | E22: =LCI!E14*Parameters!C31 -> 0.022925904 | F22: kg
B23: output | C23: Technosphere flow | D23: Electricity | E23: =E14*Parameters!C10*Parameters!C20*Parameters!C19/3.6 -> 509.0309 | F23: kWh
B24: output | C24: Technosphere flow | D24: Heat | E24: =E14*Parameters!C10*Parameters!C20*Parameters!C18 -> 2161.4235 | F24: MJ
A25: Dewatering | B25: input | C25: Technosphere flow | D25: Digestate | E25: =E13 -> 0.5558219 | F25: t
B26: input | C26: Technosphere flow | D26: electricity | E26: =E25*Parameters!C84*1000 -> 2.0184752 | F26: kWh
B27: output | C27: Technosphere flow | D27: dewatered digestate | E27: =Parameters!C68*Parameters!C82*(1/Parameters!C83) -> 0.2970039 | F27: t
B28: output | C28: Technosphere flow | D28: wastewater | E28: =(E25-E27)*1000/Parameters!C70 -> 0.25911227 | F28: m3
A29: Composting of digestate | B29: input | C29: Technosphere flow | D29: dewatered digestate | E29: =E27 -> 0.2970039 | F29: t
B30: output | C30: Elementary flow | D30: CH4 | E30: =(16/12)*Parameters!C91*(1-Parameters!C88)*((E6*1000*(1-Waste_characteristics!B4)*Waste_characteristics!B9)-((E12*(1-Parameters!C10)*Parameters!C12*(12/44)))-((E12*(Parameters!C10)*Parameters!C11*(12/16)))) -> 0.088228561 | F30: kg | H30: Cinit - C(CO2,CH4 in biogas) - C lost in water fraction of digestate
B31: output | C31: Elementary flow | D31: N2O | E31: =(E6*1000*(1-Waste_characteristics!B4)*Waste_characteristics!B8)*(1-Parameters!C85)*Parameters!C92*(44/28) -> 0.062318617 | F31: kg
B32: output | C32: Elementary flow | D32: NH3 | E32: =(E6*1000*(1-Waste_characteristics!B4)*Waste_characteristics!B8)*(1-Parameters!C85)*Parameters!C93*(17/14) -> 0.20275914 | F32: kg
B33: output | C33: Elementary flow | D33: NMVOC | E33: =E29*Parameters!C94 -> 0.030888406 | F33: kg
B34: output | C34: Elementary flow | D34: CO | E34: =(44/12)*Parameters!C95*(1-Parameters!C88)*((E6*1000*(1-Waste_characteristics!B4)*Waste_characteristics!B9)-((E13*(1-Parameters!C10)*Parameters!C12*(12/44)))-((E13*(Parameters!C10)*Parameters!C11*(12/16)))) -> 0.12509677 | F34: kg
B35: output | C35: Technosphere flow | D35: compost | E35: =E29*(1-Parameters!C96) -> 0.15444203 | F35: t
B36: input | C36: Technosphere flow | D36: electricity | E36: =E29*Parameters!C97 -> 3.1254739 | F36: kWh
B37: input | C37: Technosphere flow | D37: diesel | E37: =E29*Parameters!C98*Parameters!C99 -> 0.44883056 | F37: kg
A38: Land application of compost

Sheet params_HC
B2: Technology | I2: Pretratment technology
B3: Pretreatement technology | C3: 1 | D3: (don't select if home composting) | I3: 0 | J3: None
B4: Ratio Biowaste/WC | C4: 8_1 | I4: 1 | J4: Drum-screen + Shredder + Piston press
B5: Aeration mode for industrial composting | C5: Active | D5: (don't select if home composting) | I5: 2 | J5: Shredder + Piston press + Screw press
B6: Distance of biowaste collection | C6: 20 | D6: km | I6: 3 | J6: Separation-mill
B7: Distance of compost transport from composting site to land | C7: 20 | D7: km | I7: 4 | J7: Pulp + Drum-screen

Sheet LCI_HC
A1: Home Composting
A2: Process | B2: Flow direction | C2: Flow type | D2: Flow name | E2: Value | F2: Unit
A3: Home composting | B3: input | C3: Technosphere flow | D3: Waste | E3: 1 | F3: t
B4: output | C4: Elementary flow | D4: CH4 | E4: =[3]LCI!$B$4*1000 -> 0.34805 | F4: kg | G4: data from PaCTEA
B5: output | C5: Elementary flow | D5: N2O | E5: =[3]LCI!$B$6*1000 -> 0.070149 | F5: kg | G5: data from PaCTEA
B6: output | C6: Elementary flow | D6: NH3 | E6: =[3]LCI!$B$5*1000 -> 0.064732 | F6: kg | G6: data from PaCTEA
B7: input | C7: Technosphere flow | D7: Wood chips consumption | E7: =E3*(1/8)*1000 -> 125 | F7: kg | G7: data from PaCTEA
A8: Land application
B9: output | C9: Elementary flow | D9: NH3 | E9: =[3]LCI!$C$18*1000 -> 0.36486015 | F9: kg | G9: data from PaCTEA
B10: output | C10: Elementary flow | D10: N2O | E10: =[3]LCI!$C$19*1000 -> 0.13095325 | F10: kg | G10: data from PaCTEA
B11: output | C11: Elementary flow | D11: NO3 | E11: =[3]LCI!$C$20*1000 -> 13.608329 | F11: kg | G11: data from PaCTEA
B12: output | C12: Elementary flow | D12: (PO4)3- | E12: =[3]LCI!$C$22*1000 -> -0.08127857 | F12: kg | G12: data from PaCTEA
B13: output | C13: Elementary flow | D13: CO2 fossil | E13: =[3]LCI!$C$26*1000 -> -356.4 | F13: kg | G13: data from PaCTEA
A14: Substitued products
C15: Technosphere flow | D15: N-fertilizer | E15: =0.0116046876865655*1000 -> 11.604688 | F15: kg | G15: data from PaCTEA
C16: Technosphere flow | D16: P-fertilizer | E16: =0.00342132225661322*1000 -> 3.4213223 | F16: kg | G16: data from PaCTEA
C17: Technosphere flow | D17: K-fertilizer | E17: =0.00502189482738727*1000 -> 5.0218948 | F17: kg | G17: data from PaCTEA
C18: Technosphere flow | D18: Peat | E18: =0.438311688311688*1000 -> 438.31169 | F18: kg | G18: data from PaCTEA

Sheet LCIA_HC
A2: RECIPE - MIDPOINT
A3: Process | C3: acidification: terrestrial - terrestrial acidification potential (TAP) | D3: climate change - global warming potential (GWP100) | E3: ecotoxicity: freshwater - freshwater ecotoxicity potential (FETP) | F3: ecotoxicity: marine - marine ecotoxicity potential (METP) | G3: ecotoxicity: terrestrial - terrestrial ecotoxicity potential (TETP) | H3: energy resources: non-renewable, fossil - fossil fuel potential (FFP) | I3: eutrophication: freshwater - freshwater eutrophication potential (FEP) | J3: eutrophication: marine - marine eutrophication potential (MEP) | K3: human toxicity: carcinogenic - human toxicity potential (HTPc) | L3: human toxicity: non-carcinogenic - human toxicity potential (HTPnc) | M3: ionising radiation - ionising radiation potential (IRP) | N3: land use - agricultural land occupation (LOP) | O3: material resources: metals/minerals - surplus ore potential (SOP) | P3: ozone depletion - ozone depletion potential (ODPinfinite) | Q3: particulate matter formation - particulate matter formation potential (PMFP) | R3: photochemical oxidant formation: human health - photochemical oxidant formation potential: humans (HOFP) | S3: photochemical oxidant formation: terrestrial ecosystems - photochemical oxidant formation potential: ecosystems (EOFP) | T3: water use - water consumption potential (WCP)
A4: Composting | C4: =SUM(C5:C7) -> 0.12687472 | D4: =SUM(D5:D7) -> 32.738102 | E4: =SUM(E5:E7) -> 0 | F4: =SUM(F5:F7) -> 0 | G4: =SUM(G5:G7) -> 0 | H4: =SUM(H5:H7) -> 0 | I4: =SUM(I5:I7) -> 0 | J4: =SUM(J5:J7) -> 0 | ... T4: =SUM(T5:T7) -> 0
B5: CH4 | C5: =LCI_HC!$E4*impact_process_mid!C11 -> 0 | D5: =LCI_HC!$E4*impact_process_mid!D11 -> 11.8337 | E5: =LCI_HC!$E4*impact_process_mid!E11 -> 0 | F5: =LCI_HC!$E4*impact_process_mid!F11 -> 0 | G5: =LCI_HC!$E4*impact_process_mid!G11 -> 0 | H5: =LCI_HC!$E4*impact_process_mid!H11 -> 0 | I5: =LCI_HC!$E4*impact_process_mid!I11 -> 0 | J5: =LCI_HC!$E4*impact_process_mid!J11 -> 0 | ... T5: =LCI_HC!$E4*impact_process_mid!T11 -> 0
B6: NH3 | C6: =LCI_HC!$E6*impact_process_mid!C17 -> 0.12687472 | D6: =LCI_HC!$E6*impact_process_mid!D17 -> 0 | E6: =LCI_HC!$E6*impact_process_mid!E17 -> 0 | F6: =LCI_HC!$E6*impact_process_mid!F17 -> 0 | G6: =LCI_HC!$E6*impact_process_mid!G17 -> 0 | H6: =LCI_HC!$E6*impact_process_mid!H17 -> 0 | I6: =LCI_HC!$E6*impact_process_mid!I17 -> 0 | J6: =LCI_HC!$E6*impact_process_mid!J17 -> 0 | ... T6: =LCI_HC!$E6*impact_process_mid!T17 -> 0
B7: N2O | C7: =LCI_HC!$E5*impact_process_mid!C19 -> 0 | D7: =LCI_HC!$E5*impact_process_mid!D19 -> 20.904402 | E7: =LCI_HC!$E5*impact_process_mid!E19 -> 0 | F7: =LCI_HC!$E5*impact_process_mid!F19 -> 0 | G7: =LCI_HC!$E5*impact_process_mid!G19 -> 0 | H7: =LCI_HC!$E5*impact_process_mid!H19 -> 0 | I7: =LCI_HC!$E5*impact_process_mid!I19 -> 0 | J7: =LCI_HC!$E5*impact_process_mid!J19 -> 0 | ... T7: =LCI_HC!$E5*impact_process_mid!T19 -> 0
B8: Wood chips | C8: =LCI_HC!$E7*impact_process_mid!C33 -> 0.014295467 | D8: =LCI_HC!$E7*impact_process_mid!D33 -> 5.7556617 | E8: =LCI_HC!$E7*impact_process_mid!E33 -> 0.12930887 | F8: =LCI_HC!$E7*impact_process_mid!F33 -> 0.20158553 | G8: =LCI_HC!$E7*impact_process_mid!G33 -> 57.734745 | H8: =LCI_HC!$E7*impact_process_mid!H33 -> 1.7373117 | I8: =LCI_HC!$E7*impact_process_mid!I33 -> 0.0019765582 | J8: =LCI_HC!$E7*impact_process_mid!J33 -> 0.00031560347 | ... T8: =LCI_HC!$E7*impact_process_mid!T33 -> 0.026932346
A9: Land application
A13: RECIPE - ENDPOINT
A14: Process | C14: ecosystem quality - acidification: terrestrial | D14: ecosystem quality - climate change: freshwater ecosystems | E14: ecosystem quality - climate change: terrestrial ecosystems | F14: ecosystem quality - ecotoxicity: freshwater | G14: ecosystem quality - ecotoxicity: marine | H14: ecosystem quality - ecotoxicity: terrestrial | I14: ecosystem quality - eutrophication: freshwater | J14: ecosystem quality - eutrophication: marine | K14: ecosystem quality - land use | L14: ecosystem quality - photochemical oxidant formation: terrestrial ecosystems | M14: ecosystem quality - water use: aquatic ecosystems | N14: ecosystem quality - water use: terrestrial ecosystems | O14: human health - climate change: human health | P14: human health - human toxicity: carcinogenic | Q14: human health - human toxicity: non-carcinogenic | R14: human health - ionising radiation | S14: human health - ozone depletion | T14: human health - particulate matter formation | U14: human health - photochemical oxidant formation: human health | V14: human health - water use: human health | W14: natural resources - energy resources: non-renewable, fossil | X14: natural resources - material resources: metals/minerals | Y14: total: ecosystem quality - ecosystem quality | Z14: total: human health - human health | AA14: total: natural resources - natural resources
A15: Composting
B16: CH4 | C16: =LCI_HC!$E4*impact_process_end!C11 -> 0 | D16: =LCI_HC!$E4*impact_process_end!D11 -> 9.0493e-13 | E16: =LCI_HC!$E4*impact_process_end!E11 -> 3.313436e-08 | F16: =LCI_HC!$E4*impact_process_end!F11 -> 0 | G16: =LCI_HC!$E4*impact_process_end!G11 -> 0 | H16: =LCI_HC!$E4*impact_process_end!H11 -> 0 | I16: =LCI_HC!$E4*impact_process_end!I11 -> 0 | J16: =LCI_HC!$E4*impact_process_end!J11 -> 0 | ... AA16: =LCI_HC!$E4*impact_process_end!AA11 -> 0
B17: NH3 | C17: =LCI_HC!$E6*impact_process_end!C17 -> 2.6928512e-08 | D17: =LCI_HC!$E6*impact_process_end!D17 -> 0 | E17: =LCI_HC!$E6*impact_process_end!E17 -> 0 | F17: =LCI_HC!$E6*impact_process_end!F17 -> 0 | G17: =LCI_HC!$E6*impact_process_end!G17 -> 0 | H17: =LCI_HC!$E6*impact_process_end!H17 -> 0 | I17: =LCI_HC!$E6*impact_process_end!I17 -> 0 | J17: =LCI_HC!$E6*impact_process_end!J17 -> 0 | ... AA17: =LCI_HC!$E6*impact_process_end!AA17 -> 0
B18: N2O | C18: =LCI_HC!$E5*impact_process_end!C19 -> 0 | D18: =LCI_HC!$E5*impact_process_end!D19 -> 1.5993972e-12 | E18: =LCI_HC!$E5*impact_process_end!E19 -> 5.8504266e-08 | F18: =LCI_HC!$E5*impact_process_end!F19 -> 0 | G18: =LCI_HC!$E5*impact_process_end!G19 -> 0 | H18: =LCI_HC!$E5*impact_process_end!H19 -> 0 | I18: =LCI_HC!$E5*impact_process_end!I19 -> 0 | J18: =LCI_HC!$E5*impact_process_end!J19 -> 0 | ... AA18: =LCI_HC!$E5*impact_process_end!AA19 -> 0
B19: Wood chips | C19: =LCI_HC!$E7*impact_process_end!C33 -> 3.030288e-09 | D19: =LCI_HC!$E7*impact_process_end!D33 -> 4.4028427e-13 | E19: =LCI_HC!$E7*impact_process_end!E33 -> 1.6121281e-08 | F19: =LCI_HC!$E7*impact_process_end!F33 -> 8.9550842e-11 | G19: =LCI_HC!$E7*impact_process_end!G33 -> 2.1182825e-11 | H19: =LCI_HC!$E7*impact_process_end!H33 -> 6.5822853e-10 | I19: =LCI_HC!$E7*impact_process_end!I33 -> 1.3248147e-09 | J19: =LCI_HC!$E7*impact_process_end!J33 -> 5.3657236e-13 | ... AA19: =LCI_HC!$E7*impact_process_end!AA33 -> 0.7227007
A28: IMPACT WORLD + ENDPOINT
A29: Process | C29: Climate change, ecosystem quality, long term | D29: Climate change, ecosystem quality, short term | E29: Climate change, human health, long term | F29: Climate change, human health, short term | G29: Fisheries impact | H29: Freshwater acidification | I29: Freshwater ecotoxicity, long term | J29: Freshwater ecotoxicity, short term | K29: Freshwater eutrophication | L29: Human toxicity cancer, long term | M29: Human toxicity cancer, short term | N29: Human toxicity non-cancer, long term | O29: Human toxicity non-cancer, short term | P29: Ionizing radiations, ecosystem quality | Q29: Ionizing radiations, human health | R29: Land occupation, biodiversity | S29: Land transformation, biodiversity | T29: Marine acidification, long term | U29: Marine acidification, short term | V29: Marine ecotoxicity, long term | W29: Marine ecotoxicity, short term | X29: Marine eutrophication | Y29: Ozone layer depletion | Z29: Particulate matter formation | AA29: Photochemical ozone formation, ecosystem quality | AB29: Photochemical ozone formation, human health | AC29: Terrestrial acidification | AD29: Terrestrial ecotoxicity, long term | AE29: Terrestrial ecotoxicity, short term | AF29: Thermally polluted water | AG29: Total ecosystem quality | AH29: Total human health | AI29: Water availability, freshwater ecosystem | AJ29: Water availability, human health | AK29: Water availability, terrestrial ecosystem
A30: Composting | C30: =SUM(C31:C34) -> 5.9124722 | D30: =SUM(D31:D34) -> 4.1174273 | E30: =SUM(E31:E34) -> 7.9682226e-05 | F30: =SUM(F31:F34) -> 5.5490464e-05 | G30: =SUM(G31:G34) -> 5.6277794e-18 | H30: =SUM(H31:H34) -> 0.15195189 | I30: =SUM(I31:I34) -> 0.51155103 | J30: =SUM(J31:J34) -> 0.087051064 | ... AK30: =SUM(AK31:AK34) -> 0.00034125772
B31: CH4 | C31: =LCI_HC!$E4*'IW+_end'!C12 -> 0.21593705 | D31: =LCI_HC!$E4*'IW+_end'!D12 -> 0.82011228 | E31: =LCI_HC!$E4*'IW+_end'!E12 -> 2.9101777e-06 | F31: =LCI_HC!$E4*'IW+_end'!F12 -> 1.1052641e-05 | G31: =LCI_HC!$E4*'IW+_end'!G12 -> 0 | H31: =LCI_HC!$E4*'IW+_end'!H12 -> 0 | I31: =LCI_HC!$E4*'IW+_end'!I12 -> 0 | J31: =LCI_HC!$E4*'IW+_end'!J12 -> 0 | ... AK31: =LCI_HC!$E4*'IW+_end'!AK12 -> 0
B32: NH3 | C32: =LCI_HC!$E6*'IW+_end'!C18 -> 0 | D32: =LCI_HC!$E6*'IW+_end'!D18 -> 0 | E32: =LCI_HC!$E6*'IW+_end'!E18 -> 0 | F32: =LCI_HC!$E6*'IW+_end'!F18 -> 0 | G32: =LCI_HC!$E6*'IW+_end'!G18 -> 0 | H32: =LCI_HC!$E6*'IW+_end'!H18 -> 0.11954159 | I32: =LCI_HC!$E6*'IW+_end'!I18 -> 0 | J32: =LCI_HC!$E6*'IW+_end'!J18 -> 0 | ... AK32: =LCI_HC!$E6*'IW+_end'!AK18 -> 0
B33: N2O | C33: =LCI_HC!$E5*'IW+_end'!C20 -> 3.5672544 | D33: =LCI_HC!$E5*'IW+_end'!D20 -> 2.6464982 | E33: =LCI_HC!$E5*'IW+_end'!E20 -> 4.8075789e-05 | F33: =LCI_HC!$E5*'IW+_end'!F20 -> 3.5666784e-05 | G33: =LCI_HC!$E5*'IW+_end'!G20 -> 0 | H33: =LCI_HC!$E5*'IW+_end'!H20 -> 0 | I33: =LCI_HC!$E5*'IW+_end'!I20 -> 0 | J33: =LCI_HC!$E5*'IW+_end'!J20 -> 0 | ... AK33: =LCI_HC!$E5*'IW+_end'!AK20 -> 0
B34: Wood chips | C34: =LCI_HC!$E7*'IW+_end'!C35 -> 2.1292808 | D34: =LCI_HC!$E7*'IW+_end'!D35 -> 0.65081677 | E34: =LCI_HC!$E7*'IW+_end'!E35 -> 2.8696259e-05 | F34: =LCI_HC!$E7*'IW+_end'!F35 -> 8.7710397e-06 | G34: =LCI_HC!$E7*'IW+_end'!G35 -> 5.6277794e-18 | H34: =LCI_HC!$E7*'IW+_end'!H35 -> 0.032410306 | I34: =LCI_HC!$E7*'IW+_end'!I35 -> 0.51155103 | J34: =LCI_HC!$E7*'IW+_end'!J35 -> 0.087051064 | ... AK34: =LCI_HC!$E7*'IW+_end'!AK35 -> 0.00034125772
A35: Land application | C35: =SUM(C36:C40) -> -141.54374 | D35: =SUM(D36:D40) -> -37.189591 | E35: =SUM(E36:E40) -> -0.0019075811 | F35: =SUM(F36:F40) -> -0.00050120309 | G35: =SUM(G36:G40) -> 0 | H35: =SUM(H36:H40) -> 0.6737929 | I35: =SUM(I36:I40) -> 0 | J35: =SUM(J36:J40) -> 1.5513495e-09 | ... AK35: =SUM(AK36:AK40) -> 0
B36: NH3 | C36: =LCI_HC!$E9*'IW+_end'!C18 -> 0 | D36: =LCI_HC!$E9*'IW+_end'!D18 -> 0 | E36: =LCI_HC!$E9*'IW+_end'!E18 -> 0 | F36: =LCI_HC!$E9*'IW+_end'!F18 -> 0 | G36: =LCI_HC!$E9*'IW+_end'!G18 -> 0 | H36: =LCI_HC!$E9*'IW+_end'!H18 -> 0.6737929 | I36: =LCI_HC!$E9*'IW+_end'!I18 -> 0 | J36: =LCI_HC!$E9*'IW+_end'!J18 -> 0 | ... AK36: =LCI_HC!$E9*'IW+_end'!AK18 -> 0
B37: N2O | C37: =LCI_HC!$E10*'IW+_end'!C20 -> 6.6593046 | D37: =LCI_HC!$E10*'IW+_end'!D20 -> 4.9404488 | E37: =LCI_HC!$E10*'IW+_end'!E20 -> 8.9747264e-05 | F37: =LCI_HC!$E10*'IW+_end'!F20 -> 6.6582292e-05 | G37: =LCI_HC!$E10*'IW+_end'!G20 -> 0 | H37: =LCI_HC!$E10*'IW+_end'!H20 -> 0 | I37: =LCI_HC!$E10*'IW+_end'!I20 -> 0 | J37: =LCI_HC!$E10*'IW+_end'!J20 -> 0 | ... AK37: =LCI_HC!$E10*'IW+_end'!AK20 -> 0
B38: NO3 | C38: =LCI_HC!$E11*impact_process_end!C20 -> 0 | D38: =LCI_HC!$E11*impact_process_end!D20 -> 0 | E38: =LCI_HC!$E11*impact_process_end!E20 -> 0 | F38: =LCI_HC!$E11*impact_process_end!F20 -> 0 | G38: =LCI_HC!$E11*impact_process_end!G20 -> 0 | H38: =LCI_HC!$E11*impact_process_end!H20 -> 0 | I38: =LCI_HC!$E11*impact_process_end!I20 -> 0 | J38: =LCI_HC!$E11*impact_process_end!J20 -> 1.5513495e-09 | ... AK38: =LCI_HC!$E11*impact_process_end!AK20 -> 0
B39: (PO4)3- | C39: =LCI_HC!$E12*'IW+_end'!C25 -> 0 | D39: =LCI_HC!$E12*'IW+_end'!D25 -> 0 | E39: =LCI_HC!$E12*'IW+_end'!E25 -> 0 | F39: =LCI_HC!$E12*'IW+_end'!F25 -> 0 | G39: =LCI_HC!$E12*'IW+_end'!G25 -> 0 | H39: =LCI_HC!$E12*'IW+_end'!H25 -> 0 | I39: =LCI_HC!$E12*'IW+_end'!I25 -> 0 | J39: =LCI_HC!$E12*'IW+_end'!J25 -> 0 | ... AK39: =LCI_HC!$E12*'IW+_end'!AK25 -> 0
B40: CO2 fossil | C40: =LCI_HC!$E13*'IW+_end'!C26 -> -148.20304 | D40: =LCI_HC!$E13*'IW+_end'!D26 -> -42.130039 | E40: =LCI_HC!$E13*'IW+_end'!E26 -> -0.0019973283 | F40: =LCI_HC!$E13*'IW+_end'!F26 -> -0.00056778538 | G40: =LCI_HC!$E13*'IW+_end'!G26 -> 0 | H40: =LCI_HC!$E13*'IW+_end'!H26 -> 0 | I40: =LCI_HC!$E13*'IW+_end'!I26 -> 0 | J40: =LCI_HC!$E13*'IW+_end'!J26 -> 0 | ... AK40: =LCI_HC!$E13*'IW+_end'!AK26 -> 0
A41: Substitued products | C41: =SUM(C42:C45) -> 9.8750277 | D41: =SUM(D42:D45) -> 3.3376956 | E41: =SUM(E42:E45) -> 0.00013308548 | F41: =SUM(F42:F45) -> 4.4982031e-05 | G41: =SUM(G42:G45) -> 6.537874e-17 | H41: =SUM(H42:H45) -> 0.20461159 | I41: =SUM(I42:I45) -> 2.1024818 | J41: =SUM(J42:J45) -> 0.51323165 | ... AK41: =SUM(AK42:AK45) -> 0.065338848
B42: N-fertilizer | C42: =LCI_HC!$E15*'IW+_end'!C28 -> 6.6748424 | D42: =LCI_HC!$E15*'IW+_end'!D28 -> 2.1502978 | E42: =LCI_HC!$E15*'IW+_end'!E28 -> 8.9956668e-05 | F42: =LCI_HC!$E15*'IW+_end'!F28 -> 2.8979505e-05 | G42: =LCI_HC!$E15*'IW+_end'!G28 -> 4.6292153e-17 | H42: =LCI_HC!$E15*'IW+_end'!H28 -> 0.10295073 | I42: =LCI_HC!$E15*'IW+_end'!I28 -> 0.85618657 | J42: =LCI_HC!$E15*'IW+_end'!J28 -> 0.2846082 | ... AK42: =LCI_HC!$E15*'IW+_end'!AK28 -> 0.00037409426
B43: P-fertilizer | C43: =LCI_HC!$E16*'IW+_end'!C30 -> 0.51520429 | D43: =LCI_HC!$E16*'IW+_end'!D30 -> 0.15469606 | E43: =LCI_HC!$E16*'IW+_end'!E30 -> 6.943394e-06 | F43: =LCI_HC!$E16*'IW+_end'!F30 -> 2.0848345e-06 | G43: =LCI_HC!$E16*'IW+_end'!G30 -> 7.8331901e-18 | H43: =LCI_HC!$E16*'IW+_end'!H30 -> 0.048015645 | I43: =LCI_HC!$E16*'IW+_end'!I30 -> 0.25144538 | J43: =LCI_HC!$E16*'IW+_end'!J30 -> 0.023061628 | ... AK43: =LCI_HC!$E16*'IW+_end'!AK30 -> 0.0003676824
B44: K-fertilizer | C44: =LCI_HC!$E17*'IW+_end'!C29 -> 1.2678328 | D44: =LCI_HC!$E17*'IW+_end'!D29 -> 0.38610408 | E44: =LCI_HC!$E17*'IW+_end'!E29 -> 1.7086547e-05 | F44: =LCI_HC!$E17*'IW+_end'!F29 -> 5.2035141e-06 | G44: =LCI_HC!$E17*'IW+_end'!G29 -> 1.040552e-17 | H44: =LCI_HC!$E17*'IW+_end'!H29 -> 0.024554953 | I44: =LCI_HC!$E17*'IW+_end'!I29 -> 0.66390176 | J44: =LCI_HC!$E17*'IW+_end'!J29 -> 0.069057075 | ... AK44: =LCI_HC!$E17*'IW+_end'!AK29 -> 7.7608836e-05
B45: Peat | C45: =LCI_HC!$E18*'IW+_end'!C31 -> 1.4171482 | D45: =LCI_HC!$E18*'IW+_end'!D31 -> 0.64659756 | E45: =LCI_HC!$E18*'IW+_end'!E31 -> 1.9098867e-05 | F45: =LCI_HC!$E18*'IW+_end'!F31 -> 8.7141775e-06 | G45: =LCI_HC!$E18*'IW+_end'!G31 -> 8.4787653e-19 | H45: =LCI_HC!$E18*'IW+_end'!H31 -> 0.029090269 | I45: =LCI_HC!$E18*'IW+_end'!I31 -> 0.33094813 | J45: =LCI_HC!$E18*'IW+_end'!J31 -> 0.13650474 | ... AK45: =LCI_HC!$E18*'IW+_end'!AK31 -> 0.064519463
A48: IMPACT WORLD + MIDPOINT
A49: Process | C49: Climate change, long term | D49: Climate change, short term | E49: Fossil and nuclear energy use | F49: Freshwater acidification | G49: Freshwater ecotoxicity | H49: Freshwater eutrophication | I49: Human toxicity cancer | J49: Human toxicity non-cancer | K49: Ionizing radiations | L49: Land occupation, biodiversity | M49: Land transformation, biodiversity | N49: Marine eutrophication | O49: Mineral resources use | P49: Ozone layer depletion | Q49: Particulate matter formation | R49: Photochemical ozone formation | S49: Terrestrial acidification | T49: Water scarcity
A50: Composting | C50: =SUM(C51:C54) -> 23.266495 | D50: =SUM(D51:D54) -> 34.264521 | E50: =SUM(E51:E54) -> 89.514107 | F50: =SUM(F51:F54) -> 0.05979692 | G50: =SUM(G51:G54) -> 1068.2938 | H50: =SUM(H51:H54) -> 0.005492882 | I50: =SUM(I51:I54) -> 1.1845593e-07 | J50: =SUM(J51:J54) -> 3.3416997e-07 | ... T50: =SUM(T51:T54) -> 1.4632062
B51: CH4 | C51: =LCI_HC!$E4*'IW+_mid'!C12 -> 1.635835 | D51: =LCI_HC!$E4*'IW+_mid'!D12 -> 9.39735 | E51: =LCI_HC!$E4*'IW+_mid'!E12 -> 0 | F51: =LCI_HC!$E4*'IW+_mid'!F12 -> 0 | G51: =LCI_HC!$E4*'IW+_mid'!G12 -> 0 | H51: =LCI_HC!$E4*'IW+_mid'!H12 -> 0 | I51: =LCI_HC!$E4*'IW+_mid'!I12 -> 0 | J51: =LCI_HC!$E4*'IW+_mid'!J12 -> 0 | ... T51: =LCI_HC!$E4*'IW+_mid'!T12 -> 0
B52: NH3 | C52: =LCI_HC!$E6*'IW+_mid'!C18 -> 0 | D52: =LCI_HC!$E6*'IW+_mid'!D18 -> 0 | E52: =LCI_HC!$E6*'IW+_mid'!E18 -> 0 | F52: =LCI_HC!$E6*'IW+_mid'!F18 -> 0.044981165 | G52: =LCI_HC!$E6*'IW+_mid'!G18 -> 0 | H52: =LCI_HC!$E6*'IW+_mid'!H18 -> 0 | I52: =LCI_HC!$E6*'IW+_mid'!I18 -> 0 | J52: =LCI_HC!$E6*'IW+_mid'!J18 -> 0 | ... T52: =LCI_HC!$E6*'IW+_mid'!T18 -> 0
B53: N2O | C53: =LCI_HC!$E5*'IW+_mid'!C20 -> 16.344717 | D53: =LCI_HC!$E5*'IW+_mid'!D20 -> 19.150677 | E53: =LCI_HC!$E5*'IW+_mid'!E20 -> 0 | F53: =LCI_HC!$E5*'IW+_mid'!F20 -> 0 | G53: =LCI_HC!$E5*'IW+_mid'!G20 -> 0 | H53: =LCI_HC!$E5*'IW+_mid'!H20 -> 0 | I53: =LCI_HC!$E5*'IW+_mid'!I20 -> 0 | J53: =LCI_HC!$E5*'IW+_mid'!J20 -> 0 | ... T53: =LCI_HC!$E5*'IW+_mid'!T20 -> 0
B54: Wood chips | C54: =LCI_HC!$E7*'IW+_mid'!C35 -> 5.2859429 | D54: =LCI_HC!$E7*'IW+_mid'!D35 -> 5.716494 | E54: =LCI_HC!$E7*'IW+_mid'!E35 -> 89.514107 | F54: =LCI_HC!$E7*'IW+_mid'!F35 -> 0.014815755 | G54: =LCI_HC!$E7*'IW+_mid'!G35 -> 1068.2938 | H54: =LCI_HC!$E7*'IW+_mid'!H35 -> 0.005492882 | I54: =LCI_HC!$E7*'IW+_mid'!I35 -> 1.1845593e-07 | J54: =LCI_HC!$E7*'IW+_mid'!J35 -> 3.3416997e-07 | ... T54: =LCI_HC!$E7*'IW+_mid'!T35 -> 1.4632062
...

Sheet LCI_AD-a
A1: AD+CHP+Digestate
A2: Process | B2: Flow direction | C2: Flow type | D2: Flow name | E2: Value | F2: Unit
A3: Pretreatment | B3: input | C3: Technosphere flow | D3: Waste | E3: 1 | F3: t
B4: input | C4: Technosphere flow | D4: Electricity | E4: =E3*Parameters!C3 -> 9.98 | F4: kWh
B5: input | C5: Technosphere flow | D5: Water
B6: output | C6: Intermediate flow | D6: Pretreated biowaste | E6: =E3*Parameters!C5 -> 0.77 | F6: t
A7: Incineration | B7: input | C7: Intermediate flow | D7: transported discarded biowaste | E7: =E8*0.001*Parameters!C6 -> 2.3 | F7: tkm
B8: input | C8: Intermediate flow | D8: discarded biowaste | E8: =E3*(1-Parameters!C5)*1000 -> 230 | F8: kg
A9: AD | B9: input | C9: Intermediate flow | D9: Pretreated waste | E9: =E6 -> 0.77 | F9: t
B10: input | C10: Intermediate flow | D10: Electricity | E10: =Parameters!C14*E9 -> 22.33 | F10: kWh
B11: input | C11: Intermediate flow | D11: Heat | E11: =E9*Parameters!C15 -> 227.15 | F11: MJ
B12: output | C12: Elementary flow | D12: Methane | E12: =Parameters!C9*(Parameters!C7*(1-Waste_characteristics!B4))*E9*Parameters!C11*0.001 -> 1.5118454 | F12: kg
B13: output | C13: Intermediate flow | D13: Biogas | E13: =(((Parameters!C7*(1-Waste_characteristics!B4))/Parameters!C10)*0.001)-((E12/Parameters!C11)*(1/Parameters!C10)) -> 223.74985 | F13: m3
B14: output | C14: Technosphere flow | D14: Digestate | E14: =Parameters!C66 -> 0.5558219 | F14: t
A15: CHP | B15: input | C15: Intermediate flow | D15: Biogas | E15: =E13 -> 223.74985 | F15: m3
B16: output | C16: Elementary flow | D16: Nitrogen Oxides (NOx) | E16: =E15*Parameters!C24 -> 0.036718365 | F16: kg
B17: output | C17: Elementary flow | D17: Volatile Organic Compounds (VOCs) | E17: =E15*Parameters!C25 -> 0.3538951 | F17: kg
B18: output | C18: Elementary flow | D18: Sulfur Dioxide (SO2) | E18: =E15*Parameters!C26 -> 0.0031472884 | F18: kg
B19: output | C19: Elementary flow | D19: Particulate Matter (PM) | E19: =LCI!E14*Parameters!C27 -> 0.0076933718 | F19: kg
B20: output | C20: Elementary flow | D20: Carbon Monoxide (CO) | E20: =E15*Parameters!C28 -> 0.23901907 | F20: kg
B21: output | C21: Elementary flow | D21: Ammonia (NH3) | E21: =E15*Parameters!C29 -> 0.014337647 | F21: kg
B22: output | C22: Elementary flow | D22: Methane (CH4) | E22: =E15*Parameters!C30 -> 0.96288796 | F22: kg
B23: output | C23: Elementary flow | D23: Nitrous Oxide (N2O) | E23: =LCI!E14*Parameters!C31 -> 0.022925904 | F23: kg
B24: output | C24: Technosphere flow | D24: Electricity | E24: =E15*Parameters!C10*Parameters!C20*Parameters!C19/3.6 -> 509.0309 | F24: kWh
B25: output | C25: Technosphere flow | D25: Heat | E25: =E15*Parameters!C10*Parameters!C20*Parameters!C18 -> 2161.4235 | F25: MJ
A26: Storage | B26: input | C26: Technosphere flow | D26: Digestate | E26: =E14 -> 0.5558219 | F26: t
B27: output | C27: Elementary flow | D27: CH4 | E27: =Parameters!C74*1000 -> 1.7377103 | F27: kg
B28: output | C28: Technosphere flow | D28: Digestate after storage | E28: =E26-(E27*0.001) -> 0.55408419 | F28: t
A29: Land application of digestate | B29: input | C29: Technosphere flow | D29: Digestate after storage | E29: =E28 -> 0.55408419 | F29: t
B30: output | C30: Elementary flow | D30: N2O | E30: =Waste_characteristics!B3*Parameters!C5*(1-Waste_characteristics!B4)*Waste_characteristics!B8*Parameters!C78*(44/28)*1000 -> 0.18825189 | F30: kg | H30: NET EMISSION TO BE calculated
B31: output | C31: Elementary flow | D31: NH3 | E31: =Waste_characteristics!B3*Parameters!C5*(1-Waste_characteristics!B4)*Waste_characteristics!B8*Parameters!C79*(17/14)*1000 -> 4.4759191 | F31: kg
B32: output | C32: Elementary flow | D32: NO3 | E32: =Waste_characteristics!B3*Parameters!C5*(1-Waste_characteristics!B4)*Waste_characteristics!B8*Parameters!C80*(62/14)*1000 -> 6.1214777 | F32: kg
B33: output | C33: Elementary flow | D33: (PO4)3- | E33: =[4]LCI!$C$22*1000 -> -0.062584499 | F33: kg
B34: output | C34: Elementary flow | D34: CO2 fossil | E34: =[4]LCI!$C$26*1000 -> -291.08567 | F34: kg
A35: Substituted products
C36: Technosphere flow | D36: N-fertilizer | E36: 4.23 | F36: kg
C37: Technosphere flow | D37: P-fertilizer | E37: 1.62 | F37: kg
C38: Technosphere flow | D38: K-fertilizer | E38: 2.68 | F38: kg
C39: Technosphere flow | D39: Peat | E39: 150 | F39: kg
C40: Technosphere flow | D40: Marginal heat | E40: =E25 -> 2161.4235 | F40: MJ
...

Sheet LCI_IC
A1: Industrial composting
A2: Process | B2: Flow direction | C2: Flow type | D2: Flow name | E2: Value | F2: Unit
A3: Pretreatment | B3: input | C3: Technosphere flow | D3: Waste | E3: 1 | F3: t
B4: input | C4: Technosphere flow | D4: Electricity | E4: =E3*Parameters!C3 -> 9.98 | F4: kWh
B5: input | C5: Technosphere flow | D5: Water
B6: output | C6: Intermediate flow | D6: Pretreated biowaste | E6: =E3*Parameters!C5 -> 0.77 | F6: t
A7: Incineration | B7: input | C7: Intermediate flow | D7: discarded biowaste | E7: =E3*(1-Parameters!C5)*1000 -> 230 | F7: kg
B8: input | C8: Intermediate flow | D8: Transprted discarded biowaste | E8: =E7*0.001*Parameters!C6 -> 2.3 | F8: tkm
A9: C/N correction | B9: input | C9: Technosphere flow | D9: Pretreated biowaste | E9: =E6 -> 0.77 | F9: t
B10: input | C10: Technosphere flow | D10: Wood chips consumption | E10: =E9*(1/8)*1000 -> 96.25 | F10: kg
B11: output | C11: Technosphere flow | D11: Biowaste+WC | E11: =E9+(E10/1000) -> 0.86625 | F11: t
A12: Active composting | B12: input | C12: Technosphere flow | D12: Biowaste+WC | E12: =E11 -> 0.86625 | F12: t
B13: output | C13: Elementary flow | D13: CH4 | E13: =[4]LCI!C4*1000 -> 0.1410178 | F13: kg | G13: data from PaCTEA
B14: output | C14: Elementary flow | D14: NH3 | E14: =[4]LCI!C5*1000 -> 0.1932546 | F14: kg | G14: data from PaCTEA
B15: output | C15: Elementary flow | D15: N2O | E15: =[4]LCI!C6*1000 -> 0.06009465 | F15: kg | G15: data from PaCTEA
B16: output | C16: Elementary flow | D16: CO2 | E16: =[4]LCI!C7*1000 -> 314.006 | F16: kg | G16: data from PaCTEA
B17: output | C17: Technosphere flow | D17: Electricity (aeration) | E17: =[4]LCI!$C$31*1000 -> 6.93 | F17: kWh | G17: data from PaCTEA
B18: output | C18: Technosphere flow | D18: Diesel | E18: =[4]LCI!$C$34*1000 -> 0 | F18: l | G18: data from PaCTEA
A19: Land application | B19: output | C19: Elementary flow | D19: NH3 | E19: =[4]LCI!C18*1000 -> 0.28248773 | F19: kg | G19: data from PaCTEA
B20: output | C20: Elementary flow | D20: N2O | E20: =[4]LCI!C19*1000 -> 0.099088 | F20: kg | G20: data from PaCTEA
B21: output | C21: Elementary flow | D21: NO3 | E21: =[4]LCI!C20*1000 -> 10.35596 | F21: kg | G21: data from PaCTEA
B22: output | C22: Elementary flow | D22: (PO4)3- | E22: =[4]LCI!$C$22*1000 -> -0.062584499 | F22: kg | G22: data from PaCTEA
B23: output | C23: Elementary flow | D23: CO2 fossil | E23: =[4]LCI!$C$26*1000 -> -291.08567 | F23: kg | G23: data from PaCTEA
A24: Substitued products
C25: Technosphere flow | D25: N-fertilizer | E25: =[4]LCI!$C$17*1000 -> 9.161444 | F25: kg
C26: Technosphere flow | D26: P-fertilizer | E26: =[4]LCI!$C$21*1000 -> 2.6344181 | F26: kg
C27: Technosphere flow | D27: K-fertilizer | E27: =[4]LCI!$C$23*1000 -> 3.866859 | F27: kg
C28: Technosphere flow | D28: Peat | E28: =[4]LCI!$C$24*1000 -> 357.98611 | F28: kg

Sheet LCIA_IC
A1: Process | C1: acidification: terrestrial - terrestrial acidification potential (TAP) | D1: climate change - global warming potential (GWP100) | E1: ecotoxicity: freshwater - freshwater ecotoxicity potential (FETP) | F1: ecotoxicity: marine - marine ecotoxicity potential (METP) | G1: ecotoxicity: terrestrial - terrestrial ecotoxicity potential (TETP) | H1: energy resources: non-renewable, fossil - fossil fuel potential (FFP) | I1: eutrophication: freshwater - freshwater eutrophication potential (FEP) | J1: eutrophication: marine - marine eutrophication potential (MEP) | K1: human toxicity: carcinogenic - human toxicity potential (HTPc) | L1: human toxicity: non-carcinogenic - human toxicity potential (HTPnc) | M1: ionising radiation - ionising radiation potential (IRP) | N1: land use - agricultural land occupation (LOP) | O1: material resources: metals/minerals - surplus ore potential (SOP) | P1: ozone depletion - ozone depletion potential (ODPinfinite) | Q1: particulate matter formation - particulate matter formation potential (PMFP) | R1: photochemical oxidant formation: human health - photochemical oxidant formation potential: humans (HOFP) | S1: photochemical oxidant formation: terrestrial ecosystems - photochemical oxidant formation potential: ecosystems (EOFP) | T1: water use - water consumption potential (WCP)
A2: Pretreatment
B3: Electricity consumption | C3: =LCI!$E102*impact_process_mid!C2 -> 0.00090312822 | D3: =LCI!$E102*impact_process_mid!D2 -> 0.79247376 | E3: =LCI!$E102*impact_process_mid!E2 -> 0.061910243 | F3: =LCI!$E102*impact_process_mid!F2 -> 0.078345671 | G3: =LCI!$E102*impact_process_mid!G2 -> 5.6623345 | H3: =LCI!$E102*impact_process_mid!H2 -> 0.2432694 | I3: =LCI!$E102*impact_process_mid!I2 -> 0.00015313457 | J3: =LCI!$E102*impact_process_mid!J2 -> 0.0001154348 | ... T3: =LCI!$E102*impact_process_mid!T2 -> 0.03128965
B4: Water consumption | C4: =LCI!E$103*impact_process_mid!C3 -> 0 | D4: =LCI!F$103*impact_process_mid!D3 -> 0 | E4: =LCI!G$103*impact_process_mid!E3 -> 0 | F4: =LCI!H$103*impact_process_mid!F3 -> 0 | G4: =LCI!I$103*impact_process_mid!G3 -> 0 | H4: =LCI!J$103*impact_process_mid!H3 -> 0 | I4: =LCI!K$103*impact_process_mid!I3 -> 0 | J4: =LCI!L$103*impact_process_mid!J3 -> 0 | ... T4: =LCI!V$103*impact_process_mid!T3 -> 0
A5: Incineration
B6: Incineration | C6: =LCI!$E105*impact_process_mid!C4 -> 0.031368688 | D6: =LCI!$E105*impact_process_mid!D4 -> 9.4255904 | E6: =LCI!$E105*impact_process_mid!E4 -> 1.5611552 | F6: =LCI!$E105*impact_process_mid!F4 -> 2.0858238 | G6: =LCI!$E105*impact_process_mid!G4 -> 21.548877 | H6: =LCI!$E105*impact_process_mid!H4 -> 1.3294787 | I6: =LCI!$E105*impact_process_mid!I4 -> 0.011197026 | J6: =LCI!$E105*impact_process_mid!J4 -> 0.0027794864 | ... T6: =LCI!$E105*impact_process_mid!T4 -> 0.41857403
A7: C/N correction
B8: Wood chips consumption | C8: =LCI!$E108*impact_process_mid!C33 -> 0.011007509 | D8: =LCI!$E108*impact_process_mid!D33 -> 4.4318595 | E8: =LCI!$E108*impact_process_mid!E33 -> 0.099567826 | F8: =LCI!$E108*impact_process_mid!F33 -> 0.15522086 | G8: =LCI!$E108*impact_process_mid!G33 -> 44.455754 | H8: =LCI!$E108*impact_process_mid!H33 -> 1.33773 | I8: =LCI!$E108*impact_process_mid!I33 -> 0.0015219498 | J8: =LCI!$E108*impact_process_mid!J33 -> 0.00024301467 | ... T8: =LCI!$E108*impact_process_mid!T33 -> 0.020737907
A9: Active composting
B10: CH4direct | C10: =LCI!$E112*impact_process_mid!C11 -> 0 | D10: =LCI!$E112*impact_process_mid!D11 -> 4.7946052 | E10: =LCI!$E112*impact_process_mid!E11 -> 0 | F10: =LCI!$E112*impact_process_mid!F11 -> 0 | G10: =LCI!$E112*impact_process_mid!G11 -> 0 | H10: =LCI!$E112*impact_process_mid!H11 -> 0 | I10: =LCI!$E112*impact_process_mid!I11 -> 0 | J10: =LCI!$E112*impact_process_mid!J11 -> 0 | ... T10: =LCI!$E112*impact_process_mid!T11 -> 0
B11: NH3direct | C11: =LCI!$E113*impact_process_mid!C17 -> 0.37877902 | D11: =LCI!$E113*impact_process_mid!D17 -> 0 | E11: =LCI!$E113*impact_process_mid!E17 -> 0 | F11: =LCI!$E113*impact_process_mid!F17 -> 0 | G11: =LCI!$E113*impact_process_mid!G17 -> 0 | H11: =LCI!$E113*impact_process_mid!H17 -> 0 | I11: =LCI!$E113*impact_process_mid!I17 -> 0 | J11: =LCI!$E113*impact_process_mid!J17 -> 0 | ... T11: =LCI!$E113*impact_process_mid!T17 -> 0
B12: N2Odirect | C12: =LCI!$E114*impact_process_mid!C19 -> 0 | D12: =LCI!$E114*impact_process_mid!D19 -> 17.908206 | E12: =LCI!$E114*impact_process_mid!E19 -> 0 | F12: =LCI!$E114*impact_process_mid!F19 -> 0 | G12: =LCI!$E114*impact_process_mid!G19 -> 0 | H12: =LCI!$E114*impact_process_mid!H19 -> 0 | I12: =LCI!$E114*impact_process_mid!I19 -> 0 | J12: =LCI!$E114*impact_process_mid!J19 -> 0 | ... T12: =LCI!$E114*impact_process_mid!T19 -> 0
B13: Electricity consumption | C13: =LCI!$E116*impact_process_mid!C2 -> 0.0006271221 | D13: =LCI!$E116*impact_process_mid!D2 -> 0.55028489 | E13: =LCI!$E116*impact_process_mid!E2 -> 0.042989778 | F13: =LCI!$E116*impact_process_mid!F2 -> 0.054402355 | G13: =LCI!$E116*impact_process_mid!G2 -> 3.9318615 | H13: =LCI!$E116*impact_process_mid!H2 -> 0.16892354 | I13: =LCI!$E116*impact_process_mid!I2 -> 0.00010633493 | J13: =LCI!$E116*impact_process_mid!J2 -> 8.0156626e-05 | ... T13: =LCI!$E116*impact_process_mid!T2 -> 0.021727182
A14: Substitution
B15: Market of peat
B16: Market of Nfertilizer
B17: Market of Pfertilizer
B18: Market of Kfertilizer
A19: Use-on-land
B20: N2Onet from use-on-land
B21: NO3net from use-on-land
B22: NH3net from use on-land
B23: (PO4)3-net from use-on-land
B24: CO2net from use-on-land
A27: IMPACT WORLD + FOOTPRINT
A28: Process | C28: Carbon footprint | D28: Ecosystem quality (residual) | E28: Energetic resource depletion | F28: Human health (residual) | G28: Water footprint - Scarcity
A29: Composting | C29: =SUM(C30,C33,C36,C38) -> 35.421319 | D29: =SUM(D30,D33,D36,D38) -> 32.067942 | E29: =SUM(E30,E33,E36,E38) -> 337.21257 | F29: =SUM(F30,F33,F36,F38) -> 7.8437449e-05 | G29: =SUM(G30,G33,G36,G38) -> 13.278829
A30: Pretreatment | C30: =SUM(C31:C32) -> 0.7761065 | D30: =SUM(D31:D32) -> 0.11916921 | E30: =SUM(E31:E32) -> 116.96083 | F30: =SUM(F31:F32) -> 7.7420483e-07 | G30: =SUM(G31:G32) -> 1.2592267
B31: Electricity consumption | C31: =LCI_IC!$E4*'IW+f'!C2 -> 0.7761065 | D31: =LCI_IC!$E4*'IW+f'!D2 -> 0.11916921 | E31: =LCI_IC!$E4*'IW+f'!E2 -> 116.96083 | F31: =LCI_IC!$E4*'IW+f'!F2 -> 7.7420483e-07 | G31: =LCI_IC!$E4*'IW+f'!G2 -> 1.2592267
B32: Water consumption | C32: =LCI_IC!$E5*'IW+f'!C3 -> 0 | D32: =LCI_IC!$E5*'IW+f'!D3 -> 0 | E32: =LCI_IC!$E5*'IW+f'!E3 -> 0 | F32: =LCI_IC!$E5*'IW+f'!F3 -> 0 | G32: =LCI_IC!$E5*'IW+f'!G3 -> 0
A33: Incineration | C33: =SUM(C34:C35) -> 9.4912725 | D33: =SUM(D34:D35) -> 1.7760545 | E33: =SUM(E34:E35) -> 70.109594 | F33: =SUM(F34:F35) -> 3.9183036e-05 | G33: =SUM(G34:G35) -> 10.01854
B34: Transport | C34: =LCI_IC!$E8*'IW+f'!C4 -> 0.43472979 | D34: =LCI_IC!$E8*'IW+f'!D4 -> 0.063594202 | E34: =LCI_IC!$E8*'IW+f'!E4 -> 6.576112 | F34: =LCI_IC!$E8*'IW+f'!F4 -> 3.4579966e-07 | G34: =LCI_IC!$E8*'IW+f'!G4 -> 0.039223403
B35: Incineration | C35: =LCI_IC!$E7*'IW+f'!C5 -> 9.0565427 | D35: =LCI_IC!$E7*'IW+f'!D5 -> 1.7124603 | E35: =LCI_IC!$E7*'IW+f'!E5 -> 63.533482 | F35: =LCI_IC!$E7*'IW+f'!F5 -> 3.8837236e-05 | G35: =LCI_IC!$E7*'IW+f'!G5 -> 9.9793169
A36: C/N correction | C36: =C37 -> 4.4017004 | D36: =D37 -> 24.994858 | E36: =E37 -> 68.925863 | F36: =F37 -> 3.6601305e-06 | G36: =G37 -> 1.1266688
B37: Wood chips consumption | C37: =LCI_IC!$E10*'IW+f'!C35 -> 4.4017004 | D37: =LCI_IC!$E10*'IW+f'!D35 -> 24.994858 | E37: =LCI_IC!$E10*'IW+f'!E35 -> 68.925863 | F37: =LCI_IC!$E10*'IW+f'!F35 -> 3.6601305e-06 | G37: =LCI_IC!$E10*'IW+f'!G35 -> 1.1266688
A38: Active composting | C38: =SUM(C39:C42) -> 20.75224 | D38: =SUM(D39:D42) -> 5.1778602 | E38: =SUM(E39:E42) -> 81.216286 | F38: =SUM(F39:F42) -> 3.4820078e-05 | G38: =SUM(G39:G42) -> 0.87439288
B39: CH4 | C39: =LCI_IC!$E13*'IW+f'!C12 -> 3.8074806 | D39: =LCI_IC!$E13*'IW+f'!D12 -> 0 | E39: =LCI_IC!$E13*'IW+f'!E12 -> 0 | F39: =LCI_IC!$E13*'IW+f'!F12 -> 0 | G39: =LCI_IC!$E13*'IW+f'!G12 -> 0
B40: NH3 | C40: =LCI_IC!$E14*'IW+f'!C18 -> 0 | D40: =LCI_IC!$E14*'IW+f'!D18 -> 5.0951105 | E40: =LCI_IC!$E14*'IW+f'!E18 -> 0 | F40: =LCI_IC!$E14*'IW+f'!F18 -> 3.4282479e-05 | G40: =LCI_IC!$E14*'IW+f'!G18 -> 0
B41: N2O | C41: =LCI_IC!$E15*'IW+f'!C20 -> 16.405839 | D41: =LCI_IC!$E15*'IW+f'!D20 -> 0 | E41: =LCI_IC!$E15*'IW+f'!E20 -> 0 | F41: =LCI_IC!$E15*'IW+f'!F20 -> 0 | G41: =LCI_IC!$E15*'IW+f'!G20 -> 0
B42: Electricity consumption | C42: =LCI_IC!$E17*'IW+f'!C2 -> 0.53891964 | D42: =LCI_IC!$E17*'IW+f'!D2 -> 0.082749759 | E42: =LCI_IC!$E17*'IW+f'!E2 -> 81.216286 | F42: =LCI_IC!$E17*'IW+f'!F2 -> 5.3759914e-07 | G42: =LCI_IC!$E17*'IW+f'!G2 -> 0.87439288
...

Sheet IW+_end
A1: Process | B1: Reference unit | C1: Climate change, ecosystem quality, long term | D1: Climate change, ecosystem quality, short term | E1: Climate change, human health, long term | F1: Climate change, human health, short term | G1: Fisheries impact | H1: Freshwater acidification | I1: Freshwater ecotoxicity, long term | J1: Freshwater ecotoxicity, short term | K1: Freshwater eutrophication | L1: Human toxicity cancer, long term | M1: Human toxicity cancer, short term | N1: Human toxicity non-cancer, long term | O1: Human toxicity non-cancer, short term | P1: Ionizing radiations, ecosystem quality | Q1: Ionizing radiations, human health | R1: Land occupation, biodiversity | S1: Land transformation, biodiversity | T1: Marine acidification, long term | U1: Marine acidification, short term | V1: Marine ecotoxicity, long term | W1: Marine ecotoxicity, short term | X1: Marine eutrophication | Y1: Ozone layer depletion | Z1: Particulate matter formation | AA1: Photochemical ozone formation, ecosystem quality | AB1: Photochemical ozone formation, human health | AC1: Terrestrial acidification | AD1: Terrestrial ecotoxicity, long term | AE1: Terrestrial ecotoxicity, short term | AF1: Thermally polluted water | AG1: Total ecosystem quality | AH1: Total human health | AI1: Water availability, freshwater ecosystem | AJ1: Water availability, human health | AK1: Water availability, terrestrial ecosystem | AM1: Ecoinvent process | AN1: Region
A2: Electricity production | B2: kWh | C2: 0.029434703 | D2: 0.0090171188 | E2: 3.9669068e-07 | F2: 1.2152346e-07 | G2: 9.0220539e-21 | H2: 0.00052035185 | I2: 0.024888796 | J2: 0.0012365565 | K2: 2.1482719e-06 | L2: 8.7189411e-10 | M2: 1.6630166e-08 | N2: 1.9716035e-08 | O2: 1.0495037e-08 | P2: 4.1472255e-10 | Q2: 1.2788915e-08 | R2: 0.0016567241 | S2: 0.0011680202 | T2: 0.010269588 | U2: 0.0011147872 | V2: 9.6682892e-08 | W2: 2.6607992e-08 | X2: 6.8100187e-05 | Y2: 4.6326221e-12 | Z2: 3.7499949e-08 | AA2: 0.0015786993 | AB2: 1.5693505e-10 | AC2: 0.0034337732 | AD2: 0.0035290615 | AE2: 0.00097119172 | AF2: 0.00019042271 | AG2: 0.089082653 | AH2: 7.3991032e-07 | AI2: 1.011382e-06 | AJ2: 1.2353261e-07 | AK2: 1.4744629e-06 | AM2: market for electricity, medium voltage | electricity, medium voltage | Cutoff, U | AN2: FR
A3: Water production | B3: kg | C3: 0.00011863638 | D3: 3.5826192e-05 | E3: 1.5988593e-09 | F3: 4.828286e-10 | G3: 1.4472652e-20 | H3: 2.6983115e-06 | I3: 2.7477981e-05 | J3: 6.1320649e-06 | K3: 1.2606069e-08 | L3: 1.408413e-11 | M3: 9.2762381e-10 | N3: 3.9435252e-10 | O3: 6.711082e-11 | P3: 1.4514271e-13 | Q3: 2.798748e-12 | R3: 4.7297185e-06 | S3: 6.0711292e-06 | T3: 4.2913089e-05 | U3: 4.6582693e-06 | V3: 4.9804263e-11 | W3: 3.9972635e-11 | X3: 2.4074305e-07 | Y3: 1.3310981e-14 | Z3: 2.4250395e-10 | AA3: 6.8457405e-06 | AB3: 6.8269851e-13 | AC3: 1.7503834e-05 | AD3: 1.8179051e-06 | AE3: 1.4590012e-06 | AF3: 1.0616678e-07 | AG3: 0.00028632407 | AH3: 4.2091312e-08 | AI3: 3.140634e-07 | AJ3: 3.8360455e-08 | AK3: 8.8807766e-06 | AM3: market for tap water | tap water | Cutoff, U | AN3: Europe without Switzerland
A4: Incineration | B4: kg | C4: 0.012374672 | D4: 0.0048759181 | E4: 1.6677311e-07 | F4: 6.5712614e-08 | G4: 5.8334847e-21 | H4: 0.00030722598 | I4: 0.0040615965 | J4: 0.00051944492 | K4: 2.5327295e-05 | L4: 3.2796643e-10 | M4: 4.0155836e-08 | N4: 8.7573489e-09 | O4: 9.0145145e-08 | P4: 7.2700604e-13 | Q4: 1.1049922e-11 | R4: 0.0004489439 | S4: 0.00087792638 | T4: 0.0035383176 | U4: 0.00038409088 | V4: 1.8169613e-09 | W4: 3.963782e-09 | X4: 0.00016049954 | Y4: 1.4900648e-12 | Z4: 3.830932e-08 | AA4: 0.0022743494 | AB4: 2.3470762e-10 | AC4: 0.0023013297 | AD4: 6.6359289e-05 | AE4: 0.00014467804 | AF4: 1.6597232e-06 | AG4: 0.032363623 | AH4: 4.5290827e-07 | AI4: 3.4778817e-07 | AJ4: 4.2479678e-08 | AK4: 9.2981276e-07
A5: Transport | B5: tkm | C5: 0.07140406 | D5: 0.021808745 | E5: 9.6231055e-07 | F5: 2.9391586e-07 | G5: 1.4895501e-19 | H5: 0.00082994559 | I5: 0.0092025979 | J5: 0.0033844539 | K5: 5.2566239e-06 | L5: 6.0034348e-10 | M5: 3.4139573e-08 | N5: 2.2572496e-08 | O5: 1.5198825e-08 | P5: 6.9944357e-12 | Q5: 8.6181308e-11 | R5: 0.0040818364 | S5: 0.0047163109 | T5: 0.025800254 | U5: 0.0028006693 | V5: 9.7222144e-09 | W5: 7.9906608e-09 | X5: 0.00021342597 | Y5: 6.1437636e-12 | Z5: 1.0038796e-07 | AA5: 0.0054178322 | AB5: 5.2899951e-10 | AC5: 0.005901547 | AD5: 0.00035486896 | AE5: 0.00029165912 | AF5: 6.7079009e-06 | AG5: 0.15622312 | AH5: 1.4464434e-06 | AI5: 1.3669709e-07 | AJ5: 1.6696509e-08 | AK5: 2.7918423e-06
A6: Heat, natural gas | B6: MJ | C6: 0.02877524 | D6: 0.0088335486 | E6: 3.8780312e-07 | F6: 1.1904949e-07 | G6: 2.456039e-19 | H6: 8.7487049e-05 | I6: 0.00090902716 | J6: 0.00084404332 | K6: 1.0175098e-06 | L6: 7.3128564e-11 | M6: 5.4607132e-09 | N6: 2.1836439e-09 | O6: 1.2776592e-09 | P6: 1.4950808e-12 | Q6: 2.7539256e-11 | R6: 8.8589251e-05 | S6: 0.00041813597 | T6: 0.010404099 | U6: 0.0011293905 | V6: 2.2228437e-09 | W6: 2.0080477e-09 | X6: 1.3926728e-05 | Y6: 4.9676217e-12 | Z6: 6.0152951e-09 | AA6: 0.00061565556 | AB6: 5.6382165e-11 | AC6: 0.00061064151 | AD6: 8.1134935e-05 | AE6: 7.3293742e-05 | AF6: 1.3011011e-06 | AG6: 0.052887171 | AH6: 5.2526773e-07 | AI6: 2.7146908e-08 | AJ6: 3.3157883e-09 | AK6: 6.0708308e-07
A7: Heat, fuel | B7: MJ | C7: 0.036606595 | D7: 0.011027964 | E7: 4.9334608e-07 | F7: 1.4862357e-07 | G7: 1.8355355e-21 | H7: 0.00028862325 | I7: 0.001913816 | J7: 0.00093700432 | K7: 1.4412766e-06 | L7: 1.5012604e-10 | M7: 4.1655245e-09 | N7: 4.0009951e-09 | O7: 2.2101399e-09 | P7: 1.1573822e-12 | Q7: 2.174998e-11 | R7: 0.00012145572 | S7: 0.00099540935 | T7: 0.013271943 | U7: 0.001440703 | V7: 1.9565669e-09 | W7: 1.7764736e-09 | X7: 5.5334525e-05 | Y7: 2.9853225e-12 | Z7: 1.6704189e-08 | AA7: 0.00093625163 | AB7: 8.3728291e-11 | AC7: 0.0018442609 | AD7: 7.1423215e-05 | AE7: 6.4841285e-05 | AF7: 1.039197e-06 | AG7: 0.069578362 | AH7: 6.7176707e-07 | AI7: 2.0123922e-08 | AJ7: 2.4579839e-09 | AK7: 2.3213647e-07
