Workbook
Name Food_Type: "Baseline"
Name FW_mass: Waste_characteristics!$B$3
Name H2O_FW: Waste_characteristics!$B$4
Name Mass: Waste_characteristics!$B$2
Name mass_VS_FW: Waste_characteristics!$B$6
Name Methane_LHV: '[1]Global params'!$E$21
Name VS_FW: Waste_characteristics!$B$5

Sheet LCIA_AD-f
A3: IMPACT WORLD + FOOTPRINT
A4: Process | C4: Carbon footprint | D4: Ecosystem quality (residual) | E4: Energetic resource depletion | F4: Human health (residual) | G4: Water footprint - Scarcity
A5: AD | C5: =SUM(C6,C9,C12,C16,C27) -> 64.523122 | D5: =SUM(D6,D9,D12,D16,D27) -> 12.136919 | E5: =SUM(E6,E9,E12,E16,E27) -> 635.68927 | F5: =SUM(F6,F9,F12,F16,F27) -> 0.00013928494 | G5: =SUM(G6,G9,G12,G16,G27) -> 15.914782
A6: Pretreatment | C6: =SUM(C7:C8) -> 0.7761065 | D6: =SUM(D7:D8) -> 0.11916921 | E6: =SUM(E7:E8) -> 116.96083 | F6: =SUM(F7:F8) -> 7.7420483e-07 | G6: =SUM(G7:G8) -> 1.2592267
B7: Electricity consumption | C7: ='LCI_AD-e'!$E4*'IW+f'!C2 -> 0.7761065 | D7: ='LCI_AD-e'!$E4*'IW+f'!D2 -> 0.11916921 | E7: ='LCI_AD-e'!$E4*'IW+f'!E2 -> 116.96083 | F7: ='LCI_AD-e'!$E4*'IW+f'!F2 -> 7.7420483e-07 | G7: ='LCI_AD-e'!$E4*'IW+f'!G2 -> 1.2592267
B8: Water consumption | C8: ='LCI_AD-e'!$E5*'IW+f'!C3 -> 0 | D8: ='LCI_AD-e'!$E5*'IW+f'!D3 -> 0 | E8: ='LCI_AD-e'!$E5*'IW+f'!E3 -> 0 | F8: ='LCI_AD-e'!$E5*'IW+f'!F3 -> 0 | G8: ='LCI_AD-e'!$E5*'IW+f'!G3 -> 0
A9: Incineration | C9: =SUM(C10:C11) -> 9.4912725 | D9: =SUM(D10:D11) -> 1.7760545 | E9: =SUM(E10:E11) -> 70.109594 | F9: =SUM(F10:F11) -> 3.9183036e-05 | G9: =SUM(G10:G11) -> 10.01854
B10: Transport | C10: ='LCI_AD-e'!$E7*'IW+f'!C4 -> 0.43472979 | D10: ='LCI_AD-e'!$E7*'IW+f'!D4 -> 0.063594202 | E10: ='LCI_AD-e'!$E7*'IW+f'!E4 -> 6.576112 | F10: ='LCI_AD-e'!$E7*'IW+f'!F4 -> 3.4579966e-07 | G10: ='LCI_AD-e'!$E7*'IW+f'!G4 -> 0.039223403
B11: Incineration | C11: ='LCI_AD-e'!$E8*'IW+f'!C5 -> 9.0565427 | D11: ='LCI_AD-e'!$E8*'IW+f'!D5 -> 1.7124603 | E11: ='LCI_AD-e'!$E8*'IW+f'!E5 -> 63.533482 | F11: ='LCI_AD-e'!$E8*'IW+f'!F5 -> 3.8837236e-05 | G11: ='LCI_AD-e'!$E8*'IW+f'!G5 -> 9.9793169
A12: AD | C12: =SUM(C13:C15) -> 52.248712 | D12: =SUM(D13:D15) -> 2.7873234 | E12: =SUM(E13:E15) -> 416.86802 | F12: =SUM(F13:F15) -> 4.5598348e-05 | G12: =SUM(G13:G15) -> 4.3060094
B13: Electricity | C13: ='LCI_AD-e'!$E10*'IW+f'!C2 -> 1.7365189 | D13: ='LCI_AD-e'!$E10*'IW+f'!D2 -> 0.26663811 | E13: ='LCI_AD-e'!$E10*'IW+f'!E2 -> 261.69692 | F13: ='LCI_AD-e'!$E10*'IW+f'!F2 -> 1.7322639e-06 | G13: ='LCI_AD-e'!$E10*'IW+f'!G2 -> 2.8174882
B14: Heat | C14: ='LCI_AD-e'!$E11*'IW+f'!C11 -> 9.6923673 | D14: ='LCI_AD-e'!$E11*'IW+f'!D11 -> 2.5206853 | E14: ='LCI_AD-e'!$E11*'IW+f'!E11 -> 155.1711 | F14: ='LCI_AD-e'!$E11*'IW+f'!F11 -> 4.3866084e-05 | G14: ='LCI_AD-e'!$E11*'IW+f'!G11 -> 1.4885212
B15: CH4 | C15: ='LCI_AD-e'!$E12*'IW+f'!C12 -> 40.819826 | D15: ='LCI_AD-e'!$E12*'IW+f'!D12 -> 0 | E15: ='LCI_AD-e'!$E12*'IW+f'!E12 -> 0 | F15: ='LCI_AD-e'!$E12*'IW+f'!F12 -> 0 | G15: ='LCI_AD-e'!$E12*'IW+f'!G12 -> 0
A16: Combustion of biogas | C16: =SUM(C17:C26) -> 1.7671684 | D16: =SUM(D17:D26) -> 7.2504014 | E16: =SUM(E17:E26) -> 7.132496 | F16: =SUM(F17:F26) -> 5.3325992e-05 | G16: =SUM(G17:G26) -> 0.076790064
B17: CH4 | C17: ='LCI_AD-e'!$E17*'IW+f'!C12 -> 0.15478559 | D17: ='LCI_AD-e'!$E17*'IW+f'!D12 -> 0 | E17: ='LCI_AD-e'!$E17*'IW+f'!E12 -> 0 | F17: ='LCI_AD-e'!$E17*'IW+f'!F12 -> 0 | G17: ='LCI_AD-e'!$E17*'IW+f'!G12 -> 0
B18: N2O | C18: ='LCI_AD-e'!$E18*'IW+f'!C20 -> 1.5650543 | D18: ='LCI_AD-e'!$E18*'IW+f'!D20 -> 0 | E18: ='LCI_AD-e'!$E18*'IW+f'!E20 -> 0 | F18: ='LCI_AD-e'!$E18*'IW+f'!F20 -> 0 | G18: ='LCI_AD-e'!$E18*'IW+f'!G20 -> 0
B19: Sox | C19: ='LCI_AD-e'!$E19*'IW+f'!C19 -> 0 | D19: ='LCI_AD-e'!$E19*'IW+f'!D19 -> 0.66216543 | E19: ='LCI_AD-e'!$E19*'IW+f'!E19 -> 0 | F19: ='LCI_AD-e'!$E19*'IW+f'!F19 -> 3.6936286e-06 | G19: ='LCI_AD-e'!$E19*'IW+f'!G19 -> 0
B20: PM10 | C20: ='LCI_AD-e'!$E20*'IW+f'!C16 -> 0 | D20: ='LCI_AD-e'!$E20*'IW+f'!D16 -> 0 | E20: ='LCI_AD-e'!$E20*'IW+f'!E16 -> 0 | F20: ='LCI_AD-e'!$E20*'IW+f'!F16 -> 0 | G20: ='LCI_AD-e'!$E20*'IW+f'!G16 -> 0
B21: PM2.5 | C21: ='LCI_AD-e'!$E21*'IW+f'!C22 -> 0 | D21: ='LCI_AD-e'!$E21*'IW+f'!D22 -> 0 | E21: ='LCI_AD-e'!$E21*'IW+f'!E22 -> 0 | F21: ='LCI_AD-e'!$E21*'IW+f'!F22 -> 3.9886858e-05 | G21: ='LCI_AD-e'!$E21*'IW+f'!G22 -> 0
B22: Nox | C22: ='LCI_AD-e'!$E22*'IW+f'!C13 -> 0 | D22: ='LCI_AD-e'!$E22*'IW+f'!D13 -> 6.2616774 | E22: ='LCI_AD-e'!$E22*'IW+f'!E13 -> 0 | F22: ='LCI_AD-e'!$E22*'IW+f'!F13 -> 7.5499383e-06 | G22: ='LCI_AD-e'!$E22*'IW+f'!G13 -> 0
B23: NH3 | C23: ='LCI_AD-e'!$E23*'IW+f'!C18 -> 0 | D23: ='LCI_AD-e'!$E23*'IW+f'!D18 -> 0.31929142 | E23: ='LCI_AD-e'!$E23*'IW+f'!E18 -> 0 | F23: ='LCI_AD-e'!$E23*'IW+f'!F18 -> 2.1483541e-06 | G23: ='LCI_AD-e'!$E23*'IW+f'!G18 -> 0
B24: CO | C24: ='LCI_AD-e'!$E24*'IW+f'!C17 -> 0 | D24: ='LCI_AD-e'!$E24*'IW+f'!D17 -> 0 | E24: ='LCI_AD-e'!$E24*'IW+f'!E17 -> 0 | F24: ='LCI_AD-e'!$E24*'IW+f'!F17 -> 0 | G24: ='LCI_AD-e'!$E24*'IW+f'!G17 -> 0
B25: VOC | C25: ='LCI_AD-e'!$E25*'IW+f'!C14 -> 0 | D25: ='LCI_AD-e'!$E25*'IW+f'!D14 -> 0 | E25: ='LCI_AD-e'!$E25*'IW+f'!E14 -> 0 | F25: ='LCI_AD-e'!$E25*'IW+f'!F14 -> 0 | G25: ='LCI_AD-e'!$E25*'IW+f'!G14 -> 0
B26: Electricity | C26: ='LCI_AD-e'!$E26*'IW+f'!C2 -> 0.047328466 | D26: ='LCI_AD-e'!$E26*'IW+f'!D2 -> 0.0072671672 | E26: ='LCI_AD-e'!$E26*'IW+f'!E2 -> 7.132496 | F26: ='LCI_AD-e'!$E26*'IW+f'!F2 -> 4.7212498e-08 | G26: ='LCI_AD-e'!$E26*'IW+f'!G2 -> 0.076790064
A27: Dewatering | C27: ='LCIA_AD-b'!C25 -> 0.23986337 | D27: ='LCIA_AD-b'!D25 -> 0.20397057 | E27: ='LCIA_AD-b'!E25 -> 24.618326 | F27: ='LCIA_AD-b'!F25 -> 4.0335814e-07 | G27: ='LCIA_AD-b'!G25 -> 0.25421574
B28: electricity | C28: ='LCIA_AD-b'!C26 -> 0.15696911 | D28: ='LCIA_AD-b'!D26 -> 0.024102213 | E28: ='LCIA_AD-b'!E26 -> 23.655564 | F28: ='LCIA_AD-b'!F26 -> 1.5658449e-07 | G28: ='LCIA_AD-b'!G26 -> 0.25468114
B29: wastewater treatment | C29: ='LCIA_AD-b'!C27 -> 0.08289426 | D29: ='LCIA_AD-b'!D27 -> 0.17986836 | E29: ='LCIA_AD-b'!E27 -> 0.96276199 | F29: ='LCIA_AD-b'!F27 -> 2.4677365e-07 | G29: ='LCIA_AD-b'!G27 -> -0.00046540191
A30: Composting of digestate | C30: ='LCIA_AD-b'!C28 -> 20.023162 | D30: ='LCIA_AD-b'!D28 -> 5.537795 | E30: ='LCIA_AD-b'!E28 -> 61.671424 | F30: ='LCIA_AD-b'!F28 -> 3.6457712e-05 | G30: ='LCIA_AD-b'!G28 -> 0.42904899
B31: CH4 | C31: ='LCIA_AD-b'!C29 -> 2.3821712 | D31: ='LCIA_AD-b'!D29 -> 0 | E31: ='LCIA_AD-b'!E29 -> 0 | F31: ='LCIA_AD-b'!F29 -> 0 | G31: ='LCIA_AD-b'!G29 -> 0
B32: N2O | C32: ='LCIA_AD-b'!C30 -> 17.012982 | D32: ='LCIA_AD-b'!D30 -> 0 | E32: ='LCIA_AD-b'!E30 -> 0 | F32: ='LCIA_AD-b'!F30 -> 0 | G32: ='LCIA_AD-b'!G30 -> 0
B33: NH3 | C33: ='LCIA_AD-b'!C31 -> 0 | D33: ='LCIA_AD-b'!D31 -> 5.3456953 | E33: ='LCIA_AD-b'!E31 -> 0 | F33: ='LCIA_AD-b'!F31 -> 3.596854e-05 | G33: ='LCIA_AD-b'!G31 -> 0
B34: NMVOC | C34: ='LCIA_AD-b'!C32 -> 0 | D34: ='LCIA_AD-b'!D32 -> 0.078076707 | E34: ='LCIA_AD-b'!E32 -> 0 | F34: ='LCIA_AD-b'!F32 -> 5.0595209e-09 | G34: ='LCIA_AD-b'!G32 -> 0
B35: CO | C35: ='LCIA_AD-b'!C33 -> 0 | D35: ='LCIA_AD-b'!D33 -> 0 | E35: ='LCIA_AD-b'!E33 -> 0 | F35: ='LCIA_AD-b'!F33 -> 0 | G35: ='LCIA_AD-b'!G33 -> 0
B36: electricity | C36: ='LCIA_AD-b'!C34 -> 0.24305618 | D36: ='LCIA_AD-b'!D34 -> 0.037320666 | E36: ='LCIA_AD-b'!E34 -> 36.62906 | F36: ='LCIA_AD-b'!F34 -> 2.4246062e-07 | G36: ='LCIA_AD-b'!G34 -> 0.39435674
B37: diesel | C37: ='LCIA_AD-b'!C35 -> 0.38495173 | D37: ='LCIA_AD-b'!D35 -> 0.076702309 | E37: ='LCIA_AD-b'!E35 -> 25.042364 | F37: ='LCIA_AD-b'!F35 -> 2.4165125e-07 | G37: ='LCIA_AD-b'!G35 -> 0.034692256
A38: Land application of compost | C38: ='LCIA_AD-b'!C36 -> -27.214301 | D38: ='LCIA_AD-b'!D36 -> 7.1951541 | E38: ='LCIA_AD-b'!E36 -> 0 | F38: ='LCIA_AD-b'!F36 -> 1.4004956e-05 | G38: ='LCIA_AD-b'!G36 -> 0
B39: N2O | C39: ='LCIA_AD-b'!C37 -> 3.6020203 | D39: ='LCIA_AD-b'!D37 -> 0 | E39: ='LCIA_AD-b'!E37 -> 0 | F39: ='LCIA_AD-b'!F37 -> 0 | G39: ='LCIA_AD-b'!G37 -> 0
B40: NH3 | C40: ='LCIA_AD-b'!C38 -> 0 | D40: ='LCIA_AD-b'!D38 -> 2.0814363 | E40: ='LCIA_AD-b'!E38 -> 0 | F40: ='LCIA_AD-b'!F38 -> 1.4004956e-05 | G40: ='LCIA_AD-b'!G38 -> 0
B41: NO3 | C41: ='LCIA_AD-b'!C39 -> 0 | D41: ='LCIA_AD-b'!D39 -> 5.2372358 | E41: ='LCIA_AD-b'!E39 -> 0 | F41: ='LCIA_AD-b'!F39 -> 0 | G41: ='LCIA_AD-b'!G39 -> 0
B42: (PO4)3- | C42: ='LCIA_AD-b'!C40 -> 0 | D42: ='LCIA_AD-b'!D40 -> -0.123518 | E42: ='LCIA_AD-b'!E40 -> 0 | F42: ='LCIA_AD-b'!F40 -> 0 | G42: ='LCIA_AD-b'!G40 -> 0
...

Sheet IW+f
A1: Process | B1: Reference unit | C1: Carbon footprint | D1: Ecosystem quality (residual) | E1: Energetic resource depletion | F1: Human health (residual) | G1: Water footprint - Scarcity
A2: Electricity production | B2: kWh | C2: 0.077766182 | D2: 0.011940802 | E2: 11.719522 | F2: 7.7575634e-08 | G2: 0.12617502
A3: Water production | B3: kg | C3: 0.00031089504 | D3: 5.0457625e-05 | E3: 0.0058714946 | F3: 1.2407333e-09 | G3: 0.039180999
A4: Transport | B4: tkm | C4: 0.18901295 | D4: 0.027649653 | E4: 2.8591791 | F4: 1.5034768e-07 | G4: 0.017053654
A5: Incineration | B5: kg | C5: 0.039376273 | D5: 0.0074454798 | E5: 0.27623253 | F5: 1.6885755e-07 | G5: 0.043388334
A6: Heat, natural gas | B6: MJ | C6: 0.076822608 | D6: 0.0038834843 | E6: 1.2663162 | F6: 1.2842557e-08 | G6: 0.0033867142
A7: Heat, fuel | B7: MJ | C7: 0.095243646 | D7: 0.0066863662 | E7: 1.3193828 | F7: 2.3188317e-08 | G7: 0.0025105611
A8: Heat, coal | B8: MJ | C8: 0.13204942 | D8: 0.020669551 | E8: 1.2364959 | F8: 1.9202415e-07 | G8: 0.0044888512
A9: Heat, wood chips | B9: MJ | C9: 0.016806366 | D9: 0.025566585 | E9: 0.22657283 | F9: 5.1772645e-07 | G9: 0.013711808
A10: Heat,waste | B10: MJ
A11: Heat, mix | B11: MJ | C11: =(C6*Parameters!$C115)+(C7*Parameters!$C117)+(C8*Parameters!$C116)+(C9*Parameters!$C118)+(C10*Parameters!$C119) -> 0.042669458 | D11: =(D6*Parameters!$C115)+(D7*Parameters!$C117)+(D8*Parameters!$C116)+(D9*Parameters!$C118)+(D10*Parameters!$C119) -> 0.011097008 | E11: =(E6*Parameters!$C115)+(E7*Parameters!$C117)+(E8*Parameters!$C116)+(E9*Parameters!$C118)+(E10*Parameters!$C119) -> 0.68312173 | F11: =(F6*Parameters!$C115)+(F7*Parameters!$C117)+(F8*Parameters!$C116)+(F9*Parameters!$C118)+(F10*Parameters!$C119) -> 1.9311505e-07 | G11: =(G6*Parameters!$C115)+(G7*Parameters!$C117)+(G8*Parameters!$C116)+(G9*Parameters!$C118)+(G10*Parameters!$C119) -> 0.0065530319
A12: CH4 | B12: kg | C12: 27
A13: Nitrogen oxides | B13: kg | D13: 16.332781 | F13: 1.9693043e-05
A14: Volatile organic compounds
A15: Sulfur dioxide | B15: kg | D15: 16.649329 | F15: 9.2871715e-05
A16: Particulate matter
A17: Carbon monoxide
A18: Ammonia | B18: kg | D18: 26.364756 | F18: 0.00017739541
A19: sulfure oxides | B19: kg | D19: 16.649329 | F19: 9.2871715e-05
A20: dinitrogen monoxide | B20: kg | C20: 273
A21: Nitrate | D21: 1.976625
A22: PM2.5 | B22: kg | F22: 0.0013675986
A23: NMOVC | D23: 2.5277027 | F23: 1.638e-07
A24: H2S
A25: (PO4)3- | B25: kg | D25: 3.1274177
A26: CO2 fossil | B26: kg | C26: 1 | D26: 0.0165
A27: Diesel | B27: kg | C27: 0.85767719 | D27: 0.17089369 | E27: 55.794696 | F27: 5.3840195e-07 | G27: 0.077294773
A28: N-fertilizer | B28: kg | C28: 1.5776479 | D28: 0.20933685 | E28: 23.200022 | F28: 1.1573452e-06 | G28: 2.3755902
A29: K-fertilizer | B29: kg | C29: 0.66714793 | D29: 0.16237016 | E29: 10.816314 | F29: 7.4831828e-07 | G29: 0.31390974
A30: P-fertilizer | B30: kg | C30: 0.38986915 | D30: 0.18170442 | E30: 6.8356119 | F30: 1.4997158e-06 | G30: 0.92484418
A31: Peat | B31: kg | C31: 0.014284516 | D31: 0.0061782922 | E31: 10.072035 | F31: 1.1466261e-08 | G31: 0.032008551
A32: Activated carbon | B32: kg | C32: 3.3347072 | D32: 0.57318851 | E32: 42.034753 | F32: 4.8922716e-06 | G32: 0.41818096
A33: Zeolite | B33: kg | C33: 5.2073989 | D33: 1.0260333 | E33: 68.260494 | F33: 1.4663328e-05 | G33: 3.4287767
A34: treatment of wastewater | B34: m3 | C34: 0.31991638 | D34: 0.6941715 | E34: 3.7156171 | F34: 9.5238117e-07 | G34: -0.00179614
A35: Wood chips | B35: kg | C35: 0.045731952 | D35: 0.25968684 | E35: 0.71611286 | F35: 3.802733e-08 | G35: 0.011705649
A37: Mix marginal electricity | B37: kWh | C37: 0.037452427 | D37: 0.04902193 | E37: 0.42365828 | F37: 1.3638734e-07 | G37: 0.013714098
A38: natural gas | B38: m3 | C38: 0.73571241 | D38: 0.097093053 | E38: 47.700352 | F38: 2.2310472e-07 | G38: 0.078893247
A39: marginal heat (natural | B39: MJ | C39: 0.070715709 | D39: 0.0033274375 | E39: 1.1766142 | F39: 5.1758663e-09 | G39: 0.0014227994 | I39: heat production, natural gas, at boiler condensing modulating >100kW | heat, district or industrial, natural gas
A41: CO2 non-fossil | B41: kg | C41: 0

Sheet LCIA_AD-e
A3: IMPACT WORLD + FOOTPRINT
A4: Process | C4: Carbon footprint | D4: Ecosystem quality (residual) | E4: Energetic resource depletion | F4: Human health (residual) | G4: Water footprint - Scarcity
A5: AD | C5: =SUM(C6,C9,C12,C16,C27) -> 100.41026 | D5: =SUM(D6,D9,D12,D16,D27) -> 11.932949 | E5: =SUM(E6,E9,E12,E16,E27) -> 611.07094 | F5: =SUM(F6,F9,F12,F16,F27) -> 0.00013888158 | G5: =SUM(G6,G9,G12,G16,G27) -> 15.660566
A6: Pretreatment | C6: =SUM(C7:C8) -> 0.7761065 | D6: =SUM(D7:D8) -> 0.11916921 | E6: =SUM(E7:E8) -> 116.96083 | F6: =SUM(F7:F8) -> 7.7420483e-07 | G6: =SUM(G7:G8) -> 1.2592267
B7: Electricity consumption | C7: ='LCI_AD-e'!$E4*'IW+f'!C2 -> 0.7761065 | D7: ='LCI_AD-e'!$E4*'IW+f'!D2 -> 0.11916921 | E7: ='LCI_AD-e'!$E4*'IW+f'!E2 -> 116.96083 | F7: ='LCI_AD-e'!$E4*'IW+f'!F2 -> 7.7420483e-07 | G7: ='LCI_AD-e'!$E4*'IW+f'!G2 -> 1.2592267
B8: Water consumption | C8: ='LCI_AD-e'!$E5*'IW+f'!C3 -> 0 | D8: ='LCI_AD-e'!$E5*'IW+f'!D3 -> 0 | E8: ='LCI_AD-e'!$E5*'IW+f'!E3 -> 0 | F8: ='LCI_AD-e'!$E5*'IW+f'!F3 -> 0 | G8: ='LCI_AD-e'!$E5*'IW+f'!G3 -> 0
A9: Incineration | C9: =SUM(C10:C11) -> 9.4912725 | D9: =SUM(D10:D11) -> 1.7760545 | E9: =SUM(E10:E11) -> 70.109594 | F9: =SUM(F10:F11) -> 3.9183036e-05 | G9: =SUM(G10:G11) -> 10.01854
B10: Transport | C10: ='LCI_AD-e'!$E7*'IW+f'!C4 -> 0.43472979 | D10: ='LCI_AD-e'!$E7*'IW+f'!D4 -> 0.063594202 | E10: ='LCI_AD-e'!$E7*'IW+f'!E4 -> 6.576112 | F10: ='LCI_AD-e'!$E7*'IW+f'!F4 -> 3.4579966e-07 | G10: ='LCI_AD-e'!$E7*'IW+f'!G4 -> 0.039223403
B11: Incineration | C11: ='LCI_AD-e'!$E8*'IW+f'!C5 -> 9.0565427 | D11: ='LCI_AD-e'!$E8*'IW+f'!D5 -> 1.7124603 | E11: ='LCI_AD-e'!$E8*'IW+f'!E5 -> 63.533482 | F11: ='LCI_AD-e'!$E8*'IW+f'!F5 -> 3.8837236e-05 | G11: ='LCI_AD-e'!$E8*'IW+f'!G5 -> 9.9793169
A12: AD | C12: =SUM(C13:C15) -> 52.248712 | D12: =SUM(D13:D15) -> 2.7873234 | E12: =SUM(E13:E15) -> 416.86802 | F12: =SUM(F13:F15) -> 4.5598348e-05 | G12: =SUM(G13:G15) -> 4.3060094
B13: Electricity | C13: ='LCI_AD-e'!$E10*'IW+f'!C2 -> 1.7365189 | D13: ='LCI_AD-e'!$E10*'IW+f'!D2 -> 0.26663811 | E13: ='LCI_AD-e'!$E10*'IW+f'!E2 -> 261.69692 | F13: ='LCI_AD-e'!$E10*'IW+f'!F2 -> 1.7322639e-06 | G13: ='LCI_AD-e'!$E10*'IW+f'!G2 -> 2.8174882
B14: Heat | C14: ='LCI_AD-e'!$E11*'IW+f'!C11 -> 9.6923673 | D14: ='LCI_AD-e'!$E11*'IW+f'!D11 -> 2.5206853 | E14: ='LCI_AD-e'!$E11*'IW+f'!E11 -> 155.1711 | F14: ='LCI_AD-e'!$E11*'IW+f'!F11 -> 4.3866084e-05 | G14: ='LCI_AD-e'!$E11*'IW+f'!G11 -> 1.4885212
B15: CH4 | C15: ='LCI_AD-e'!$E12*'IW+f'!C12 -> 40.819826 | D15: ='LCI_AD-e'!$E12*'IW+f'!D12 -> 0 | E15: ='LCI_AD-e'!$E12*'IW+f'!E12 -> 0 | F15: ='LCI_AD-e'!$E12*'IW+f'!F12 -> 0 | G15: ='LCI_AD-e'!$E12*'IW+f'!G12 -> 0
A16: Combustion of biogas | C16: =SUM(C17:C26) -> 1.7671684 | D16: =SUM(D17:D26) -> 7.2504014 | E16: =SUM(E17:E26) -> 7.132496 | F16: =SUM(F17:F26) -> 5.3325992e-05 | G16: =SUM(G17:G26) -> 0.076790064
B17: CH4 | C17: ='LCI_AD-e'!$E17*'IW+f'!C12 -> 0.15478559 | D17: ='LCI_AD-e'!$E17*'IW+f'!D12 -> 0 | E17: ='LCI_AD-e'!$E17*'IW+f'!E12 -> 0 | F17: ='LCI_AD-e'!$E17*'IW+f'!F12 -> 0 | G17: ='LCI_AD-e'!$E17*'IW+f'!G12 -> 0
B18: N2O | C18: ='LCI_AD-e'!$E18*'IW+f'!C20 -> 1.5650543 | D18: ='LCI_AD-e'!$E18*'IW+f'!D20 -> 0 | E18: ='LCI_AD-e'!$E18*'IW+f'!E20 -> 0 | F18: ='LCI_AD-e'!$E18*'IW+f'!F20 -> 0 | G18: ='LCI_AD-e'!$E18*'IW+f'!G20 -> 0
B19: Sox | C19: ='LCI_AD-e'!$E19*'IW+f'!C19 -> 0 | D19: ='LCI_AD-e'!$E19*'IW+f'!D19 -> 0.66216543 | E19: ='LCI_AD-e'!$E19*'IW+f'!E19 -> 0 | F19: ='LCI_AD-e'!$E19*'IW+f'!F19 -> 3.6936286e-06 | G19: ='LCI_AD-e'!$E19*'IW+f'!G19 -> 0
B20: PM10 | C20: ='LCI_AD-e'!$E20*'IW+f'!C16 -> 0 | D20: ='LCI_AD-e'!$E20*'IW+f'!D16 -> 0 | E20: ='LCI_AD-e'!$E20*'IW+f'!E16 -> 0 | F20: ='LCI_AD-e'!$E20*'IW+f'!F16 -> 0 | G20: ='LCI_AD-e'!$E20*'IW+f'!G16 -> 0
B21: PM2.5 | C21: ='LCI_AD-e'!$E21*'IW+f'!C22 -> 0 | D21: ='LCI_AD-e'!$E21*'IW+f'!D22 -> 0 | E21: ='LCI_AD-e'!$E21*'IW+f'!E22 -> 0 | F21: ='LCI_AD-e'!$E21*'IW+f'!F22 -> 3.9886858e-05 | G21: ='LCI_AD-e'!$E21*'IW+f'!G22 -> 0
B22: Nox | C22: ='LCI_AD-e'!$E22*'IW+f'!C13 -> 0 | D22: ='LCI_AD-e'!$E22*'IW+f'!D13 -> 6.2616774 | E22: ='LCI_AD-e'!$E22*'IW+f'!E13 -> 0 | F22: ='LCI_AD-e'!$E22*'IW+f'!F13 -> 7.5499383e-06 | G22: ='LCI_AD-e'!$E22*'IW+f'!G13 -> 0
B23: NH3 | C23: ='LCI_AD-e'!$E23*'IW+f'!C18 -> 0 | D23: ='LCI_AD-e'!$E23*'IW+f'!D18 -> 0.31929142 | E23: ='LCI_AD-e'!$E23*'IW+f'!E18 -> 0 | F23: ='LCI_AD-e'!$E23*'IW+f'!F18 -> 2.1483541e-06 | G23: ='LCI_AD-e'!$E23*'IW+f'!G18 -> 0
B24: CO | C24: ='LCI_AD-e'!$E24*'IW+f'!C17 -> 0 | D24: ='LCI_AD-e'!$E24*'IW+f'!D17 -> 0 | E24: ='LCI_AD-e'!$E24*'IW+f'!E17 -> 0 | F24: ='LCI_AD-e'!$E24*'IW+f'!F17 -> 0 | G24: ='LCI_AD-e'!$E24*'IW+f'!G17 -> 0
B25: VOC | C25: ='LCI_AD-e'!$E25*'IW+f'!C14 -> 0 | D25: ='LCI_AD-e'!$E25*'IW+f'!D14 -> 0 | E25: ='LCI_AD-e'!$E25*'IW+f'!E14 -> 0 | F25: ='LCI_AD-e'!$E25*'IW+f'!F14 -> 0 | G25: ='LCI_AD-e'!$E25*'IW+f'!G14 -> 0
B26: Electricity | C26: ='LCI_AD-e'!$E26*'IW+f'!C2 -> 0.047328466 | D26: ='LCI_AD-e'!$E26*'IW+f'!D2 -> 0.0072671672 | E26: ='LCI_AD-e'!$E26*'IW+f'!E2 -> 7.132496 | F26: ='LCI_AD-e'!$E26*'IW+f'!F2 -> 4.7212498e-08 | G26: ='LCI_AD-e'!$E26*'IW+f'!G2 -> 0.076790064
A27: Storage | C27: =C28 -> 36.126998 | D27: =D28 -> 0 | E27: =E28 -> 0 | F27: =F28 -> 0 | G27: =G28 -> 0
B28: CH4 | C28: ='LCI_AD-a'!$E27*'IW+f'!C12 -> 36.126998 | D28: ='LCI_AD-a'!$E27*'IW+f'!D12 -> 0 | E28: ='LCI_AD-a'!$E27*'IW+f'!E12 -> 0 | F28: ='LCI_AD-a'!$E27*'IW+f'!F12 -> 0 | G28: ='LCI_AD-a'!$E27*'IW+f'!G12 -> 0
A29: Land application of digestate | C29: =SUM(C30:C34) -> -96.310983 | D29: =SUM(D30:D34) -> 108.30291 | E29: =SUM(E30:E34) -> 0 | F29: =SUM(F30:F34) -> 0.00076801641 | G29: =SUM(G30:G34) -> 0
B30: N2O | C30: ='LCI_AD-a'!$E30*'IW+f'!C20 -> 19.040939 | D30: ='LCI_AD-a'!$E30*'IW+f'!D20 -> 0 | E30: ='LCI_AD-a'!$E30*'IW+f'!E20 -> 0 | F30: ='LCI_AD-a'!$E30*'IW+f'!F20 -> 0 | G30: ='LCI_AD-a'!$E30*'IW+f'!G20 -> 0
B31: NH3 | C31: ='LCI_AD-a'!$E31*'IW+f'!C18 -> 0 | D31: ='LCI_AD-a'!$E31*'IW+f'!D18 -> 114.14368 | E31: ='LCI_AD-a'!$E31*'IW+f'!E18 -> 0 | F31: ='LCI_AD-a'!$E31*'IW+f'!F18 -> 0.00076801641 | G31: ='LCI_AD-a'!$E31*'IW+f'!G18 -> 0
B32: NO3 | C32: ='LCI_AD-a'!$E32*'IW+f'!C21 -> 0 | D32: ='LCI_AD-a'!$E32*'IW+f'!D21 -> -3.7432544 | E32: ='LCI_AD-a'!$E32*'IW+f'!E21 -> 0 | F32: ='LCI_AD-a'!$E32*'IW+f'!F21 -> 0 | G32: ='LCI_AD-a'!$E32*'IW+f'!G21 -> 0
B33: (PO4)3- | C33: ='LCI_AD-a'!$E33*'IW+f'!C25 -> 0 | D33: ='LCI_AD-a'!$E33*'IW+f'!D25 -> -0.1942107 | E33: ='LCI_AD-a'!$E33*'IW+f'!E25 -> 0 | F33: ='LCI_AD-a'!$E33*'IW+f'!F25 -> 0 | G33: ='LCI_AD-a'!$E33*'IW+f'!G25 -> 0
B34: CO2 fossil | C34: ='LCI_AD-a'!$E34*'IW+f'!C26 -> -115.35192 | D34: ='LCI_AD-a'!$E34*'IW+f'!D26 -> -1.9033067 | E34: ='LCI_AD-a'!$E34*'IW+f'!E26 -> 0 | F34: ='LCI_AD-a'!$E34*'IW+f'!F26 -> 0 | G34: ='LCI_AD-a'!$E34*'IW+f'!G26 -> 0
A35: Substituted products | C35: =SUM(C36:C40) -> 0 | D35: =SUM(D36:D40) -> 29.772595 | E35: =SUM(E36:E40) -> 7109.9944 | F35: =SUM(F36:F40) -> 0.00013187706 | G35: =SUM(G36:G40) -> 105.59637
B36: N-fertilizer | C36: 0 | D36: ='LCI_AD-a'!$E36*'IW+f'!D28 -> 3.7699223 | E36: ='LCI_AD-a'!$E36*'IW+f'!E28 -> 417.80642 | F36: ='LCI_AD-a'!$E36*'IW+f'!F28 -> 2.0842492e-05 | G36: ='LCI_AD-a'!$E36*'IW+f'!G28 -> 42.781721
B37: P-fertilizer | C37: 0 | D37: ='LCI_AD-a'!$E37*'IW+f'!D30 -> 9.1248032 | E37: ='LCI_AD-a'!$E37*'IW+f'!E30 -> 343.26966 | F37: ='LCI_AD-a'!$E37*'IW+f'!F30 -> 7.5312485e-05 | G37: ='LCI_AD-a'!$E37*'IW+f'!G30 -> 46.443677
B38: K-fertilizer | C38: 0 | D38: ='LCI_AD-a'!$E38*'IW+f'!D29 -> 3.005312 | E38: ='LCI_AD-a'!$E38*'IW+f'!E29 -> 200.19933 | F38: ='LCI_AD-a'!$E38*'IW+f'!F29 -> 1.3850636e-05 | G38: ='LCI_AD-a'!$E38*'IW+f'!G29 -> 5.8101607
B39: Peat | C39: 0 | D39: ='LCI_AD-a'!$E39*'IW+f'!D31 -> 0.97385909 | E39: ='LCI_AD-a'!$E39*'IW+f'!E31 -> 1587.6139 | F39: ='LCI_AD-a'!$E39*'IW+f'!F31 -> 1.8073802e-06 | G39: ='LCI_AD-a'!$E39*'IW+f'!G31 -> 5.0453778
B40: Marginal heat | C40: 0 | D40: ='LCI_AD-e'!$E27*'IW+f'!D39 -> 12.898699 | E40: ='LCI_AD-e'!$E27*'IW+f'!E39 -> 4561.1051 | F40: ='LCI_AD-e'!$E27*'IW+f'!F39 -> 2.006407e-05 | G40: ='LCI_AD-e'!$E27*'IW+f'!G39 -> 5.5154334
A42: Total impact | C42: =C5+C29-C35 -> 4.0992744 | D42: =D5+D29-D35 -> 90.463265 | E42: =E5+E29-E35 -> -6498.9235 | F42: =F5+F29-F35 -> 0.00077502092 | G42: =G5+G29-G35 -> -89.935803
A45: Process
...

Sheet LCI_AD-e
A1: AD+combustion+digestate
A2: Process | B2: Flow direction | C2: Flow type | D2: Flow name | E2: Value | F2: Unit
A3: Pretreatment | B3: input | C3: Technosphere flow | D3: Waste | E3: 1 | F3: t
B4: input | C4: Technosphere flow | D4: Electricity | E4: =E3*Parameters!C3 -> 9.98 | F4: kWh
B5: input | C5: Technosphere flow | D5: Water
B6: output | C6: Intermediate flow | D6: Pretreated biowaste | E6: =E3*Parameters!C5 -> 0.77 | F6: t
A7: Incineration | B7: input | C7: Intermediate flow | D7: transported discarded biowaste | E7: =E8*0.001*Parameters!C6 -> 2.3 | F7: tkm
B8: input | C8: Intermediate flow | D8: discarded biowaste | E8: =E3*(1-Parameters!C5)*1000 -> 230 | F8: kg
A9: AD | B9: input | C9: Intermediate flow | D9: Pretreated waste | E9: =E6 -> 0.77 | F9: t
B10: input | C10: Intermediate flow | D10: Electricity | E10: =Parameters!C14*E9 -> 22.33 | F10: kWh
B11: input | C11: Intermediate flow | D11: Heat | E11: =E9*Parameters!C15 -> 227.15 | F11: MJ
B12: output | C12: Elementary flow | D12: Methane | E12: =Parameters!C9*(Parameters!C7*(1-Waste_characteristics!B4))*E9*Parameters!C11*0.001 -> 1.5118454 | F12: kg
B13: output | C13: Intermediate flow | D13: Biogas | E13: =(((Parameters!C7*(1-Waste_characteristics!B4))/Parameters!C10)*0.001)-((E12/Parameters!C11)*(1/Parameters!C10)) -> 223.74985 | F13: m3
B14: output | C14: Technosphere flow | D14: Digestate | E14: =Parameters!C66*E9 -> 0.5558219 | F14: t
A15: Combustion of biogas | B15: input | C15: Intermediate flow | D15: Biogas | E15: =E13 -> 223.74985 | F15: m3
B16: output | C16: Elementary flow | D16: CO2 | E16: =Parameters!C34*E15 -> 449.66648 | F16: kg
B17: output | C17: Elementary flow | D17: CH4 | E17: =$E$15*Parameters!C35 -> 0.0057327997 | F17: kg
B18: output | C18: Elementary flow | D18: N2O | E18: =$E$15*Parameters!C36 -> 0.0057327997 | F18: kg
B19: output | C19: Elementary flow | D19: Sox | E19: =$E$15*Parameters!C37 -> 0.039771298 | F19: kg
B20: output | C20: Elementary flow | D20: PM10 | E20: =$E$15*Parameters!C38 -> 0.029165619 | F20: kg
B21: output | C21: Elementary flow | D21: PM2.5 | E21: =$E$15*Parameters!C39 -> 0.029165619 | F21: kg
B22: output | C22: Elementary flow | D22: Nox | E22: =$E$15*Parameters!C40 -> 0.38338098 | F22: kg
B23: output | C23: Elementary flow | D23: NH3 | E23: =$E$15*Parameters!C41 -> 0.012110539 | F23: kg
B24: output | C24: Elementary flow | D24: CO | E24: =$E$15*Parameters!C42 -> 0.32246998 | F24: kg
B25: output | C25: Elementary flow | D25: VOC | E25: =$E$15*Parameters!C43 -> 0.019276539 | F25: kg
B26: input | C26: Technosphere flow | D26: Electricity | E26: =$E$15*Parameters!C44 -> 0.60859958 | F26: kWh
B27: output | C27: Technosphere flow | D27: Heat | E27: =E15*Parameters!C10*Parameters!C20*Parameters!C33 -> 3876.4661 | F27: MJ
A28: Storage | B28: input | C28: Technosphere flow | D28: Digestate | E28: ='LCI_AD-a'!E26 -> 0.5558219 | F28: t
B29: output | C29: Elementary flow | D29: CH4 | E29: ='LCI_AD-a'!E27 -> 1.338037 | F29: kg
B30: output | C30: Technosphere flow | D30: Digestate after storage | E30: ='LCI_AD-a'!E28 -> 0.55448387 | F30: t
A31: Land application of digestate | B31: input | C31: Technosphere flow | D31: Digestate after storage | E31: ='LCI_AD-a'!E29 -> 0.55448387 | F31: t
B32: output | C32: Elementary flow | D32: N2O | E32: ='LCI_AD-a'!E30 -> 0.069747028 | F32: kg
B33: output | C33: Elementary flow | D33: NH3 | E33: ='LCI_AD-a'!E31 -> 4.329404 | F33: kg
B34: output | C34: Elementary flow | D34: NO3 | E34: ='LCI_AD-a'!E32 -> -1.8937605 | F34: kg
B35: output | C35: Elementary flow | D35: (PO4)3- | E35: ='LCI_AD-a'!E33 -> -0.06209938 | F35: kg
B36: output | C36: Elementary flow | D36: CO2 fossil | E36: ='LCI_AD-a'!E34 -> -115.35192 | F36: kg
A37: Substituted products | E37: ='LCI_AD-a'!E35 -> 0
C38: Technosphere flow | D38: N-fertilizer | E38: ='LCI_AD-a'!E36 -> 18.00888 | F38: kg
C39: Technosphere flow | D39: P-fertilizer | E39: ='LCI_AD-a'!E37 -> 50.217839 | F39: kg
C40: Technosphere flow | D40: K-fertilizer | E40: ='LCI_AD-a'!E38 -> 18.509017 | F40: kg
...

Sheet LCI_AD-f
A1: AD+combustion+composting
A2: Process | B2: Flow direction | C2: Flow type | D2: Flow name | E2: Value | F2: Unit
A3: Pretreatment | B3: input | C3: Technosphere flow | D3: Waste | E3: 1 | F3: t
B4: input | C4: Technosphere flow | D4: Electricity | E4: =E3*Parameters!C3 -> 9.98 | F4: kWh
B5: input | C5: Technosphere flow | D5: Water
B6: output | C6: Intermediate flow | D6: Pretreated biowaste | E6: =E3*Parameters!C5 -> 0.77 | F6: t
A7: Incineration | B7: input | C7: Intermediate flow | D7: transported discarded biowaste | E7: =E8*0.001*Parameters!C6 -> 2.3 | F7: tkm
B8: input | C8: Intermediate flow | D8: discarded biowaste | E8: =E3*(1-Parameters!C5)*1000 -> 230 | F8: kg
A9: AD | B9: input | C9: Intermediate flow | D9: Pretreated waste | E9: =E6 -> 0.77 | F9: t
B10: input | C10: Intermediate flow | D10: Electricity | E10: =Parameters!C14*E9 -> 22.33 | F10: kWh
B11: input | C11: Intermediate flow | D11: Heat | E11: =E9*Parameters!C15 -> 227.15 | F11: MJ
B12: output | C12: Elementary flow | D12: Methane | E12: =Parameters!C9*(Parameters!C7*(1-Waste_characteristics!B4))*E9*Parameters!C11*0.001 -> 1.5118454 | F12: kg
B13: output | C13: Intermediate flow | D13: Biogas | E13: =(((Parameters!C7*(1-Waste_characteristics!B4))/Parameters!C10)*0.001)-((E12/Parameters!C11)*(1/Parameters!C10)) -> 223.74985 | F13: m3
B14: output | C14: Technosphere flow | D14: Digestate | E14: =Parameters!C66*E9 -> 0.5558219 | F14: t
A15: Combustion of biogas | B15: input | C15: Intermediate flow | D15: Biogas | E15: =E13 -> 223.74985 | F15: m3
B16: output | C16: Elementary flow | D16: CO2 | E16: =Parameters!C34*E15 -> 449.66648 | F16: kg
B17: output | C17: Elementary flow | D17: CH4 | E17: =$E$15*Parameters!C35 -> 0.0057327997 | F17: kg
B18: output | C18: Elementary flow | D18: N2O | E18: =$E$15*Parameters!C36 -> 0.0057327997 | F18: kg
B19: output | C19: Elementary flow | D19: Sox | E19: =$E$15*Parameters!C37 -> 0.039771298 | F19: kg
B20: output | C20: Elementary flow | D20: PM10 | E20: =$E$15*Parameters!C38 -> 0.029165619 | F20: kg
B21: output | C21: Elementary flow | D21: PM2.5 | E21: =$E$15*Parameters!C39 -> 0.029165619 | F21: kg
B22: output | C22: Elementary flow | D22: Nox | E22: =$E$15*Parameters!C40 -> 0.38338098 | F22: kg
B23: output | C23: Elementary flow | D23: NH3 | E23: =$E$15*Parameters!C41 -> 0.012110539 | F23: kg
B24: output | C24: Elementary flow | D24: CO | E24: =$E$15*Parameters!C42 -> 0.32246998 | F24: kg
B25: output | C25: Elementary flow | D25: VOC | E25: =$E$15*Parameters!C43 -> 0.019276539 | F25: kg
B26: input | C26: Technosphere flow | D26: Electricity | E26: =$E$15*Parameters!C44 -> 0.60859958 | F26: kWh
B27: output | C27: Technosphere flow | D27: Heat | E27: =E15*Parameters!C10*Parameters!C20*Parameters!C33 -> 3876.4661 | F27: MJ
A28: Dewatering | B28: input | C28: Technosphere flow | D28: Digestate | E28: ='LCI_AD-d'!E24 -> 0.5558219 | F28: t
B29: input | C29: Technosphere flow | D29: electricity | E29: ='LCI_AD-d'!E25 -> 2.0184752 | F29: kWh
B30: output | C30: Technosphere flow | D30: dewatered digestate | E30: ='LCI_AD-d'!E26 -> 0.2970039 | F30: t
B31: output | C31: Technosphere flow | D31: wastewater | E31: ='LCI_AD-d'!E27 -> 0.25911227 | F31: m3
A32: Composting of digestate | B32: input | C32: Technosphere flow | D32: dewatered digestate | E32: ='LCI_AD-d'!E28 -> 0.2970039 | F32: t
B33: output | C33: Elementary flow | D33: CH4 | E33: ='LCI_AD-d'!E29 -> 0.088228561 | F33: kg
B34: output | C34: Elementary flow | D34: N2O | E34: ='LCI_AD-d'!E30 -> 0.062318617 | F34: kg
B35: output | C35: Elementary flow | D35: NH3 | E35: ='LCI_AD-d'!E31 -> 0.20275914 | F35: kg
B36: output | C36: Elementary flow | D36: NMVOC | E36: ='LCI_AD-d'!E32 -> 0.030888406 | F36: kg
B37: output | C37: Elementary flow | D37: CO | E37: ='LCI_AD-d'!E33 -> 0.12509677 | F37: kg
B38: output | C38: Technosphere flow | D38: compost | E38: ='LCI_AD-d'!E34 -> 0.15444203 | F38: t
B39: input | C39: Technosphere flow | D39: electricity | E39: ='LCI_AD-d'!E35 -> 3.1254739 | F39: kWh
B40: input | C40: Technosphere flow | D40: diesel | E40: ='LCI_AD-d'!E36 -> 0.44883056 | F40: kg
...

Sheet LCIA_AD-d
A3: IMPACT WORLD + FOOTPRINT
A4: Process | C4: Carbon footprint | D4: Ecosystem quality (residual) | E4: Energetic resource depletion | F4: Human health (residual) | G4: Water footprint - Scarcity
A5: AD | C5: =SUM(C6,C9,C12,C16,C23,C26) -> 150.20131 | D5: =SUM(D6,D9,D12,D16,D23,D26) -> 17.579183 | E5: =SUM(E6,E9,E12,E16,E23,E26) -> 1771.9129 | F5: =SUM(F6,F9,F12,F16,F23,F26) -> 0.00018730311 | G5: =SUM(G6,G9,G12,G16,G23,G26) -> 35.078615
A6: Pretreatment | C6: =SUM(C7:C8) -> 0.7761065 | D6: =SUM(D7:D8) -> 0.11916921 | E6: =SUM(E7:E8) -> 116.96083 | F6: =SUM(F7:F8) -> 7.7420483e-07 | G6: =SUM(G7:G8) -> 1.2592267
B7: Electricity consumption | C7: ='LCI_AD-d'!$E4*'IW+f'!C2 -> 0.7761065 | D7: ='LCI_AD-d'!$E4*'IW+f'!D2 -> 0.11916921 | E7: ='LCI_AD-d'!$E4*'IW+f'!E2 -> 116.96083 | F7: ='LCI_AD-d'!$E4*'IW+f'!F2 -> 7.7420483e-07 | G7: ='LCI_AD-d'!$E4*'IW+f'!G2 -> 1.2592267
B8: Water consumption | C8: ='LCI_AD-d'!$E5*'IW+f'!C3 -> 0 | D8: ='LCI_AD-d'!$E5*'IW+f'!D3 -> 0 | E8: ='LCI_AD-d'!$E5*'IW+f'!E3 -> 0 | F8: ='LCI_AD-d'!$E5*'IW+f'!F3 -> 0 | G8: ='LCI_AD-d'!$E5*'IW+f'!G3 -> 0
A9: Incineration | C9: =SUM(C10:C11) -> 9.4912725 | D9: =SUM(D10:D11) -> 1.7760545 | E9: =SUM(E10:E11) -> 70.109594 | F9: =SUM(F10:F11) -> 3.9183036e-05 | G9: =SUM(G10:G11) -> 10.01854
B10: Transport | C10: ='LCI_AD-d'!$E7*'IW+f'!C4 -> 0.43472979 | D10: ='LCI_AD-d'!$E7*'IW+f'!D4 -> 0.063594202 | E10: ='LCI_AD-d'!$E7*'IW+f'!E4 -> 6.576112 | F10: ='LCI_AD-d'!$E7*'IW+f'!F4 -> 3.4579966e-07 | G10: ='LCI_AD-d'!$E7*'IW+f'!G4 -> 0.039223403
B11: Incineration | C11: ='LCI_AD-d'!$E8*'IW+f'!C5 -> 9.0565427 | D11: ='LCI_AD-d'!$E8*'IW+f'!D5 -> 1.7124603 | E11: ='LCI_AD-d'!$E8*'IW+f'!E5 -> 63.533482 | F11: ='LCI_AD-d'!$E8*'IW+f'!F5 -> 3.8837236e-05 | G11: ='LCI_AD-d'!$E8*'IW+f'!G5 -> 9.9793169
A12: AD | C12: =SUM(C13:C15) -> 52.248712 | D12: =SUM(D13:D15) -> 2.7873234 | E12: =SUM(E13:E15) -> 416.86802 | F12: =SUM(F13:F15) -> 4.5598348e-05 | G12: =SUM(G13:G15) -> 4.3060094
B13: Electricity | C13: ='LCI_AD-d'!$E10*'IW+f'!C2 -> 1.7365189 | D13: ='LCI_AD-d'!$E10*'IW+f'!D2 -> 0.26663811 | E13: ='LCI_AD-d'!$E10*'IW+f'!E2 -> 261.69692 | F13: ='LCI_AD-d'!$E10*'IW+f'!F2 -> 1.7322639e-06 | G13: ='LCI_AD-d'!$E10*'IW+f'!G2 -> 2.8174882
B14: Heat | C14: ='LCI_AD-d'!$E11*'IW+f'!C11 -> 9.6923673 | D14: ='LCI_AD-d'!$E11*'IW+f'!D11 -> 2.5206853 | E14: ='LCI_AD-d'!$E11*'IW+f'!E11 -> 155.1711 | F14: ='LCI_AD-d'!$E11*'IW+f'!F11 -> 4.3866084e-05 | G14: ='LCI_AD-d'!$E11*'IW+f'!G11 -> 1.4885212
B15: CH4 | C15: ='LCI_AD-d'!$E12*'IW+f'!C12 -> 40.819826 | D15: ='LCI_AD-d'!$E12*'IW+f'!D12 -> 0 | E15: ='LCI_AD-d'!$E12*'IW+f'!E12 -> 0 | F15: ='LCI_AD-d'!$E12*'IW+f'!F12 -> 0 | G15: ='LCI_AD-d'!$E12*'IW+f'!G12 -> 0
A16: Biogas upgrading | C16: =SUM(C17:C22) -> 67.422192 | D16: =SUM(D17:D22) -> 3.7790662 | E16: =SUM(E17:E22) -> 1081.6847 | F16: =SUM(F17:F22) -> 4.6055862e-05 | G16: =SUM(G17:G22) -> 18.811574
B17: CH4 | C17: ='LCI_AD-d'!$E17*'IW+f'!C12 -> 46.976728 | D17: ='LCI_AD-d'!$E17*'IW+f'!D12 -> 0 | E17: ='LCI_AD-d'!$E17*'IW+f'!E12 -> 0 | F17: ='LCI_AD-d'!$E17*'IW+f'!F12 -> 0 | G17: ='LCI_AD-d'!$E17*'IW+f'!G12 -> 0
B18: H2S | C18: ='LCI_AD-d'!$E18*'IW+f'!C24 -> 0 | D18: ='LCI_AD-d'!$E18*'IW+f'!D24 -> 0 | E18: ='LCI_AD-d'!$E18*'IW+f'!E24 -> 0 | F18: ='LCI_AD-d'!$E18*'IW+f'!F24 -> 0 | G18: ='LCI_AD-d'!$E18*'IW+f'!G24 -> 0
B19: Sox | C19: ='LCI_AD-d'!$E19*'IW+f'!C19 -> 0 | D19: ='LCI_AD-d'!$E19*'IW+f'!D19 -> 0.02458688 | E19: ='LCI_AD-d'!$E19*'IW+f'!E19 -> 0 | F19: ='LCI_AD-d'!$E19*'IW+f'!F19 -> 1.3714821e-07 | G19: ='LCI_AD-d'!$E19*'IW+f'!G19 -> 0
B20: Electricity | C20: ='LCI_AD-d'!$E20*'IW+f'!C2 -> 5.9160582 | D20: ='LCI_AD-d'!$E20*'IW+f'!D2 -> 0.9083959 | E20: ='LCI_AD-d'!$E20*'IW+f'!E2 -> 891.56201 | F20: ='LCI_AD-d'!$E20*'IW+f'!F2 -> 5.9015623e-06 | G20: ='LCI_AD-d'!$E20*'IW+f'!G2 -> 9.598758
B21: Activated carbon | C21: ='LCI_AD-d'!$E21*'IW+f'!C32 -> 0.6640648 | D21: ='LCI_AD-d'!$E21*'IW+f'!D32 -> 0.11414325 | E21: ='LCI_AD-d'!$E21*'IW+f'!E32 -> 8.3706898 | F21: ='LCI_AD-d'!$E21*'IW+f'!F32 -> 9.7423406e-07 | G21: ='LCI_AD-d'!$E21*'IW+f'!G32 -> 0.083275453
B22: Zeolite | C22: ='LCI_AD-d'!$E22*'IW+f'!C33 -> 13.865341 | D22: ='LCI_AD-d'!$E22*'IW+f'!D33 -> 2.7319401 | E22: ='LCI_AD-d'!$E22*'IW+f'!E33 -> 181.75197 | F22: ='LCI_AD-d'!$E22*'IW+f'!F33 -> 3.9042917e-05 | G22: ='LCI_AD-d'!$E22*'IW+f'!G33 -> 9.1295404
A23: Dewatering | C23: =SUM(C24:C25) -> 0.23986337 | D23: =SUM(D24:D25) -> 0.20397057 | E23: =SUM(E24:E25) -> 24.618326 | F23: =SUM(F24:F25) -> 4.0335814e-07 | G23: =SUM(G24:G25) -> 0.25421574
B24: electricity | C24: ='LCI_AD-d'!$E25*'IW+f'!C2 -> 0.15696911 | D24: ='LCI_AD-d'!$E25*'IW+f'!D2 -> 0.024102213 | E24: ='LCI_AD-d'!$E25*'IW+f'!E2 -> 23.655564 | F24: ='LCI_AD-d'!$E25*'IW+f'!F2 -> 1.5658449e-07 | G24: ='LCI_AD-d'!$E25*'IW+f'!G2 -> 0.25468114
B25: wastewater treatment | C25: ='LCI_AD-d'!$E27*'IW+f'!C34 -> 0.08289426 | D25: ='LCI_AD-d'!$E27*'IW+f'!D34 -> 0.17986836 | E25: ='LCI_AD-d'!$E27*'IW+f'!E34 -> 0.96276199 | F25: ='LCI_AD-d'!$E27*'IW+f'!F34 -> 2.4677365e-07 | G25: ='LCI_AD-d'!$E27*'IW+f'!G34 -> -0.00046540191
A26: Composting of digestate | C26: =SUM(C27:C33) -> 20.023162 | D26: =SUM(D27:D33) -> 8.9135986 | E26: =SUM(E27:E33) -> 61.671424 | F26: =SUM(F27:F33) -> 5.5288301e-05 | G26: =SUM(G27:G33) -> 0.42904899
B27: CH4 | C27: ='LCI_AD-d'!$E29*'IW+f'!C12 -> 2.3821712 | D27: ='LCI_AD-d'!$E29*'IW+f'!D12 -> 0 | E27: ='LCI_AD-d'!$E29*'IW+f'!E12 -> 0 | F27: ='LCI_AD-d'!$E29*'IW+f'!F12 -> 0 | G27: ='LCI_AD-d'!$E29*'IW+f'!G12 -> 0
B28: N2O | C28: ='LCI_AD-d'!$E30*'IW+f'!C20 -> 17.012982 | D28: ='LCI_AD-d'!$E30*'IW+f'!D20 -> 0 | E28: ='LCI_AD-d'!$E30*'IW+f'!E20 -> 0 | F28: ='LCI_AD-d'!$E30*'IW+f'!F20 -> 0 | G28: ='LCI_AD-d'!$E30*'IW+f'!G20 -> 0
B29: NH3 | C29: ='LCI_AD-d'!$E31*'IW+f'!C18 -> 0 | D29: ='LCI_AD-d'!$E31*'IW+f'!D18 -> 5.3456953 | E29: ='LCI_AD-d'!$E31*'IW+f'!E18 -> 0 | F29: ='LCI_AD-d'!$E31*'IW+f'!F18 -> 3.596854e-05 | G29: ='LCI_AD-d'!$E31*'IW+f'!G18 -> 0
B30: NMVOC | C30: ='LCI_AD-d'!$E32*'IW+f'!C23 -> 0 | D30: ='LCI_AD-d'!$E32*'IW+f'!D23 -> 0.078076707 | E30: ='LCI_AD-d'!$E32*'IW+f'!E23 -> 0 | F30: ='LCI_AD-d'!$E32*'IW+f'!F23 -> 5.0595209e-09 | G30: ='LCI_AD-d'!$E32*'IW+f'!G23 -> 0
B31: CO | C31: ='LCI_AD-b'!$E33*'IW+f'!C15 -> 0 | D31: ='LCI_AD-b'!$E33*'IW+f'!D15 -> 3.3758036 | E31: ='LCI_AD-b'!$E33*'IW+f'!E15 -> 0 | F31: ='LCI_AD-b'!$E33*'IW+f'!F15 -> 1.8830589e-05 | G31: ='LCI_AD-b'!$E33*'IW+f'!G15 -> 0
B32: electricity | C32: ='LCI_AD-d'!$E35*'IW+f'!C2 -> 0.24305618 | D32: ='LCI_AD-d'!$E35*'IW+f'!D2 -> 0.037320666 | E32: ='LCI_AD-d'!$E35*'IW+f'!E2 -> 36.62906 | F32: ='LCI_AD-d'!$E35*'IW+f'!F2 -> 2.4246062e-07 | G32: ='LCI_AD-d'!$E35*'IW+f'!G2 -> 0.39435674
B33: diesel | C33: ='LCI_AD-d'!$E36*'IW+f'!C27 -> 0.38495173 | D33: ='LCI_AD-d'!$E36*'IW+f'!D27 -> 0.076702309 | E33: ='LCI_AD-d'!$E36*'IW+f'!E27 -> 25.042364 | F33: ='LCI_AD-d'!$E36*'IW+f'!F27 -> 2.4165125e-07 | G33: ='LCI_AD-d'!$E36*'IW+f'!G27 -> 0.034692256
A34: Land application of compost | C34: =SUM(C35:C39) -> -27.214301 | D34: =SUM(D35:D39) -> 6.6866848 | E34: =SUM(E35:E39) -> 0 | F34: =SUM(F35:F39) -> 1.4004956e-05 | G34: =SUM(G35:G39) -> 0
B35: N2O | C35: ='LCI_AD-d'!$E38*'IW+f'!C20 -> 3.6020203 | D35: ='LCI_AD-d'!$E38*'IW+f'!D20 -> 0 | E35: ='LCI_AD-d'!$E38*'IW+f'!E20 -> 0 | F35: ='LCI_AD-d'!$E38*'IW+f'!F20 -> 0 | G35: ='LCI_AD-d'!$E38*'IW+f'!G20 -> 0
B36: NH3 | C36: ='LCI_AD-d'!$E39*'IW+f'!C18 -> 0 | D36: ='LCI_AD-d'!$E39*'IW+f'!D18 -> 2.0814363 | E36: ='LCI_AD-d'!$E39*'IW+f'!E18 -> 0 | F36: ='LCI_AD-d'!$E39*'IW+f'!F18 -> 1.4004956e-05 | G36: ='LCI_AD-d'!$E39*'IW+f'!G18 -> 0
B37: NO3 | C37: ='LCI_AD-d'!$E40*'IW+f'!C21 -> 0 | D37: ='LCI_AD-d'!$E40*'IW+f'!D21 -> 5.2372358 | E37: ='LCI_AD-d'!$E40*'IW+f'!E21 -> 0 | F37: ='LCI_AD-d'!$E40*'IW+f'!F21 -> 0 | G37: ='LCI_AD-d'!$E40*'IW+f'!G21 -> 0
B38: (PO4)3- | C38: ='LCI_AD-d'!$E41*'IW+f'!C25 -> 0 | D38: ='LCI_AD-d'!$E41*'IW+f'!D25 -> -0.123518 | E38: ='LCI_AD-d'!$E41*'IW+f'!E25 -> 0 | F38: ='LCI_AD-d'!$E41*'IW+f'!F25 -> 0 | G38: ='LCI_AD-d'!$E41*'IW+f'!G25 -> 0
B39: CO2 fossil | C39: ='LCI_AD-d'!$E42*'IW+f'!C26 -> -30.816321 | D39: ='LCI_AD-d'!$E42*'IW+f'!D26 -> -0.5084693 | E39: ='LCI_AD-d'!$E42*'IW+f'!E26 -> 0 | F39: ='LCI_AD-d'!$E42*'IW+f'!F26 -> 0 | G39: ='LCI_AD-d'!$E42*'IW+f'!G26 -> 0
A40: Substituted products | C40: =SUM(C41:C45) -> 0 | D40: =SUM(D41:D45) -> 21.385562 | E40: =SUM(E41:E45) -> 7190.0103 | F40: =SUM(F41:F45) -> 9.1311749e-05 | G40: =SUM(G41:G45) -> 65.554188
B41: N-fertilizer | C41: 0 | D41: ='LCI_AD-d'!$E44*'IW+f'!D28 -> 2.0596946 | E41: ='LCI_AD-d'!$E44*'IW+f'!E28 -> 228.26827 | F41: ='LCI_AD-d'!$E44*'IW+f'!F28 -> 1.1387282e-05 | G41: ='LCI_AD-d'!$E44*'IW+f'!G28 -> 23.373766
B42: P-fertilizer | C42: 0 | D42: ='LCI_AD-d'!$E45*'IW+f'!D30 -> 5.8033748 | E42: ='LCI_AD-d'!$E45*'IW+f'!E30 -> 218.3195 | F42: ='LCI_AD-d'!$E45*'IW+f'!F30 -> 4.7898741e-05 | G42: ='LCI_AD-d'!$E45*'IW+f'!G30 -> 29.538178
...

Sheet Waste_characteristics
C1: Unit
A2: Mass | B2: 1 | C2: t
A3: FW | B3: =B2-B7 -> 1 | C3: t
A4: Moisture content, FW | B4: =[2]mass_composition!$D$99/[2]mass_composition!$C$99 -> 0.63542863 | C4: %FW | D4: 0.72
A5: VS, FW | B5: =[2]mass_composition!$F$99/[2]mass_composition!$E$99 -> 0.96463821 | C5: %TS
A6: VS, FW | B6: =B3*(1-B4)*B5 -> 0.35167947 | C6: t
A7: impurities | B7: 0 | C7: t
A8: Nitrogen content, FW | B8: =[2]mass_composition!$R$99/[2]mass_composition!$E$99 -> 0.032826764 | C8: % of dry mass of FW
A9: Carbon content, FW | B9: =[2]mass_composition!$J$99/[2]mass_composition!$E$99 -> 0.46707763 | C9: % of dry mass of FW
A10: Phosphorus content, FW | B10: =[2]mass_composition!$U$99/[2]mass_composition!$E$99 -> 0.0040243826 | C10: % of dry mass of FW
A11: Potassium content, FW | B11: =[2]mass_composition!$Q$99/[2]mass_composition!$E$99 -> 0.0082642017 | C11: % of dry mass of FW
A13: Nitrogen content, FW | B13: =B8*(1-H2O_FW) -> 0.011967698 | C13: t/t of FW
A14: Carbon content, FW | B14: =B9*(1-H2O_FW) -> 0.17028313 | C14: t/t of FW
A15: Phosphorus content, FW | B15: =B10*(1-H2O_FW) -> 0.0014671747 | C15: t/t of FW
A16: Potassium content, FW | B16: =B8*(1-H2O_FW) -> 0.011967698 | C16: t/t of FW
J35: https://journals.sagepub.com/doi/full/10.1177/0734242X14545374#bibr26-0734242X14545374

Sheet Parameters
B1: Pretreatment
A2: Process | B2: Parameter | C2: Value | D2: Unit | F2: Source
A3: Pretreatment | B3: Electricity requirement | C3: 9.98 | D3: kWh/t | E3: Drum-screen + Shredder + Piston press
B4: Sorting efficiency for impurities | C4: 1 | D4: % of impurities sorted
B5: Sorting efficiency for biowaste | C5: 0.77 | D5: % of biowaste retained
B6: Distance between the industrial plant and the incineration plan | C6: 10 | D6: km
A7: AD | B7: Methane production | C7: =374*1000 -> 374000 | D7: L/dry-t | F7: https://catalog.data.gov/dataset/food-waste-management-life-cycle-inventory-tool-v1-0-0
B8: VS conversion | C8: 0.86 | D8: %VS initial
B9: Fugitive methane loss | C9: 0.02 | F9: https://catalog.data.gov/dataset/food-waste-management-life-cycle-inventory-tool-v1-0-1
B10: Methane volume share in biogas | C10: 0.6 | F10: https://catalog.data.gov/dataset/food-waste-management-life-cycle-inventory-tool-v1-0-2
B11: Methane density | C11: 0.72 | D11: kg/m3 | F11: https://catalog.data.gov/dataset/food-waste-management-life-cycle-inventory-tool-v1-0-3
B12: CO2 density | C12: 1.98 | D12: kg/m3
B13: biogas density | C13: =(C10*C11)+((1-C10)*C12) -> 1.224 | D13: kg/m3
B14: Electricity requirement | C14: 29 | D14: kWh/t | F14: https://catalog.data.gov/dataset/food-waste-management-life-cycle-inventory-tool-v1-0-4
B15: Heat requirement | C15: 295 | D15: MJ/t | F15: https://catalog.data.gov/dataset/food-waste-management-life-cycle-inventory-tool-v1-0-5
B16: Water requriement | C16: 0 | D16: %of Biowaste
A17: CHP | B17: Efficiency | F17: https://catalog.data.gov/dataset/food-waste-management-life-cycle-inventory-tool-v1-0-6
B18: Thermal | C18: 0.46 | F18: https://catalog.data.gov/dataset/food-waste-management-life-cycle-inventory-tool-v1-0-7
B19: Electric | C19: 0.39 | F19: https://catalog.data.gov/dataset/food-waste-management-life-cycle-inventory-tool-v1-0-8
B20: Methane_lhv | C20: 35 | D20: MJ/m3 | F20: https://catalog.data.gov/dataset/food-waste-management-life-cycle-inventory-tool-v1-0-9
B21: Electricity requirement | F21: https://www.sciencedirect.com/science/article/pii/S0013935122009598?casa_token=b-5UAciDODcAAAAA:iPTgJGz224xsnoQdrEctjVyXjbgpRksrTp6NPBa96VQZoPJqxyo5SRxUSGA4QFvLo7qp_-bQrQ
B22: Lubricating oil | C22: 1.54 | D22: g/m3 of biogas | F22: https://www.sciencedirect.com/science/article/pii/S0013935122009598?casa_token=b-5UAciDODcAAAAA:iPTgJGz224xsnoQdrEctjVyXjbgpRksrTp6NPBa96VQZoPJqxyo5SRxUSGA4QFvLo7qp_-bQrQ
B23: Emissions
B24: Nitrogen Oxides (NOx) | C24: 0.00016410454 | D24: kg/m3 biogas combusted | F24: https://catalog.data.gov/dataset/food-waste-management-life-cycle-inventory-tool-v1-0-0
B25: Volatile Organic Compounds (VOCs) | C25: 0.0015816552 | D25: kg/m3 biogas combusted | F25: https://catalog.data.gov/dataset/food-waste-management-life-cycle-inventory-tool-v1-0-1
B26: Sulfur Dioxide (SO2) | C26: 1.4066103e-05 | D26: kg/m3 biogas combusted | F26: https://catalog.data.gov/dataset/food-waste-management-life-cycle-inventory-tool-v1-0-2
B27: Particulate Matter (PM2.5) | C27: 3.4383808e-05 | D27: kg/m3 biogas combusted | F27: https://catalog.data.gov/dataset/food-waste-management-life-cycle-inventory-tool-v1-0-3
B28: Carbon Monoxide (CO) | C28: 0.0010682424 | D28: kg/m3 biogas combusted | F28: https://catalog.data.gov/dataset/food-waste-management-life-cycle-inventory-tool-v1-0-4
B29: Ammonia (NH3) | C29: 6.4078915e-05 | D29: kg/m3 biogas combusted | F29: https://catalog.data.gov/dataset/food-waste-management-life-cycle-inventory-tool-v1-0-5
B30: Methane (CH4) | C30: 0.0043034128 | D30: kg/m3 biogas combusted | F30: https://catalog.data.gov/dataset/food-waste-management-life-cycle-inventory-tool-v1-0-6
B31: Nitrous Oxide (N2O) | C31: 0.00010246221 | D31: kg/m3 biogas combusted | F31: https://catalog.data.gov/dataset/food-waste-management-life-cycle-inventory-tool-v1-0-7
A32: Biogas boiler
B33: Efficiency | C33: 0.825 | F33: https://pureadmin.qub.ac.uk/ws/files/135497181/Document2.pdf
B34: CO2 | C34: =L37*L$48 -> 2.009684 | D34: kg/m3 of biogas | E34: Labutong, 2012
B35: CH4 | C35: =L38*L$48 -> 2.5621469e-05 | D35: kg/m3 of biogas | E35: Labutong, 2012
B36: N2O | C36: =L39*L$48 -> 2.5621469e-05 | D36: kg/m3 of biogas | E36: Labutong, 2012
B37: Sox | C37: =L40*L$48 -> 0.00017774894 | D37: kg/m3 of biogas | E37: Labutong, 2012 | K37: CO2 | L37: =39.1+86.4 -> 125.5 | M37: lb/MCF
B38: PM10 | C38: =L41*L$48 -> 0.00013034922 | D38: kg/m3 of biogas | E38: Labutong, 2012 | K38: CH4 | L38: 0.0016 | M38: lb/MCF
B39: PM2.5 | C39: =L42*L$48 -> 0.00013034922 | D39: kg/m3 of biogas | E39: Labutong, 2012 | K39: N2O | L39: 0.0016 | M39: lb/MCF
B40: Nox | C40: =L43*L$48 -> 0.0017134357 | D40: kg/m3 of biogas | E40: Labutong, 2012 | K40: Sox | L40: 0.0111 | M40: lb/MCF
...

Sheet LCI_AD-b
A1: AD+CHP+Composting
A2: Process | B2: Flow direction | C2: Flow type | D2: Flow name | E2: Value | F2: Unit
A3: Pretreatment | B3: input | C3: Technosphere flow | D3: Waste | E3: 1 | F3: t
B4: input | C4: Technosphere flow | D4: Electricity | E4: =E3*Parameters!C3 -> 9.98 | F4: kWh
B5: input | C5: Technosphere flow | D5: Water
B6: output | C6: Intermediate flow | D6: Pretreated biowaste | E6: =E3*Parameters!C5 -> 0.77 | F6: t
A7: Incineration | B7: input | C7: Intermediate flow | D7: transported discarded biowaste | E7: =E8*0.001*Parameters!C6 -> 2.3 | F7: tkm
B8: input | C8: Intermediate flow | D8: discarded biowaste | E8: =E3*(1-Parameters!C5)*1000 -> 230 | F8: kg
A9: AD | B9: input | C9: Intermediate flow | D9: Pretreated waste | E9: =E6 -> 0.77 | F9: t
B10: input | C10: Intermediate flow | D10: Electricity | E10: =Parameters!C14*E9 -> 22.33 | F10: kWh
B11: input | C11: Intermediate flow | D11: Heat | E11: =E9*Parameters!C15 -> 227.15 | F11: MJ
B12: output | C12: Elementary flow | D12: Methane | E12: =Parameters!C9*(Parameters!C7*(1-Waste_characteristics!B4))*E9*Parameters!C11*0.001 -> 1.5118454 | F12: kg
B13: output | C13: Intermediate flow | D13: Biogas | E13: =(((Parameters!C7*(1-Waste_characteristics!B4))/Parameters!C10)*0.001)-((E12/Parameters!C11)*(1/Parameters!C10)) -> 223.74985 | F13: m3
B14: output | C14: Technosphere flow | D14: Digestate | E14: =Parameters!C66*E9 -> 0.5558219 | F14: t
A15: CHP | B15: input | C15: Intermediate flow | D15: Biogas | E15: =E13 -> 223.74985 | F15: m3
B16: output | C16: Elementary flow | D16: Nitrogen Oxides (NOx) | E16: =E15*Parameters!C24 -> 0.036718365 | F16: kg
B17: output | C17: Elementary flow | D17: Volatile Organic Compounds (VOCs) | E17: =E15*Parameters!C25 -> 0.3538951 | F17: kg
B18: output | C18: Elementary flow | D18: Sulfur Dioxide (SO2) | E18: =E15*Parameters!C26 -> 0.0031472884 | F18: kg
B19: output | C19: Elementary flow | D19: Particulate Matter (PM) | E19: =LCI!E14*Parameters!C27 -> 0.0076933718 | F19: kg
B20: output | C20: Elementary flow | D20: Carbon Monoxide (CO) | E20: =E15*Parameters!C28 -> 0.23901907 | F20: kg
B21: output | C21: Elementary flow | D21: Ammonia (NH3) | E21: =E15*Parameters!C29 -> 0.014337647 | F21: kg
B22: output | C22: Elementary flow | D22: Methane (CH4) | E22: =E15*Parameters!C30 -> 0.96288796 | F22: kg
B23: output | C23: Elementary flow | D23: Nitrous Oxide (N2O) | E23: =LCI!E14*Parameters!C31 -> 0.022925904 | F23: kg
B24: output | C24: Technosphere flow | D24: Electricity | E24: =E15*Parameters!C10*Parameters!C20*Parameters!C19/3.6 -> 509.0309 | F24: kWh
B25: output | C25: Technosphere flow | D25: Heat | E25: =E15*Parameters!C10*Parameters!C20*Parameters!C18 -> 2161.4235 | F25: MJ
A26: Dewatering | B26: input | C26: Technosphere flow | D26: Digestate | E26: =E14 -> 0.5558219 | F26: t
B27: input | C27: Technosphere flow | D27: electricity | E27: =E26*Parameters!C90*1000 -> 2.0184752 | F27: kWh
B28: output | C28: Technosphere flow | D28: dewatered digestate | E28: =Parameters!C68*E9*Parameters!C88*(1/Parameters!C89) -> 0.2970039 | F28: t
B29: output | C29: Technosphere flow | D29: wastewater | E29: =(E26-E28)*1000/Parameters!C70 -> 0.25911227 | F29: m3
A30: Composting of digestate | B30: input | C30: Technosphere flow | D30: dewatered digestate | E30: =E28 -> 0.2970039 | F30: t
B31: output | C31: Elementary flow | D31: CH4 | E31: =(16/12)*Parameters!C98*(1-Parameters!C94)*((E6*1000*(1-Waste_characteristics!B4)*Waste_characteristics!B9)-((E13*(1-Parameters!C10)*Parameters!C12*(12/44)))-((E13*(Parameters!C10)*Parameters!C11*(12/16)))) -> 0.088228561 | F31: kg | H31: Cinit - C(CO2,CH4 in biogas) - C lost in water fraction of digestate
B32: output | C32: Elementary flow | D32: N2O | E32: =(E6*1000*(1-Waste_characteristics!B4)*Waste_characteristics!B8)*(1-Parameters!C91)*Parameters!C99*(44/28) -> 0.062318617 | F32: kg
B33: output | C33: Elementary flow | D33: NH3 | E33: =(E6*1000*(1-Waste_characteristics!B4)*Waste_characteristics!B8)*(1-Parameters!C91)*Parameters!C100*(17/14) -> 0.20275914 | F33: kg
B34: output | C34: Elementary flow | D34: NMVOC | E34: =E30*Parameters!C101 -> 0.030888406 | F34: kg
B35: output | C35: Elementary flow | D35: CO | E35: =(44/12)*Parameters!C102*(1-Parameters!C94)*((E6*1000*(1-Waste_characteristics!B4)*Waste_characteristics!B9)-((E14*(1-Parameters!C10)*Parameters!C12*(12/44)))-((E14*(Parameters!C10)*Parameters!C11*(12/16)))) -> 0.12509677 | F35: kg
B36: output | C36: Technosphere flow | D36: compost | E36: =E30*(1-Parameters!C103) -> 0.15444203 | F36: t
B37: input | C37: Technosphere flow | D37: electricity | E37: =E30*Parameters!C104 -> 3.1254739 | F37: kWh
B38: input | C38: Technosphere flow | D38: diesel | E38: =E30*Parameters!C105*Parameters!C106 -> 0.44883056 | F38: kg
A39: Land application of compost
B40: output | C40: Elementary flow | D40: N2O | E40: =(Parameters!C107*E9*1000*Parameters!C108*44/28)-(E46*Parameters!C123*Parameters!C125*44/28) -> 0.013194214 | F40: kg
...

Sheet LCI
A2: Process | B2: Flow direction | C2: Flow type | D2: Flow name | E2: Value | F2: Unit | I2: UF | J2: Treatment of 1t of biowaste
A3: Pretreatment | B3: input | C3: Technosphere flow | D3: Waste | E3: 1 | F3: t
B4: input | C4: Technosphere flow | D4: Electricity | E4: =E3*Parameters!C3 -> 9.98 | F4: kWh
B5: input | C5: Technosphere flow | D5: Water
B6: output | C6: Intermediate flow | D6: Pretreated biowaste | E6: =E3*Parameters!C5 -> 0.77 | F6: t
A7: Incineration | B7: input | C7: Intermediate flow | D7: discarded biowaste | E7: =E3*(1-Parameters!C5)*1000 -> 230 | F7: kg
A9: AD | B9: input | C9: Intermediate flow | D9: Pretreated waste | E9: =E6 -> 0.77 | F9: t
B10: input | C10: Intermediate flow | D10: Electricity | E10: =Parameters!C14*LCI!E9 -> 22.33 | F10: kWh
B11: input | C11: Intermediate flow | D11: Heat | E11: =E9*Parameters!C15 -> 227.15 | F11: MJ
B12: output | C12: Elementary flow | D12: Methane | E12: =Parameters!C9*(Parameters!C7*(1-Waste_characteristics!B4))*LCI!E9*Parameters!C11*0.001 -> 1.5118454 | F12: kg
B13: output | C13: Intermediate flow | D13: Biogas | E13: =(((Parameters!C7*(1-Waste_characteristics!B4))/Parameters!C10)*0.001)-((E12/Parameters!C11)*(1/Parameters!C10)) -> 223.74985 | F13: m3
A14: CHP | B14: input | C14: Intermediate flow | D14: Biogas | E14: =E13 -> 223.74985 | F14: m3
B15: output | C15: Elementary flow | D15: Nitrogen Oxides (NOx) | E15: =E14*Parameters!C24 -> 0.036718365 | F15: kg
B16: output | C16: Elementary flow | D16: Volatile Organic Compounds (VOCs) | E16: =E14*Parameters!C25 -> 0.3538951 | F16: kg
B17: output | C17: Elementary flow | D17: Sulfur Dioxide (SO2) | E17: =E14*Parameters!C26 -> 0.0031472884 | F17: kg
B18: output | C18: Elementary flow | D18: Particulate Matter (PM) | E18: =LCI!E14*Parameters!C27 -> 0.0076933718 | F18: kg
B19: output | C19: Elementary flow | D19: Carbon Monoxide (CO) | E19: =E14*Parameters!C28 -> 0.23901907 | F19: kg
B20: output | C20: Elementary flow | D20: Ammonia (NH3) | E20: =E14*Parameters!C29 -> 0.014337647 | F20: kg
B21: output | C21: Elementary flow | D21: Methane (CH4) | E21: =E14*Parameters!C30 -> 0.96288796 | F21: kg
B22: output | C22: Elementary flow | D22: Nitrous Oxide (N2O) | E22: =LCI!E14*Parameters!C31 -> 0.022925904 | F22: kg
B23: output | C23: Technosphere flow | D23: Electricity | E23: =E14*Parameters!C10*Parameters!C20*Parameters!C19/3.6 -> 509.0309 | F23: kWh
B24: output | C24: Technosphere flow | D24: Heat | E24: =E14*Parameters!C10*Parameters!C20*Parameters!C18 -> 2161.4235 | F24: MJ
A27: Biogas boiler | B27: input | C27: Intermediate flow | D27: Biogas | E27: =E13 -> 223.74985 | F27: m3
B28: output | C28: Elementary flow | D28: CO2 | E28: =$E$27*Parameters!C34 -> 449.66648 | F28: kg
B29: output | C29: Elementary flow | D29: CH4 | E29: =$E$27*Parameters!C35 -> 0.0057327997 | F29: kg
B30: output | C30: Elementary flow | D30: N2O | E30: =$E$27*Parameters!C36 -> 0.0057327997 | F30: kg
B31: output | C31: Elementary flow | D31: Sox | E31: =$E$27*Parameters!C37 -> 0.039771298 | F31: kg
B32: output | C32: Elementary flow | D32: PM10 | E32: =$E$27*Parameters!C38 -> 0.029165619 | F32: kg
B33: output | C33: Elementary flow | D33: PM2.5 | E33: =$E$27*Parameters!C39 -> 0.029165619 | F33: kg
B34: output | C34: Elementary flow | D34: Nox | E34: =$E$27*Parameters!C40 -> 0.38338098 | F34: kg
B35: output | C35: Elementary flow | D35: NH3 | E35: =$E$27*Parameters!C41 -> 0.012110539 | F35: kg
B36: output | C36: Elementary flow | D36: CO | E36: =$E$27*Parameters!C42 -> 0.32246998 | F36: kg
B37: output | C37: Elementary flow | D37: VOC | E37: =$E$27*Parameters!C43 -> 0.019276539 | F37: kg
B38: input | C38: Technosphere flow | D38: Electricity | E38: =Parameters!C44*LCI!E27 -> 0.60859958 | F38: kWh
B39: output | C39: Technosphere flow | D39: Heat | E39: =E27*Parameters!C10*Parameters!C20*Parameters!C33 -> 3876.4661 | F39: MJ
A42: Biogas upgrading | B42: input | C42: Technosphere flow | D42: Biogas | E42: =E13 -> 223.74985 | F42: m3
B43: output | C43: Elementary flow | D43: CO2 | E43: =E42*(1-Parameters!C10)*Parameters!C47*Parameters!C12 -> 174.55173 | F43: kg
B44: output | C44: Elementary flow | D44: CH4 | E44: =E42*Parameters!C10*Parameters!C48*Parameters!C11 -> 1.7398788 | F44: kg
B45: output | C45: Elementary flow | D45: H2S | E45: =Parameters!C49*LCI!E42 -> 0.0013424991 | F45: kg
B46: output | C46: Elementary flow | D46: Sox | E46: =E42*Parameters!C50 -> 0.001476749 | F46: kg
...

Sheet LCI_AD-a
A1: AD+CHP+Digestate
A2: Process | B2: Flow direction | C2: Flow type | D2: Flow name | E2: Value | F2: Unit
A3: Pretreatment | B3: input | C3: Technosphere flow | D3: Waste | E3: 1 | F3: t
B4: input | C4: Technosphere flow | D4: Electricity | E4: =E3*Parameters!C3 -> 9.98 | F4: kWh
B5: input | C5: Technosphere flow | D5: Water
B6: output | C6: Intermediate flow | D6: Pretreated biowaste | E6: =E3*Parameters!C5 -> 0.77 | F6: t
A7: Incineration | B7: input | C7: Intermediate flow | D7: transported discarded biowaste | E7: =E8*0.001*Parameters!C6 -> 2.3 | F7: tkm
B8: input | C8: Intermediate flow | D8: discarded biowaste | E8: =E3*(1-Parameters!C5)*1000 -> 230 | F8: kg
A9: AD | B9: input | C9: Intermediate flow | D9: Pretreated waste | E9: =E6 -> 0.77 | F9: t
B10: input | C10: Intermediate flow | D10: Electricity | E10: =Parameters!C14*E9 -> 22.33 | F10: kWh
B11: input | C11: Intermediate flow | D11: Heat | E11: =E9*Parameters!C15 -> 227.15 | F11: MJ
B12: output | C12: Elementary flow | D12: Methane | E12: =Parameters!C9*(Parameters!C7*(1-Waste_characteristics!B4))*E9*Parameters!C11*0.001 -> 1.5118454 | F12: kg
B13: output | C13: Intermediate flow | D13: Biogas | E13: =(((Parameters!C7*(1-Waste_characteristics!B4))/Parameters!C10)*0.001)-((E12/Parameters!C11)*(1/Parameters!C10)) -> 223.74985 | F13: m3
B14: output | C14: Technosphere flow | D14: Digestate | E14: =Parameters!C66*E9 -> 0.5558219 | F14: t
A15: CHP | B15: input | C15: Intermediate flow | D15: Biogas | E15: =E13 -> 223.74985 | F15: m3
B16: output | C16: Elementary flow | D16: Nitrogen Oxides (NOx) | E16: =E15*Parameters!C24 -> 0.036718365 | F16: kg
B17: output | C17: Elementary flow | D17: Volatile Organic Compounds (VOCs) | E17: =E15*Parameters!C25 -> 0.3538951 | F17: kg
B18: output | C18: Elementary flow | D18: Sulfur Dioxide (SO2) | E18: =E15*Parameters!C26 -> 0.0031472884 | F18: kg
B19: output | C19: Elementary flow | D19: Particulate Matter (PM) | E19: =LCI!E14*Parameters!C27 -> 0.0076933718 | F19: kg
B20: output | C20: Elementary flow | D20: Carbon Monoxide (CO) | E20: =E15*Parameters!C28 -> 0.23901907 | F20: kg
B21: output | C21: Elementary flow | D21: Ammonia (NH3) | E21: =E15*Parameters!C29 -> 0.014337647 | F21: kg
B22: output | C22: Elementary flow | D22: Methane (CH4) | E22: =E15*Parameters!C30 -> 0.96288796 | F22: kg
B23: output | C23: Elementary flow | D23: Nitrous Oxide (N2O) | E23: =LCI!E14*Parameters!C31 -> 0.022925904 | F23: kg
B24: output | C24: Technosphere flow | D24: Electricity | E24: =E15*Parameters!C10*Parameters!C20*Parameters!C19/3.6 -> 509.0309 | F24: kWh
B25: output | C25: Technosphere flow | D25: Heat | E25: =E15*Parameters!C10*Parameters!C20*Parameters!C18 -> 2161.4235 | F25: MJ
A26: Storage | B26: input | C26: Technosphere flow | D26: Digestate | E26: =E14 -> 0.5558219 | F26: t
B27: output | C27: Elementary flow | D27: CH4 | E27: =Parameters!C75*E9*1000 -> 1.338037 | F27: kg
B28: output | C28: Technosphere flow | D28: Digestate after storage | E28: =E26-(E27*0.001) -> 0.55448387 | F28: t
A29: Land application of digestate | B29: input | C29: Technosphere flow | D29: Digestate after storage | E29: =E28 -> 0.55448387 | F29: t
B30: output | C30: Elementary flow | D30: N2O | E30: =(Parameters!C82*'LCI_AD-a'!E9*1000*Parameters!C79*44/28)-(E36*Parameters!C123*Parameters!C125*44/28) -> 0.069747028 | F30: kg | H30: NET EMISSION TO BE calculated
B31: output | C31: Elementary flow | D31: NH3 | E31: =(Parameters!C82*'LCI_AD-a'!E9*1000*Parameters!C80*17/14)-(E36*Parameters!C123*Parameters!C124*17/14) -> 4.329404 | F31: kg
B32: output | C32: Elementary flow | D32: NO3 | E32: =(Parameters!C82*'LCI_AD-a'!E9*1000*Parameters!C81*62/14)-(E36*Parameters!C123*Parameters!C126*62/14) -> -1.8937605 | F32: kg
B33: output | C33: Elementary flow | D33: (PO4)3- | E33: =-Parameters!C129*'LCI_AD-a'!E37*Parameters!C128*0.001 -> -0.06209938 | F33: kg
B34: output | C34: Elementary flow | D34: CO2 fossil | E34: =-E39*Parameters!C136*Parameters!C134*44/12 -> -115.35192 | F34: kg
A35: Substituted products
C36: Technosphere flow | D36: N-fertilizer | E36: =(Parameters!C83/Parameters!C127)*FW_mass*1000*E6/Parameters!C123 -> 18.00888 | F36: kg | G36: NH4NO3
C37: Technosphere flow | D37: P-fertilizer | E37: =(Parameters!C86/Parameters!C131)*1000*'LCI_AD-a'!E9/Parameters!C128 -> 50.217839 | F37: kg | G37: single superphosphate
C38: Technosphere flow | D38: K-fertilizer | E38: =(Parameters!C85/Parameters!C132)*'LCI_AD-a'!E9*1000 -> 18.509017 | F38: kg
C39: Technosphere flow | D39: Peat | E39: =(Parameters!C84/Parameters!C136)*1000*E9 -> 157.62594 | F39: kg
C40: Technosphere flow | D40: Marginal heat | E40: =E25 -> 2161.4235 | F40: MJ
...

Sheet LCI_AD-c
A1: AD+injection+Digestate
A2: Process | B2: Flow direction | C2: Flow type | D2: Flow name | E2: Value | F2: Unit
A3: Pretreatment | B3: input | C3: Technosphere flow | D3: Waste | E3: 1 | F3: t
B4: input | C4: Technosphere flow | D4: Electricity | E4: =E3*Parameters!C3 -> 9.98 | F4: kWh
B5: input | C5: Technosphere flow | D5: Water
B6: output | C6: Intermediate flow | D6: Pretreated biowaste | E6: =E3*Parameters!C5 -> 0.77 | F6: t
A7: Incineration | B7: input | C7: Intermediate flow | D7: transported discarded biowaste | E7: =E8*0.001*Parameters!C6 -> 2.3 | F7: tkm
B8: input | C8: Intermediate flow | D8: discarded biowaste | E8: =E3*(1-Parameters!C5)*1000 -> 230 | F8: kg
A9: AD | B9: input | C9: Intermediate flow | D9: Pretreated waste | E9: =E6 -> 0.77 | F9: t
B10: input | C10: Intermediate flow | D10: Electricity | E10: =Parameters!C14*E9 -> 22.33 | F10: kWh
B11: input | C11: Intermediate flow | D11: Heat | E11: =E9*Parameters!C15 -> 227.15 | F11: MJ
B12: output | C12: Elementary flow | D12: Methane | E12: =Parameters!C9*(Parameters!C7*(1-Waste_characteristics!B4))*E9*Parameters!C11*0.001 -> 1.5118454 | F12: kg
B13: output | C13: Intermediate flow | D13: Biogas | E13: =(((Parameters!C7*(1-Waste_characteristics!B4))/Parameters!C10)*0.001)-((E12/Parameters!C11)*(1/Parameters!C10)) -> 223.74985 | F13: m3
B14: output | C14: Technosphere flow | D14: Digestate | E14: =Parameters!C66*E9 -> 0.5558219 | F14: t
A15: Biogas upgrading | B15: input | C15: Technosphere flow | D15: Biogas | E15: =E13 -> 223.74985 | F15: m3
B16: output | C16: Elementary flow | D16: CO2 | E16: =E15*(1-Parameters!C10)*Parameters!C47*Parameters!C12 -> 174.55173 | F16: kg
B17: output | C17: Elementary flow | D17: CH4 | E17: =E15*Parameters!C10*Parameters!C48*Parameters!C11 -> 1.7398788 | F17: kg
B18: output | C18: Elementary flow | D18: H2S | E18: =Parameters!C49*E15 -> 0.0013424991 | F18: kg
