Workbook
Name Food_Type: "Baseline"
Name FW_mass: Waste_characteristics!$B$3
Name H2O_FW: Waste_characteristics!$B$4
Name Mass: Waste_characteristics!$B$2
Name mass_VS_FW: Waste_characteristics!$B$6
Name Methane_LHV: '[1]Global params'!$E$21
Name VS_FW: Waste_characteristics!$B$5

Sheet LCIA_AD-f
A3: IMPACT WORLD + FOOTPRINT
A4: Process | C4: Carbon footprint | D4: Ecosystem quality (residual) | E4: Energetic resource depletion | F4: Human health (residual) | G4: Water footprint - Scarcity
A5: AD | C5: =SUM(C6,C9,C12,C16,C27) -> 64.523122 | D5: =SUM(D6,D9,D12,D16,D27) -> 12.136919 | E5: =SUM(E6,E9,E12,E16,E27) -> 635.68927 | F5: =SUM(F6,F9,F12,F16,F27) -> 0.00013928494 | G5: =SUM(G6,G9,G12,G16,G27) -> 15.914782
A6: Pretreatment | C6: =SUM(C7:C8) -> 0.7761065 | D6: =SUM(D7:D8) -> 0.11916921 | E6: =SUM(E7:E8) -> 116.96083 | F6: =SUM(F7:F8) -> 7.7420483e-07 | G6: =SUM(G7:G8) -> 1.2592267
B7: Electricity consumption | C7: ='LCI_AD-e'!$E4*'IW+f'!C2 -> 0.7761065 | D7: ='LCI_AD-e'!$E4*'IW+f'!D2 -> 0.11916921 | E7: ='LCI_AD-e'!$E4*'IW+f'!E2 -> 116.96083 | F7: ='LCI_AD-e'!$E4*'IW+f'!F2 -> 7.7420483e-07 | G7: ='LCI_AD-e'!$E4*'IW+f'!G2 -> 1.2592267
B8: Water consumption | C8: ='LCI_AD-e'!$E5*'IW+f'!C3 -> 0 | D8: ='LCI_AD-e'!$E5*'IW+f'!D3 -> 0 | E8: ='LCI_AD-e'!$E5*'IW+f'!E3 -> 0 | F8: ='LCI_AD-e'!$E5*'IW+f'!F3 -> 0 | G8: ='LCI_AD-e'!$E5*'IW+f'!G3 -> 0
A9: Incineration | C9: =SUM(C10:C11) -> 9.4912725 | D9: =SUM(D10:D11) -> 1.7760545 | E9: =SUM(E10:E11) -> 70.109594 | F9: =SUM(F10:F11) -> 3.9183036e-05 | G9: =SUM(G10:G11) -> 10.01854
B10: Transport | C10: ='LCI_AD-e'!$E7*'IW+f'!C4 -> 0.43472979 | D10: ='LCI_AD-e'!$E7*'IW+f'!D4 -> 0.063594202 | E10: ='LCI_AD-e'!$E7*'IW+f'!E4 -> 6.576112 | F10: ='LCI_AD-e'!$E7*'IW+f'!F4 -> 3.4579966e-07 | G10: ='LCI_AD-e'!$E7*'IW+f'!G4 -> 0.039223403
B11: Incineration | C11: ='LCI_AD-e'!$E8*'IW+f'!C5 -> 9.0565427 | D11: ='LCI_AD-e'!$E8*'IW+f'!D5 -> 1.7124603 | E11: ='LCI_AD-e'!$E8*'IW+f'!E5 -> 63.533482 | F11: ='LCI_AD-e'!$E8*'IW+f'!F5 -> 3.8837236e-05 | G11: ='LCI_AD-e'!$E8*'IW+f'!G5 -> 9.9793169
A12: AD | C12: =SUM(C13:C15) -> 52.248712 | D12: =SUM(D13:D15) -> 2.7873234 | E12: =SUM(E13:E15) -> 416.86802 | F12: =SUM(F13:F15) -> 4.5598348e-05 | G12: =SUM(G13:G15) -> 4.3060094
B13: Electricity | C13: ='LCI_AD-e'!$E10*'IW+f'!C2 -> 1.7365189 | D13: ='LCI_AD-e'!$E10*'IW+f'!D2 -> 0.26663811 | E13: ='LCI_AD-e'!$E10*'IW+f'!E2 -> 261.69692 | F13: ='LCI_AD-e'!$E10*'IW+f'!F2 -> 1.7322639e-06 | G13: ='LCI_AD-e'!$E10*'IW+f'!G2 -> 2.8174882
B14: Heat | C14: ='LCI_AD-e'!$E11*'IW+f'!C11 -> 9.6923673 | D14: ='LCI_AD-e'!$E11*'IW+f'!D11 -> 2.5206853 | E14: ='LCI_AD-e'!$E11*'IW+f'!E11 -> 155.1711 | F14: ='LCI_AD-e'!$E11*'IW+f'!F11 -> 4.3866084e-05 | G14: ='LCI_AD-e'!$E11*'IW+f'!G11 -> 1.4885212
B15: CH4 | C15: ='LCI_AD-e'!$E12*'IW+f'!C12 -> 40.819826 | D15: ='LCI_AD-e'!$E12*'IW+f'!D12 -> 0 | E15: ='LCI_AD-e'!$E12*'IW+f'!E12 -> 0 | F15: ='LCI_AD-e'!$E12*'IW+f'!F12 -> 0 | G15: ='LCI_AD-e'!$E12*'IW+f'!G12 -> 0
A16: Combustion of biogas | C16: =SUM(C17:C26) -> 1.7671684 | D16: =SUM(D17:D26) -> 7.2504014 | E16: =SUM(E17:E26) -> 7.132496 | F16: =SUM(F17:F26) -> 5.3325992e-05 | G16: =SUM(G17:G26) -> 0.076790064
B17: CH4 | C17: ='LCI_AD-e'!$E17*'IW+f'!C12 -> 0.15478559 | D17: ='LCI_AD-e'!$E17*'IW+f'!D12 -> 0 | E17: ='LCI_AD-e'!$E17*'IW+f'!E12 -> 0 | F17: ='LCI_AD-e'!$E17*'IW+f'!F12 -> 0 | G17: ='LCI_AD-e'!$E17*'IW+f'!G12 -> 0
B18: N2O | C18: ='LCI_AD-e'!$E18*'IW+f'!C20 -> 1.5650543 | D18: ='LCI_AD-e'!$E18*'IW+f'!D20 -> 0 | E18: ='LCI_AD-e'!$E18*'IW+f'!E20 -> 0 | F18: ='LCI_AD-e'!$E18*'IW+f'!F20 -> 0 | G18: ='LCI_AD-e'!$E18*'IW+f'!G20 -> 0
B19: Sox | C19: ='LCI_AD-e'!$E19*'IW+f'!C19 -> 0 | D19: ='LCI_AD-e'!$E19*'IW+f'!D19 -> 0.66216543 | E19: ='LCI_AD-e'!$E19*'IW+f'!E19 -> 0 | F19: ='LCI_AD-e'!$E19*'IW+f'!F19 -> 3.6936286e-06 | G19: ='LCI_AD-e'!$E19*'IW+f'!G19 -> 0
B20: PM10 | C20: ='LCI_AD-e'!$E20*'IW+f'!C16 -> 0 | D20: ='LCI_AD-e'!$E20*'IW+f'!D16 -> 0 | E20: ='LCI_AD-e'!$E20*'IW+f'!E16 -> 0 | F20: ='LCI_AD-e'!$E20*'IW+f'!F16 -> 0 | G20: ='LCI_AD-e'!$E20*'IW+f'!G16 -> 0
B21: PM2.5 | C21: ='LCI_AD-e'!$E21*'IW+f'!C22 -> 0 | D21: ='LCI_AD-e'!$E21*'IW+f'!D22 -> 0 | E21: ='LCI_AD-e'!$E21*'IW+f'!E22 -> 0 | F21: ='LCI_AD-e'!$E21*'IW+f'!F22 -> 3.9886858e-05 | G21: ='LCI_AD-e'!$E21*'IW+f'!G22 -> 0
B22: Nox | C22: ='LCI_AD-e'!$E22*'IW+f'!C13 -> 0 | D22: ='LCI_AD-e'!$E22*'IW+f'!D13 -> 6.2616774 | E22: ='LCI_AD-e'!$E22*'IW+f'!E13 -> 0 | F22: ='LCI_AD-e'!$E22*'IW+f'!F13 -> 7.5499383e-06 | G22: ='LCI_AD-e'!$E22*'IW+f'!G13 -> 0
B23: NH3 | C23: ='LCI_AD-e'!$E23*'IW+f'!C18 -> 0 | D23: ='LCI_AD-e'!$E23*'IW+f'!D18 -> 0.31929142 | E23: ='LCI_AD-e'!$E23*'IW+f'!E18 -> 0 | F23: ='LCI_AD-e'!$E23*'IW+f'!F18 -> 2.1483541e-06 | G23: ='LCI_AD-e'!$E23*'IW+f'!G18 -> 0
B24: CO | C24: ='LCI_AD-e'!$E24*'IW+f'!C17 -> 0 | D24: ='LCI_AD-e'!$E24*'IW+f'!D17 -> 0 | E24: ='LCI_AD-e'!$E24*'IW+f'!E17 -> 0 | F24: ='LCI_AD-e'!$E24*'IW+f'!F17 -> 0 | G24: ='LCI_AD-e'!$E24*'IW+f'!G17 -> 0
B25: VOC | C25: ='LCI_AD-e'!$E25*'IW+f'!C14 -> 0 | D25: ='LCI_AD-e'!$E25*'IW+f'!D14 -> 0 | E25: ='LCI_AD-e'!$E25*'IW+f'!E14 -> 0 | F25: ='LCI_AD-e'!$E25*'IW+f'!F14 -> 0 | G25: ='LCI_AD-e'!$E25*'IW+f'!G14 -> 0
B26: Electricity | C26: ='LCI_AD-e'!$E26*'IW+f'!C2 -> 0.047328466 | D26: ='LCI_AD-e'!$E26*'IW+f'!D2 -> 0.0072671672 | E26: ='LCI_AD-e'!$E26*'IW+f'!E2 -> 7.132496 | F26: ='LCI_AD-e'!$E26*'IW+f'!F2 -> 4.7212498e-08 | G26: ='LCI_AD-e'!$E26*'IW+f'!G2 -> 0.076790064
A27: Dewatering | C27: ='LCIA_AD-b'!C25 -> 0.23986337 | D27: ='LCIA_AD-b'!D25 -> 0.20397057 | E27: ='LCIA_AD-b'!E25 -> 24.618326 | F27: ='LCIA_AD-b'!F25 -> 4.0335814e-07 | G27: ='LCIA_AD-b'!G25 -> 0.25421574
B28: electricity | C28: ='LCIA_AD-b'!C26 -> 0.15696911 | D28: ='LCIA_AD-b'!D26 -> 0.024102213 | E28: ='LCIA_AD-b'!E26 -> 23.655564 | F28: ='LCIA_AD-b'!F26 -> 1.5658449e-07 | G28: ='LCIA_AD-b'!G26 -> 0.25468114
B29: wastewater treatment | C29: ='LCIA_AD-b'!C27 -> 0.08289426 | D29: ='LCIA_AD-b'!D27 -> 0.17986836 | E29: ='LCIA_AD-b'!E27 -> 0.96276199 | F29: ='LCIA_AD-b'!F27 -> 2.4677365e-07 | G29: ='LCIA_AD-b'!G27 -> -0.00046540191
A30: Composting of digestate | C30: ='LCIA_AD-b'!C28 -> 20.023162 | D30: ='LCIA_AD-b'!D28 -> 5.537795 | E30: ='LCIA_AD-b'!E28 -> 61.671424 | F30: ='LCIA_AD-b'!F28 -> 3.6457712e-05 | G30: ='LCIA_AD-b'!G28 -> 0.42904899
B31: CH4 | C31: ='LCIA_AD-b'!C29 -> 2.3821712 | D31: ='LCIA_AD-b'!D29 -> 0 | E31: ='LCIA_AD-b'!E29 -> 0 | F31: ='LCIA_AD-b'!F29 -> 0 | G31: ='LCIA_AD-b'!G29 -> 0
B32: N2O | C32: ='LCIA_AD-b'!C30 -> 17.012982 | D32: ='LCIA_AD-b'!D30 -> 0 | E32: ='LCIA_AD-b'!E30 -> 0 | F32: ='LCIA_AD-b'!F30 -> 0 | G32: ='LCIA_AD-b'!G30 -> 0
B33: NH3 | C33: ='LCIA_AD-b'!C31 -> 0 | D33: ='LCIA_AD-b'!D31 -> 5.3456953 | E33: ='LCIA_AD-b'!E31 -> 0 | F33: ='LCIA_AD-b'!F31 -> 3.596854e-05 | G33: ='LCIA_AD-b'!G31 -> 0
B34: NMVOC | C34: ='LCIA_AD-b'!C32 -> 0 | D34: ='LCIA_AD-b'!D32 -> 0.078076707 | E34: ='LCIA_AD-b'!E32 -> 0 | F34: ='LCIA_AD-b'!F32 -> 5.0595209e-09 | G34: ='LCIA_AD-b'!G32 -> 0
B35: CO | C35: ='LCIA_AD-b'!C33 -> 0 | D35: ='LCIA_AD-b'!D33 -> 0 | E35: ='LCIA_AD-b'!E33 -> 0 | F35: ='LCIA_AD-b'!F33 -> 0 | G35: ='LCIA_AD-b'!G33 -> 0
B36: electricity | C36: ='LCIA_AD-b'!C34 -> 0.24305618 | D36: ='LCIA_AD-b'!D34 -> 0.037320666 | E36: ='LCIA_AD-b'!E34 -> 36.62906 | F36: ='LCIA_AD-b'!F34 -> 2.4246062e-07 | G36: ='LCIA_AD-b'!G34 -> 0.39435674
B37: diesel | C37: ='LCIA_AD-b'!C35 -> 0.38495173 | D37: ='LCIA_AD-b'!D35 -> 0.076702309 | E37: ='LCIA_AD-b'!E35 -> 25.042364 | F37: ='LCIA_AD-b'!F35 -> 2.4165125e-07 | G37: ='LCIA_AD-b'!G35 -> 0.034692256
A38: Land application of compost | C38: ='LCIA_AD-b'!C36 -> -27.214301 | D38: ='LCIA_AD-b'!D36 -> 7.1951541 | E38: ='LCIA_AD-b'!E36 -> 0 | F38: ='LCIA_AD-b'!F36 -> 1.4004956e-05 | G38: ='LCIA_AD-b'!G36 -> 0
B39: N2O | C39: ='LCIA_AD-b'!C37 -> 3.6020203 | D39: ='LCIA_AD-b'!D37 -> 0 | E39: ='LCIA_AD-b'!E37 -> 0 | F39: ='LCIA_AD-b'!F37 -> 0 | G39: ='LCIA_AD-b'!G37 -> 0
B40: NH3 | C40: ='LCIA_AD-b'!C38 -> 0 | D40: ='LCIA_AD-b'!D38 -> 2.0814363 | E40: ='LCIA_AD-b'!E38 -> 0 | F40: ='LCIA_AD-b'!F38 -> 1.4004956e-05 | G40: ='LCIA_AD-b'!G38 -> 0
B41: NO3 | C41: ='LCIA_AD-b'!C39 -> 0 | D41: ='LCIA_AD-b'!D39 -> 5.2372358 | E41: ='LCIA_AD-b'!E39 -> 0 | F41: ='LCIA_AD-b'!F39 -> 0 | G41: ='LCIA_AD-b'!G39 -> 0
B42: (PO4)3- | C42: ='LCIA_AD-b'!C40 -> 0 | D42: ='LCIA_AD-b'!D40 -> -0.123518 | E42: ='LCIA_AD-b'!E40 -> 0 | F42: ='LCIA_AD-b'!F40 -> 0 | G42: ='LCIA_AD-b'!G40 -> 0
...

Sheet IW+_end
A1: Process | B1: Reference unit | C1: Fisheries impact | D1: Freshwater acidification | E1: Freshwater ecotoxicity, long term | F1: Freshwater ecotoxicity, short term | G1: Freshwater eutrophication | H1: Human toxicity cancer, long term | I1: Human toxicity cancer, short term | J1: Human toxicity non-cancer, long term | K1: Human toxicity non-cancer, short term | L1: Ionizing radiations, ecosystem quality | M1: Ionizing radiations, human health | N1: Land occupation, biodiversity | O1: Land transformation, biodiversity | P1: Marine acidification, long term | Q1: Marine acidification, short term | R1: Marine ecotoxicity, long term | S1: Marine ecotoxicity, short term | T1: Marine eutrophication | U1: Ozone layer depletion | V1: Particulate matter formation | W1: Photochemical ozone formation, ecosystem quality | X1: Photochemical ozone formation, human health | Y1: Terrestrial acidification | Z1: Terrestrial ecotoxicity, long term | AA1: Terrestrial ecotoxicity, short term | AB1: Thermally polluted water | AC1: Total ecosystem quality | AD1: Total human health | AE1: Water availability, freshwater ecosystem | AF1: Water availability, human health | AG1: Water availability, terrestrial ecosystem | AI1: Ecoinvent process | AJ1: Region
A2: Electricity production | B2: kWh | C2: 9.0220539e-21 | D2: 0.00052035185 | E2: 0.024888796 | F2: 0.0012365565 | G2: 2.1482719e-06 | H2: 8.7189411e-10 | I2: 1.6630166e-08 | J2: 1.9716035e-08 | K2: 1.0495037e-08 | L2: 4.1472255e-10 | M2: 1.2788915e-08 | N2: 0.0016567241 | O2: 0.0011680202 | P2: 0.010269588 | Q2: 0.0011147872 | R2: 9.6682892e-08 | S2: 2.6607992e-08 | T2: 6.8100187e-05 | U2: 4.6326221e-12 | V2: 3.7499949e-08 | W2: 0.0015786993 | X2: 1.5693505e-10 | Y2: 0.0034337732 | Z2: 0.0035290615 | AA2: 0.00097119172 | AB2: 0.00019042271 | AC2: =SUM(C2:G2)+L2+SUM(N2:T2)+W2+SUM(Y2:AB2)+AE2+AG2 -> 0.050630831 | AD2: =SUM(H2:K2)+M2+SUM(U2:V2)+X2+AF2 -> 2.2169617e-07 | AE2: 1.011382e-06 | AF2: 1.2353261e-07 | AG2: 1.4744629e-06 | AI2: market for electricity, medium voltage | electricity, medium voltage | Cutoff, U | AJ2: FR
A3: Water production | B3: kg | C3: 1.4472652e-20 | D3: 2.6983115e-06 | E3: 2.7477981e-05 | F3: 6.1320649e-06 | G3: 1.2606069e-08 | H3: 1.408413e-11 | I3: 9.2762381e-10 | J3: 3.9435252e-10 | K3: 6.711082e-11 | L3: 1.4514271e-13 | M3: 2.798748e-12 | N3: 4.7297185e-06 | O3: 6.0711292e-06 | P3: 4.2913089e-05 | Q3: 4.6582693e-06 | R3: 4.9804263e-11 | S3: 3.9972635e-11 | T3: 2.4074305e-07 | U3: 1.3310981e-14 | V3: 2.4250395e-10 | W3: 6.8457405e-06 | X3: 6.8269851e-13 | Y3: 1.7503834e-05 | Z3: 1.8179051e-06 | AA3: 1.4590012e-06 | AB3: 1.0616678e-07 | AC3: =SUM(C3:G3)+L3+SUM(N3:T3)+W3+SUM(Y3:AB3)+AE3+AG3 -> 0.00013186149 | AD3: =SUM(H3:K3)+M3+SUM(U3:V3)+X3+AF3 -> 4.0009625e-08 | AE3: 3.140634e-07 | AF3: 3.8360455e-08 | AG3: 8.8807766e-06 | AI3: market for tap water | tap water | Cutoff, U | AJ3: Europe without Switzerland
A4: Incineration | B4: kg | C4: 5.8334847e-21 | D4: 0.00030722598 | E4: 0.0040615965 | F4: 0.00051944492 | G4: 2.5327295e-05 | H4: 3.2796643e-10 | I4: 4.0155836e-08 | J4: 8.7573489e-09 | K4: 9.0145145e-08 | L4: 7.2700604e-13 | M4: 1.1049922e-11 | N4: 0.0004489439 | O4: 0.00087792638 | P4: 0.0035383176 | Q4: 0.00038409088 | R4: 1.8169613e-09 | S4: 3.963782e-09 | T4: 0.00016049954 | U4: 1.4900648e-12 | V4: 3.830932e-08 | W4: 0.0022743494 | X4: 2.3470762e-10 | Y4: 0.0023013297 | Z4: 6.6359289e-05 | AA4: 0.00014467804 | AB4: 1.6597232e-06 | AC4: =SUM(C4:G4)+L4+SUM(N4:T4)+W4+SUM(Y4:AB4)+AE4+AG4 -> 0.015113033 | AD4: =SUM(H4:K4)+M4+SUM(U4:V4)+X4+AF4 -> 2.2042254e-07 | AE4: 3.4778817e-07 | AF4: 4.2479678e-08 | AG4: 9.2981276e-07
A5: Transport | B5: tkm | C5: 1.4895501e-19 | D5: 0.00082994559 | E5: 0.0092025979 | F5: 0.0033844539 | G5: 5.2566239e-06 | H5: 6.0034348e-10 | I5: 3.4139573e-08 | J5: 2.2572496e-08 | K5: 1.5198825e-08 | L5: 6.9944357e-12 | M5: 8.6181308e-11 | N5: 0.0040818364 | O5: 0.0047163109 | P5: 0.025800254 | Q5: 0.0028006693 | R5: 9.7222144e-09 | S5: 7.9906608e-09 | T5: 0.00021342597 | U5: 6.1437636e-12 | V5: 1.0038796e-07 | W5: 0.0054178322 | X5: 5.2899951e-10 | Y5: 0.005901547 | Z5: 0.00035486896 | AA5: 0.00029165912 | AB5: 6.7079009e-06 | AC5: =SUM(C5:G5)+L5+SUM(N5:T5)+W5+SUM(Y5:AB5)+AE5+AG5 -> 0.063010312 | AD5: =SUM(H5:K5)+M5+SUM(U5:V5)+X5+AF5 -> 1.9021703e-07 | AE5: 1.3669709e-07 | AF5: 1.6696509e-08 | AG5: 2.7918423e-06 | AH5: =AH2-AD2 -> -2.2169617e-07
A6: Heat, natural gas | B6: MJ | C6: 2.456039e-19 | D6: 8.7487049e-05 | E6: 0.00090902716 | F6: 0.00084404332 | G6: 1.0175098e-06 | H6: 7.3128564e-11 | I6: 5.4607132e-09 | J6: 2.1836439e-09 | K6: 1.2776592e-09 | L6: 1.4950808e-12 | M6: 2.7539256e-11 | N6: 8.8589251e-05 | O6: 0.00041813597 | P6: 0.010404099 | Q6: 0.0011293905 | R6: 2.2228437e-09 | S6: 2.0080477e-09 | T6: 1.3926728e-05 | U6: 4.9676217e-12 | V6: 6.0152951e-09 | W6: 0.00061565556 | X6: 5.6382165e-11 | Y6: 0.00061064151 | Z6: 8.1134935e-05 | AA6: 7.3293742e-05 | AB6: 1.3011011e-06 | AC6: =SUM(C6:G6)+L6+SUM(N6:T6)+W6+SUM(Y6:AB6)+AE6+AG6 -> 0.015278382 | AD6: =SUM(H6:K6)+M6+SUM(U6:V6)+X6+AF6 -> 1.8415117e-08 | AE6: 2.7146908e-08 | AF6: 3.3157883e-09 | AG6: 6.0708308e-07
A7: Heat, fuel | B7: MJ | C7: 1.8355355e-21 | D7: 0.00028862325 | E7: 0.001913816 | F7: 0.00093700432 | G7: 1.4412766e-06 | H7: 1.5012604e-10 | I7: 4.1655245e-09 | J7: 4.0009951e-09 | K7: 2.2101399e-09 | L7: 1.1573822e-12 | M7: 2.174998e-11 | N7: 0.00012145572 | O7: 0.00099540935 | P7: 0.013271943 | Q7: 0.001440703 | R7: 1.9565669e-09 | S7: 1.7764736e-09 | T7: 5.5334525e-05 | U7: 2.9853225e-12 | V7: 1.6704189e-08 | W7: 0.00093625163 | X7: 8.3728291e-11 | Y7: 0.0018442609 | Z7: 7.1423215e-05 | AA7: 6.4841285e-05 | AB7: 1.039197e-06 | AC7: =SUM(C7:G7)+L7+SUM(N7:T7)+W7+SUM(Y7:AB7)+AE7+AG7 -> 0.021943803 | AD7: =SUM(H7:K7)+M7+SUM(U7:V7)+X7+AF7 -> 2.9797422e-08 | AE7: 2.0123922e-08 | AF7: 2.4579839e-09 | AG7: 2.3213647e-07
A8: Heat, coal | B8: MJ | C8: 1.4763407e-21 | D8: 0.0018246418 | E8: 0.024268278 | F8: 0.00038523926 | G8: 3.2761443e-07 | H8: 5.3314861e-10 | I8: 5.0909973e-09 | J8: 1.6240445e-08 | K8: 9.0877925e-09 | L8: 2.8551303e-12 | M8: 4.9809633e-11 | N8: 0.00053115688 | O8: 0.00098265018 | P8: 0.018710325 | Q8: 0.0020310485 | R8: 2.583604e-08 | S8: 1.3618008e-08 | T8: 8.781569e-05 | U8: 1.7481896e-13 | V8: 1.7750187e-07 | W8: 0.002837239 | X8: 2.9350262e-10 | Y8: 0.011489983 | Z8: 0.00094302658 | AA8: 0.00049705728 | AB8: 2.3780798e-06 | AC8: =SUM(C8:G8)+L8+SUM(N8:T8)+W8+SUM(Y8:AB8)+AE8+AG8 -> 0.064594667 | AD8: =SUM(H8:K8)+M8+SUM(U8:V8)+X8+AF8 -> 2.1319258e-07 | AE8: 3.5981315e-08 | AF8: 4.3948438e-09 | AG8: 3.4249237e-06
A9: Heat, wood chips | B9: MJ | C9: 1.0746197e-20 | D9: 0.00035685042 | E9: 0.012324661 | F9: 0.00065584737 | G9: 5.9519004e-06 | H9: 2.0411295e-10 | I9: 4.4194286e-09 | J9: 7.8800496e-09 | K9: 6.0846186e-09 | L9: 2.2079745e-12 | M9: 3.2533633e-11 | N9: 0.015167811 | O9: 0.0021577357 | P9: 0.0021074606 | Q9: 0.00022876865 | R9: 5.6782298e-08 | S9: 3.592671e-08 | T9: 8.8430731e-05 | U9: 2.6955337e-13 | V9: 5.0689546e-07 | W9: 0.0028524829 | X9: 2.9414464e-10 | Y9: 0.0027377653 | Z9: 0.0020725612 | AA9: 0.0013113249 | AB9: 3.5809585e-06 | AC9: =SUM(C9:G9)+L9+SUM(N9:T9)+W9+SUM(Y9:AB9)+AE9+AG9 -> 0.042072296 | AD9: =SUM(H9:K9)+M9+SUM(U9:V9)+X9+AF9 -> 5.3923526e-07 | AE9: 1.0990983e-07 | AF9: 1.342465e-08 | AG9: 8.6057214e-07
A10: Heat,waste | B10: MJ
A11: Heat, mix | B11: MJ | C11: =(C6*Parameters!$C115)+(C7*Parameters!$C117)+(C8*Parameters!$C116)+(C9*Parameters!$C118)+(C10*Parameters!$C119) -> 1.1956472e-19 | D11: =(D6*Parameters!$C115)+(D7*Parameters!$C117)+(D8*Parameters!$C116)+(D9*Parameters!$C118)+(D10*Parameters!$C119) -> 0.00017338512 | E11: =(E6*Parameters!$C115)+(E7*Parameters!$C117)+(E8*Parameters!$C116)+(E9*Parameters!$C118)+(E10*Parameters!$C119) -> 0.0049148544 | F11: =(F6*Parameters!$C115)+(F7*Parameters!$C117)+(F8*Parameters!$C116)+(F9*Parameters!$C118)+(F10*Parameters!$C119) -> 0.00063684546 | G11: =(G6*Parameters!$C115)+(G7*Parameters!$C117)+(G8*Parameters!$C116)+(G9*Parameters!$C118)+(G10*Parameters!$C119) -> 2.6296321e-06 | H11: =(H6*Parameters!$C115)+(H7*Parameters!$C117)+(H8*Parameters!$C116)+(H9*Parameters!$C118)+(H10*Parameters!$C119) -> 1.0922635e-10 | I11: =(I6*Parameters!$C115)+(I7*Parameters!$C117)+(I8*Parameters!$C116)+(I9*Parameters!$C118)+(I10*Parameters!$C119) -> 4.1834016e-09 | J11: =(J6*Parameters!$C115)+(J7*Parameters!$C117)+(J8*Parameters!$C116)+(J9*Parameters!$C118)+(J10*Parameters!$C119) -> 3.9047305e-09 | ... AG11: =(AG6*Parameters!$C115)+(AG7*Parameters!$C117)+(AG8*Parameters!$C116)+(AG9*Parameters!$C118)+(AG10*Parameters!$C119) -> 6.0212379e-07
A12: CH4 | B12: kg | AC12: =SUM(C12:G12)+L12+SUM(N12:T12)+W12+SUM(Y12:AB12)+AE12+AG12 -> 0 | AD12: =SUM(H12:K12)+M12+SUM(U12:V12)+X12+AF12 -> 0
A13: Nitrogen oxides | B13: kg | D13: 0.79919441 | T13: 0.26330224 | V13: 1.8783043e-05 | W13: 8.7162162 | X13: 9.1e-07 | Y13: 6.5540677 | AC13: =SUM(C13:G13)+L13+SUM(N13:T13)+W13+SUM(Y13:AB13)+AE13+AG13 -> 16.332781 | AD13: =SUM(H13:K13)+M13+SUM(U13:V13)+X13+AF13 -> 1.9693043e-05
A14: Volatile organic compounds | B14: kg | AC14: =SUM(C14:G14)+L14+SUM(N14:T14)+W14+SUM(Y14:AB14)+AE14+AG14 -> 0 | AD14: =SUM(H14:K14)+M14+SUM(U14:V14)+X14+AF14 -> 0
A15: Sulfur dioxide | B15: kg | D15: 2.392596 | V15: 9.2871715e-05 | Y15: 14.256733 | AC15: =SUM(C15:G15)+L15+SUM(N15:T15)+W15+SUM(Y15:AB15)+AE15+AG15 -> 16.649329 | AD15: =SUM(H15:K15)+M15+SUM(U15:V15)+X15+AF15 -> 9.2871715e-05
A16: Particulate matter | B16: kg | AC16: =SUM(C16:G16)+L16+SUM(N16:T16)+W16+SUM(Y16:AB16)+AE16+AG16 -> 0 | AD16: =SUM(H16:K16)+M16+SUM(U16:V16)+X16+AF16 -> 0
A17: Carbon monoxide (non-fossil) | B17: kg | AC17: =SUM(C17:G17)+L17+SUM(N17:T17)+W17+SUM(Y17:AB17)+AE17+AG17 -> 0 | AD17: =SUM(H17:K17)+M17+SUM(U17:V17)+X17+AF17 -> 0
A18: Ammonia | B18: kg | D18: 1.8467155 | T18: 0.70894827 | V18: 0.00017739541 | Y18: 23.809093 | AC18: =SUM(C18:G18)+L18+SUM(N18:T18)+W18+SUM(Y18:AB18)+AE18+AG18 -> 26.364756 | AD18: =SUM(H18:K18)+M18+SUM(U18:V18)+X18+AF18 -> 0.00017739541
A19: sulfure oxides | B19: kg | D19: 2.392596 | V19: 9.2871715e-05 | Y19: 14.256733 | AC19: =SUM(C19:G19)+L19+SUM(N19:T19)+W19+SUM(Y19:AB19)+AE19+AG19 -> 16.649329 | AD19: =SUM(H19:K19)+M19+SUM(U19:V19)+X19+AF19 -> 9.2871715e-05
A20: dinitrogen monoxide | B20: kg | AC20: =SUM(C20:G20)+L20+SUM(N20:T20)+W20+SUM(Y20:AB20)+AE20+AG20 -> 0 | AD20: =SUM(H20:K20)+M20+SUM(U20:V20)+X20+AF20 -> 0
A21: Nitrate | B21: kg | T21: 1.976625 | AC21: =SUM(C21:G21)+L21+SUM(N21:T21)+W21+SUM(Y21:AB21)+AE21+AG21 -> 1.976625 | AD21: =SUM(H21:K21)+M21+SUM(U21:V21)+X21+AF21 -> 0
A22: PM2.5 | B22: kg | V22: 0.0013675986 | AC22: =SUM(C22:G22)+L22+SUM(N22:T22)+W22+SUM(Y22:AB22)+AE22+AG22 -> 0 | AD22: =SUM(H22:K22)+M22+SUM(U22:V22)+X22+AF22 -> 0.0013675986
A23: NMOVC | B23: kg | W23: 2.5277027 | X23: 1.638e-07 | AC23: =SUM(C23:G23)+L23+SUM(N23:T23)+W23+SUM(Y23:AB23)+AE23+AG23 -> 2.5277027 | AD23: =SUM(H23:K23)+M23+SUM(U23:V23)+X23+AF23 -> 1.638e-07
A24: H2S | AC24: =SUM(C24:G24)+L24+SUM(N24:T24)+W24+SUM(Y24:AB24)+AE24+AG24 -> 0 | AD24: =SUM(H24:K24)+M24+SUM(U24:V24)+X24+AF24 -> 0
A25: (PO4)3- | B25: kg | G25: 3.1274177 | AC25: =SUM(C25:G25)+L25+SUM(N25:T25)+W25+SUM(Y25:AB25)+AE25+AG25 -> 3.1274177 | AD25: =SUM(H25:K25)+M25+SUM(U25:V25)+X25+AF25 -> 0
A26: CO2 fossil | B26: kg | P26: 0.152 | Q26: 0.0165 | AC26: =SUM(C26:G26)+L26+SUM(N26:T26)+W26+SUM(Y26:AB26)+AE26+AG26 -> 0.1685 | AD26: =SUM(H26:K26)+M26+SUM(U26:V26)+X26+AF26 -> 0
A27: Diesel | B27: kg | C27: 3.5939e-20 | D27: 0.0060276802 | E27: 0.053909966 | F27: 0.039281157 | G27: 5.4524179e-05 | H27: 3.0249295e-09 | I27: 1.1490511e-07 | J27: 7.5469177e-08 | K27: 5.8572071e-08 | L27: 2.8259643e-11 | M27: 5.2537187e-10 | N27: 0.0046989474 | O27: 0.042316085 | P27: 0.08052196 | Q27: 0.0087408311 | R27: 1.8677781e-08 | S27: 1.6488823e-08 | T27: 0.0020073884 | U27: 1.2694832e-10 | V27: 3.6191034e-07 | W27: 0.028325675 | X27: 2.3621059e-09 | Y27: 0.038813115 | Z27: 0.00068185265 | AA27: 0.00060184205 | AB27: 2.6424477e-05 | AC27: =SUM(C27:G27)+L27+SUM(N27:T27)+W27+SUM(Y27:AB27)+AE27+AG27 -> 0.3060155 | AD27: =SUM(H27:K27)+M27+SUM(U27:V27)+X27+AF27 -> 6.9257209e-07 | AE27: 6.1957224e-07 | AF27: 7.5676035e-08 | AG27: 7.3917021e-06
A28: N-fertilizer | B28: kg | C28: 3.9890908e-18 | D28: 0.0088714777 | E28: 0.073779372 | F28: 0.024525279 | G28: 3.6074949e-05 | H28: 5.5072058e-09 | I28: 2.5858965e-07 | J28: 1.7938782e-07 | K28: 1.8156288e-07 | L28: 7.754779e-11 | M28: 1.4008319e-09 | N28: 0.010508556 | O28: 0.018970044 | P28: 0.19897551 | Q28: 0.021599272 | R28: 3.8568777e-07 | S28: 5.248735e-07 | T28: 0.0036257269 | U28: 6.0235592e-11 | V28: 7.1374671e-07 | W28: 0.020639576 | X28: 1.9849033e-09 | Y28: 0.081315348 | Z28: 0.014077665 | AA28: 0.019157883 | AB28: 8.7088127e-05 | AC28: =SUM(C28:G28)+L28+SUM(N28:T28)+W28+SUM(Y28:AB28)+AE28+AG28 -> 0.49622106 | AD28: =SUM(H28:K28)+M28+SUM(U28:V28)+X28+AF28 -> 3.6680799e-06 | AE28: 1.9042035e-05 | AF28: 2.3258397e-06 | AG28: 3.2236478e-05
A29: K-fertilizer | B29: kg | C29: 2.0720307e-18 | D29: 0.0048895793 | E29: 0.13220145 | F29: 0.013751199 | G29: 2.4885782e-05 | H29: 3.6714451e-09 | I29: 1.8273609e-07 | J29: 1.2199789e-07 | K29: 1.1346391e-07 | L29: 4.5438068e-11 | M29: 7.8933779e-10 | N29: 0.023650481 | O29: 0.043627548 | P29: 0.091304599 | Q29: 0.0099112967 | R29: 2.2604764e-07 | S29: 2.8296064e-07 | T29: 0.00080009028 | U29: 2.6968749e-11 | V29: 4.4915067e-07 | W29: 0.021631556 | X29: 2.151307e-09 | Y29: 0.03370436 | Z29: 0.0082507835 | AA29: 0.010328064 | AB29: 5.0815971e-05 | AC29: =SUM(C29:G29)+L29+SUM(N29:T29)+W29+SUM(Y29:AB29)+AE29+AG29 -> 0.39414518 | AD29: =SUM(H29:K29)+M29+SUM(U29:V29)+X29+AF29 -> 1.1813233e-06 | AE29: 2.5162084e-06 | AF29: 3.0733571e-07 | AG29: 1.5454094e-05
A30: P-fertilizer | B30: kg | C30: 2.2895213e-18 | D30: 0.014034236 | E30: 0.073493625 | F30: 0.0067405601 | G30: 0.0031201993 | H30: 3.9097242e-09 | I30: 1.4645927e-07 | J30: 1.2555538e-07 | K30: 2.1940333e-07 | L30: 1.4550959e-10 | M30: 2.9605534e-09 | N30: 0.021390802 | O30: 0.024768996 | P30: 0.054203603 | Q30: 0.0058839215 | R30: 2.2661926e-07 | S30: 3.0071084e-07 | T30: 0.0004511621 | U30: 1.1973211e-11 | V30: 1.1300162e-06 | W30: 0.0086391901 | X30: 8.6442606e-10 | Y30: 0.085578092 | Z30: 0.008271718 | AA30: 0.010975946 | AB30: 0.00012100943 | AC30: =SUM(C30:G30)+L30+SUM(N30:T30)+W30+SUM(Y30:AB30)+AE30+AG30 -> 0.31778847 | AD30: =SUM(H30:K30)+M30+SUM(U30:V30)+X30+AF30 -> 2.5346566e-06 | AE30: 7.4132798e-06 | AF30: 9.0547572e-07 | AG30: 0.00010746792
A31: Peat | B31: kg | C31: 1.9344146e-21 | D31: 6.636891e-05 | E31: 0.00075505204 | F31: 0.00031143304 | G31: 3.5965966e-07 | H31: 4.2855048e-11 | I31: 3.2113094e-09 | J31: 1.3619544e-09 | K31: 1.1392657e-09 | L31: 1.0164771e-11 | M31: 1.2800993e-10 | N31: 0.00075630767 | O31: 0.0039219773 | P31: 0.0010931182 | Q31: 0.00011865993 | R31: 2.7437095e-09 | S31: 1.8314112e-09 | T31: 1.4534952e-05 | U31: 1.9514453e-13 | V31: 6.9437348e-09 | W31: 0.00043203666 | X31: 4.3746169e-11 | Y31: 0.00048190886 | Z31: 0.00010014674 | AA31: 6.6846509e-05 | AB31: 7.8568836e-06 | AC31: =SUM(C31:G31)+L31+SUM(N31:T31)+W31+SUM(Y31:AB31)+AE31+AG31 -> 0.0082740685 | AD31: =SUM(H31:K31)+M31+SUM(U31:V31)+X31+AF31 -> 4.4209285e-08 | AE31: 2.5657116e-07 | AF31: 3.1338215e-08 | AG31: 0.00014719996
A32: Activated carbon | B32: kg | C32: 1.1804704e-19 | D32: 0.037539918 | E32: 0.47772922 | F32: 0.10027248 | G32: 1.9677838e-05 | H32: 1.1821866e-08 | I32: 1.6797788e-07 | J32: 3.552976e-07 | K32: 1.9853155e-07 | L32: 1.9926703e-10 | M32: 3.3445848e-09 | N32: 0.022971069 | O32: 0.040682935 | P32: 0.45706972 | Q32: 0.049615971 | R32: 4.7965579e-07 | S32: 2.6578996e-07 | T32: 0.0022087376 | U32: 2.8627356e-11 | V32: 4.5150881e-06 | W32: 0.071239533 | X32: 7.3007938e-09 | Y32: 0.23869151 | Z32: 0.017507683 | AA32: 0.0097013334 | AB32: 0.00024508409 | AC32: =SUM(C32:G32)+L32+SUM(N32:T32)+W32+SUM(Y32:AB32)+AE32+AG32 -> 1.5259613 | AD32: =SUM(H32:K32)+M32+SUM(U32:V32)+X32+AF32 -> 5.6688143e-06 | AE32: 3.352016e-06 | AF32: 4.0942324e-07 | AG32: 0.00046230986
A33: Zeolite | B33: kg | C33: 1.3097601e-17 | D33: 0.049898833 | E33: 8.8435677 | F33: 0.17100584 | G33: 0.0004896338 | H33: 4.6252072e-08 | I33: 6.2794828e-06 | J33: 1.3863795e-06 | K33: 2.8909316e-06 | L33: 5.018278e-10 | M33: 8.0697764e-09 | N33: 0.070209896 | O33: 0.11857824 | P33: 0.71575874 | Q33: 0.077697233 | R33: 1.7757897e-06 | S33: 2.0566413e-06 | T33: 0.0073018259 | U33: 1.5803457e-09 | V33: 5.4700677e-06 | W33: 0.13034452 | X33: 1.3195848e-08 | Y33: 0.32466584 | Z33: 0.064937117 | AA33: 0.075067407 | AB33: 0.0007720175 | AC33: =SUM(C33:G33)+L33+SUM(N33:T33)+W33+SUM(Y33:AB33)+AE33+AG33 -> 10.650704 | AD33: =SUM(H33:K33)+M33+SUM(U33:V33)+X33+AF33 -> 1.945293e-05 | AE33: 2.7484069e-05 | AF33: 3.3569699e-06 | AG33: 0.00037810453
A34: treatment of wastewater | B34: m3 | C34: 1.3270271e-19 | D34: 0.0020338406 | E34: 2.9789716 | F34: 0.006712429 | G34: 0.01275068 | H34: 1.7899238e-08 | I34: 1.1926514e-07 | J34: 8.5934994e-07 | K34: 6.4789762e-07 | L34: 7.8842573e-11 | M34: 1.5130176e-09 | N34: 0.0045994251 | O34: 0.010311723 | P34: 0.029900955 | Q34: 0.0032458105 | R34: 2.6654644e-05 | S34: 1.3034913e-05 | T34: 0.15593723 | U34: 5.1364404e-12 | V34: 1.8298016e-07 | W34: 0.0071055638 | X34: 7.2009464e-10 | Y34: 0.01562842 | Z34: 0.97289573 | AA34: 0.47577434 | AB34: 5.9002177e-05 | AC34: =SUM(C34:G34)+L34+SUM(N34:T34)+W34+SUM(Y34:AB34)+AE34+AG34 -> 4.6759803 | AD34: =SUM(H34:K34)+M34+SUM(U34:V34)+X34+AF34 -> 1.8278718e-06 | AE34: -1.4397331e-08 | AF34: -1.7585245e-09 | AG34: 1.3912061e-05
A35: Wood chips | B35: kg | C35: 4.5022236e-20 | D35: 0.00025928245 | E35: 0.0040924082 | F35: 0.00069640851 | G35: 0.00013742829 | H35: 1.3237861e-10 | I35: 1.0765567e-08 | J35: 4.3734986e-09 | K35: 2.8445728e-09 | L35: 5.9988814e-12 | M35: 1.0531279e-10 | N35: 0.25176696 | O35: 0.001898717 | P35: 0.0062365076 | Q35: 0.00067695974 | R35: 9.3271388e-09 | S35: 6.9917796e-09 | T35: 6.4355289e-05 | U35: 1.3828851e-12 | V35: 2.4117589e-08 | W35: 0.0020503153 | X35: 1.9290481e-10 | Y35: 0.0018745501 | Z35: 0.00034044697 | AA35: 0.00025519996 | AB35: 6.6555555e-06 | AC35: =SUM(C35:G35)+L35+SUM(N35:T35)+W35+SUM(Y35:AB35)+AE35+AG35 -> 0.27035904 | AD35: =SUM(H35:K35)+M35+SUM(U35:V35)+X35+AF35 -> 5.3993712e-08 | AE35: 9.3829054e-08 | AF35: 1.1460505e-08 | AG35: 2.7300618e-06
A37: Mix marginal electricity | B37: kWh | C37: 0 | D37: 0.0004648549 | E37: 0.023786994 | F37: 0.0028233329 | G37: 7.9803112e-06 | H37: 1.0699068e-09 | I37: 2.6189697e-08 | J37: 3.7103557e-08 | K37: 3.8354561e-08 | L37: 2.4781029e-13 | M37: 8.4198596e-12 | N37: 0.033195713 | O37: 0.0026553411 | P37: 0.0045994162 | Q37: 0.00049926962 | R37: 1.2243212e-07 | S37: 1.0121042e-07 | T37: 9.2096628e-05 | U37: 1.714088e-12 | V37: 7.1625227e-08 | W37: 0.0020593876 | X37: 2.0771818e-10 | Y37: 0.0035156093 | Z37: 0.0044687847 | AA37: 0.0036941803 | AB37: 1.4063127e-05 | AC37: =SUM(C37:G37)+L37+SUM(N37:T37)+W37+SUM(Y37:AB37)+AE37+AG37 -> 0.08187996 | AD37: =SUM(H37:K37)+M37+SUM(U37:V37)+X37+AF37 -> 1.8798769e-07 | AE37: 1.0992819e-07 | AF37: 1.3426891e-08 | AG37: 2.6021033e-06
A38: natural gas | B38: m3 | C38: 0 | D38: 0.0025264039 | E38: 0.027002481 | F38: 0.031055896 | G38: 4.0494623e-06 | H38: 1.4981608e-09 | I38: 1.2329245e-08 | J38: 4.4427159e-08 | K38: 2.9351524e-08 | L38: 5.7241307e-12 | M38: 1.2261411e-10 | N38: 0.0034303236 | O38: 0.014342243 | P38: 0.066426259 | Q38: 0.0072106913 | R38: 4.8755255e-08 | S38: 4.2659541e-08 | T38: 0.00039935439 | U38: 2.162732e-10 | V38: 1.7938466e-07 | W38: 0.018893856 | X38: 1.7004089e-09 | Y38: 0.017655913 | Z38: 0.0017796015 | AA38: 0.0015570732 | AB38: 1.7206803e-05 | AC38: =SUM(C38:G38)+L38+SUM(N38:T38)+W38+SUM(Y38:AB38)+AE38+AG38 -> 0.19232076 | AD38: =SUM(H38:K38)+M38+SUM(U38:V38)+X38+AF38 -> 3.4627108e-07 | AE38: 6.3238513e-07 | AF38: 7.7241032e-08 | AG38: 1.8680467e-05
A39: Mix marginal heat | B39: MJ | C39: 1.8355355e-21 | D39: 0.00028862325 | E39: 0.001913816 | F39: 0.00093700432 | G39: 1.4412766e-06 | H39: 1.5012604e-10 | I39: 4.1655245e-09 | J39: 4.0009951e-09 | K39: 2.2101399e-09 | L39: 1.1573822e-12 | M39: 2.174998e-11 | N39: 0.00012145572 | O39: 0.00099540935 | P39: 0.013271943 | Q39: 0.001440703 | R39: 1.9565669e-09 | S39: 1.7764736e-09 | T39: 5.5334525e-05 | U39: 2.9853225e-12 | V39: 1.6704189e-08 | W39: 0.00093625163 | X39: 8.3728291e-11 | Y39: 0.0018442609 | Z39: 7.1423215e-05 | AA39: 6.4841285e-05 | AB39: 1.039197e-06 | AC39: =SUM(C39:G39)+L39+SUM(N39:T39)+W39+SUM(Y39:AB39)+AE39+AG39 -> 0.021943803 | AD39: =SUM(H39:K39)+M39+SUM(U39:V39)+X39+AF39 -> 2.9797422e-08 | AE39: 2.0123922e-08 | AF39: 2.4579839e-09 | AG39: 2.3213647e-07 | AI39: heat production, natural gas, at boiler condensing modulating >100kW | heat, district or industrial, natural gas

Sheet LCI_AD-e
A1: AD+combustion+digestate
A2: Process | B2: Flow direction | C2: Flow type | D2: Flow name | E2: Value | F2: Unit
A3: Pretreatment | B3: input | C3: Technosphere flow | D3: Waste | E3: 1 | F3: t
B4: input | C4: Technosphere flow | D4: Electricity | E4: =E3*Parameters!C3 -> 9.98 | F4: kWh
B5: input | C5: Technosphere flow | D5: Water
B6: output | C6: Intermediate flow | D6: Pretreated biowaste | E6: =E3*Parameters!C5 -> 0.77 | F6: t
A7: Incineration | B7: input | C7: Intermediate flow | D7: transported discarded biowaste | E7: =E8*0.001*Parameters!C6 -> 2.3 | F7: tkm
B8: input | C8: Intermediate flow | D8: discarded biowaste | E8: =E3*(1-Parameters!C5)*1000 -> 230 | F8: kg
A9: AD | B9: input | C9: Intermediate flow | D9: Pretreated waste | E9: =E6 -> 0.77 | F9: t
B10: input | C10: Intermediate flow | D10: Electricity | E10: =Parameters!C14*E9 -> 22.33 | F10: kWh
B11: input | C11: Intermediate flow | D11: Heat | E11: =E9*Parameters!C15 -> 227.15 | F11: MJ
B12: output | C12: Elementary flow | D12: Methane | E12: =Parameters!C9*(Parameters!C7*(1-Waste_characteristics!B4))*E9*Parameters!C11*0.001 -> 1.5118454 | F12: kg
B13: output | C13: Intermediate flow | D13: Biogas | E13: =(((Parameters!C7*(1-Waste_characteristics!B4))/Parameters!C10)*0.001)-((E12/Parameters!C11)*(1/Parameters!C10)) -> 223.74985 | F13: m3
B14: output | C14: Technosphere flow | D14: Digestate | E14: =Parameters!C66*E9 -> 0.5558219 | F14: t
A15: Combustion of biogas | B15: input | C15: Intermediate flow | D15: Biogas | E15: =E13 -> 223.74985 | F15: m3
B16: output | C16: Elementary flow | D16: CO2 | E16: =Parameters!C34*E15 -> 449.66648 | F16: kg
B17: output | C17: Elementary flow | D17: CH4 | E17: =$E$15*Parameters!C35 -> 0.0057327997 | F17: kg
B18: output | C18: Elementary flow | D18: N2O | E18: =$E$15*Parameters!C36 -> 0.0057327997 | F18: kg
B19: output | C19: Elementary flow | D19: Sox | E19: =$E$15*Parameters!C37 -> 0.039771298 | F19: kg
B20: output | C20: Elementary flow | D20: PM10 | E20: =$E$15*Parameters!C38 -> 0.029165619 | F20: kg
B21: output | C21: Elementary flow | D21: PM2.5 | E21: =$E$15*Parameters!C39 -> 0.029165619 | F21: kg
B22: output | C22: Elementary flow | D22: Nox | E22: =$E$15*Parameters!C40 -> 0.38338098 | F22: kg
B23: output | C23: Elementary flow | D23: NH3 | E23: =$E$15*Parameters!C41 -> 0.012110539 | F23: kg
B24: output | C24: Elementary flow | D24: CO | E24: =$E$15*Parameters!C42 -> 0.32246998 | F24: kg
B25: output | C25: Elementary flow | D25: VOC | E25: =$E$15*Parameters!C43 -> 0.019276539 | F25: kg
B26: input | C26: Technosphere flow | D26: Electricity | E26: =$E$15*Parameters!C44 -> 0.60859958 | F26: kWh
B27: output | C27: Technosphere flow | D27: Heat | E27: =E15*Parameters!C10*Parameters!C20*Parameters!C33 -> 3876.4661 | F27: MJ
A28: Storage | B28: input | C28: Technosphere flow | D28: Digestate | E28: ='LCI_AD-a'!E26 -> 0.5558219 | F28: t
B29: output | C29: Elementary flow | D29: CH4 | E29: ='LCI_AD-a'!E27 -> 1.338037 | F29: kg
B30: output | C30: Technosphere flow | D30: Digestate after storage | E30: ='LCI_AD-a'!E28 -> 0.55448387 | F30: t
A31: Land application of digestate | B31: input | C31: Technosphere flow | D31: Digestate after storage | E31: ='LCI_AD-a'!E29 -> 0.55448387 | F31: t
B32: output | C32: Elementary flow | D32: N2O | E32: ='LCI_AD-a'!E30 -> 0.069747028 | F32: kg
B33: output | C33: Elementary flow | D33: NH3 | E33: ='LCI_AD-a'!E31 -> 4.329404 | F33: kg
B34: output | C34: Elementary flow | D34: NO3 | E34: ='LCI_AD-a'!E32 -> -1.8937605 | F34: kg
B35: output | C35: Elementary flow | D35: (PO4)3- | E35: ='LCI_AD-a'!E33 -> -0.06209938 | F35: kg
B36: output | C36: Elementary flow | D36: CO2 fossil | E36: ='LCI_AD-a'!E34 -> -115.35192 | F36: kg
A37: Substituted products | E37: ='LCI_AD-a'!E35 -> 0
C38: Technosphere flow | D38: N-fertilizer | E38: ='LCI_AD-a'!E36 -> 18.00888 | F38: kg
C39: Technosphere flow | D39: P-fertilizer | E39: ='LCI_AD-a'!E37 -> 50.217839 | F39: kg
C40: Technosphere flow | D40: K-fertilizer | E40: ='LCI_AD-a'!E38 -> 18.509017 | F40: kg
...

Sheet LCI_AD-f
A1: AD+combustion+composting
A2: Process | B2: Flow direction | C2: Flow type | D2: Flow name | E2: Value | F2: Unit
A3: Pretreatment | B3: input | C3: Technosphere flow | D3: Waste | E3: 1 | F3: t
B4: input | C4: Technosphere flow | D4: Electricity | E4: =E3*Parameters!C3 -> 9.98 | F4: kWh
B5: input | C5: Technosphere flow | D5: Water
B6: output | C6: Intermediate flow | D6: Pretreated biowaste | E6: =E3*Parameters!C5 -> 0.77 | F6: t
A7: Incineration | B7: input | C7: Intermediate flow | D7: transported discarded biowaste | E7: =E8*0.001*Parameters!C6 -> 2.3 | F7: tkm
B8: input | C8: Intermediate flow | D8: discarded biowaste | E8: =E3*(1-Parameters!C5)*1000 -> 230 | F8: kg
A9: AD | B9: input | C9: Intermediate flow | D9: Pretreated waste | E9: =E6 -> 0.77 | F9: t
B10: input | C10: Intermediate flow | D10: Electricity | E10: =Parameters!C14*E9 -> 22.33 | F10: kWh
B11: input | C11: Intermediate flow | D11: Heat | E11: =E9*Parameters!C15 -> 227.15 | F11: MJ
B12: output | C12: Elementary flow | D12: Methane | E12: =Parameters!C9*(Parameters!C7*(1-Waste_characteristics!B4))*E9*Parameters!C11*0.001 -> 1.5118454 | F12: kg
B13: output | C13: Intermediate flow | D13: Biogas | E13: =(((Parameters!C7*(1-Waste_characteristics!B4))/Parameters!C10)*0.001)-((E12/Parameters!C11)*(1/Parameters!C10)) -> 223.74985 | F13: m3
B14: output | C14: Technosphere flow | D14: Digestate | E14: =Parameters!C66*E9 -> 0.5558219 | F14: t
A15: Combustion of biogas | B15: input | C15: Intermediate flow | D15: Biogas | E15: =E13 -> 223.74985 | F15: m3
B16: output | C16: Elementary flow | D16: CO2 | E16: =Parameters!C34*E15 -> 449.66648 | F16: kg
B17: output | C17: Elementary flow | D17: CH4 | E17: =$E$15*Parameters!C35 -> 0.0057327997 | F17: kg
B18: output | C18: Elementary flow | D18: N2O | E18: =$E$15*Parameters!C36 -> 0.0057327997 | F18: kg
B19: output | C19: Elementary flow | D19: Sox | E19: =$E$15*Parameters!C37 -> 0.039771298 | F19: kg
B20: output | C20: Elementary flow | D20: PM10 | E20: =$E$15*Parameters!C38 -> 0.029165619 | F20: kg
B21: output | C21: Elementary flow | D21: PM2.5 | E21: =$E$15*Parameters!C39 -> 0.029165619 | F21: kg
B22: output | C22: Elementary flow | D22: Nox | E22: =$E$15*Parameters!C40 -> 0.38338098 | F22: kg
B23: output | C23: Elementary flow | D23: NH3 | E23: =$E$15*Parameters!C41 -> 0.012110539 | F23: kg
B24: output | C24: Elementary flow | D24: CO | E24: =$E$15*Parameters!C42 -> 0.32246998 | F24: kg
B25: output | C25: Elementary flow | D25: VOC | E25: =$E$15*Parameters!C43 -> 0.019276539 | F25: kg
B26: input | C26: Technosphere flow | D26: Electricity | E26: =$E$15*Parameters!C44 -> 0.60859958 | F26: kWh
B27: output | C27: Technosphere flow | D27: Heat | E27: =E15*Parameters!C10*Parameters!C20*Parameters!C33 -> 3876.4661 | F27: MJ
A28: Dewatering | B28: input | C28: Technosphere flow | D28: Digestate | E28: ='LCI_AD-d'!E24 -> 0.5558219 | F28: t
B29: input | C29: Technosphere flow | D29: electricity | E29: ='LCI_AD-d'!E25 -> 2.0184752 | F29: kWh
B30: output | C30: Technosphere flow | D30: dewatered digestate | E30: ='LCI_AD-d'!E26 -> 0.2970039 | F30: t
B31: output | C31: Technosphere flow | D31: wastewater | E31: ='LCI_AD-d'!E27 -> 0.25911227 | F31: m3
A32: Composting of digestate | B32: input | C32: Technosphere flow | D32: dewatered digestate | E32: ='LCI_AD-d'!E28 -> 0.2970039 | F32: t
B33: output | C33: Elementary flow | D33: CH4 | E33: ='LCI_AD-d'!E29 -> 0.088228561 | F33: kg
B34: output | C34: Elementary flow | D34: N2O | E34: ='LCI_AD-d'!E30 -> 0.062318617 | F34: kg
B35: output | C35: Elementary flow | D35: NH3 | E35: ='LCI_AD-d'!E31 -> 0.20275914 | F35: kg
B36: output | C36: Elementary flow | D36: NMVOC | E36: ='LCI_AD-d'!E32 -> 0.030888406 | F36: kg
B37: output | C37: Elementary flow | D37: CO | E37: ='LCI_AD-d'!E33 -> 0.12509677 | F37: kg
B38: output | C38: Technosphere flow | D38: compost | E38: ='LCI_AD-d'!E34 -> 0.15444203 | F38: t
B39: input | C39: Technosphere flow | D39: electricity | E39: ='LCI_AD-d'!E35 -> 3.1254739 | F39: kWh
B40: input | C40: Technosphere flow | D40: diesel | E40: ='LCI_AD-d'!E36 -> 0.44883056 | F40: kg
...

Sheet Waste_characteristics
C1: Unit
A2: Mass | B2: 1 | C2: t
A3: FW | B3: =B2-B7 -> 1 | C3: t
A4: Moisture content, FW | B4: =[2]mass_composition!$D$99/[2]mass_composition!$C$99 -> 0.63542863 | C4: %FW | D4: 0.72
A5: VS, FW | B5: =[2]mass_composition!$F$99/[2]mass_composition!$E$99 -> 0.96463821 | C5: %TS
A6: VS, FW | B6: =B3*(1-B4)*B5 -> 0.35167947 | C6: t
A7: impurities | B7: 0 | C7: t
A8: Nitrogen content, FW | B8: =[2]mass_composition!$R$99/[2]mass_composition!$E$99 -> 0.032826764 | C8: % of dry mass of FW
A9: Carbon content, FW | B9: =[2]mass_composition!$J$99/[2]mass_composition!$E$99 -> 0.46707763 | C9: % of dry mass of FW
A10: Phosphorus content, FW | B10: =[2]mass_composition!$U$99/[2]mass_composition!$E$99 -> 0.0040243826 | C10: % of dry mass of FW
A11: Potassium content, FW | B11: =[2]mass_composition!$Q$99/[2]mass_composition!$E$99 -> 0.0082642017 | C11: % of dry mass of FW
A13: Nitrogen content, FW | B13: =B8*(1-H2O_FW) -> 0.011967698 | C13: t/t of FW
A14: Carbon content, FW | B14: =B9*(1-H2O_FW) -> 0.17028313 | C14: t/t of FW
A15: Phosphorus content, FW | B15: =B10*(1-H2O_FW) -> 0.0014671747 | C15: t/t of FW
A16: Potassium content, FW | B16: =B8*(1-H2O_FW) -> 0.011967698 | C16: t/t of FW
J35: https://journals.sagepub.com/doi/full/10.1177/0734242X14545374#bibr26-0734242X14545374

Sheet Parameters
B1: Pretreatment
A2: Process | B2: Parameter | C2: Value | D2: Unit | F2: Source
A3: Pretreatment | B3: Electricity requirement | C3: 9.98 | D3: kWh/t | E3: Drum-screen + Shredder + Piston press
B4: Sorting efficiency for impurities | C4: 1 | D4: % of impurities sorted
B5: Sorting efficiency for biowaste | C5: 0.77 | D5: % of biowaste retained
B6: Distance between the industrial plant and the incineration plan | C6: 10 | D6: km
A7: AD | B7: Methane production | C7: =374*1000 -> 374000 | D7: L/dry-t | F7: https://catalog.data.gov/dataset/food-waste-management-life-cycle-inventory-tool-v1-0-0
B8: VS conversion | C8: 0.86 | D8: %VS initial
B9: Fugitive methane loss | C9: 0.02 | F9: https://catalog.data.gov/dataset/food-waste-management-life-cycle-inventory-tool-v1-0-1
B10: Methane volume share in biogas | C10: 0.6 | F10: https://catalog.data.gov/dataset/food-waste-management-life-cycle-inventory-tool-v1-0-2
B11: Methane density | C11: 0.72 | D11: kg/m3 | F11: https://catalog.data.gov/dataset/food-waste-management-life-cycle-inventory-tool-v1-0-3
B12: CO2 density | C12: 1.98 | D12: kg/m3
B13: biogas density | C13: =(C10*C11)+((1-C10)*C12) -> 1.224 | D13: kg/m3
B14: Electricity requirement | C14: 29 | D14: kWh/t | F14: https://catalog.data.gov/dataset/food-waste-management-life-cycle-inventory-tool-v1-0-4
B15: Heat requirement | C15: 295 | D15: MJ/t | F15: https://catalog.data.gov/dataset/food-waste-management-life-cycle-inventory-tool-v1-0-5
B16: Water requriement | C16: 0 | D16: %of Biowaste
A17: CHP | B17: Efficiency | F17: https://catalog.data.gov/dataset/food-waste-management-life-cycle-inventory-tool-v1-0-6
B18: Thermal | C18: 0.46 | F18: https://catalog.data.gov/dataset/food-waste-management-life-cycle-inventory-tool-v1-0-7
B19: Electric | C19: 0.39 | F19: https://catalog.data.gov/dataset/food-waste-management-life-cycle-inventory-tool-v1-0-8
B20: Methane_lhv | C20: 35 | D20: MJ/m3 | F20: https://catalog.data.gov/dataset/food-waste-management-life-cycle-inventory-tool-v1-0-9
B21: Electricity requirement | F21: https://www.sciencedirect.com/science/article/pii/S0013935122009598?casa_token=b-5UAciDODcAAAAA:iPTgJGz224xsnoQdrEctjVyXjbgpRksrTp6NPBa96VQZoPJqxyo5SRxUSGA4QFvLo7qp_-bQrQ
B22: Lubricating oil | C22: 1.54 | D22: g/m3 of biogas | F22: https://www.sciencedirect.com/science/article/pii/S0013935122009598?casa_token=b-5UAciDODcAAAAA:iPTgJGz224xsnoQdrEctjVyXjbgpRksrTp6NPBa96VQZoPJqxyo5SRxUSGA4QFvLo7qp_-bQrQ
B23: Emissions
B24: Nitrogen Oxides (NOx) | C24: 0.00016410454 | D24: kg/m3 biogas combusted | F24: https://catalog.data.gov/dataset/food-waste-management-life-cycle-inventory-tool-v1-0-0
B25: Volatile Organic Compounds (VOCs) | C25: 0.0015816552 | D25: kg/m3 biogas combusted | F25: https://catalog.data.gov/dataset/food-waste-management-life-cycle-inventory-tool-v1-0-1
B26: Sulfur Dioxide (SO2) | C26: 1.4066103e-05 | D26: kg/m3 biogas combusted | F26: https://catalog.data.gov/dataset/food-waste-management-life-cycle-inventory-tool-v1-0-2
B27: Particulate Matter (PM2.5) | C27: 3.4383808e-05 | D27: kg/m3 biogas combusted | F27: https://catalog.data.gov/dataset/food-waste-management-life-cycle-inventory-tool-v1-0-3
B28: Carbon Monoxide (CO) | C28: 0.0010682424 | D28: kg/m3 biogas combusted | F28: https://catalog.data.gov/dataset/food-waste-management-life-cycle-inventory-tool-v1-0-4
B29: Ammonia (NH3) | C29: 6.4078915e-05 | D29: kg/m3 biogas combusted | F29: https://catalog.data.gov/dataset/food-waste-management-life-cycle-inventory-tool-v1-0-5
B30: Methane (CH4) | C30: 0.0043034128 | D30: kg/m3 biogas combusted | F30: https://catalog.data.gov/dataset/food-waste-management-life-cycle-inventory-tool-v1-0-6
B31: Nitrous Oxide (N2O) | C31: 0.00010246221 | D31: kg/m3 biogas combusted | F31: https://catalog.data.gov/dataset/food-waste-management-life-cycle-inventory-tool-v1-0-7
A32: Biogas boiler
B33: Efficiency | C33: 0.825 | F33: https://pureadmin.qub.ac.uk/ws/files/135497181/Document2.pdf
B34: CO2 | C34: =L37*L$48 -> 2.009684 | D34: kg/m3 of biogas | E34: Labutong, 2012
B35: CH4 | C35: =L38*L$48 -> 2.5621469e-05 | D35: kg/m3 of biogas | E35: Labutong, 2012
B36: N2O | C36: =L39*L$48 -> 2.5621469e-05 | D36: kg/m3 of biogas | E36: Labutong, 2012
B37: Sox | C37: =L40*L$48 -> 0.00017774894 | D37: kg/m3 of biogas | E37: Labutong, 2012 | K37: CO2 | L37: =39.1+86.4 -> 125.5 | M37: lb/MCF
B38: PM10 | C38: =L41*L$48 -> 0.00013034922 | D38: kg/m3 of biogas | E38: Labutong, 2012 | K38: CH4 | L38: 0.0016 | M38: lb/MCF
B39: PM2.5 | C39: =L42*L$48 -> 0.00013034922 | D39: kg/m3 of biogas | E39: Labutong, 2012 | K39: N2O | L39: 0.0016 | M39: lb/MCF
B40: Nox | C40: =L43*L$48 -> 0.0017134357 | D40: kg/m3 of biogas | E40: Labutong, 2012 | K40: Sox | L40: 0.0111 | M40: lb/MCF
...

Sheet LCI
A2: Process | B2: Flow direction | C2: Flow type | D2: Flow name | E2: Value | F2: Unit | I2: UF | J2: Treatment of 1t of biowaste
A3: Pretreatment | B3: input | C3: Technosphere flow | D3: Waste | E3: 1 | F3: t
B4: input | C4: Technosphere flow | D4: Electricity | E4: =E3*Parameters!C3 -> 9.98 | F4: kWh
B5: input | C5: Technosphere flow | D5: Water
B6: output | C6: Intermediate flow | D6: Pretreated biowaste | E6: =E3*Parameters!C5 -> 0.77 | F6: t
A7: Incineration | B7: input | C7: Intermediate flow | D7: discarded biowaste | E7: =E3*(1-Parameters!C5)*1000 -> 230 | F7: kg
A9: AD | B9: input | C9: Intermediate flow | D9: Pretreated waste | E9: =E6 -> 0.77 | F9: t
B10: input | C10: Intermediate flow | D10: Electricity | E10: =Parameters!C14*LCI!E9 -> 22.33 | F10: kWh
B11: input | C11: Intermediate flow | D11: Heat | E11: =E9*Parameters!C15 -> 227.15 | F11: MJ
B12: output | C12: Elementary flow | D12: Methane | E12: =Parameters!C9*(Parameters!C7*(1-Waste_characteristics!B4))*LCI!E9*Parameters!C11*0.001 -> 1.5118454 | F12: kg
B13: output | C13: Intermediate flow | D13: Biogas | E13: =(((Parameters!C7*(1-Waste_characteristics!B4))/Parameters!C10)*0.001)-((E12/Parameters!C11)*(1/Parameters!C10)) -> 223.74985 | F13: m3
A14: CHP | B14: input | C14: Intermediate flow | D14: Biogas | E14: =E13 -> 223.74985 | F14: m3
B15: output | C15: Elementary flow | D15: Nitrogen Oxides (NOx) | E15: =E14*Parameters!C24 -> 0.036718365 | F15: kg
B16: output | C16: Elementary flow | D16: Volatile Organic Compounds (VOCs) | E16: =E14*Parameters!C25 -> 0.3538951 | F16: kg
B17: output | C17: Elementary flow | D17: Sulfur Dioxide (SO2) | E17: =E14*Parameters!C26 -> 0.0031472884 | F17: kg
B18: output | C18: Elementary flow | D18: Particulate Matter (PM) | E18: =LCI!E14*Parameters!C27 -> 0.0076933718 | F18: kg
B19: output | C19: Elementary flow | D19: Carbon Monoxide (CO) | E19: =E14*Parameters!C28 -> 0.23901907 | F19: kg
B20: output | C20: Elementary flow | D20: Ammonia (NH3) | E20: =E14*Parameters!C29 -> 0.014337647 | F20: kg
B21: output | C21: Elementary flow | D21: Methane (CH4) | E21: =E14*Parameters!C30 -> 0.96288796 | F21: kg
B22: output | C22: Elementary flow | D22: Nitrous Oxide (N2O) | E22: =LCI!E14*Parameters!C31 -> 0.022925904 | F22: kg
B23: output | C23: Technosphere flow | D23: Electricity | E23: =E14*Parameters!C10*Parameters!C20*Parameters!C19/3.6 -> 509.0309 | F23: kWh
B24: output | C24: Technosphere flow | D24: Heat | E24: =E14*Parameters!C10*Parameters!C20*Parameters!C18 -> 2161.4235 | F24: MJ
A27: Biogas boiler | B27: input | C27: Intermediate flow | D27: Biogas | E27: =E13 -> 223.74985 | F27: m3
B28: output | C28: Elementary flow | D28: CO2 | E28: =$E$27*Parameters!C34 -> 449.66648 | F28: kg
B29: output | C29: Elementary flow | D29: CH4 | E29: =$E$27*Parameters!C35 -> 0.0057327997 | F29: kg
B30: output | C30: Elementary flow | D30: N2O | E30: =$E$27*Parameters!C36 -> 0.0057327997 | F30: kg
B31: output | C31: Elementary flow | D31: Sox | E31: =$E$27*Parameters!C37 -> 0.039771298 | F31: kg
B32: output | C32: Elementary flow | D32: PM10 | E32: =$E$27*Parameters!C38 -> 0.029165619 | F32: kg
B33: output | C33: Elementary flow | D33: PM2.5 | E33: =$E$27*Parameters!C39 -> 0.029165619 | F33: kg
B34: output | C34: Elementary flow | D34: Nox | E34: =$E$27*Parameters!C40 -> 0.38338098 | F34: kg
B35: output | C35: Elementary flow | D35: NH3 | E35: =$E$27*Parameters!C41 -> 0.012110539 | F35: kg
B36: output | C36: Elementary flow | D36: CO | E36: =$E$27*Parameters!C42 -> 0.32246998 | F36: kg
B37: output | C37: Elementary flow | D37: VOC | E37: =$E$27*Parameters!C43 -> 0.019276539 | F37: kg
B38: input | C38: Technosphere flow | D38: Electricity | E38: =Parameters!C44*LCI!E27 -> 0.60859958 | F38: kWh
B39: output | C39: Technosphere flow | D39: Heat | E39: =E27*Parameters!C10*Parameters!C20*Parameters!C33 -> 3876.4661 | F39: MJ
A42: Biogas upgrading | B42: input | C42: Technosphere flow | D42: Biogas | E42: =E13 -> 223.74985 | F42: m3
B43: output | C43: Elementary flow | D43: CO2 | E43: =E42*(1-Parameters!C10)*Parameters!C47*Parameters!C12 -> 174.55173 | F43: kg
B44: output | C44: Elementary flow | D44: CH4 | E44: =E42*Parameters!C10*Parameters!C48*Parameters!C11 -> 1.7398788 | F44: kg
B45: output | C45: Elementary flow | D45: H2S | E45: =Parameters!C49*LCI!E42 -> 0.0013424991 | F45: kg
B46: output | C46: Elementary flow | D46: Sox | E46: =E42*Parameters!C50 -> 0.001476749 | F46: kg
...

Sheet LCI_AD-d
A1: AD+injection+Composting of digestate
A2: Process | B2: Flow direction | C2: Flow type | D2: Flow name | E2: Value | F2: Unit
A3: Pretreatment | B3: input | C3: Technosphere flow | D3: Waste | E3: 1 | F3: t
B4: input | C4: Technosphere flow | D4: Electricity | E4: =E3*Parameters!C3 -> 9.98 | F4: kWh
B5: input | C5: Technosphere flow | D5: Water
B6: output | C6: Intermediate flow | D6: Pretreated biowaste | E6: =E3*Parameters!C5 -> 0.77 | F6: t
A7: Incineration | B7: input | C7: Intermediate flow | D7: transported discarded biowaste | E7: =E8*0.001*Parameters!C6 -> 2.3 | F7: tkm
B8: input | C8: Intermediate flow | D8: discarded biowaste | E8: =E3*(1-Parameters!C5)*1000 -> 230 | F8: kg
A9: AD | B9: input | C9: Intermediate flow | D9: Pretreated waste | E9: =E6 -> 0.77 | F9: t
B10: input | C10: Intermediate flow | D10: Electricity | E10: =Parameters!C14*E9 -> 22.33 | F10: kWh
B11: input | C11: Intermediate flow | D11: Heat | E11: =E9*Parameters!C15 -> 227.15 | F11: MJ
B12: output | C12: Elementary flow | D12: Methane | E12: =Parameters!C9*(Parameters!C7*(1-Waste_characteristics!B4))*E9*Parameters!C11*0.001 -> 1.5118454 | F12: kg
B13: output | C13: Intermediate flow | D13: Biogas | E13: =(((Parameters!C7*(1-Waste_characteristics!B4))/Parameters!C10)*0.001)-((E12/Parameters!C11)*(1/Parameters!C10)) -> 223.74985 | F13: m3
B14: output | C14: Technosphere flow | D14: Digestate | E14: =Parameters!C66*E9 -> 0.5558219 | F14: t
A15: Biogas upgrading | B15: input | C15: Technosphere flow | D15: Biogas | E15: =E13 -> 223.74985 | F15: m3
B16: output | C16: Elementary flow | D16: CO2 | E16: =E15*(1-Parameters!C10)*Parameters!C47*Parameters!C12 -> 174.55173 | F16: kg
B17: output | C17: Elementary flow | D17: CH4 | E17: =E15*Parameters!C10*Parameters!C48*Parameters!C11 -> 1.7398788 | F17: kg
B18: output | C18: Elementary flow | D18: H2S | E18: =Parameters!C49*E15 -> 0.0013424991 | F18: kg
B19: output | C19: Elementary flow | D19: Sox | E19: =E15*Parameters!C50 -> 0.001476749 | F19: kg
B20: input | C20: Technosphere flow | D20: Electricity requirement | E20: =E15*Parameters!C51 -> 76.074947 | F20: kWh
B21: input | C21: Technosphere flow | D21: Activated carbon | E21: =E15*Parameters!C52 -> 0.19913736 | F21: kg
B22: input | C22: Technosphere flow | D22: Zeolite | E22: =E15*Parameters!C53 -> 2.6626232 | F22: kg
B23: output | C23: Technosphere flow | D23: Biomethane | E23: =(E15*Parameters!C10*(1-Parameters!C48)) -> 131.83341 | F23: m3
A24: Dewatering | B24: input | C24: Technosphere flow | D24: Digestate | E24: =E14 -> 0.5558219 | F24: t
B25: input | C25: Technosphere flow | D25: electricity | E25: =E24*Parameters!C90*1000 -> 2.0184752 | F25: kWh
B26: output | C26: Technosphere flow | D26: dewatered digestate | E26: =Parameters!C68*Parameters!C88*(1/Parameters!C89)*E9 -> 0.2970039 | F26: t
B27: output | C27: Technosphere flow | D27: wastewater | E27: =(E24-E26)*1000/Parameters!C70 -> 0.25911227 | F27: m3
A28: Composting of digestate | B28: input | C28: Technosphere flow | D28: dewatered digestate | E28: =E26 -> 0.2970039 | F28: t
B29: output | C29: Elementary flow | D29: CH4 | E29: =(16/12)*Parameters!C98*(1-Parameters!C94)*((E6*1000*(1-Waste_characteristics!B4)*Waste_characteristics!B9)-((E13*(1-Parameters!C10)*Parameters!C12*(12/44)))-((E13*(Parameters!C10)*Parameters!C11*(12/16)))) -> 0.088228561 | F29: kg
B30: output | C30: Elementary flow | D30: N2O | E30: =(E6*1000*(1-Waste_characteristics!B4)*Waste_characteristics!B8)*(1-Parameters!C91)*Parameters!C99*(44/28) -> 0.062318617 | F30: kg
B31: output | C31: Elementary flow | D31: NH3 | E31: =(E6*1000*(1-Waste_characteristics!B4)*Waste_characteristics!B8)*(1-Parameters!C91)*Parameters!C100*(17/14) -> 0.20275914 | F31: kg
B32: output | C32: Elementary flow | D32: NMVOC | E32: =E28*Parameters!C101 -> 0.030888406 | F32: kg
B33: output | C33: Elementary flow | D33: CO | E33: =(44/12)*Parameters!C102*(1-Parameters!C94)*((E6*1000*(1-Waste_characteristics!B4)*Waste_characteristics!B9)-((E14*(1-Parameters!C10)*Parameters!C12*(12/44)))-((E14*(Parameters!C10)*Parameters!C11*(12/16)))) -> 0.12509677 | F33: kg
B34: output | C34: Technosphere flow | D34: compost | E34: =E28*(1-Parameters!C103) -> 0.15444203 | F34: t
B35: input | C35: Technosphere flow | D35: electricity | E35: =E28*Parameters!C104 -> 3.1254739 | F35: kWh
B36: input | C36: Technosphere flow | D36: diesel | E36: =E28*Parameters!C105*Parameters!C106 -> 0.44883056 | F36: kg
A37: Land application of compost
B38: output | C38: Elementary flow | D38: N2O | E38: ='LCI_AD-b'!E40 -> 0.013194214 | F38: kg
B39: output | C39: Elementary flow | D39: NH3 | E39: ='LCI_AD-b'!E41 -> 0.078947678 | F39: kg
B40: output | C40: Elementary flow | D40: NO3 | E40: ='LCI_AD-b'!E42 -> 2.6495849 | F40: kg
...

Sheet params_HC
B2: Technology | I2: Pretratment technology
B3: Pretreatement technology | C3: 1 | D3: (don't select if home composting) | I3: 0 | J3: None
B4: Ratio Biowaste/WC | C4: 8_1 | I4: 1 | J4: Drum-screen + Shredder + Piston press
B5: Aeration mode for industrial composting | C5: Active | D5: (don't select if home composting) | I5: 2 | J5: Shredder + Piston press + Screw press
B6: Distance of biowaste collection | C6: 20 | D6: km | I6: 3 | J6: Separation-mill
B7: Distance of compost transport from composting site to land | C7: 20 | D7: km | I7: 4 | J7: Pulp + Drum-screen

Sheet LCI_HC
A1: Home Composting
A2: Process | B2: Flow direction | C2: Flow type | D2: Flow name | E2: Value | F2: Unit
A3: Home composting | B3: input | C3: Technosphere flow | D3: Waste | E3: 1 | F3: t
B4: output | C4: Elementary flow | D4: CH4 | E4: =[3]LCI!$B$4*1000 -> 0.34805 | F4: kg | G4: data from PaCTEA
B5: output | C5: Elementary flow | D5: N2O | E5: =[3]LCI!$B$6*1000 -> 0.070149 | F5: kg | G5: data from PaCTEA
B6: output | C6: Elementary flow | D6: NH3 | E6: =[3]LCI!$B$5*1000 -> 0.064732 | F6: kg | G6: data from PaCTEA
B7: input | C7: Technosphere flow | D7: Wood chips consumption | E7: =E3*(1/8)*1000 -> 125 | F7: kg | G7: data from PaCTEA
A8: Land application
B9: output | C9: Elementary flow | D9: NH3 | E9: =[3]LCI!$C$18*1000 -> 0.36486015 | F9: kg | G9: data from PaCTEA
B10: output | C10: Elementary flow | D10: N2O | E10: =[3]LCI!$C$19*1000 -> 0.13095325 | F10: kg | G10: data from PaCTEA
B11: output | C11: Elementary flow | D11: NO3 | E11: =[3]LCI!$C$20*1000 -> 13.608329 | F11: kg | G11: data from PaCTEA
B12: output | C12: Elementary flow | D12: (PO4)3- | E12: =[3]LCI!$C$22*1000 -> -0.08127857 | F12: kg | G12: data from PaCTEA
B13: output | C13: Elementary flow | D13: CO2 fossil | E13: =[3]LCI!$C$26*1000 -> -356.4 | F13: kg | G13: data from PaCTEA
A14: Substitued products
C15: Technosphere flow | D15: N-fertilizer | E15: =0.0116046876865655*1000 -> 11.604688 | F15: kg | G15: data from PaCTEA
C16: Technosphere flow | D16: P-fertilizer | E16: =0.00342132225661322*1000 -> 3.4213223 | F16: kg | G16: data from PaCTEA
C17: Technosphere flow | D17: K-fertilizer | E17: =0.00502189482738727*1000 -> 5.0218948 | F17: kg | G17: data from PaCTEA
C18: Technosphere flow | D18: Peat | E18: =0.438311688311688*1000 -> 438.31169 | F18: kg | G18: data from PaCTEA

Sheet LCI_AD-a
A1: AD+CHP+Digestate
A2: Process | B2: Flow direction | C2: Flow type | D2: Flow name | E2: Value | F2: Unit
A3: Pretreatment | B3: input | C3: Technosphere flow | D3: Waste | E3: 1 | F3: t
B4: input | C4: Technosphere flow | D4: Electricity | E4: =E3*Parameters!C3 -> 9.98 | F4: kWh
B5: input | C5: Technosphere flow | D5: Water
B6: output | C6: Intermediate flow | D6: Pretreated biowaste | E6: =E3*Parameters!C5 -> 0.77 | F6: t
A7: Incineration | B7: input | C7: Intermediate flow | D7: transported discarded biowaste | E7: =E8*0.001*Parameters!C6 -> 2.3 | F7: tkm
B8: input | C8: Intermediate flow | D8: discarded biowaste | E8: =E3*(1-Parameters!C5)*1000 -> 230 | F8: kg
A9: AD | B9: input | C9: Intermediate flow | D9: Pretreated waste | E9: =E6 -> 0.77 | F9: t
B10: input | C10: Intermediate flow | D10: Electricity | E10: =Parameters!C14*E9 -> 22.33 | F10: kWh
B11: input | C11: Intermediate flow | D11: Heat | E11: =E9*Parameters!C15 -> 227.15 | F11: MJ
B12: output | C12: Elementary flow | D12: Methane | E12: =Parameters!C9*(Parameters!C7*(1-Waste_characteristics!B4))*E9*Parameters!C11*0.001 -> 1.5118454 | F12: kg
B13: output | C13: Intermediate flow | D13: Biogas | E13: =(((Parameters!C7*(1-Waste_characteristics!B4))/Parameters!C10)*0.001)-((E12/Parameters!C11)*(1/Parameters!C10)) -> 223.74985 | F13: m3
B14: output | C14: Technosphere flow | D14: Digestate | E14: =Parameters!C66*E9 -> 0.5558219 | F14: t
A15: CHP | B15: input | C15: Intermediate flow | D15: Biogas | E15: =E13 -> 223.74985 | F15: m3
B16: output | C16: Elementary flow | D16: Nitrogen Oxides (NOx) | E16: =E15*Parameters!C24 -> 0.036718365 | F16: kg
B17: output | C17: Elementary flow | D17: Volatile Organic Compounds (VOCs) | E17: =E15*Parameters!C25 -> 0.3538951 | F17: kg
B18: output | C18: Elementary flow | D18: Sulfur Dioxide (SO2) | E18: =E15*Parameters!C26 -> 0.0031472884 | F18: kg
B19: output | C19: Elementary flow | D19: Particulate Matter (PM) | E19: =LCI!E14*Parameters!C27 -> 0.0076933718 | F19: kg
B20: output | C20: Elementary flow | D20: Carbon Monoxide (CO) | E20: =E15*Parameters!C28 -> 0.23901907 | F20: kg
B21: output | C21: Elementary flow | D21: Ammonia (NH3) | E21: =E15*Parameters!C29 -> 0.014337647 | F21: kg
B22: output | C22: Elementary flow | D22: Methane (CH4) | E22: =E15*Parameters!C30 -> 0.96288796 | F22: kg
B23: output | C23: Elementary flow | D23: Nitrous Oxide (N2O) | E23: =LCI!E14*Parameters!C31 -> 0.022925904 | F23: kg
B24: output | C24: Technosphere flow | D24: Electricity | E24: =E15*Parameters!C10*Parameters!C20*Parameters!C19/3.6 -> 509.0309 | F24: kWh
B25: output | C25: Technosphere flow | D25: Heat | E25: =E15*Parameters!C10*Parameters!C20*Parameters!C18 -> 2161.4235 | F25: MJ
A26: Storage | B26: input | C26: Technosphere flow | D26: Digestate | E26: =E14 -> 0.5558219 | F26: t
B27: output | C27: Elementary flow | D27: CH4 | E27: =Parameters!C75*E9*1000 -> 1.338037 | F27: kg
B28: output | C28: Technosphere flow | D28: Digestate after storage | E28: =E26-(E27*0.001) -> 0.55448387 | F28: t
A29: Land application of digestate | B29: input | C29: Technosphere flow | D29: Digestate after storage | E29: =E28 -> 0.55448387 | F29: t
B30: output | C30: Elementary flow | D30: N2O | E30: =(Parameters!C82*'LCI_AD-a'!E9*1000*Parameters!C79*44/28)-(E36*Parameters!C123*Parameters!C125*44/28) -> 0.069747028 | F30: kg | H30: NET EMISSION TO BE calculated
B31: output | C31: Elementary flow | D31: NH3 | E31: =(Parameters!C82*'LCI_AD-a'!E9*1000*Parameters!C80*17/14)-(E36*Parameters!C123*Parameters!C124*17/14) -> 4.329404 | F31: kg
B32: output | C32: Elementary flow | D32: NO3 | E32: =(Parameters!C82*'LCI_AD-a'!E9*1000*Parameters!C81*62/14)-(E36*Parameters!C123*Parameters!C126*62/14) -> -1.8937605 | F32: kg
B33: output | C33: Elementary flow | D33: (PO4)3- | E33: =-Parameters!C129*'LCI_AD-a'!E37*Parameters!C128*0.001 -> -0.06209938 | F33: kg
B34: output | C34: Elementary flow | D34: CO2 fossil | E34: =-E39*Parameters!C136*Parameters!C134*44/12 -> -115.35192 | F34: kg
A35: Substituted products
C36: Technosphere flow | D36: N-fertilizer | E36: =(Parameters!C83/Parameters!C127)*FW_mass*1000*E6/Parameters!C123 -> 18.00888 | F36: kg | G36: NH4NO3
C37: Technosphere flow | D37: P-fertilizer | E37: =(Parameters!C86/Parameters!C131)*1000*'LCI_AD-a'!E9/Parameters!C128 -> 50.217839 | F37: kg | G37: single superphosphate
C38: Technosphere flow | D38: K-fertilizer | E38: =(Parameters!C85/Parameters!C132)*'LCI_AD-a'!E9*1000 -> 18.509017 | F38: kg
C39: Technosphere flow | D39: Peat | E39: =(Parameters!C84/Parameters!C136)*1000*E9 -> 157.62594 | F39: kg
C40: Technosphere flow | D40: Marginal heat | E40: =E25 -> 2161.4235 | F40: MJ
...

Sheet LCI_AD-c
A1: AD+injection+Digestate
A2: Process | B2: Flow direction | C2: Flow type | D2: Flow name | E2: Value | F2: Unit
A3: Pretreatment | B3: input | C3: Technosphere flow | D3: Waste | E3: 1 | F3: t
