Workbook

Sheet Parameters
B2: Ambient temperature | C2: 25°C
B3: Ratio biowaste/WC | C3: 8_1
B4: Pretreatement technology | C4: 1

Sheet raw_data
A1: Category | B1: Name | C1: Mass (kg) | D1: Water(%) | E1: TS(%) | F1: VS (%TS) | G1: Ash(%TS) | H1: Energy (MJ/kgTS) | I1: CH4pot (m3/tonVS) | J1: Cbio (%TS) | K1: Cbioand (%TS) | L1: Cfossil (%TS) | M1: Ca (%TS) | N1: Cl (%TS) | O1: F (%TS) | P1: H (%TS) | Q1: K (%TS) | R1: N (%TS) | S1: Na (%TS) | T1: O (%TS) | U1: P (%TS) | V1: S (%TS) | W1: Ag (%TS) | X1: Al (%TS) | Y1: Ar (%TS) | Z1: As (%TS) | AA1: Au (%TS) | AB1: B (%TS) | AC1: Ba (%TS) | AD1: Be (%TS) | AE1: Bi (%TS) | AF1: Br (%TS) | AG1: Cd (%TS) | AH1: Co (%TS) | AI1: Cr (%TS) | AJ1: Cu (%TS) | AK1: Fe (%TS) | AL1: Ga (%TS) | AM1: Hg (%TS) | AN1: In (%TS) | AO1: Li (%TS) | AP1: Mg (%TS) | AQ1: Mn (%TS) | AR1: Mo (%TS) | AS1: Ni (%TS) | AT1: Pb (%TS) | AU1: Pd (%TS) | AV1: Pt (%TS) | AW1: Sb (%TS) | AX1: Se (%TS) | AY1: Si (%TS) | AZ1: Sn (%TS) | BA1: Sr (%TS) | BB1: Ta (%TS) | BC1: Ti (%TS) | BD1: V (%TS) | BE1: Zn (%TS) | BF1: Zr (%TS) | BG1: Toluene (%TS) | BH1: PAH (%TS) | BI1: Sucrose (%TS) | BJ1: Starch (%TS) | BK1: Cellulose (%TS) | BL1: Hemicellulose (%TS) | BM1: Pectin (%TS) | BN1: Lignin (%TS) | BO1: Proteins (%TS) | BP1: Lipids (%TS) | BQ1: Acetic acid (%TS) | BR1: Carbohydrates (%TS) | BS1: Digestible energy (MJ/kgTS) | BT1: SFU (FU/kgTS) | BU1: Fructose (%TS) | BV1: Glucose (%TS) | BW1: Lactose (%TS) | BX1: Maltose (%TS) | BY1: All sugars (%TS) | BZ1: Energy for humans (MJ/kg TS) | CA1: Alcohol | CB1: OtherVS
A2: Food product | B2: Average Biscuits, DSW | D2: 3.565 | E2: 96.44 | F2: 98.694938 | G2: 1.3050617 | H2: 20.707367 | I2: 558.22695 | J2: 50.939982 | K2: 50.939982 | L2: 0 | M2: 0.0093482694 | N2: 0.30951204 | O2: 0 | P2: 7.3773427 | Q2: 0.051960458 | R2: 1.0321918 | S2: 0.2777654 | T2: 39.344664 | U2: 0.026625621 | V2: 0.20868593 | W2: 0 | X2: 0 | Y2: 0 | Z2: 9.2668024e-08 | AA2: 0 | AB2: 0 | AC2: 0 | AD2: 0 | AE2: 0 | AF2: 0 | AG2: 5.186363e-07 | AH2: 0 | AI2: 8.4504466e-07 | AJ2: 3.3948982e-05 | AK2: 0.00041709092 | AL2: 0 | AM2: 2.2403259e-08 | AN2: 0 | AO2: 0 | AP2: 0.0075552512 | AQ2: 0.00014870774 | AR2: 0 | AS2: 3.3647383e-06 | AT2: 7.6374745e-08 | AU2: 0 | AV2: 0 | AW2: 0 | AX2: 6.9704862e-07 | AY2: 0 | AZ2: 0 | BA2: 0 | BB2: 0 | BC2: 0 | BD2: 0 | BE2: 0.00014820016 | BF2: 0 | BG2: 0 | BH2: 0 | BI2: 21.786321 | BJ2: 30.974587 | BK2: 0.023421589 | BL2: 0 | BM2: 0 | BN2: 0 | BO2: 5.8769672 | BP2: 22.82156 | BQ2: 0 | BR2: 69.986138 | BS2: 20.761268 | BT2: 1.6842894 | BU2: 0.65699032 | BV2: 1.3474234 | BW2: 0.78243838 | BX2: 0.52431828 | BY2: 25.097917 | BZ2: 21.015834 | CA2: 0 | CB2: 13.900911
A3: Food product | B3: Average Cake, DSW | D3: 20.2 | E3: 79.8 | F3: 98.830712 | G3: 1.1692877 | H3: 20.496507 | I3: 557.00194 | J3: 50.344228 | K3: 50.32149 | L3: 0 | M3: 0.026744161 | N3: 0.078472887 | O3: 0 | P3: 7.4438744 | Q3: 0.15348666 | R3: 0.97386995 | S3: 0.28487272 | T3: 40.045504 | U3: 0.035541544 | V3: 0.2014445 | W3: 0 | X3: 0 | Y3: 0 | Z3: 3.2467532e-07 | AA3: 0 | AB3: 0 | AC3: 0 | AD3: 0 | AE3: 0 | AF3: 0 | AG3: 3.1348639e-07 | AH3: 1.6233766e-07 | AI3: 2.4776614e-06 | AJ3: 3.7047143e-05 | AK3: 0.0011067575 | AL3: 0 | AM3: 3.2467532e-08 | AN3: 0 | AO3: 0 | AP3: 0.0057887984 | AQ3: 6.9190785e-05 | AR3: 1.6233766e-06 | AS3: 5.2116867e-06 | AT3: 1.1363636e-06 | AU3: 0 | AV3: 0 | AW3: 0 | AX3: 8.990405e-07 | AY3: 0 | AZ3: 0 | BA3: 0 | BB3: 0 | BC3: 0 | BD3: 0 | BE3: 0.00017183451 | BF3: 0 | BG3: 0 | BH3: 0 | BI3: 9.4432427 | BJ3: 5.1971608 | BK3: 0.016233766 | BL3: 0 | BM3: 0 | BN3: 0.032467532 | BO3: 5.6730357 | BP3: 22.673777 | BQ3: 0 | BR3: 70.467666 | BS3: 20.739432 | BT3: 1.6821017 | BU3: 0.39084314 | BV3: 1.3182643 | BW3: 0.43693957 | BX3: 0.98645747 | BY3: 12.569097 | BZ3: 21.20444 | CA3: 0 | CB3: 52.66229
A4: Food product | B4: Average Pasta, DSA | D4: 28.733333 | E4: 71.266667 | F4: 98.912823 | G4: 1.0871774 | H4: 16.627433 | I4: 439.60034 | J4: 44.503932 | K4: 44.468974 | L4: 0 | M4: 0.033154322 | N4: 0 | O4: 0 | P4: 6.4423206 | Q4: 0.33902514 | R4: 2.5375872 | S4: 0.0046191977 | T4: 45.425526 | U4: 0.23866954 | V4: 0.51336484 | W4: 0 | X4: 0 | Y4: 0 | Z4: 6.6887174e-07 | AA4: 0 | AB4: 0 | AC4: 0 | AD4: 0 | AE4: 0 | AF4: 0 | AG4: 1.9863513e-06 | AH4: 0 | AI4: 3.5663108e-06 | AJ4: 0.0003454591 | AK4: 0.0027096957 | AL4: 0 | AM4: 1.6170526e-07 | AN4: 0 | AO4: 0 | AP4: 0.047375973 | AQ4: 0.00060555806 | AR4: 1.4523947e-05 | AS4: 4.8587922e-06 | AT4: 1.3247486e-06 | AU4: 0 | AV4: 0 | AW4: 0 | AX4: 4.3434705e-06 | AY4: 0 | AZ4: 0 | BA4: 0 | BB4: 0 | BC4: 0 | BD4: 0 | BE4: 0.0014363094 | BF4: 0 | BG4: 0 | BH4: 0 | BI4: 0 | BJ4: 54.724265 | BK4: 0 | BL4: 0 | BM4: 0 | BN4: 0.049915828 | BO4: 14.457268 | BP4: 2.137766 | BQ4: 0 | BR4: 82.317789 | BS4: 18.000149 | BT4: 1.4111714 | BU4: 0 | BV4: 0 | BW4: 0 | BX4: 0 | BY4: 0 | BZ4: 16.63565 | CA4: 0 | CB4: 27.543608
A5: Food product | B5: Average Rice, DSA | D5: 10.642857 | E5: 89.357143 | F5: 97.837284 | G5: 2.1627163 | H5: 16.561773 | I5: 451.67257 | J5: 43.970329 | K5: 43.852377 | L5: 0 | M5: 0.035115715 | N5: 0 | O5: 0 | P5: 6.51878 | Q5: 0.333033 | R5: 1.3621364 | S5: 0.0020752433 | T5: 45.91316 | U5: 0.42288798 | V5: 0.28991477 | W5: 0 | X5: 0 | Y5: 0 | Z5: 8.3391252e-06 | AA5: 0 | AB5: 0 | AC5: 0 | AD5: 0 | AE5: 0 | AF5: 0 | AG5: 1.2352887e-06 | AH5: 0 | AI5: 6.7349075e-07 | AJ5: 0.00012506021 | AK5: 0.0035841636 | AL5: 0 | AM5: 1.4276707e-07 | AN5: 0 | AO5: 0 | AP5: 0.03607487 | AQ5: 0.0012506555 | AR5: 1.2830282e-05 | AS5: 1.5780964e-05 | AT5: 6.5686408e-07 | AU5: 0 | AV5: 0 | AW5: 0 | AX5: 1.9556735e-06 | AY5: 0 | AZ5: 0 | BA5: 0 | BB5: 0 | BC5: 0 | BD5: 0 | BE5: 0.0010742351 | BF5: 0 | BG5: 0 | BH5: 0 | BI5: 0 | BJ5: 23.583093 | BK5: 0.27428377 | BL5: 0 | BM5: 0 | BN5: 0.16842223 | BO5: 8.1645159 | BP5: 4.7013367 | BQ5: 0 | BR5: 85.003295 | BS5: 17.790584 | BT5: 1.3903426 | BU5: 0 | BV5: 0 | BW5: 0 | BX5: 0 | BY5: 0 | BZ5: 17.159497 | CA5: 0 | CB5: 60.945632
A6: Food product | B6: Average Wheat, DSA | D6: 8.7888889 | E6: 91.211111 | F6: 98.452374 | G6: 1.547626 | H6: 19.205826 | I6: 513.9981 | J6: 48.44661 | K6: 48.316321 | L6: 0 | M6: 0.025281767 | N6: 0 | O6: 0 | P6: 7.0319365 | Q6: 0.34678988 | R6: 2.0961754 | S6: 0.080970012 | T6: 40.850813 | U6: 0.28331089 | V6: 0.42891066 | W6: 0 | X6: 0 | Y6: 0 | Z6: 1.4731402e-06 | AA6: 0 | AB6: 0 | AC6: 0 | AD6: 0 | AE6: 0 | AF6: 0 | AG6: 4.7500011e-06 | AH6: 4.9273039e-07 | AI6: 8.9534338e-07 | AJ6: 0.00028574867 | AK6: 0.0021944275 | AL6: 0 | AM6: 1.6107903e-07 | AN6: 0 | AO6: 0 | AP6: 0.084927597 | AQ6: 0.0035022977 | AR6: 1.2286976e-05 | AS6: 2.2185232e-05 | AT6: 1.5234092e-06 | AU6: 0 | AV6: 0 | AW6: 0 | AX6: 1.6339977e-06 | AY6: 0 | AZ6: 0 | BA6: 0 | BB6: 0 | BC6: 0 | BD6: 0 | BE6: 0.0036050704 | BF6: 0 | BG6: 0 | BH6: 0 | BI6: 0.26455858 | BJ6: 34.328419 | BK6: 0.85390644 | BL6: 0 | BM6: 0 | BN6: 0.18603802 | BO6: 12.078888 | BP6: 14.891207 | BQ6: 0 | BR6: 71.469878 | BS6: 19.789689 | BT6: 1.5880389 | BU6: 0 | BV6: 0 | BW6: 0 | BX6: 0 | BY6: 2.134274 | BZ6: 19.095712 | CA6: 0 | CB6: 35.849357
A7: Food product | B7: Average Pizza, DSA | D7: 49.945455 | E7: 50.054545 | F7: 95.69052 | G7: 4.3094795 | H7: 19.347023 | I7: 539.46658 | J7: 47.66761 | K7: 47.66761 | L7: 0 | M7: 0.33650324 | N7: 1.6652305 | O7: 0 | P7: 7.1201828 | Q7: 0.38378207 | R7: 3.3944885 | S7: 1.0079475 | T7: 37.170545 | U7: 0.16864015 | V7: 0.75400961 | W7: 0 | X7: 0 | Y7: 0 | Z7: 5.7461407e-07 | AA7: 0 | AB7: 0 | AC7: 0 | AD7: 0 | AE7: 0 | AF7: 0 | AG7: 1.1835391e-06 | AH7: 0 | AI7: 0 | AJ7: 0.00017869143 | AK7: 0.0026245669 | AL7: 0 | AM7: 0 | AN7: 0 | AO7: 0 | AP7: 0.04289488 | AQ7: 0.00029724404 | AR7: 0 | AS7: 1.9151814e-05 | AT7: 5.4873176e-06 | AU7: 0 | AV7: 0 | AW7: 0 | AX7: 0 | AY7: 0 | AZ7: 0.00011512608 | BA7: 0 | BB7: 0 | BC7: 0 | BD7: 0 | BE7: 0.002576309 | BF7: 0 | BG7: 0 | BH7: 0 | BI7: 0 | BJ7: 0 | BK7: 0 | BL7: 0 | BM7: 0 | BN7: 0 | BO7: 21.234253 | BP7: 17.003306 | BQ7: 0 | BR7: 57.532679 | BS7: 20.293004 | BT7: 1.6379781 | BU7: 0 | BV7: 0 | BW7: 0 | BX7: 0 | BY7: 0 | BZ7: 19.279272 | CA7: 0 | CB7: 57.452962
A8: Food product | B8: Average Sandwich, DSA | D8: 54.807143 | E8: 45.214286 | F8: 95.955611 | G8: 4.0443888 | H8: 20.474825 | I8: 569.0871 | J8: 49.544285 | K8: 49.544285 | L8: 0 | M8: 0.094605715 | N8: 1.5992989 | O8: 0 | P8: 7.3595279 | Q8: 0.43942263 | R8: 3.4280751 | S8: 1.0497923 | T8: 35.279745 | U8: 0.24094319 | V8: 0.7620646 | W8: 0 | X8: 0 | Y8: 0 | Z8: 0 | AA8: 0 | AB8: 0 | AC8: 0 | AD8: 0 | AE8: 0 | AF8: 0 | AG8: 0 | AH8: 0 | AI8: 0 | AJ8: 0.00018661008 | AK8: 0.0017961721 | AL8: 0 | AM8: 0 | AN8: 0 | AO8: 0 | AP8: 0.042365235 | AQ8: 0.0005556966 | AR8: 0 | AS8: 0 | AT8: 0 | AU8: 0 | AV8: 0 | AW8: 0 | AX8: 0 | AY8: 0 | AZ8: 0 | BA8: 0 | BB8: 0 | BC8: 0 | BD8: 0 | BE8: 0.002504109 | BF8: 0 | BG8: 0 | BH8: 0 | BI8: 0 | BJ8: 0 | BK8: 0 | BL8: 0 | BM8: 0 | BN8: 0 | BO8: 21.461096 | BP8: 21.778964 | BQ8: 0 | BR8: 52.711007 | BS8: 21.124451 | BT8: 1.7202082 | BU8: 0 | BV8: 0 | BW8: 0 | BX8: 0 | BY8: 0 | BZ8: 20.315078 | CA8: 0 | CB8: 52.715551
A9: Food product | B9: Average Charcuterie, CHA | D9: 58.366667 | E9: 41.633333 | F9: 91.35092 | G9: 8.6490798 | H9: 25.771842 | I9: 743.09678 | J9: 57.147639 | K9: 57.147639 | L9: 0 | M9: 0.037887324 | N9: 2.7017804 | O9: 0 | P9: 8.2849967 | Q9: 0.59134707 | R9: 6.006137 | S9: 3.1353014 | T9: 19.326851 | U9: 0.46758788 | V9: 1.3316614 | W9: 0 | X9: 0 | Y9: 0 | Z9: 1.2911784e-06 | AA9: 0 | AB9: 0 | AC9: 0 | AD9: 0 | AE9: 0 | AF9: 0 | AG9: 1.7312228e-06 | AH9: 0 | AI9: 1.6161598e-05 | AJ9: 0.00027628314 | AK9: 0.0045496977 | AL9: 0 | AM9: 2.2003784e-07 | AN9: 0 | AO9: 0 | AP9: 0.040439279 | AQ9: 0.00051176912 | AR9: 3.488267e-06 | AS9: 1.2310401e-05 | AT9: 4.8489019e-06 | AU9: 0 | AV9: 0 | AW9: 0 | AX9: 1.9825931e-05 | AY9: 0 | AZ9: 0 | BA9: 0 | BB9: 0 | BC9: 0 | BD9: 0 | BE9: 0.0046431238 | BF9: 0 | BG9: 0 | BH9: 0 | BI9: 0.092709207 | BJ9: 1.035133 | BK9: 0.018784789 | BL9: 0 | BM9: 0 | BN9: 0 | BO9: 37.501957 | BP9: 45.399244 | BQ9: 0 | BR9: 7.8627278 | BS9: 25.175808 | BT9: 2.1208874 | BU9: 0.0035180299 | BV9: 0.0052770449 | BW9: 1.3755239 | BX9: 0 | BY9: 1.4770282 | BZ9: 24.483705 | CA9: 0 | CB9: 5.9187736
A10: Food product | B10: Average Milk, FDP | D10: 80.565217 | E10: 19.443478 | F10: 93.220497 | G10: 6.7795028 | H10: 18.958191 | I10: 539.36806 | J10: 46.486673 | K10: 46.486673 | L10: 0 | M10: 1.026321 | N10: 0.52653571 | O10: 0 | P10: 6.9570373 | Q10: 1.381597 | R10: 4.7143872 | S10: 0.35185081 | T10: 34.490861 | U10: 0.81121297 | V10: 1.0679109 | W10: 0 | X10: 0 | Y10: 0 | Z10: 1.5579565e-06 | AA10: 0 | AB10: 0 | AC10: 0 | AD10: 0 | AE10: 0 | AF10: 0 | AG10: 1.2279418e-07 | AH10: 0 | AI10: 3.8886365e-06 | AJ10: 0.00017927492 | AK10: 0.00056195451 | AL10: 0 | AM10: 2.531861e-07 | AN10: 0 | AO10: 0 | AP10: 0.10978937 | AQ10: 7.230938e-05 | AR10: 3.6269289e-05 | AS10: 2.399125e-05 | AT10: 6.1834328e-07 | AU10: 0 | AV10: 0 | AW10: 0 | AX10: 1.4515024e-05 | AY10: 0 | AZ10: 0 | BA10: 0 | BB10: 0 | BC10: 0 | BD10: 0 | BE10: 0.0036867778 | BF10: 0 | BG10: 0 | BH10: 0 | BI10: 6.7008672 | BJ10: 0 | BK10: 0.36717942 | BL10: 0 | BM10: 0 | BN10: 0 | BO10: 30.074272 | BP10: 15.325597 | BQ10: 0 | BR10: 47.92997 | BS10: 20.165157 | BT10: 1.625334 | BU10: 0.012978585 | BV10: 0.015345975 | BW10: 35.488767 | BX10: 0 | BY10: 43.901765 | BZ10: 18.743301 | CA10: 0 | CB10: 5.235489
A11: Food product | B11: Average Yogurt, FDP | D11: 82.714286 | E11: 17.307143 | F11: 94.551525 | G11: 5.4484746 | H11: 18.695702 | I11: 528.34762 | J11: 46.314213 | K11: 46.314213 | L11: 0 | M11: 0.77588848 | N11: 0.18138609 | O11: 0 | P11: 6.9778276 | Q11: 0.93642367 | R11: 3.5695733 | S11: 0.24323037 | T11: 37.25703 | U11: 0.58585569 | V11: 0.80861236 | W11: 0 | X11: 0 | Y11: 0 | Z11: 8.9581099e-07 | AA11: 0 | AB11: 0 | AC11: 0 | AD11: 0 | AE11: 0 | AF11: 0 | AG11: 7.7509362e-09 | AH11: 0 | AI11: 8.5468234e-07 | AJ11: 7.5072157e-05 | AK11: 0.00032982805 | AL11: 0 | AM11: 8.9581099e-08 | AN11: 0 | AO11: 0 | AP11: 0.07426473 | AQ11: 0.00010493203 | AR11: 7.4918301e-06 | AS11: 1.014079e-05 | AT11: 3.4491666e-07 | AU11: 0 | AV11: 0 | AW11: 0 | AX11: 1.1057634e-05 | AY11: 0 | AZ11: 0 | BA11: 0 | BB11: 0 | BC11: 0 | BD11: 0 | BE11: 0.0028770698 | BF11: 0 | BG11: 0 | BH11: 0 | BI11: 19.664522 | BJ11: 0 | BK11: 0 | BL11: 0 | BM11: 0 | BN11: 0 | BO11: 22.771963 | BP11: 14.839953 | BQ11: 0 | BR11: 57.702942 | BS11: 19.845924 | BT11: 1.5937618 | BU11: 3.9894136 | BV11: 3.6492334 | BW11: 16.6123 | BX11: 0 | BY11: 49.227328 | BZ11: 18.737553 | CA11: 0 | CB11: 13.02414
A12: Food product | B12: Average Egg, FDP | D12: 61.595 | E12: 38.43 | F12: 94.234878 | G12: 5.7651218 | H12: 24.758165 | I12: 691.08826 | J12: 55.79993 | K12: 55.79993 | L12: 0 | M12: 0.20068131 | N12: 1.2544612 | O12: 0 | P12: 8.1767754 | Q12: 0.59446318 | R12: 8.0446397 | S12: 1.3516872 | T12: 21.417606 | U12: 0.69863005 | V12: 1.7860519 | W12: 0 | X12: 0 | Y12: 0 | Z12: 0 | AA12: 0 | AB12: 0 | AC12: 0 | AD12: 0 | AE12: 0 | AF12: 0 | AG12: 3.1847134e-08 | AH12: 0 | AI12: 2.220915e-06 | AJ12: 0.00018822723 | AK12: 0.0071756216 | AL12: 0 | AM12: 0 | AN12: 0 | AO12: 0 | AP12: 0.046230486 | AQ12: 0.00010139695 | AR12: 1.8046709e-06 | AS12: 6.8103871e-07 | AT12: 2.1231423e-07 | AU12: 0 | AV12: 0 | AW12: 0 | AX12: 7.4643817e-05 | AY12: 0 | AZ12: 0 | BA12: 0 | BB12: 0 | BC12: 0 | BD12: 0 | BE12: 0.0045121114 | BF12: 0 | BG12: 0 | BH12: 0 | BI12: 0.99009901 | BJ12: 0 | BK12: 0 | BL12: 0 | BM12: 0 | BN12: 0 | BO12: 50.298402 | BP12: 36.646162 | BQ12: 0 | BR12: 7.2925073 | BS12: 25.087242 | BT12: 2.1121282 | BU12: 0 | BV12: 0.060190775 | BW12: 0 | BX12: 0 | BY12: 1.4988716 | BZ12: 23.344006 | CA12: 0 | CB12: 6.2400246
A13: Food product | B13: Average Cream, FDP | D13: 68.763636 | E13: 31.236364 | F13: 97.638892 | G13: 2.3611085 | H13: 31.362676 | I13: 856.92446 | J13: 67.669335 | K13: 67.669335 | L13: 0 | M13: 0.3690318 | N13: 0.19381621 | O13: 0 | P13: 9.6421633 | Q13: 0.47011397 | R13: 1.9802933 | S13: 0.13925516 | T13: 18.117059 | U13: 0.3148841 | V13: 0.44655179 | W13: 0 | X13: 0 | Y13: 0 | Z13: 1.4280469e-06 | AA13: 0 | AB13: 0 | AC13: 0 | AD13: 0 | AE13: 0 | AF13: 0 | AG13: 7.6850795e-09 | AH13: 0 | AI13: 4.2271129e-07 | AJ13: 7.032549e-05 | AK13: 0.00018205812 | AL13: 0 | AM13: 1.8498989e-07 | AN13: 0 | AO13: 0 | AP13: 0.036728948 | AQ13: 1.8092111e-05 | AR13: 2.0391941e-05 | AS13: 1.3455167e-06 | AT13: 3.4198604e-07 | AU13: 0 | AV13: 0 | AW13: 0 | AX13: 6.9140552e-06 | AY13: 0 | AZ13: 0 | BA13: 0 | BB13: 0 | BC13: 0 | BD13: 0 | BE13: 0.0013065206 | BF13: 0 | BG13: 0 | BH13: 0 | BI13: 0 | BJ13: 0 | BK13: 0 | BL13: 0 | BM13: 0 | BN13: 0 | BO13: 12.575693 | BP13: 70.506909 | BQ13: 0 | BR13: 14.503126 | BS13: 28.708752 | BT13: 2.4702956 | BU13: 0 | BV13: 0.054226475 | BW13: 12.446308 | BX13: 0 | BY13: 13.158772 | BZ13: 30.653309 | CA13: 0 | CB13: 2.0557546
... A45: Food product | B45: Average Cauliflower, F&V | D45: 91.6 | E45: 8.4 | F45: 91.228584 | G45: 8.7714157 | H45: 16.223873 | I45: 472.26846 | J45: 41.641887 | K45: 41.557641 | L45: 0 | M45: 0.29471885 | N45: 0 | O45: 0 | P45: 6.3556871 | Q45: 3.4403914 | R45: 4.7440413 | S45: 0.20449879 | T45: 38.041669 | U45: 0.57861129 | V45: 1.0483981 | W45: 0 | X45: 0 | Y45: 0 | Z45: 2.7172017e-06 | AA45: 0 | AB45: 0 | AC45: 0 | AD45: 0 | AE45: 0 | AF45: 0 | AG45: 7.6352825e-06 | AH45: 0 | AI45: 1.1928339e-05 | AJ45: 0.00050523231 | AK45: 0.004835795 | AL45: 0 | AM45: 9.4210126e-07 | AN45: 0 | AO45: 0 | AP45: 0.1587873 | AQ45: 0.0027667484 | AR45: 0 | AS45: 7.4928134e-05 | AT45: 8.9497106e-06 | AU45: 0 | AV45: 0 | AW45: 0 | AX45: 6.4881175e-06 | AY45: 0 | AZ45: 0 | BA45: 0 | BB45: 0 | BC45: 0 | BD45: 0 | BE45: 0.0031396579 | BF45: 0 | BG45: 0 | BH45: 0 | BI45: 0.72176044 | BJ45: 0.12029341 | BK45: 13.472862 | BL45: 0 | BM45: 0 | BN45: 0.12029341 | BO45: 29.524756 | BP45: 4.8117363 | BQ45: 0 | BR45: 56.490485 | BS45: 18.055889 | BT45: 1.4166231 | BU45: 15.758436 | BV45: 6.1349638 | BW45: 0 | BX45: 0 | BY45: 22.61516 | BZ45: 13.749673 | CA45: 0 | CB45: 20.563483
A46: Food product | B46: Average Artichoke, F&V | C46: 3 | D46: 84.9 | E46: 15.1 | F46: 92.715232 | G46: 7.2847682 | H46: 15.378574 | I46: 442.65 | J46: 40.691911 | K46: 40.691911 | L46: 0 | M46: 0.39735099 | N46: 0 | O46: 0 | P46: 6.2103865 | Q46: 2.6754967 | R46: 3.4635762 | S46: 0.17880795 | T46: 41.97177 | U46: 0.47880795 | V46: 0.77602711 | W46: 0 | X46: 0 | Y46: 0 | Z46: 0 | AA46: 0 | AB46: 0 | AC46: 0 | AD46: 0 | AE46: 0 | AF46: 0 | AG46: 0 | AH46: 0 | AI46: 0 | AJ46: 0 | AK46: 0.0072847682 | AL46: 0 | AM46: 0 | AN46: 0 | AO46: 0 | AP46: 0.23576159 | AQ46: 0 | AR46: 0 | AS46: 0 | AT46: 0 | AU46: 0 | AV46: 0 | AW46: 0 | AX46: 0 | AY46: 0 | AZ46: 0 | BA46: 0 | BB46: 0 | BC46: 0 | BD46: 0 | BE46: 0 | BF46: 0 | BG46: 0 | BH46: 0 | BI46: 0 | BJ46: 0 | BK46: 0 | BL46: 0 | BM46: 0 | BN46: 0 | BO46: 21.854305 | BP46: 1.3245033 | BQ46: 0 | BR46: 69.536424 | BS46: 17.287195 | BT46: 1.3407036 | BU46: 0 | BV46: 0 | BW46: 0 | BX46: 0 | BY46: 0 | BZ46: 14.437086 | CA46: 0 | CB46: 69.536424
A47: Food product | B47: Average Celeriac, F&V | D47: 78.15 | E47: 21.85 | F47: 88.785098 | G47: 11.214902 | H47: 15.692781 | I47: 469.9833 | J47: 40.716249 | K47: 40.530319 | L47: 0 | M47: 0.37498634 | N47: 0 | O47: 0 | P47: 6.1068596 | Q47: 2.1563695 | R47: 2.4823555 | S47: 2.1054709 | T47: 39.205921 | U47: 0.53422375 | V47: 0.55680611 | W47: 0 | X47: 0 | Y47: 0 | Z47: 2.2123894e-06 | AA47: 0 | AB47: 0 | AC47: 0 | AD47: 0 | AE47: 0 | AF47: 0 | AG47: 3.7422703e-05 | AH47: 3.0864198e-06 | AI47: 3.6854037e-05 | AJ47: 0.00049287119 | AK47: 0.0063176008 | AL47: 0 | AM47: 2.5210314e-06 | AN47: 0 | AO47: 0 | AP47: 0.13602098 | AQ47: 0.0012192724 | AR47: 0 | AS47: 5.3873047e-05 | AT47: 1.4701737e-05 | AU47: 0 | AV47: 0 | AW47: 0 | AX47: 1.0144215e-05 | AY47: 0 | AZ47: 0 | BA47: 0 | BB47: 0 | BC47: 0 | BD47: 0 | BE47: 0.0027174151 | BF47: 0 | BG47: 0 | BH47: 0 | BI47: 7.5663717 | BJ47: 1.6371681 | BK47: 6.1504425 | BL47: 0 | BM47: 0 | BN47: 0.26548673 | BO47: 15.680651 | BP47: 6.1113842 | BQ47: 0 | BR47: 66.993062 | BS47: 16.90973 | BT47: 1.303142 | BU47: 0.3539823 | BV47: 0 | BW47: 0 | BX47: 0 | BY47: 7.920354 | BZ47: 14.315115 | CA47: 0 | CB47: 51.019611
A48: Food product | B48: Average Savoy cabbage, F&V | D48: 91 | E48: 9 | F48: 91.111111 | G48: 8.8888889 | H48: 15.100079 | I48: 442.06098 | J48: 39.95739 | K48: 39.95739 | L48: 0 | M48: 0.38888889 | N48: 0 | O48: 0 | P48: 6.100401 | Q48: 2.5555556 | R48: 3.5555556 | S48: 0.31111111 | T48: 41.147489 | U48: 0.46666667 | V48: 0.78909154 | W48: 0 | X48: 0 | Y48: 0 | Z48: 0 | AA48: 0 | AB48: 0 | AC48: 0 | AD48: 0 | AE48: 0 | AF48: 0 | AG48: 0 | AH48: 0 | AI48: 0 | AJ48: 0.00068888889 | AK48: 0.0044444444 | AL48: 0 | AM48: 0 | AN48: 0 | AO48: 0 | AP48: 0.31111111 | AQ48: 0.002 | AR48: 0 | AS48: 2.3333333e-05 | AT48: 0 | AU48: 0 | AV48: 0 | AW48: 0 | AX48: 0 | AY48: 0 | AZ48: 0 | BA48: 0 | BB48: 0 | BC48: 0 | BD48: 0 | BE48: 0.003 | BF48: 0 | BG48: 0 | BH48: 0 | BI48: 0 | BJ48: 0 | BK48: 0 | BL48: 0 | BM48: 0 | BN48: 0 | BO48: 22.222222 | BP48: 1.1111111 | BQ48: 0 | BR48: 67.777778 | BS48: 16.99897 | BT48: 1.3121981 | BU48: 0 | BV48: 0 | BW48: 0 | BX48: 0 | BY48: 0 | BZ48: 12.555556 | CA48: 0 | CB48: 67.777778
A49: Food product | B49: Average Radish, F&V | D49: 94.633333 | E49: 5.3666667 | F49: 86.570015 | G49: 13.429985 | H49: 14.317388 | I49: 441.21876 | J49: 37.986705 | K49: 37.758953 | L49: 0 | M49: 0.70459947 | N49: 0 | O49: 0 | P49: 5.7965177 | Q49: 5.1950196 | R49: 2.4429814 | S49: 0.37667861 | T49: 40.103141 | U49: 0.48485986 | V49: 0.54217574 | W49: 0 | X49: 0 | Y49: 0 | Z49: 0 | AA49: 0 | AB49: 0 | AC49: 0 | AD49: 0 | AE49: 0 | AF49: 0 | AG49: 2.6516573e-05 | AH49: 0 | AI49: 1.3258286e-05 | AJ49: 0.0012273012 | AK49: 0.010379214 | AL49: 0 | AM49: 1.3258286e-06 | AN49: 0 | AO49: 0 | AP49: 0.21629427 | AQ49: 0.0012909659 | AR49: 0 | AS49: 5.3033146e-05 | AT49: 1.3258286e-05 | AU49: 0 | AV49: 0 | AW49: 0 | AX49: 1.3258286e-06 | AY49: 0 | AZ49: 0 | BA49: 0 | BB49: 0 | BC49: 0 | BD49: 0 | BE49: 0.0051517426 | BF49: 0 | BG49: 0 | BH49: 0 | BI49: 0 | BJ49: 0 | BK49: 5.6910569 | BL49: 0 | BM49: 0 | BN49: 0.32520325 | BO49: 15.268634 | BP49: 1.9318892 | BQ49: 0 | BR49: 69.369492 | BS49: 15.808659 | BT49: 1.1941943 | BU49: 3.0894309 | BV49: 7.1544715 | BW49: 0 | BX49: 0 | BY49: 10.243902 | BZ49: 12.853488 | CA49: 0 | CB49: 53.10933
A50: Food product | B50: Average Walnut, F&V | D50: 2.8 | E50: 97.2 | F50: 98.251029 | G50: 1.7489712 | H50: 30.566884 | I50: 830.43455 | J50: 66.457171 | K50: 66.457171 | L50: 0 | M50: 0.085493827 | N50: 0 | O50: 0 | P50: 9.4967726 | Q50: 0.4845679 | R50: 2.7757202 | S50: 0.0041152263 | T50: 19.71128 | U50: 0.3899177 | V50: 0.52240782 | W50: 0 | X50: 0 | Y50: 0 | Z50: 0 | AA50: 0 | AB50: 0 | AC50: 0 | AD50: 0 | AE50: 0 | AF50: 0 | AG50: 7.2016461e-07 | AH50: 0 | AI50: 1.2345679e-06 | AJ50: 0.0013786008 | AK50: 0.0021604938 | AL50: 0 | AM50: 8.2304527e-07 | AN50: 0 | AO50: 0 | AP50: 0.14814815 | AQ50: 0.0021604938 | AR50: 0 | AS50: 0.00032921811 | AT50: 7.0987654e-06 | AU50: 0 | AV50: 0 | AW50: 0 | AX50: 1.7489712e-06 | AY50: 0 | AZ50: 0 | BA50: 0 | BB50: 0 | BC50: 0 | BD50: 0 | BE50: 0.0027777778 | BF50: 0 | BG50: 0 | BH50: 0 | BI50: 0 | BJ50: 0.61728395 | BK50: 0 | BL50: 0 | BM50: 0 | BN50: 0 | BO50: 14.711934 | BP50: 66.152263 | BQ50: 0 | BR50: 17.386831 | BS50: 28.249483 | BT50: 2.4248739 | BU50: 0 | BV50: 0 | BW50: 0 | BX50: 0 | BY50: 2.5720165 | BZ50: 29.41358 | CA50: 0 | CB50: 16.769547
A51: Food product | B51: Average Broccoli, F&V | D51: 88.3 | E51: 11.7 | F51: 90.598291 | G51: 9.4017094 | H51: 16.845553 | I51: 488.23113 | J51: 42.295391 | K51: 42.115818 | L51: 0 | M51: 0.37777778 | N51: 0 | O51: 0 | P51: 6.4694594 | Q51: 3.3589744 | R51: 7.2478632 | S51: 0.068376068 | T51: 33.871554 | U51: 0.74273504 | V51: 1.6085327 | W51: 0 | X51: 0 | Y51: 0 | Z51: 0 | AA51: 0 | AB51: 0 | AC51: 0 | AD51: 0 | AE51: 0 | AF51: 0 | AG51: 0 | AH51: 0 | AI51: 8.5470085e-06 | AJ51: 0.0005982906 | AK51: 0.0060683761 | AL51: 0 | AM51: 0 | AN51: 0 | AO51: 0 | AP51: 0.17692308 | AQ51: 0.004957265 | AR51: 0 | AS51: 7.3504274e-05 | AT51: 0 | AU51: 0 | AV51: 0 | AW51: 0 | AX51: 5.1282051e-06 | AY51: 0 | AZ51: 0 | BA51: 0 | BB51: 0 | BC51: 0 | BD51: 0 | BE51: 0.0033333333 | BF51: 0 | BG51: 0 | BH51: 0 | BI51: 3.4188034 | BJ51: 0 | BK51: 7.0940171 | BL51: 0 | BM51: 0 | BN51: 0.25641026 | BO51: 45.299145 | BP51: 5.1282051 | BQ51: 0 | BR51: 40.17094 | BS51: 18.980988 | BT51: 1.5079972 | BU51: 11.111111 | BV51: 6.8376068 | BW51: 0 | BX51: 0 | BY51: 21.367521 | BZ51: 13.931624 | CA51: 0 | CB51: 11.452991
A52: Food product | B52: Average Pumpkin, F&V | D52: 94.6 | E52: 5.4 | F52: 90.740741 | G52: 9.2592593 | H52: 14.582489 | I52: 437.14286 | J52: 38.966121 | K52: 38.966121 | L52: 0 | M52: 0.37222222 | N52: 0 | O52: 0 | P52: 6.0754022 | Q52: 4.5 | R52: 1.7777778 | S52: 0.037037037 | T52: 43.746302 | U52: 0.61111111 | V52: 0.39454577 | W52: 0 | X52: 0 | Y52: 0 | Z52: 0 | AA52: 0 | AB52: 0 | AC52: 0 | AD52: 0 | AE52: 0 | AF52: 0 | AG52: 0 | AH52: 0 | AI52: 3.7037037e-05 | AJ52: 0.0014814815 | AK52: 0.005 | AL52: 0 | AM52: 0 | AN52: 0 | AO52: 0 | AP52: 0.20740741 | AQ52: 0.00074074074 | AR52: 3.7037037e-05 | AS52: 0 | AT52: 0 | AU52: 0 | AV52: 0 | AW52: 0 | AX52: 0 | AY52: 0 | AZ52: 0 | BA52: 0 | BB52: 0 | BC52: 0 | BD52: 0 | BE52: 0.0037037037 | BF52: 0 | BG52: 0 | BH52: 0 | BI52: 12.962963 | BJ52: 11.111111 | BK52: 0 | BL52: 0 | BM52: 0 | BN52: 0 | BO52: 11.111111 | BP52: 1.8518519 | BQ52: 0 | BR52: 77.777778 | BS52: 16.337653 | BT52: 1.2467938 | BU52: 16.666667 | BV52: 20.37037 | BW52: 0 | BX52: 0 | BY52: 50 | BZ52: 13.888889 | CA52: 0 | CB52: 16.666667
A53: Food product | B53: Average Shallot, F&V | D53: 87.8 | E53: 12.2 | F53: 95.901639 | G53: 4.0983607 | H53: 15.659455 | I53: 438.95299 | J53: 41.611163 | K53: 41.20933 | L53: 0 | M53: 0.18770492 | N53: 0 | O53: 0 | P53: 6.4535065 | Q53: 1.5819672 | R53: 2.0655738 | S53: 0.023770492 | T53: 45.53189 | U53: 0.32868852 | V53: 0.46569337 | W53: 0 | X53: 0 | Y53: 0 | Z53: 2.7868852e-06 | AA53: 0 | AB53: 0 | AC53: 0 | AD53: 0 | AE53: 0 | AF53: 0 | AG53: 1.1803279e-05 | AH53: 0 | AI53: 5.7377049e-06 | AJ53: 0.0005 | AK53: 0.002704918 | AL53: 0 | AM53: 7.3770492e-07 | AN53: 0 | AO53: 0 | AP53: 0.078688525 | AQ53: 0.0018852459 | AR53: 0 | AS53: 2.9098361e-05 | AT53: 2.4590164e-06 | AU53: 0 | AV53: 0 | AW53: 0 | AX53: 4.0983607e-06 | AY53: 0 | AZ53: 0 | BA53: 0 | BB53: 0 | BC53: 0 | BD53: 0 | BE53: 0.0013114754 | BF53: 0 | BG53: 0 | BH53: 0 | BI53: 15.655738 | BJ53: 0 | BK53: 7.0491803 | BL53: 0 | BM53: 0 | BN53: 0.57377049 | BO53: 13.114754 | BP53: 2.4590164 | BQ53: 0 | BR53: 81.147541 | BS53: 17.297552 | BT53: 1.3412301 | BU53: 15 | BV53: 18.360656 | BW53: 0 | BX53: 0 | BY53: 49.016393 | BZ53: 15.409836 | CA53: 0 | CB53: 23.688525
A54: Food product | B54: Average Celery, F&V | D54: 92.9 | E54: 7.1 | F54: 84.507042 | G54: 15.492958 | H54: 13.887309 | I54: 444.41667 | J54: 36.914567 | K54: 36.914567 | L54: 0 | M54: 0.79859155 | N54: 0 | O54: 0 | P54: 5.6765264 | Q54: 4.4788732 | R54: 1.6760563 | S54: 0.87323944 | T54: 40.18308 | U54: 0.42394366 | V54: 0.35008991 | W54: 0 | X54: 0 | Y54: 0 | Z54: 9.8591549e-06 | AA54: 0 | AB54: 0 | AC54: 0 | AD54: 0 | AE54: 0 | AF54: 0 | AG54: 2.2253521e-05 | AH54: 0 | AI54: 2.2535211e-05 | AJ54: 0.0015492958 | AK54: 0.0056338028 | AL54: 0 | AM54: 9.8591549e-07 | AN54: 0 | AO54: 0 | AP54: 0.11267606 | AQ54: 0 | AR54: 0 | AS54: 2.4647887e-05 | AT54: 1.2676056e-05 | AU54: 0 | AV54: 0 | AW54: 0 | AX54: 6.4788732e-07 | AY54: 0 | AZ54: 0 | BA54: 0 | BB54: 0 | BC54: 0 | BD54: 0 | BE54: 0.0014084507 | BF54: 0 | BG54: 0 | BH54: 0 | BI54: 4.2253521 | BJ54: 1.4084507 | BK54: 0 | BL54: 0 | BM54: 0 | BN54: 0 | BO54: 9.8591549 | BP54: 2.8169014 | BQ54: 0 | BR54: 71.830986 | BS54: 15.334245 | BT54: 1.1475569 | BU54: 5.6338028 | BV54: 7.0422535 | BW54: 0 | BX54: 0 | BY54: 16.901408 | BZ54: 12.816901 | CA54: 0 | CB54: 53.521127
A55: Food product | B55: Average Aubergine, F&V | D55: 93.5 | E55: 6.5 | F55: 92.307692 | G55: 7.6923077 | H55: 14.762229 | I55: 437.13333 | J55: 39.340515 | K55: 39.340515 | L55: 0 | M55: 0.12923077 | N55: 0 | O55: 0 | P55: 6.219731 | Q55: 3.6923077 | R55: 2.3230769 | S55: 0.046153846 | T55: 44.313813 | U55: 0.46615385 | V55: 0.49166473 | W55: 0 | X55: 0 | Y55: 0 | Z55: 2.4615385e-06 | AA55: 0 | AB55: 0 | AC55: 0 | AD55: 0 | AE55: 0 | AF55: 0 | AG55: 1.0615385e-05 | AH55: 0 | AI55: 1.0769231e-05 | AJ55: 0.0012307692 | AK55: 0.0061538462 | AL55: 0 | AM55: 1.5384615e-05 | AN55: 0 | AO55: 0 | AP55: 0.15384615 | AQ55: 0.0038461538 | AR55: 0 | AS55: 6.0769231e-06 | AT55: 5.3846154e-06 | AU55: 0 | AV55: 0 | AW55: 0 | AX55: 3.0769231e-06 | AY55: 0 | AZ55: 0 | BA55: 0 | BB55: 0 | BC55: 0 | BD55: 0 | BE55: 0.0024615385 | BF55: 0 | BG55: 0 | BH55: 0 | BI55: 1.5384615 | BJ55: 3.0769231 | BK55: 0 | BL55: 0 | BM55: 0 | BN55: 0 | BO55: 13.846154 | BP55: 1.5384615 | BQ55: 0 | BR55: 76.923077 | BS55: 16.734592 | BT55: 1.2860512 | BU55: 21.538462 | BV55: 21.538462 | BW55: 0 | BX55: 0 | BY55: 44.615385 | BZ55: 12.769231 | CA55: 0 | CB55: 29.230769
A56: Food product | B56: Average Valerian, F&V | D56: 95 | E56: 5 | F56: 89.377784 | G56: 10.622216 | H56: 15.54352 | I56: 463.22917 | J56: 40.35421 | K56: 40.35421 | L56: 0 | M56: 0.56349528 | N56: 0 | O56: 0 | P56: 6.1336624 | Q56: 4.1706604 | R56: 3.8337944 | S56: 0.32354685 | T56: 38.667499 | U56: 0.54203856 | V56: 0.85305032 | W56: 0 | X56: 0 | Y56: 0 | Z56: 5.6737589e-07 | AA56: 0 | AB56: 0 | AC56: 0 | AD56: 0 | AE56: 0 | AF56: 0 | AG56: 1.177305e-05 | AH56: 0 | AI56: 2.8368794e-06 | AJ56: 0.00067088017 | AK56: 0.013752888 | AL56: 0 | AM56: 1.4184397e-07 | AN56: 0 | AO56: 0 | AP56: 0.2273374 | AQ56: 0.0035439952 | AR56: 0 | AS56: 2.9078014e-05 | AT56: 1.4184397e-06 | AU56: 0 | AV56: 0 | AW56: 0 | AX56: 1.4184397e-06 | AY56: 0 | AZ56: 0 | BA56: 0 | BB56: 0 | BC56: 0 | BD56: 0 | BE56: 0.0037789947 | BF56: 0 | BG56: 0 | BH56: 0 | BI56: 0 | BJ56: 0 | BK56: 0 | BL56: 0 | BM56: 0 | BN56: 0 | BO56: 24.023416 | BP56: 3.9216159 | BQ56: 0 | BR56: 62.113025 | BS56: 17.269016 | BT56: 1.3389057 | BU56: 0 | BV56: 0 | BW56: 0 | BX56: 0 | BY56: 0 | BZ56: 13.093174 | CA56: 0 | CB56: 61.432753
A57: Food product | B57: Average Asparagus, F&V | D57: 92.733333 | E57: 7.2666667 | F57: 92.658637 | G57: 7.3413634 | H57: 16.316709 | I57: 464.01859 | J57: 42.148391 | K57: 41.799965 | L57: 0 | M57: 0.27364284 | N57: 0 | O57: 0 | P57: 6.389256 | Q57: 2.9328699 | R57: 4.4965488 | S57: 0.08205717 | T57: 39.203325 | U57: 0.82510998 | V57: 0.99351149 | W57: 0 | X57: 0 | Y57: 0 | Z57: 0 | AA57: 0 | AB57: 0 | AC57: 0 | AD57: 0 | AE57: 0 | AF57: 0 | AG57: 0 | AH57: 0 | AI57: 0 | AJ57: 0.00027363184 | AK57: 0.0024875622 | AL57: 0 | AM57: 0 | AN57: 0 | AO57: 0 | AP57: 0.13051837 | AQ57: 0 | AR57: 0 | AS57: 8.9552239e-05 | AT57: 0 | AU57: 0 | AV57: 0 | AW57: 0 | AX57: 4.9751244e-06 | AY57: 0 | AZ57: 0 | BA57: 0 | BB57: 0 | BC57: 0 | BD57: 0 | BE57: 0.0021890547 | BF57: 0 | BG57: 0 | BH57: 0 | BI57: 0.89552239 | BJ57: 0 | BK57: 3.7313433 | BL57: 0 | BM57: 0 | BN57: 0.49751244 | BO57: 27.979052 | BP57: 4.1416601 | BQ57: 0 | BR57: 60.537924 | BS57: 17.996031 | BT57: 1.4103758 | BU57: 3.3333333 | BV57: 1.5920398 | BW57: 0 | BX57: 0 | BY57: 5.8208955 | BZ57: 14.351514 | CA57: 0 | CB57: 50.488173
A58: Food product | B58: Average Chestnut, F&V | D58: 51.7 | E58: 48.3 | F58: 97.929607 | G58: 2.0703934 | H58: 16.830822 | I58: 452.61734 | J58: 44.820507 | K58: 44.820507 | L58: 0 | M58: 0.064182195 | N58: 0 | O58: 0 | P58: 6.4494291 | Q58: 1.2401656 | R58: 0.66252588 | S58: 0.0082815735 | T58: 45.931875 | U58: 0.15320911 | V58: 0.14703569 | W58: 0 | X58: 0 | Y58: 0 | Z58: 0 | AA58: 0 | AB58: 0 | AC58: 0 | AD58: 0 | AE58: 0 | AF58: 0 | AG58: 0 | AH58: 0 | AI58: 0 | AJ58: 0.00047619048 | AK58: 0.001863354 | AL58: 0 | AM58: 0 | AN58: 0 | AO58: 0 | AP58: 0.078674948 | AQ58: 0.0075983437 | AR58: 0 | AS58: 0 | AT58: 0 | AU58: 0 | AV58: 0 | AW58: 0 | AX58: 0 | AY58: 0 | AZ58: 0 | BA58: 0 | BB58: 0 | BC58: 0 | BD58: 0 | BE58: 0 | BF58: 0 | BG58: 0 | BH58: 0 | BI58: 0 | BJ58: 55.693582 | BK58: 0 | BL58: 0 | BM58: 0 | BN58: 0 | BO58: 4.1407867 | BP58: 5.5900621 | BQ58: 0 | BR58: 88.198758 | BS58: 17.735115 | BT58: 1.3850029 | BU58: 0 | BV58: 0 | BW58: 0 | BX58: 0 | BY58: 14.492754 | BZ58: 16.501035 | CA58: 0 | CB58: 32.505176
... A95: Food product | B95: Average Gourmet, GO | D95: 19.472202 | E95: 80.529048 | F95: 98.634642 | G95: 1.3653575 | H95: 21.471104 | I95: 583.38124 | J95: 51.939992 | K95: 51.934307 | L95: 0 | M95: 0.020778841 | N95: 0.10229926 | O95: 0 | P95: 7.6174645 | Q95: 0.085513611 | R95: 1.0558839 | S95: 0.23300222 | T95: 38.000951 | U95: 0.036856185 | V95: 0.21743078 | W95: 0 | X95: 0 | Y95: 0 | Z95: 1.0433584e-07 | AA95: 0 | AB95: 0 | AC95: 0 | AD95: 0 | AE95: 0 | AF95: 0 | AG95: 2.0803067e-07 | AH95: 4.0584416e-08 | AI95: 8.3067651e-07 | AJ95: 1.7749031e-05 | AK95: 0.00075527896 | AL95: 0 | AM95: 1.3717698e-08 | AN95: 0 | AO95: 0 | AP95: 0.0077500908 | AQ95: 5.4474631e-05 | AR95: 4.0584416e-07 | AS95: 2.1441063e-06 | AT95: 3.031846e-07 | AU95: 0 | AV95: 0 | AW95: 0 | AX95: 4.9064654e-07 | AY95: 0 | AZ95: 0 | BA95: 0 | BB95: 0 | BC95: 0 | BD95: 0 | BE95: 0.00023836204 | BF95: 0 | BG95: 0 | BH95: 0 | BI95: 8.7245987 | BJ95: 9.3919628 | BK95: 0.0099138387 | BL95: 0 | BM95: 0 | BN95: 0.0081168831 | BO95: 6.1232379 | BP95: 26.89539 | BQ95: 0 | BR95: 65.486354 | BS95: 21.4223 | BT95: 1.7496585 | BU95: 0.31417698 | BV95: 0.74380288 | BW95: 0.34624059 | BX95: 0.39254783 | BY95: 10.517944 | BZ95: 21.901754 | CA95: 0 | CB95: 45.684654
A96: Structuring material | B96: Wood chips | D96: 10 | E96: 90 | G96: 2.39 | BK96: 32.9 | BL96: 14.22 | BN96: 31.15
E97: 58.85 | F97: =(47.13/58.85)*100 -> 80.084962 | R97: =(2.13/58.85)*100 -> 3.6193713
B98: Total
A99: ABBREVIATIONS
A100: DSW | B100: Dry sweet
A101: DSA | B101: Dry savoury
A102: CHA | B102: Charcuterie
A103: FDP | B103: Fresh dairy products
A104: F&V | B104: Fruits and vegetables
A105: PO | B105: Poultry
A106: ME | B106: Meat
A107: CH | B107: Cheese
...

Sheet mass_composition
A1: Category | B1: Name | C1: Mass (kg) | D1: Water(kg) | E1: TS(kg) | F1: VS (kg) | G1: Ash(kg) | H1: Energy (MJ/kgTS) | I1: CH4pot (m3/tonVS) | J1: Cbio (kg) | K1: Cbioand (kg) | L1: Cfossil (kg) | M1: Ca (kg) | N1: Cl (kg) | O1: F (kg) | P1: H (kg) | Q1: K (kg) | R1: N (kg) | S1: Na (kg) | T1: O (kg) | U1: P (kg) | V1: S (kg) | W1: Ag (kg) | X1: Al (kg) | Y1: Ar(kg) | Z1: As(kg) | AA1: Au (kg) | AB1: B (kg) | AC1: Ba (kg) | AD1: Be (kg) | AE1: Bi (kg) | AF1: Br (kg) | AG1: Cd (kg) | AH1: Co (kg) | AI1: Cr(kg) | AJ1: Cu (kg) | AK1: Fe (kg) | AL1: Ga(kg) | AM1: Hg (kg) | AN1: In (kg) | AO1: Li (kg) | AP1: Mg (kg) | AQ1: Mn (kg) | AR1: Mo (kg) | AS1: Ni (kg) | AT1: Pb (kg) | AU1: Pd (kg) | AV1: Pt (kg) | AW1: Sb (kg) | AX1: Se (kg) | AY1: Si (kg) | AZ1: Sn (kg) | BA1: Sr (kg) | BB1: Ta(kg) | BC1: Ti (kg) | BD1: V (kg) | BE1: Zn (kg) | BF1: Zr (kg) | BG1: Toluene (kg) | BH1: PAH (%TS) | BI1: Sucrose (%TS) | BJ1: Starch (%TS) | BK1: Cellulose (kg) | BL1: Hemicellulose (kg) | BM1: Pectin (%TS) | BN1: Lignin (kg) | BO1: Proteins (kg) | BP1: Lipids (kg) | BQ1: Acetic acid (%TS) | BR1: Carbohydrates (kg) | BS1: Digestible energy (MJ/kgTS) | BT1: SFU (FU/kgTS) | BU1: Fructose (%TS) | BV1: Glucose (%TS) | BW1: Lactose (%TS) | BX1: Maltose (%TS) | BY1: All sugars (%TS) | BZ1: Energy for humans (MJ/kg TS) | CA1: Alcohol | CB1: OtherVS | CD1: valorgas - waste from Ludlow, UK
A2: Food product | B2: Average Biscuits, DSW | D2: =raw_data!$D2*$C2/100 -> 0 | E2: =raw_data!$E2*$C2/100 -> 0 | F2: =raw_data!$F2*$E2/100 -> 0 | G2: =raw_data!$G2*$E2/100 -> 0 | H2: 20.707367 | I2: 558.22695 | J2: =raw_data!$J2*mass_composition!$E2/100 -> 0 | K2: =raw_data!$K2*mass_composition!$E2/100 -> 0 | L2: =raw_data!$L2*mass_composition!$E2/100 -> 0 | M2: =raw_data!$M2*mass_composition!$E2/100 -> 0 | N2: =raw_data!$N2*mass_composition!$E2/100 -> 0 | O2: =raw_data!$O2*mass_composition!$E2/100 -> 0 | P2: =raw_data!$P2*mass_composition!$E2/100 -> 0 | Q2: =raw_data!$Q2*mass_composition!$E2/100 -> 0 | R2: =raw_data!$R2*mass_composition!$E2/100 -> 0 | S2: =raw_data!$S2*mass_composition!$E2/100 -> 0 | T2: =raw_data!$T2*mass_composition!$E2/100 -> 0 | U2: =raw_data!$U2*mass_composition!$E2/100 -> 0 | V2: =raw_data!$V2*mass_composition!$E2/100 -> 0 | W2: =raw_data!$W2*mass_composition!$E2/100 -> 0 | X2: =raw_data!$X2*mass_composition!$E2/100 -> 0 | Y2: =raw_data!$Y2*mass_composition!$E2/100 -> 0 | Z2: =raw_data!$Z2*mass_composition!$E2/100 -> 0 | AA2: =raw_data!$AA2*mass_composition!$E2/100 -> 0 | AB2: =raw_data!$AB2*mass_composition!$E2/100 -> 0 | AC2: =raw_data!$AC2*mass_composition!$E2/100 -> 0 | AD2: =raw_data!$AD2*mass_composition!$E2/100 -> 0 | AE2: =raw_data!$AE2*mass_composition!$E2/100 -> 0 | AF2: =raw_data!$AF2*mass_composition!$E2/100 -> 0 | AG2: =raw_data!$AG2*mass_composition!$E2/100 -> 0 | AH2: =raw_data!$AH2*mass_composition!$E2/100 -> 0 | AI2: =raw_data!$AI2*mass_composition!$E2/100 -> 0 | AJ2: =raw_data!$AJ2*mass_composition!$E2/100 -> 0 | AK2: =raw_data!$AK2*mass_composition!$E2/100 -> 0 | AL2: =raw_data!$AL2*mass_composition!$E2/100 -> 0 | AM2: =raw_data!$AM2*mass_composition!$E2/100 -> 0 | AN2: =raw_data!$AN2*mass_composition!$E2/100 -> 0 | AO2: =raw_data!$AO2*mass_composition!$E2/100 -> 0 | AP2: =raw_data!$AP2*mass_composition!$E2/100 -> 0 | AQ2: =raw_data!$AQ2*mass_composition!$E2/100 -> 0 | AR2: =raw_data!$AR2*mass_composition!$E2/100 -> 0 | AS2: =raw_data!$AS2*mass_composition!$E2/100 -> 0 | AT2: =raw_data!$AT2*mass_composition!$E2/100 -> 0 | AU2: =raw_data!$AU2*mass_composition!$E2/100 -> 0 | AV2: =raw_data!$AV2*mass_composition!$E2/100 -> 0 | AW2: =raw_data!$AW2*mass_composition!$E2/100 -> 0 | AX2: =raw_data!$AX2*mass_composition!$E2/100 -> 0 | AY2: =raw_data!$AY2*mass_composition!$E2/100 -> 0 | AZ2: =raw_data!$AZ2*mass_composition!$E2/100 -> 0 | BA2: =raw_data!$BA2*mass_composition!$E2/100 -> 0 | BB2: =raw_data!$BB2*mass_composition!$E2/100 -> 0 | BC2: =raw_data!$BC2*mass_composition!$E2/100 -> 0 | BD2: =raw_data!$BD2*mass_composition!$E2/100 -> 0 | BE2: =raw_data!$BE2*mass_composition!$E2/100 -> 0 | BF2: =raw_data!$BF2*mass_composition!$E2/100 -> 0 | BG2: =raw_data!$BG2*mass_composition!$E2/100 -> 0 | BH2: =raw_data!$BF2*mass_composition!$E2/100 -> 0 | BI2: =raw_data!$BF2*mass_composition!$E2/100 -> 0 | BJ2: =raw_data!$BF2*mass_composition!$E2/100 -> 0 | BK2: =raw_data!$BK2*$E2/100 -> 0 | BL2: =raw_data!$BL2*$E2/100 -> 0 | BM2: 0 | BN2: =raw_data!$BN2*$E2/100 -> 0 | BO2: =raw_data!$BO2*$E2/100 -> 0 | BP2: =raw_data!$BP2*$E2/100 -> 0 | BQ2: 0 | BR2: =raw_data!$BR2*$E2/100 -> 0 | BS2: 20.761268 | BT2: 1.6842894 | BU2: 0.65699032 | BV2: 1.3474234 | BW2: 0.78243838 | BX2: 0.52431828 | BY2: 25.097917 | BZ2: 21.015834 | CA2: 0 | CB2: 13.900911
A3: Food product | B3: Average Cake, DSW | D3: =raw_data!$D3*$C3/100 -> 0 | E3: =raw_data!$E3*$C3/100 -> 0 | F3: =raw_data!$F3*$E3/100 -> 0 | G3: =raw_data!$G3*$E3/100 -> 0 | H3: 20.496507 | I3: 557.00194 | J3: =raw_data!$J3*mass_composition!$E3/100 -> 0 | K3: =raw_data!$K3*mass_composition!$E3/100 -> 0 | L3: =raw_data!$L3*mass_composition!$E3/100 -> 0 | M3: =raw_data!$M3*mass_composition!$E3/100 -> 0 | N3: =raw_data!$N3*mass_composition!$E3/100 -> 0 | O3: =raw_data!$O3*mass_composition!$E3/100 -> 0 | P3: =raw_data!$P3*mass_composition!$E3/100 -> 0 | Q3: =raw_data!$Q3*mass_composition!$E3/100 -> 0 | R3: =raw_data!$R3*mass_composition!$E3/100 -> 0 | S3: =raw_data!$S3*mass_composition!$E3/100 -> 0 | T3: =raw_data!$T3*mass_composition!$E3/100 -> 0 | U3: =raw_data!$U3*mass_composition!$E3/100 -> 0 | V3: =raw_data!$V3*mass_composition!$E3/100 -> 0 | W3: =raw_data!$W3*mass_composition!$E3/100 -> 0 | X3: =raw_data!$X3*mass_composition!$E3/100 -> 0 | Y3: =raw_data!$Y3*mass_composition!$E3/100 -> 0 | Z3: =raw_data!$Z3*mass_composition!$E3/100 -> 0 | AA3: =raw_data!$AA3*mass_composition!$E3/100 -> 0 | AB3: =raw_data!$AB3*mass_composition!$E3/100 -> 0 | AC3: =raw_data!$AC3*mass_composition!$E3/100 -> 0 | AD3: =raw_data!$AD3*mass_composition!$E3/100 -> 0 | AE3: =raw_data!$AE3*mass_composition!$E3/100 -> 0 | AF3: =raw_data!$AF3*mass_composition!$E3/100 -> 0 | AG3: =raw_data!$AG3*mass_composition!$E3/100 -> 0 | AH3: =raw_data!$AH3*mass_composition!$E3/100 -> 0 | AI3: =raw_data!$AI3*mass_composition!$E3/100 -> 0 | AJ3: =raw_data!$AJ3*mass_composition!$E3/100 -> 0 | AK3: =raw_data!$AK3*mass_composition!$E3/100 -> 0 | AL3: =raw_data!$AL3*mass_composition!$E3/100 -> 0 | AM3: =raw_data!$AM3*mass_composition!$E3/100 -> 0 | AN3: =raw_data!$AN3*mass_composition!$E3/100 -> 0 | AO3: =raw_data!$AO3*mass_composition!$E3/100 -> 0 | AP3: =raw_data!$AP3*mass_composition!$E3/100 -> 0 | AQ3: =raw_data!$AQ3*mass_composition!$E3/100 -> 0 | AR3: =raw_data!$AR3*mass_composition!$E3/100 -> 0 | AS3: =raw_data!$AS3*mass_composition!$E3/100 -> 0 | AT3: =raw_data!$AT3*mass_composition!$E3/100 -> 0 | AU3: =raw_data!$AU3*mass_composition!$E3/100 -> 0 | AV3: =raw_data!$AV3*mass_composition!$E3/100 -> 0 | AW3: =raw_data!$AW3*mass_composition!$E3/100 -> 0 | AX3: =raw_data!$AX3*mass_composition!$E3/100 -> 0 | AY3: =raw_data!$AY3*mass_composition!$E3/100 -> 0 | AZ3: =raw_data!$AZ3*mass_composition!$E3/100 -> 0 | BA3: =raw_data!$BA3*mass_composition!$E3/100 -> 0 | BB3: =raw_data!$BB3*mass_composition!$E3/100 -> 0 | BC3: =raw_data!$BC3*mass_composition!$E3/100 -> 0 | BD3: =raw_data!$BD3*mass_composition!$E3/100 -> 0 | BE3: =raw_data!$BE3*mass_composition!$E3/100 -> 0 | BF3: =raw_data!$BF3*mass_composition!$E3/100 -> 0 | BG3: =raw_data!$BG3*mass_composition!$E3/100 -> 0 | BH3: 0 | BI3: 9.4432427 | BJ3: 5.1971608 | BK3: =raw_data!$BK3*$E3/100 -> 0 | BL3: =raw_data!$BL3*$E3/100 -> 0 | BM3: 0 | BN3: =raw_data!$BN3*$E3/100 -> 0 | BO3: =raw_data!$BO3*$E3/100 -> 0 | BP3: =raw_data!$BP3*$E3/100 -> 0 | BQ3: 0 | BR3: =raw_data!$BR3*$E3/100 -> 0 | BS3: 20.739432 | BT3: 1.6821017 | BU3: 0.39084314 | BV3: 1.3182643 | BW3: 0.43693957 | BX3: 0.98645747 | BY3: 12.569097 | BZ3: 21.20444 | CA3: 0 | CB3: 52.66229
A4: Food product | B4: Average Pasta, DSA | C4: =26.0249554367201/3 -> 8.6749851 | D4: =raw_data!$D4*$C4/100 -> 2.4926124 | E4: =raw_data!$E4*$C4/100 -> 6.1823727 | F4: =raw_data!$F4*$E4/100 -> 6.1151594 | G4: =raw_data!$G4*$E4/100 -> 0.067213359 | H4: 16.627433 | I4: 439.60034 | J4: =raw_data!$J4*mass_composition!$E4/100 -> 2.751399 | K4: =raw_data!$K4*mass_composition!$E4/100 -> 2.7492377 | L4: =raw_data!$L4*mass_composition!$E4/100 -> 0 | M4: =raw_data!$M4*mass_composition!$E4/100 -> 0.0020497238 | N4: =raw_data!$N4*mass_composition!$E4/100 -> 0 | O4: =raw_data!$O4*mass_composition!$E4/100 -> 0 | P4: =raw_data!$P4*mass_composition!$E4/100 -> 0.39828828 | Q4: =raw_data!$Q4*mass_composition!$E4/100 -> 0.020959798 | R4: =raw_data!$R4*mass_composition!$E4/100 -> 0.1568831 | S4: =raw_data!$S4*mass_composition!$E4/100 -> 0.00028557602 | T4: =raw_data!$T4*mass_composition!$E4/100 -> 2.8083753 | U4: =raw_data!$U4*mass_composition!$E4/100 -> 0.014755441 | V4: =raw_data!$V4*mass_composition!$E4/100 -> 0.031738128 | W4: =raw_data!$W4*mass_composition!$E4/100 -> 0 | X4: =raw_data!$X4*mass_composition!$E4/100 -> 0 | Y4: =raw_data!$Y4*mass_composition!$E4/100 -> 0 | Z4: =raw_data!$Z4*mass_composition!$E4/100 -> 4.1352144e-08 | AA4: =raw_data!$AA4*mass_composition!$E4/100 -> 0 | AB4: =raw_data!$AB4*mass_composition!$E4/100 -> 0 | AC4: =raw_data!$AC4*mass_composition!$E4/100 -> 0 | AD4: =raw_data!$AD4*mass_composition!$E4/100 -> 0 | AE4: =raw_data!$AE4*mass_composition!$E4/100 -> 0 | AF4: =raw_data!$AF4*mass_composition!$E4/100 -> 0 | AG4: =raw_data!$AG4*mass_composition!$E4/100 -> 1.2280364e-07 | AH4: =raw_data!$AH4*mass_composition!$E4/100 -> 0 | AI4: =raw_data!$AI4*mass_composition!$E4/100 -> 2.2048263e-07 | AJ4: =raw_data!$AJ4*mass_composition!$E4/100 -> 2.1357569e-05 | AK4: =raw_data!$AK4*mass_composition!$E4/100 -> 0.00016752349 | AL4: =raw_data!$AL4*mass_composition!$E4/100 -> 0 | AM4: =raw_data!$AM4*mass_composition!$E4/100 -> 9.9972216e-09 | AN4: =raw_data!$AN4*mass_composition!$E4/100 -> 0 | AO4: =raw_data!$AO4*mass_composition!$E4/100 -> 0 | AP4: =raw_data!$AP4*mass_composition!$E4/100 -> 0.0029289592 | AQ4: =raw_data!$AQ4*mass_composition!$E4/100 -> 3.7437857e-05 | AR4: =raw_data!$AR4*mass_composition!$E4/100 -> 8.9792452e-07 | AS4: =raw_data!$AS4*mass_composition!$E4/100 -> 3.0038864e-07 | AT4: =raw_data!$AT4*mass_composition!$E4/100 -> 8.1900895e-08 | AU4: =raw_data!$AU4*mass_composition!$E4/100 -> 0 | AV4: =raw_data!$AV4*mass_composition!$E4/100 -> 0 | AW4: =raw_data!$AW4*mass_composition!$E4/100 -> 0 | AX4: =raw_data!$AX4*mass_composition!$E4/100 -> 2.6852954e-07 | AY4: =raw_data!$AY4*mass_composition!$E4/100 -> 0 | AZ4: =raw_data!$AZ4*mass_composition!$E4/100 -> 0 | BA4: =raw_data!$BA4*mass_composition!$E4/100 -> 0 | BB4: =raw_data!$BB4*mass_composition!$E4/100 -> 0 | BC4: =raw_data!$BC4*mass_composition!$E4/100 -> 0 | BD4: =raw_data!$BD4*mass_composition!$E4/100 -> 0 | BE4: =raw_data!$BE4*mass_composition!$E4/100 -> 8.8798002e-05 | BF4: =raw_data!$BF4*mass_composition!$E4/100 -> 0 | BG4: =raw_data!$BG4*mass_composition!$E4/100 -> 0 | BH4: 0 | BI4: 0 | BJ4: 54.724265 | BK4: =raw_data!$BK4*$E4/100 -> 0 | BL4: =raw_data!$BL4*$E4/100 -> 0 | BM4: 0 | BN4: =raw_data!$BN4*$E4/100 -> 0.0030859825 | BO4: =raw_data!$BO4*$E4/100 -> 0.89380217 | BP4: =raw_data!$BP4*$E4/100 -> 0.13216466 | BQ4: 0 | BR4: =raw_data!$BR4*$E4/100 -> 5.0891925 | BS4: 18.000149 | BT4: 1.4111714 | BU4: 0 | BV4: 0 | BW4: 0 | BX4: 0 | BY4: 0 | BZ4: 16.63565 | CA4: 0 | CB4: 27.543608
A5: Food product | B5: Average Rice, DSA | C5: =26.0249554367201/3 -> 8.6749851 | D5: =raw_data!$D5*$C5/100 -> 0.92326628 | E5: =raw_data!$E5*$C5/100 -> 7.7517189 | F5: =raw_data!$F5*$E5/100 -> 7.5840712 | G5: =raw_data!$G5*$E5/100 -> 0.16764769 | H5: 16.561773 | I5: 451.67257 | J5: =raw_data!$J5*mass_composition!$E5/100 -> 3.4084563 | K5: =raw_data!$K5*mass_composition!$E5/100 -> 3.399313 | L5: =raw_data!$L5*mass_composition!$E5/100 -> 0 | M5: =raw_data!$M5*mass_composition!$E5/100 -> 0.0027220715 | N5: =raw_data!$N5*mass_composition!$E5/100 -> 0 | O5: =raw_data!$O5*mass_composition!$E5/100 -> 0 | P5: =raw_data!$P5*mass_composition!$E5/100 -> 0.5053175 | Q5: =raw_data!$Q5*mass_composition!$E5/100 -> 0.025815782 | R5: =raw_data!$R5*mass_composition!$E5/100 -> 0.10558899 | S5: =raw_data!$S5*mass_composition!$E5/100 -> 0.00016086703 | T5: =raw_data!$T5*mass_composition!$E5/100 -> 3.5590591 | U5: =raw_data!$U5*mass_composition!$E5/100 -> 0.032781087 | V5: =raw_data!$V5*mass_composition!$E5/100 -> 0.022473378 | W5: =raw_data!$W5*mass_composition!$E5/100 -> 0 | X5: =raw_data!$X5*mass_composition!$E5/100 -> 0 | Y5: =raw_data!$Y5*mass_composition!$E5/100 -> 0 | Z5: =raw_data!$Z5*mass_composition!$E5/100 -> 6.4642554e-07 | AA5: =raw_data!$AA5*mass_composition!$E5/100 -> 0 | AB5: =raw_data!$AB5*mass_composition!$E5/100 -> 0 | AC5: =raw_data!$AC5*mass_composition!$E5/100 -> 0 | AD5: =raw_data!$AD5*mass_composition!$E5/100 -> 0 | AE5: =raw_data!$AE5*mass_composition!$E5/100 -> 0 | AF5: =raw_data!$AF5*mass_composition!$E5/100 -> 0 | AG5: =raw_data!$AG5*mass_composition!$E5/100 -> 9.5756111e-08 | AH5: =raw_data!$AH5*mass_composition!$E5/100 -> 0 | AI5: =raw_data!$AI5*mass_composition!$E5/100 -> 5.2207109e-08 | AJ5: =raw_data!$AJ5*mass_composition!$E5/100 -> 9.6943156e-06 | AK5: =raw_data!$AK5*mass_composition!$E5/100 -> 0.00027783428 | AL5: =raw_data!$AL5*mass_composition!$E5/100 -> 0 | AM5: =raw_data!$AM5*mass_composition!$E5/100 -> 1.1066902e-08 | AN5: =raw_data!$AN5*mass_composition!$E5/100 -> 0 | AO5: =raw_data!$AO5*mass_composition!$E5/100 -> 0 | AP5: =raw_data!$AP5*mass_composition!$E5/100 -> 0.0027964225 | AQ5: =raw_data!$AQ5*mass_composition!$E5/100 -> 9.6947301e-05 | AR5: =raw_data!$AR5*mass_composition!$E5/100 -> 9.9456743e-07 | AS5: =raw_data!$AS5*mass_composition!$E5/100 -> 1.2232959e-06 | AT5: =raw_data!$AT5*mass_composition!$E5/100 -> 5.0918256e-08 | AU5: =raw_data!$AU5*mass_composition!$E5/100 -> 0 | AV5: =raw_data!$AV5*mass_composition!$E5/100 -> 0 | AW5: =raw_data!$AW5*mass_composition!$E5/100 -> 0 | AX5: =raw_data!$AX5*mass_composition!$E5/100 -> 1.5159832e-07 | AY5: =raw_data!$AY5*mass_composition!$E5/100 -> 0 | AZ5: =raw_data!$AZ5*mass_composition!$E5/100 -> 0 | BA5: =raw_data!$BA5*mass_composition!$E5/100 -> 0 | BB5: =raw_data!$BB5*mass_composition!$E5/100 -> 0 | BC5: =raw_data!$BC5*mass_composition!$E5/100 -> 0 | BD5: =raw_data!$BD5*mass_composition!$E5/100 -> 0 | BE5: =raw_data!$BE5*mass_composition!$E5/100 -> 8.3271685e-05 | BF5: =raw_data!$BF5*mass_composition!$E5/100 -> 0 | BG5: =raw_data!$BG5*mass_composition!$E5/100 -> 0 | BH5: 0 | BI5: 0 | BJ5: 23.583093 | BK5: =raw_data!$BK5*$E5/100 -> 0.021261707 | BL5: =raw_data!$BL5*$E5/100 -> 0 | BM5: 0 | BN5: =raw_data!$BN5*$E5/100 -> 0.013055618 | BO5: =raw_data!$BO5*$E5/100 -> 0.63289032 | BP5: =raw_data!$BP5*$E5/100 -> 0.3644344 | BQ5: 0 | BR5: =raw_data!$BR5*$E5/100 -> 6.5892164 | BS5: 17.790584 | BT5: 1.3903426 | BU5: 0 | BV5: 0 | BW5: 0 | BX5: 0 | BY5: 0 | BZ5: 17.159497 | CA5: 0 | CB5: 60.945632
A6: Food product | B6: Average Wheat, DSA | C6: =26.0249554367201/3 -> 8.6749851 | D6: =raw_data!$D6*$C6/100 -> 0.76243481 | E6: =raw_data!$E6*$C6/100 -> 7.9125503 | F6: =raw_data!$F6*$E6/100 -> 7.7900937 | G6: =raw_data!$G6*$E6/100 -> 0.12245669 | H6: 19.205826 | I6: 513.9981 | J6: =raw_data!$J6*mass_composition!$E6/100 -> 3.8333624 | K6: =raw_data!$K6*mass_composition!$E6/100 -> 3.8230532 | L6: =raw_data!$L6*mass_composition!$E6/100 -> 0 | M6: =raw_data!$M6*mass_composition!$E6/100 -> 0.0020004325 | N6: =raw_data!$N6*mass_composition!$E6/100 -> 0 | O6: =raw_data!$O6*mass_composition!$E6/100 -> 0 | P6: =raw_data!$P6*mass_composition!$E6/100 -> 0.55640552 | Q6: =raw_data!$Q6*mass_composition!$E6/100 -> 0.027439923 | R6: =raw_data!$R6*mass_composition!$E6/100 -> 0.16586094 | S6: =raw_data!$S6*mass_composition!$E6/100 -> 0.006406793 | T6: =raw_data!$T6*mass_composition!$E6/100 -> 3.2323411 | U6: =raw_data!$U6*mass_composition!$E6/100 -> 0.022417117 | V6: =raw_data!$V6*mass_composition!$E6/100 -> 0.033937772 | W6: =raw_data!$W6*mass_composition!$E6/100 -> 0 | X6: =raw_data!$X6*mass_composition!$E6/100 -> 0 | Y6: =raw_data!$Y6*mass_composition!$E6/100 -> 0 | Z6: =raw_data!$Z6*mass_composition!$E6/100 -> 1.1656296e-07 | AA6: =raw_data!$AA6*mass_composition!$E6/100 -> 0 | AB6: =raw_data!$AB6*mass_composition!$E6/100 -> 0 | AC6: =raw_data!$AC6*mass_composition!$E6/100 -> 0 | AD6: =raw_data!$AD6*mass_composition!$E6/100 -> 0 | AE6: =raw_data!$AE6*mass_composition!$E6/100 -> 0 | AF6: =raw_data!$AF6*mass_composition!$E6/100 -> 0 | AG6: =raw_data!$AG6*mass_composition!$E6/100 -> 3.7584623e-07 | AH6: =raw_data!$AH6*mass_composition!$E6/100 -> 3.898754e-08 | AI6: =raw_data!$AI6*mass_composition!$E6/100 -> 7.0844496e-08 | AJ6: =raw_data!$AJ6*mass_composition!$E6/100 -> 2.2610007e-05 | AK6: =raw_data!$AK6*mass_composition!$E6/100 -> 0.00017363518 | AL6: =raw_data!$AL6*mass_composition!$E6/100 -> 0 | AM6: =raw_data!$AM6*mass_composition!$E6/100 -> 1.274546e-08 | AN6: =raw_data!$AN6*mass_composition!$E6/100 -> 0 | AO6: =raw_data!$AO6*mass_composition!$E6/100 -> 0 | AP6: =raw_data!$AP6*mass_composition!$E6/100 -> 0.0067199389 | AQ6: =raw_data!$AQ6*mass_composition!$E6/100 -> 0.00027712107 | AR6: =raw_data!$AR6*mass_composition!$E6/100 -> 9.7221313e-07 | AS6: =raw_data!$AS6*mass_composition!$E6/100 -> 1.7554177e-06 | AT6: =raw_data!$AT6*mass_composition!$E6/100 -> 1.2054052e-07 | AU6: =raw_data!$AU6*mass_composition!$E6/100 -> 0 | AV6: =raw_data!$AV6*mass_composition!$E6/100 -> 0 | AW6: =raw_data!$AW6*mass_composition!$E6/100 -> 0 | AX6: =raw_data!$AX6*mass_composition!$E6/100 -> 1.2929089e-07 | AY6: =raw_data!$AY6*mass_composition!$E6/100 -> 0 | AZ6: =raw_data!$AZ6*mass_composition!$E6/100 -> 0 | BA6: =raw_data!$BA6*mass_composition!$E6/100 -> 0 | BB6: =raw_data!$BB6*mass_composition!$E6/100 -> 0 | BC6: =raw_data!$BC6*mass_composition!$E6/100 -> 0 | BD6: =raw_data!$BD6*mass_composition!$E6/100 -> 0 | BE6: =raw_data!$BE6*mass_composition!$E6/100 -> 0.00028525301 | BF6: =raw_data!$BF6*mass_composition!$E6/100 -> 0 | BG6: =raw_data!$BG6*mass_composition!$E6/100 -> 0 | BH6: 0 | BI6: 0.26455858 | BJ6: 34.328419 | BK6: =raw_data!$BK6*$E6/100 -> 0.067565777 | BL6: =raw_data!$BL6*$E6/100 -> 0 | BM6: 0 | BN6: =raw_data!$BN6*$E6/100 -> 0.014720352 | BO6: =raw_data!$BO6*$E6/100 -> 0.95574805 | BP6: =raw_data!$BP6*$E6/100 -> 1.1782743 | BQ6: 0 | BR6: =raw_data!$BR6*$E6/100 -> 5.6550901 | BS6: 19.789689 | BT6: 1.5880389 | BU6: 0 | BV6: 0 | BW6: 0 | BX6: 0 | BY6: 2.134274 | BZ6: 19.095712 | CA6: 0 | CB6: 35.849357
A7: Food product | B7: Average Pizza, DSA | D7: =raw_data!$D7*$C7/100 -> 0 | E7: =raw_data!$E7*$C7/100 -> 0 | F7: =raw_data!$F7*$E7/100 -> 0 | G7: =raw_data!$G7*$E7/100 -> 0 | H7: 19.347023 | I7: 539.46658 | J7: =raw_data!$J7*mass_composition!$E7/100 -> 0 | K7: =raw_data!$K7*mass_composition!$E7/100 -> 0 | L7: =raw_data!$L7*mass_composition!$E7/100 -> 0 | M7: =raw_data!$M7*mass_composition!$E7/100 -> 0 | N7: =raw_data!$N7*mass_composition!$E7/100 -> 0 | O7: =raw_data!$O7*mass_composition!$E7/100 -> 0 | P7: =raw_data!$P7*mass_composition!$E7/100 -> 0 | Q7: =raw_data!$Q7*mass_composition!$E7/100 -> 0 | R7: =raw_data!$R7*mass_composition!$E7/100 -> 0 | S7: =raw_data!$S7*mass_composition!$E7/100 -> 0 | T7: =raw_data!$T7*mass_composition!$E7/100 -> 0 | U7: =raw_data!$U7*mass_composition!$E7/100 -> 0 | V7: =raw_data!$V7*mass_composition!$E7/100 -> 0 | W7: =raw_data!$W7*mass_composition!$E7/100 -> 0 | X7: =raw_data!$X7*mass_composition!$E7/100 -> 0 | Y7: =raw_data!$Y7*mass_composition!$E7/100 -> 0 | Z7: =raw_data!$Z7*mass_composition!$E7/100 -> 0 | AA7: =raw_data!$AA7*mass_composition!$E7/100 -> 0 | AB7: =raw_data!$AB7*mass_composition!$E7/100 -> 0 | AC7: =raw_data!$AC7*mass_composition!$E7/100 -> 0 | AD7: =raw_data!$AD7*mass_composition!$E7/100 -> 0 | AE7: =raw_data!$AE7*mass_composition!$E7/100 -> 0 | AF7: =raw_data!$AF7*mass_composition!$E7/100 -> 0 | AG7: =raw_data!$AG7*mass_composition!$E7/100 -> 0 | AH7: =raw_data!$AH7*mass_composition!$E7/100 -> 0 | AI7: =raw_data!$AI7*mass_composition!$E7/100 -> 0 | AJ7: =raw_data!$AJ7*mass_composition!$E7/100 -> 0 | AK7: =raw_data!$AK7*mass_composition!$E7/100 -> 0 | AL7: =raw_data!$AL7*mass_composition!$E7/100 -> 0 | AM7: =raw_data!$AM7*mass_composition!$E7/100 -> 0 | AN7: =raw_data!$AN7*mass_composition!$E7/100 -> 0 | AO7: =raw_data!$AO7*mass_composition!$E7/100 -> 0 | AP7: =raw_data!$AP7*mass_composition!$E7/100 -> 0 | AQ7: =raw_data!$AQ7*mass_composition!$E7/100 -> 0 | AR7: =raw_data!$AR7*mass_composition!$E7/100 -> 0 | AS7: =raw_data!$AS7*mass_composition!$E7/100 -> 0 | AT7: =raw_data!$AT7*mass_composition!$E7/100 -> 0 | AU7: =raw_data!$AU7*mass_composition!$E7/100 -> 0 | AV7: =raw_data!$AV7*mass_composition!$E7/100 -> 0 | AW7: =raw_data!$AW7*mass_composition!$E7/100 -> 0 | AX7: =raw_data!$AX7*mass_composition!$E7/100 -> 0 | AY7: =raw_data!$AY7*mass_composition!$E7/100 -> 0 | AZ7: =raw_data!$AZ7*mass_composition!$E7/100 -> 0 | BA7: =raw_data!$BA7*mass_composition!$E7/100 -> 0 | BB7: =raw_data!$BB7*mass_composition!$E7/100 -> 0 | BC7: =raw_data!$BC7*mass_composition!$E7/100 -> 0 | BD7: =raw_data!$BD7*mass_composition!$E7/100 -> 0 | BE7: =raw_data!$BE7*mass_composition!$E7/100 -> 0 | BF7: =raw_data!$BF7*mass_composition!$E7/100 -> 0 | BG7: =raw_data!$BG7*mass_composition!$E7/100 -> 0 | BH7: 0 | BI7: 0 | BJ7: 0 | BK7: =raw_data!$BK7*$E7/100 -> 0 | BL7: =raw_data!$BL7*$E7/100 -> 0 | BM7: 0 | BN7: =raw_data!$BN7*$E7/100 -> 0 | BO7: =raw_data!$BO7*$E7/100 -> 0 | BP7: =raw_data!$BP7*$E7/100 -> 0 | BQ7: 0 | BR7: =raw_data!$BR7*$E7/100 -> 0 | BS7: 20.293004 | BT7: 1.6379781 | BU7: 0 | BV7: 0 | BW7: 0 | BX7: 0 | BY7: 0 | BZ7: 19.279272 | CA7: 0 | CB7: 57.452962
A8: Food product | B8: Average Sandwich, DSA | D8: =raw_data!$D8*$C8/100 -> 0 | E8: =raw_data!$E8*$C8/100 -> 0 | F8: =raw_data!$F8*$E8/100 -> 0 | G8: =raw_data!$G8*$E8/100 -> 0 | H8: 20.474825 | I8: 569.0871 | J8: =raw_data!$J8*mass_composition!$E8/100 -> 0 | K8: =raw_data!$K8*mass_composition!$E8/100 -> 0 | L8: =raw_data!$L8*mass_composition!$E8/100 -> 0 | M8: =raw_data!$M8*mass_composition!$E8/100 -> 0 | N8: =raw_data!$N8*mass_composition!$E8/100 -> 0 | O8: =raw_data!$O8*mass_composition!$E8/100 -> 0 | P8: =raw_data!$P8*mass_composition!$E8/100 -> 0 | Q8: =raw_data!$Q8*mass_composition!$E8/100 -> 0 | R8: =raw_data!$R8*mass_composition!$E8/100 -> 0 | S8: =raw_data!$S8*mass_composition!$E8/100 -> 0 | T8: =raw_data!$T8*mass_composition!$E8/100 -> 0 | U8: =raw_data!$U8*mass_composition!$E8/100 -> 0 | V8: =raw_data!$V8*mass_composition!$E8/100 -> 0 | W8: =raw_data!$W8*mass_composition!$E8/100 -> 0 | X8: =raw_data!$X8*mass_composition!$E8/100 -> 0 | Y8: =raw_data!$Y8*mass_composition!$E8/100 -> 0 | Z8: =raw_data!$Z8*mass_composition!$E8/100 -> 0 | AA8: =raw_data!$AA8*mass_composition!$E8/100 -> 0 | AB8: =raw_data!$AB8*mass_composition!$E8/100 -> 0 | AC8: =raw_data!$AC8*mass_composition!$E8/100 -> 0 | AD8: =raw_data!$AD8*mass_composition!$E8/100 -> 0 | AE8: =raw_data!$AE8*mass_composition!$E8/100 -> 0 | AF8: =raw_data!$AF8*mass_composition!$E8/100 -> 0 | AG8: =raw_data!$AG8*mass_composition!$E8/100 -> 0 | AH8: =raw_data!$AH8*mass_composition!$E8/100 -> 0 | AI8: =raw_data!$AI8*mass_composition!$E8/100 -> 0 | AJ8: =raw_data!$AJ8*mass_composition!$E8/100 -> 0 | AK8: =raw_data!$AK8*mass_composition!$E8/100 -> 0 | AL8: =raw_data!$AL8*mass_composition!$E8/100 -> 0 | AM8: =raw_data!$AM8*mass_composition!$E8/100 -> 0 | AN8: =raw_data!$AN8*mass_composition!$E8/100 -> 0 | AO8: =raw_data!$AO8*mass_composition!$E8/100 -> 0 | AP8: =raw_data!$AP8*mass_composition!$E8/100 -> 0 | AQ8: =raw_data!$AQ8*mass_composition!$E8/100 -> 0 | AR8: =raw_data!$AR8*mass_composition!$E8/100 -> 0 | AS8: =raw_data!$AS8*mass_composition!$E8/100 -> 0 | AT8: =raw_data!$AT8*mass_composition!$E8/100 -> 0 | AU8: =raw_data!$AU8*mass_composition!$E8/100 -> 0 | AV8: =raw_data!$AV8*mass_composition!$E8/100 -> 0 | AW8: =raw_data!$AW8*mass_composition!$E8/100 -> 0 | AX8: =raw_data!$AX8*mass_composition!$E8/100 -> 0 | AY8: =raw_data!$AY8*mass_composition!$E8/100 -> 0 | AZ8: =raw_data!$AZ8*mass_composition!$E8/100 -> 0 | BA8: =raw_data!$BA8*mass_composition!$E8/100 -> 0 | BB8: =raw_data!$BB8*mass_composition!$E8/100 -> 0 | BC8: =raw_data!$BC8*mass_composition!$E8/100 -> 0 | BD8: =raw_data!$BD8*mass_composition!$E8/100 -> 0 | BE8: =raw_data!$BE8*mass_composition!$E8/100 -> 0 | BF8: =raw_data!$BF8*mass_composition!$E8/100 -> 0 | BG8: =raw_data!$BG8*mass_composition!$E8/100 -> 0 | BH8: 0 | BI8: 0 | BJ8: 0 | BK8: =raw_data!$BK8*$E8/100 -> 0 | BL8: =raw_data!$BL8*$E8/100 -> 0 | BM8: 0 | BN8: =raw_data!$BN8*$E8/100 -> 0 | BO8: =raw_data!$BO8*$E8/100 -> 0 | BP8: =raw_data!$BP8*$E8/100 -> 0 | BQ8: 0 | BR8: =raw_data!$BR8*$E8/100 -> 0 | BS8: 21.124451 | BT8: 1.7202082 | BU8: 0 | BV8: 0 | BW8: 0 | BX8: 0 | BY8: 0 | BZ8: 20.315078 | CA8: 0 | CB8: 52.715551
