Workbook
Name Food_Type: "Baseline"
Name FW_mass: Waste_characteristics!$B$3
Name H2O_FW: Waste_characteristics!$B$4
Name Mass: Waste_characteristics!$B$2
Name mass_VS_FW: Waste_characteristics!$B$6
Name Methane_LHV: '[1]Global params'!$E$21
Name VS_FW: Waste_characteristics!$B$5

Sheet LCIA_AD-f
A3: IMPACT WORLD + FOOTPRINT
A4: Process | C4: Carbon footprint | D4: Ecosystem quality (residual) | E4: Energetic resource depletion | F4: Human health (residual) | G4: Water footprint - Scarcity
A5: AD | C5: =SUM(C6,C9,C12,C16,C27) -> 64.523122 | D5: =SUM(D6,D9,D12,D16,D27) -> 12.136919 | E5: =SUM(E6,E9,E12,E16,E27) -> 635.68927 | F5: =SUM(F6,F9,F12,F16,F27) -> 0.00013928494 | G5: =SUM(G6,G9,G12,G16,G27) -> 15.914782
A6: Pretreatment | C6: =SUM(C7:C8) -> 0.7761065 | D6: =SUM(D7:D8) -> 0.11916921 | E6: =SUM(E7:E8) -> 116.96083 | F6: =SUM(F7:F8) -> 7.7420483e-07 | G6: =SUM(G7:G8) -> 1.2592267
B7: Electricity consumption | C7: ='LCI_AD-e'!$E4*'IW+f'!C2 -> 0.7761065 | D7: ='LCI_AD-e'!$E4*'IW+f'!D2 -> 0.11916921 | E7: ='LCI_AD-e'!$E4*'IW+f'!E2 -> 116.96083 | F7: ='LCI_AD-e'!$E4*'IW+f'!F2 -> 7.7420483e-07 | G7: ='LCI_AD-e'!$E4*'IW+f'!G2 -> 1.2592267
B8: Water consumption | C8: ='LCI_AD-e'!$E5*'IW+f'!C3 -> 0 | D8: ='LCI_AD-e'!$E5*'IW+f'!D3 -> 0 | E8: ='LCI_AD-e'!$E5*'IW+f'!E3 -> 0 | F8: ='LCI_AD-e'!$E5*'IW+f'!F3 -> 0 | G8: ='LCI_AD-e'!$E5*'IW+f'!G3 -> 0
A9: Incineration | C9: =SUM(C10:C11) -> 9.4912725 | D9: =SUM(D10:D11) -> 1.7760545 | E9: =SUM(E10:E11) -> 70.109594 | F9: =SUM(F10:F11) -> 3.9183036e-05 | G9: =SUM(G10:G11) -> 10.01854
B10: Transport | C10: ='LCI_AD-e'!$E7*'IW+f'!C4 -> 0.43472979 | D10: ='LCI_AD-e'!$E7*'IW+f'!D4 -> 0.063594202 | E10: ='LCI_AD-e'!$E7*'IW+f'!E4 -> 6.576112 | F10: ='LCI_AD-e'!$E7*'IW+f'!F4 -> 3.4579966e-07 | G10: ='LCI_AD-e'!$E7*'IW+f'!G4 -> 0.039223403
B11: Incineration | C11: ='LCI_AD-e'!$E8*'IW+f'!C5 -> 9.0565427 | D11: ='LCI_AD-e'!$E8*'IW+f'!D5 -> 1.7124603 | E11: ='LCI_AD-e'!$E8*'IW+f'!E5 -> 63.533482 | F11: ='LCI_AD-e'!$E8*'IW+f'!F5 -> 3.8837236e-05 | G11: ='LCI_AD-e'!$E8*'IW+f'!G5 -> 9.9793169
A12: AD | C12: =SUM(C13:C15) -> 52.248712 | D12: =SUM(D13:D15) -> 2.7873234 | E12: =SUM(E13:E15) -> 416.86802 | F12: =SUM(F13:F15) -> 4.5598348e-05 | G12: =SUM(G13:G15) -> 4.3060094
B13: Electricity | C13: ='LCI_AD-e'!$E10*'IW+f'!C2 -> 1.7365189 | D13: ='LCI_AD-e'!$E10*'IW+f'!D2 -> 0.26663811 | E13: ='LCI_AD-e'!$E10*'IW+f'!E2 -> 261.69692 | F13: ='LCI_AD-e'!$E10*'IW+f'!F2 -> 1.7322639e-06 | G13: ='LCI_AD-e'!$E10*'IW+f'!G2 -> 2.8174882
B14: Heat | C14: ='LCI_AD-e'!$E11*'IW+f'!C11 -> 9.6923673 | D14: ='LCI_AD-e'!$E11*'IW+f'!D11 -> 2.5206853 | E14: ='LCI_AD-e'!$E11*'IW+f'!E11 -> 155.1711 | F14: ='LCI_AD-e'!$E11*'IW+f'!F11 -> 4.3866084e-05 | G14: ='LCI_AD-e'!$E11*'IW+f'!G11 -> 1.4885212
B15: CH4 | C15: ='LCI_AD-e'!$E12*'IW+f'!C12 -> 40.819826 | D15: ='LCI_AD-e'!$E12*'IW+f'!D12 -> 0 | E15: ='LCI_AD-e'!$E12*'IW+f'!E12 -> 0 | F15: ='LCI_AD-e'!$E12*'IW+f'!F12 -> 0 | G15: ='LCI_AD-e'!$E12*'IW+f'!G12 -> 0
A16: Combustion of biogas | C16: =SUM(C17:C26) -> 1.7671684 | D16: =SUM(D17:D26) -> 7.2504014 | E16: =SUM(E17:E26) -> 7.132496 | F16: =SUM(F17:F26) -> 5.3325992e-05 | G16: =SUM(G17:G26) -> 0.076790064
B17: CH4 | C17: ='LCI_AD-e'!$E17*'IW+f'!C12 -> 0.15478559 | D17: ='LCI_AD-e'!$E17*'IW+f'!D12 -> 0 | E17: ='LCI_AD-e'!$E17*'IW+f'!E12 -> 0 | F17: ='LCI_AD-e'!$E17*'IW+f'!F12 -> 0 | G17: ='LCI_AD-e'!$E17*'IW+f'!G12 -> 0
B18: N2O | C18: ='LCI_AD-e'!$E18*'IW+f'!C20 -> 1.5650543 | D18: ='LCI_AD-e'!$E18*'IW+f'!D20 -> 0 | E18: ='LCI_AD-e'!$E18*'IW+f'!E20 -> 0 | F18: ='LCI_AD-e'!$E18*'IW+f'!F20 -> 0 | G18: ='LCI_AD-e'!$E18*'IW+f'!G20 -> 0
B19: Sox | C19: ='LCI_AD-e'!$E19*'IW+f'!C19 -> 0 | D19: ='LCI_AD-e'!$E19*'IW+f'!D19 -> 0.66216543 | E19: ='LCI_AD-e'!$E19*'IW+f'!E19 -> 0 | F19: ='LCI_AD-e'!$E19*'IW+f'!F19 -> 3.6936286e-06 | G19: ='LCI_AD-e'!$E19*'IW+f'!G19 -> 0
B20: PM10 | C20: ='LCI_AD-e'!$E20*'IW+f'!C16 -> 0 | D20: ='LCI_AD-e'!$E20*'IW+f'!D16 -> 0 | E20: ='LCI_AD-e'!$E20*'IW+f'!E16 -> 0 | F20: ='LCI_AD-e'!$E20*'IW+f'!F16 -> 0 | G20: ='LCI_AD-e'!$E20*'IW+f'!G16 -> 0
B21: PM2.5 | C21: ='LCI_AD-e'!$E21*'IW+f'!C22 -> 0 | D21: ='LCI_AD-e'!$E21*'IW+f'!D22 -> 0 | E21: ='LCI_AD-e'!$E21*'IW+f'!E22 -> 0 | F21: ='LCI_AD-e'!$E21*'IW+f'!F22 -> 3.9886858e-05 | G21: ='LCI_AD-e'!$E21*'IW+f'!G22 -> 0
B22: Nox | C22: ='LCI_AD-e'!$E22*'IW+f'!C13 -> 0 | D22: ='LCI_AD-e'!$E22*'IW+f'!D13 -> 6.2616774 | E22: ='LCI_AD-e'!$E22*'IW+f'!E13 -> 0 | F22: ='LCI_AD-e'!$E22*'IW+f'!F13 -> 7.5499383e-06 | G22: ='LCI_AD-e'!$E22*'IW+f'!G13 -> 0
B23: NH3 | C23: ='LCI_AD-e'!$E23*'IW+f'!C18 -> 0 | D23: ='LCI_AD-e'!$E23*'IW+f'!D18 -> 0.31929142 | E23: ='LCI_AD-e'!$E23*'IW+f'!E18 -> 0 | F23: ='LCI_AD-e'!$E23*'IW+f'!F18 -> 2.1483541e-06 | G23: ='LCI_AD-e'!$E23*'IW+f'!G18 -> 0
B24: CO | C24: ='LCI_AD-e'!$E24*'IW+f'!C17 -> 0 | D24: ='LCI_AD-e'!$E24*'IW+f'!D17 -> 0 | E24: ='LCI_AD-e'!$E24*'IW+f'!E17 -> 0 | F24: ='LCI_AD-e'!$E24*'IW+f'!F17 -> 0 | G24: ='LCI_AD-e'!$E24*'IW+f'!G17 -> 0
B25: VOC | C25: ='LCI_AD-e'!$E25*'IW+f'!C14 -> 0 | D25: ='LCI_AD-e'!$E25*'IW+f'!D14 -> 0 | E25: ='LCI_AD-e'!$E25*'IW+f'!E14 -> 0 | F25: ='LCI_AD-e'!$E25*'IW+f'!F14 -> 0 | G25: ='LCI_AD-e'!$E25*'IW+f'!G14 -> 0
B26: Electricity | C26: ='LCI_AD-e'!$E26*'IW+f'!C2 -> 0.047328466 | D26: ='LCI_AD-e'!$E26*'IW+f'!D2 -> 0.0072671672 | E26: ='LCI_AD-e'!$E26*'IW+f'!E2 -> 7.132496 | F26: ='LCI_AD-e'!$E26*'IW+f'!F2 -> 4.7212498e-08 | G26: ='LCI_AD-e'!$E26*'IW+f'!G2 -> 0.076790064
A27: Dewatering | C27: ='LCIA_AD-b'!C25 -> 0.23986337 | D27: ='LCIA_AD-b'!D25 -> 0.20397057 | E27: ='LCIA_AD-b'!E25 -> 24.618326 | F27: ='LCIA_AD-b'!F25 -> 4.0335814e-07 | G27: ='LCIA_AD-b'!G25 -> 0.25421574
B28: electricity | C28: ='LCIA_AD-b'!C26 -> 0.15696911 | D28: ='LCIA_AD-b'!D26 -> 0.024102213 | E28: ='LCIA_AD-b'!E26 -> 23.655564 | F28: ='LCIA_AD-b'!F26 -> 1.5658449e-07 | G28: ='LCIA_AD-b'!G26 -> 0.25468114
B29: wastewater treatment | C29: ='LCIA_AD-b'!C27 -> 0.08289426 | D29: ='LCIA_AD-b'!D27 -> 0.17986836 | E29: ='LCIA_AD-b'!E27 -> 0.96276199 | F29: ='LCIA_AD-b'!F27 -> 2.4677365e-07 | G29: ='LCIA_AD-b'!G27 -> -0.00046540191
A30: Composting of digestate | C30: ='LCIA_AD-b'!C28 -> 20.023162 | D30: ='LCIA_AD-b'!D28 -> 5.537795 | E30: ='LCIA_AD-b'!E28 -> 61.671424 | F30: ='LCIA_AD-b'!F28 -> 3.6457712e-05 | G30: ='LCIA_AD-b'!G28 -> 0.42904899
B31: CH4 | C31: ='LCIA_AD-b'!C29 -> 2.3821712 | D31: ='LCIA_AD-b'!D29 -> 0 | E31: ='LCIA_AD-b'!E29 -> 0 | F31: ='LCIA_AD-b'!F29 -> 0 | G31: ='LCIA_AD-b'!G29 -> 0
B32: N2O | C32: ='LCIA_AD-b'!C30 -> 17.012982 | D32: ='LCIA_AD-b'!D30 -> 0 | E32: ='LCIA_AD-b'!E30 -> 0 | F32: ='LCIA_AD-b'!F30 -> 0 | G32: ='LCIA_AD-b'!G30 -> 0
B33: NH3 | C33: ='LCIA_AD-b'!C31 -> 0 | D33: ='LCIA_AD-b'!D31 -> 5.3456953 | E33: ='LCIA_AD-b'!E31 -> 0 | F33: ='LCIA_AD-b'!F31 -> 3.596854e-05 | G33: ='LCIA_AD-b'!G31 -> 0
B34: NMVOC | C34: ='LCIA_AD-b'!C32 -> 0 | D34: ='LCIA_AD-b'!D32 -> 0.078076707 | E34: ='LCIA_AD-b'!E32 -> 0 | F34: ='LCIA_AD-b'!F32 -> 5.0595209e-09 | G34: ='LCIA_AD-b'!G32 -> 0
B35: CO | C35: ='LCIA_AD-b'!C33 -> 0 | D35: ='LCIA_AD-b'!D33 -> 0 | E35: ='LCIA_AD-b'!E33 -> 0 | F35: ='LCIA_AD-b'!F33 -> 0 | G35: ='LCIA_AD-b'!G33 -> 0
B36: electricity | C36: ='LCIA_AD-b'!C34 -> 0.24305618 | D36: ='LCIA_AD-b'!D34 -> 0.037320666 | E36: ='LCIA_AD-b'!E34 -> 36.62906 | F36: ='LCIA_AD-b'!F34 -> 2.4246062e-07 | G36: ='LCIA_AD-b'!G34 -> 0.39435674
B37: diesel | C37: ='LCIA_AD-b'!C35 -> 0.38495173 | D37: ='LCIA_AD-b'!D35 -> 0.076702309 | E37: ='LCIA_AD-b'!E35 -> 25.042364 | F37: ='LCIA_AD-b'!F35 -> 2.4165125e-07 | G37: ='LCIA_AD-b'!G35 -> 0.034692256
A38: Land application of compost | C38: ='LCIA_AD-b'!C36 -> 3.6020203 | D38: ='LCIA_AD-b'!D36 -> 7.1951541 | E38: ='LCIA_AD-b'!E36 -> 0 | F38: ='LCIA_AD-b'!F36 -> 1.4004956e-05 | G38: ='LCIA_AD-b'!G36 -> 0
B39: N2O | C39: ='LCIA_AD-b'!C37 -> 3.6020203 | D39: ='LCIA_AD-b'!D37 -> 0 | E39: ='LCIA_AD-b'!E37 -> 0 | F39: ='LCIA_AD-b'!F37 -> 0 | G39: ='LCIA_AD-b'!G37 -> 0
B40: NH3 | C40: ='LCIA_AD-b'!C38 -> 0 | D40: ='LCIA_AD-b'!D38 -> 2.0814363 | E40: ='LCIA_AD-b'!E38 -> 0 | F40: ='LCIA_AD-b'!F38 -> 1.4004956e-05 | G40: ='LCIA_AD-b'!G38 -> 0
B41: NO3 | C41: ='LCIA_AD-b'!C39 -> 0 | D41: ='LCIA_AD-b'!D39 -> 5.2372358 | E41: ='LCIA_AD-b'!E39 -> 0 | F41: ='LCIA_AD-b'!F39 -> 0 | G41: ='LCIA_AD-b'!G39 -> 0
B42: (PO4)3- | C42: ='LCIA_AD-b'!C40 -> 0 | D42: ='LCIA_AD-b'!D40 -> -0.123518 | E42: ='LCIA_AD-b'!E40 -> 0 | F42: ='LCIA_AD-b'!F40 -> 0 | G42: ='LCIA_AD-b'!G40 -> 0
...

Sheet IW+_end
A1: Process | B1: Reference unit | C1: Climate change, ecosystem quality, long term | D1: Climate change, ecosystem quality, short term | E1: Climate change, human health, long term | F1: Climate change, human health, short term | G1: Fisheries impact | H1: Freshwater acidification | I1: Freshwater ecotoxicity, long term | J1: Freshwater ecotoxicity, short term | K1: Freshwater eutrophication | L1: Human toxicity cancer, long term | M1: Human toxicity cancer, short term | N1: Human toxicity non-cancer, long term | O1: Human toxicity non-cancer, short term | P1: Ionizing radiations, ecosystem quality | Q1: Ionizing radiations, human health | R1: Land occupation, biodiversity | S1: Land transformation, biodiversity | T1: Marine acidification, long term | U1: Marine acidification, short term | V1: Marine ecotoxicity, long term | W1: Marine ecotoxicity, short term | X1: Marine eutrophication | Y1: Ozone layer depletion | Z1: Particulate matter formation | AA1: Photochemical ozone formation, ecosystem quality | AB1: Photochemical ozone formation, human health | AC1: Terrestrial acidification | AD1: Terrestrial ecotoxicity, long term | AE1: Terrestrial ecotoxicity, short term | AF1: Thermally polluted water | AG1: Total ecosystem quality | AH1: Total human health | AI1: Water availability, freshwater ecosystem | AJ1: Water availability, human health | AK1: Water availability, terrestrial ecosystem | AM1: Ecoinvent process | AN1: Region
A2: Electricity production | B2: kWh | C2: 0.029434703 | D2: 0.0090171188 | E2: 3.9669068e-07 | F2: 1.2152346e-07 | G2: 9.0220539e-21 | H2: 0.00052035185 | I2: 0.024888796 | J2: 0.0012365565 | K2: 2.1482719e-06 | L2: 8.7189411e-10 | M2: 1.6630166e-08 | N2: 1.9716035e-08 | O2: 1.0495037e-08 | P2: 4.1472255e-10 | Q2: 1.2788915e-08 | R2: 0.0016567241 | S2: 0.0011680202 | T2: 0.010269588 | U2: 0.0011147872 | V2: 9.6682892e-08 | W2: 2.6607992e-08 | X2: 6.8100187e-05 | Y2: 4.6326221e-12 | Z2: 3.7499949e-08 | AA2: 0.0015786993 | AB2: 1.5693505e-10 | AC2: 0.0034337732 | AD2: 0.0035290615 | AE2: 0.00097119172 | AF2: 0.00019042271 | AG2: 0.089082653 | AH2: 7.3991032e-07 | AI2: 1.011382e-06 | AJ2: 1.2353261e-07 | AK2: 1.4744629e-06 | AM2: market for electricity, medium voltage | electricity, medium voltage | Cutoff, U | AN2: FR
A3: Water production | B3: kg | C3: 0.00011863638 | D3: 3.5826192e-05 | E3: 1.5988593e-09 | F3: 4.828286e-10 | G3: 1.4472652e-20 | H3: 2.6983115e-06 | I3: 2.7477981e-05 | J3: 6.1320649e-06 | K3: 1.2606069e-08 | L3: 1.408413e-11 | M3: 9.2762381e-10 | N3: 3.9435252e-10 | O3: 6.711082e-11 | P3: 1.4514271e-13 | Q3: 2.798748e-12 | R3: 4.7297185e-06 | S3: 6.0711292e-06 | T3: 4.2913089e-05 | U3: 4.6582693e-06 | V3: 4.9804263e-11 | W3: 3.9972635e-11 | X3: 2.4074305e-07 | Y3: 1.3310981e-14 | Z3: 2.4250395e-10 | AA3: 6.8457405e-06 | AB3: 6.8269851e-13 | AC3: 1.7503834e-05 | AD3: 1.8179051e-06 | AE3: 1.4590012e-06 | AF3: 1.0616678e-07 | AG3: 0.00028632407 | AH3: 4.2091312e-08 | AI3: 3.140634e-07 | AJ3: 3.8360455e-08 | AK3: 8.8807766e-06 | AM3: market for tap water | tap water | Cutoff, U | AN3: Europe without Switzerland
A4: Incineration | B4: kg | C4: 0.012374672 | D4: 0.0048759181 | E4: 1.6677311e-07 | F4: 6.5712614e-08 | G4: 5.8334847e-21 | H4: 0.00030722598 | I4: 0.0040615965 | J4: 0.00051944492 | K4: 2.5327295e-05 | L4: 3.2796643e-10 | M4: 4.0155836e-08 | N4: 8.7573489e-09 | O4: 9.0145145e-08 | P4: 7.2700604e-13 | Q4: 1.1049922e-11 | R4: 0.0004489439 | S4: 0.00087792638 | T4: 0.0035383176 | U4: 0.00038409088 | V4: 1.8169613e-09 | W4: 3.963782e-09 | X4: 0.00016049954 | Y4: 1.4900648e-12 | Z4: 3.830932e-08 | AA4: 0.0022743494 | AB4: 2.3470762e-10 | AC4: 0.0023013297 | AD4: 6.6359289e-05 | AE4: 0.00014467804 | AF4: 1.6597232e-06 | AG4: 0.032363623 | AH4: 4.5290827e-07 | AI4: 3.4778817e-07 | AJ4: 4.2479678e-08 | AK4: 9.2981276e-07
A5: Transport | B5: tkm | C5: 0.07140406 | D5: 0.021808745 | E5: 9.6231055e-07 | F5: 2.9391586e-07 | G5: 1.4895501e-19 | H5: 0.00082994559 | I5: 0.0092025979 | J5: 0.0033844539 | K5: 5.2566239e-06 | L5: 6.0034348e-10 | M5: 3.4139573e-08 | N5: 2.2572496e-08 | O5: 1.5198825e-08 | P5: 6.9944357e-12 | Q5: 8.6181308e-11 | R5: 0.0040818364 | S5: 0.0047163109 | T5: 0.025800254 | U5: 0.0028006693 | V5: 9.7222144e-09 | W5: 7.9906608e-09 | X5: 0.00021342597 | Y5: 6.1437636e-12 | Z5: 1.0038796e-07 | AA5: 0.0054178322 | AB5: 5.2899951e-10 | AC5: 0.005901547 | AD5: 0.00035486896 | AE5: 0.00029165912 | AF5: 6.7079009e-06 | AG5: 0.15622312 | AH5: 1.4464434e-06 | AI5: 1.3669709e-07 | AJ5: 1.6696509e-08 | AK5: 2.7918423e-06
A6: Heat, natural gas | B6: MJ | C6: 0.02877524 | D6: 0.0088335486 | E6: 3.8780312e-07 | F6: 1.1904949e-07 | G6: 2.456039e-19 | H6: 8.7487049e-05 | I6: 0.00090902716 | J6: 0.00084404332 | K6: 1.0175098e-06 | L6: 7.3128564e-11 | M6: 5.4607132e-09 | N6: 2.1836439e-09 | O6: 1.2776592e-09 | P6: 1.4950808e-12 | Q6: 2.7539256e-11 | R6: 8.8589251e-05 | S6: 0.00041813597 | T6: 0.010404099 | U6: 0.0011293905 | V6: 2.2228437e-09 | W6: 2.0080477e-09 | X6: 1.3926728e-05 | Y6: 4.9676217e-12 | Z6: 6.0152951e-09 | AA6: 0.00061565556 | AB6: 5.6382165e-11 | AC6: 0.00061064151 | AD6: 8.1134935e-05 | AE6: 7.3293742e-05 | AF6: 1.3011011e-06 | AG6: 0.052887171 | AH6: 5.2526773e-07 | AI6: 2.7146908e-08 | AJ6: 3.3157883e-09 | AK6: 6.0708308e-07
A7: Heat, fuel | B7: MJ | C7: 0.036606595 | D7: 0.011027964 | E7: 4.9334608e-07 | F7: 1.4862357e-07 | G7: 1.8355355e-21 | H7: 0.00028862325 | I7: 0.001913816 | J7: 0.00093700432 | K7: 1.4412766e-06 | L7: 1.5012604e-10 | M7: 4.1655245e-09 | N7: 4.0009951e-09 | O7: 2.2101399e-09 | P7: 1.1573822e-12 | Q7: 2.174998e-11 | R7: 0.00012145572 | S7: 0.00099540935 | T7: 0.013271943 | U7: 0.001440703 | V7: 1.9565669e-09 | W7: 1.7764736e-09 | X7: 5.5334525e-05 | Y7: 2.9853225e-12 | Z7: 1.6704189e-08 | AA7: 0.00093625163 | AB7: 8.3728291e-11 | AC7: 0.0018442609 | AD7: 7.1423215e-05 | AE7: 6.4841285e-05 | AF7: 1.039197e-06 | AG7: 0.069578362 | AH7: 6.7176707e-07 | AI7: 2.0123922e-08 | AJ7: 2.4579839e-09 | AK7: 2.3213647e-07
A8: Heat, coal | B8: MJ | C8: 0.051481483 | D8: 0.015338013 | E8: 6.9381453e-07 | F8: 2.0670998e-07 | G8: 1.4763407e-21 | H8: 0.0018246418 | I8: 0.024268278 | J8: 0.00038523926 | K8: 3.2761443e-07 | L8: 5.3314861e-10 | M8: 5.0909973e-09 | N8: 1.6240445e-08 | O8: 9.0877925e-09 | P8: 2.8551303e-12 | Q8: 4.9809633e-11 | R8: 0.00053115688 | S8: 0.00098265018 | T8: 0.018710325 | U8: 0.0020310485 | V8: 2.583604e-08 | W8: 1.3618008e-08 | X8: 8.781569e-05 | Y8: 1.7481896e-13 | Z8: 1.7750187e-07 | AA8: 0.002837239 | AB8: 2.9350262e-10 | AC8: 0.011489983 | AD8: 0.00094302658 | AE8: 0.00049705728 | AF8: 2.3780798e-06 | AG8: 0.13141416 | AH8: 1.1137171e-06 | AI8: 3.5981315e-08 | AJ8: 4.3948438e-09 | AK8: 3.4249237e-06
A9: Heat, wood chips | B9: MJ | C9: 0.0060444079 | D9: 0.0019503037 | E9: 8.1460319e-08 | F9: 2.6284189e-08 | G9: 1.0746197e-20 | H9: 0.00035685042 | I9: 0.012324661 | J9: 0.00065584737 | K9: 5.9519004e-06 | L9: 2.0411295e-10 | M9: 4.4194286e-09 | N9: 7.8800496e-09 | O9: 6.0846186e-09 | P9: 2.2079745e-12 | Q9: 3.2533633e-11 | R9: 0.015167811 | S9: 0.0021577357 | T9: 0.0021074606 | U9: 0.00022876865 | V9: 5.6782298e-08 | W9: 3.592671e-08 | X9: 8.8430731e-05 | Y9: 2.6955337e-13 | Z9: 5.0689546e-07 | AA9: 0.0028524829 | AB9: 2.9414464e-10 | AC9: 0.0027377653 | AD9: 0.0020725612 | AE9: 0.0013113249 | AF9: 3.5809585e-06 | AG9: 0.050067008 | AH9: 6.4697977e-07 | AI9: 1.0990983e-07 | AJ9: 1.342465e-08 | AK9: 8.6057214e-07
A10: Heat,waste | B10: MJ
A11: Heat, mix | B11: MJ | C11: =(C6*Parameters!$C115)+(C7*Parameters!$C117)+(C8*Parameters!$C116)+(C9*Parameters!$C118)+(C10*Parameters!$C119) -> 0.015897437 | D11: =(D6*Parameters!$C115)+(D7*Parameters!$C117)+(D8*Parameters!$C116)+(D9*Parameters!$C118)+(D10*Parameters!$C119) -> 0.0049132377 | E11: =(E6*Parameters!$C115)+(E7*Parameters!$C117)+(E8*Parameters!$C116)+(E9*Parameters!$C118)+(E10*Parameters!$C119) -> 2.1424932e-07 | F11: =(F6*Parameters!$C115)+(F7*Parameters!$C117)+(F8*Parameters!$C116)+(F9*Parameters!$C118)+(F10*Parameters!$C119) -> 6.621557e-08 | G11: =(G6*Parameters!$C115)+(G7*Parameters!$C117)+(G8*Parameters!$C116)+(G9*Parameters!$C118)+(G10*Parameters!$C119) -> 1.1956472e-19 | H11: =(H6*Parameters!$C115)+(H7*Parameters!$C117)+(H8*Parameters!$C116)+(H9*Parameters!$C118)+(H10*Parameters!$C119) -> 0.00017338512 | I11: =(I6*Parameters!$C115)+(I7*Parameters!$C117)+(I8*Parameters!$C116)+(I9*Parameters!$C118)+(I10*Parameters!$C119) -> 0.0049148544 | J11: =(J6*Parameters!$C115)+(J7*Parameters!$C117)+(J8*Parameters!$C116)+(J9*Parameters!$C118)+(J10*Parameters!$C119) -> 0.00063684546 | ... AK11: =(AK6*Parameters!$C115)+(AK7*Parameters!$C117)+(AK8*Parameters!$C116)+(AK9*Parameters!$C118)+(AK10*Parameters!$C119) -> 6.0212379e-07
A12: CH4 | B12: kg | C12: 0.62041963 | D12: 2.3563059 | E12: 8.3613783e-06 | F12: 3.17559e-05 | AG12: =SUM(C12:D12,G12,H12,I12,J12,K12,P12,R12,S12,T12,U12,V12,W12,X12,AA12,AC12:AF12) -> 2.9767256 | AH12: =SUM(C12:AF12)-AG12 -> 4.0117278e-05
A13: Nitrogen oxides | B13: kg | H13: 0.79919441 | X13: 0.26330224 | Z13: 1.8783043e-05 | AA13: 8.7162162 | AB13: 9.1e-07 | AC13: 6.5540677 | AG13: =SUM(C13:D13,G13,H13,I13,J13,K13,P13,R13,S13,T13,U13,V13,W13,X13,AA13,AC13:AF13) -> 16.332781 | AH13: =SUM(C13:AF13)-AG13 -> 1.9693043e-05
A14: Volatile organic compounds | B14: kg | AG14: =SUM(C14:D14,G14,H14,I14,J14,K14,P14,R14,S14,T14,U14,V14,W14,X14,AA14,AC14:AF14) -> 0 | AH14: =SUM(C14:AF14)-AG14 -> 0
A15: Sulfur dioxide | B15: kg | H15: 2.392596 | Z15: 9.2871715e-05 | AC15: 14.256733 | AG15: =SUM(C15:D15,G15,H15,I15,J15,K15,P15,R15,S15,T15,U15,V15,W15,X15,AA15,AC15:AF15) -> 16.649329 | AH15: =SUM(C15:AF15)-AG15 -> 9.2871715e-05
A16: Particulate matter | B16: kg | AG16: =SUM(C16:D16,G16,H16,I16,J16,K16,P16,R16,S16,T16,U16,V16,W16,X16,AA16,AC16:AF16) -> 0 | AH16: =SUM(C16:AF16)-AG16 -> 0
A17: Carbon monoxide (non-fossil) | B17: kg | AG17: =SUM(C17:D17,G17,H17,I17,J17,K17,P17,R17,S17,T17,U17,V17,W17,X17,AA17,AC17:AF17) -> 0 | AH17: =SUM(C17:AF17)-AG17 -> 0
A18: Ammonia | B18: kg | H18: 1.8467155 | X18: 0.70894827 | Z18: 0.00017739541 | AC18: 23.809093 | AG18: =SUM(C18:D18,G18,H18,I18,J18,K18,P18,R18,S18,T18,U18,V18,W18,X18,AA18,AC18:AF18) -> 26.364756 | AH18: =SUM(C18:AF18)-AG18 -> 0.00017739541
A19: sulfure oxides | B19: kg | H19: 2.392596 | Z19: 9.2871715e-05 | AC19: 14.256733 | AG19: =SUM(C19:D19,G19,H19,I19,J19,K19,P19,R19,S19,T19,U19,V19,W19,X19,AA19,AC19:AF19) -> 16.649329 | AH19: =SUM(C19:AF19)-AG19 -> 9.2871715e-05
A20: dinitrogen monoxide | B20: kg | C20: 50.852534 | D20: 37.726813 | E20: 0.0006853382 | F20: 0.00050844322 | AG20: =SUM(C20:D20,G20,H20,I20,J20,K20,P20,R20,S20,T20,U20,V20,W20,X20,AA20,AC20:AF20) -> 88.579347 | AH20: =SUM(C20:AF20)-AG20 -> 0.0011937814
A21: Nitrate | B21: kg | X21: 1.976625 | AG21: =SUM(C21:D21,G21,H21,I21,J21,K21,P21,R21,S21,T21,U21,V21,W21,X21,AA21,AC21:AF21) -> 1.976625 | AH21: =SUM(C21:AF21)-AG21 -> 0
A22: PM2.5 | B22: kg | Z22: 0.0013675986 | AG22: =SUM(C22:D22,G22,H22,I22,J22,K22,P22,R22,S22,T22,U22,V22,W22,X22,AA22,AC22:AF22) -> 0 | AH22: =SUM(C22:AF22)-AG22 -> 0.0013675986
A23: NMOVC | B23: kg | AA23: 2.5277027 | AB23: 1.638e-07 | AG23: =SUM(C23:D23,G23,H23,I23,J23,K23,P23,R23,S23,T23,U23,V23,W23,X23,AA23,AC23:AF23) -> 2.5277027 | AH23: =SUM(C23:AF23)-AG23 -> 1.638e-07
A24: H2S | AG24: =SUM(C24:D24,G24,H24,I24,J24,K24,P24,R24,S24,T24,U24,V24,W24,X24,AA24,AC24:AF24) -> 0 | AH24: =SUM(C24:AF24)-AG24 -> 0
A25: (PO4)3- | B25: kg | K25: 3.1274177 | AG25: =SUM(C25:D25,G25,H25,I25,J25,K25,P25,R25,S25,T25,U25,V25,W25,X25,AA25,AC25:AF25) -> 3.1274177 | AH25: =SUM(C25:AF25)-AG25 -> 0
A26: CO2 fossil | B26: kg | C26: 0.41583346 | D26: 0.11820999 | E26: 5.604176e-06 | F26: 1.5931127e-06 | T26: 0.152 | U26: 0.0165 | AG26: =SUM(C26:D26,G26,H26,I26,J26,K26,P26,R26,S26,T26,U26,V26,W26,X26,AA26,AC26:AF26) -> 0.70254344 | AH26: =SUM(C26:AF26)-AG26 -> 7.1972888e-06
A27: Diesel | B27: kg | C27: 0.23152335 | D27: 0.091497995 | E27: 3.1202337e-06 | F27: 1.233116e-06 | G27: 3.5939e-20 | H27: 0.0060276802 | I27: 0.053909966 | J27: 0.039281157 | K27: 5.4524179e-05 | L27: 3.0249295e-09 | M27: 1.1490511e-07 | N27: 7.5469177e-08 | O27: 5.8572071e-08 | P27: 2.8259643e-11 | Q27: 5.2537187e-10 | R27: 0.0046989474 | S27: 0.042316085 | T27: 0.08052196 | U27: 0.0087408311 | V27: 1.8677781e-08 | W27: 1.6488823e-08 | X27: 0.0020073884 | Y27: 1.2694832e-10 | Z27: 3.6191034e-07 | AA27: 0.028325675 | AB27: 2.3621059e-09 | AC27: 0.038813115 | AD27: 0.00068185265 | AE27: 0.00060184205 | AF27: 2.6424477e-05 | AG27: 0.62903684 | AH27: 5.0459218e-06 | AI27: 6.1957224e-07 | AJ27: 7.5676035e-08 | AK27: 7.3917021e-06
A28: N-fertilizer | B28: kg | C28: 0.57518501 | D28: 0.18529562 | E28: 7.7517526e-06 | F28: 2.497224e-06 | G28: 3.9890908e-18 | H28: 0.0088714777 | I28: 0.073779372 | J28: 0.024525279 | K28: 3.6074949e-05 | L28: 5.5072058e-09 | M28: 2.5858965e-07 | N28: 1.7938782e-07 | O28: 1.8156288e-07 | P28: 7.754779e-11 | Q28: 1.4008319e-09 | R28: 0.010508556 | S28: 0.018970044 | T28: 0.19897551 | U28: 0.021599272 | V28: 3.8568777e-07 | W28: 5.248735e-07 | X28: 0.0036257269 | Y28: 6.0235592e-11 | Z28: 7.1374671e-07 | AA28: 0.020639576 | AB28: 1.9849033e-09 | AC28: 0.081315348 | AD28: 0.014077665 | AE28: 0.019157883 | AF28: 8.7088127e-05 | AG28: 1.2567017 | AH28: 1.3917057e-05 | AI28: 1.9042035e-05 | AJ28: 2.3258397e-06 | AK28: 3.2236478e-05
A29: K-fertilizer | B29: kg | C29: 0.25246104 | D29: 0.076884144 | E29: 3.4024105e-06 | F29: 1.0361655e-06 | G29: 2.0720307e-18 | H29: 0.0048895793 | I29: 0.13220145 | J29: 0.013751199 | K29: 2.4885782e-05 | L29: 3.6714451e-09 | M29: 1.8273609e-07 | N29: 1.2199789e-07 | O29: 1.1346391e-07 | P29: 4.5438068e-11 | Q29: 7.8933779e-10 | R29: 0.023650481 | S29: 0.043627548 | T29: 0.091304599 | U29: 0.0099112967 | V29: 2.2604764e-07 | W29: 2.8296064e-07 | X29: 0.00080009028 | Y29: 2.6968749e-11 | Z29: 4.4915067e-07 | AA29: 0.021631556 | AB29: 2.151307e-09 | AC29: 0.03370436 | AD29: 0.0082507835 | AE29: 0.010328064 | AF29: 5.0815971e-05 | AG29: 0.72349037 | AH29: 5.6198993e-06 | AI29: 2.5162084e-06 | AJ29: 3.0733571e-07 | AK29: 1.5454094e-05
A30: P-fertilizer | B30: kg | C30: 0.15058631 | D30: 0.045215285 | E30: 2.0294475e-06 | F30: 6.0936515e-07 | G30: 2.2895213e-18 | H30: 0.014034236 | I30: 0.073493625 | J30: 0.0067405601 | K30: 0.0031201993 | L30: 3.9097242e-09 | M30: 1.4645927e-07 | N30: 1.2555538e-07 | O30: 2.1940333e-07 | P30: 1.4550959e-10 | Q30: 2.9605534e-09 | R30: 0.021390802 | S30: 0.024768996 | T30: 0.054203603 | U30: 0.0058839215 | V30: 2.2661926e-07 | W30: 3.0071084e-07 | X30: 0.0004511621 | Y30: 1.1973211e-11 | Z30: 1.1300162e-06 | AA30: 0.0086391901 | AB30: 8.6442606e-10 | AC30: 0.085578092 | AD30: 0.008271718 | AE30: 0.010975946 | AF30: 0.00012100943 | AG30: 0.51359006 | AH30: 5.1734693e-06 | AI30: 7.4132798e-06 | AJ30: 9.0547572e-07 | AK30: 0.00010746792
A31: Peat | B31: kg | C31: 0.0032331973 | D31: 0.0014752004 | E31: 4.357371e-08 | F31: 1.9881235e-08 | G31: 1.9344146e-21 | H31: 6.636891e-05 | I31: 0.00075505204 | J31: 0.00031143304 | K31: 3.5965966e-07 | L31: 4.2855048e-11 | M31: 3.2113094e-09 | N31: 1.3619544e-09 | O31: 1.1392657e-09 | P31: 1.0164771e-11 | Q31: 1.2800993e-10 | R31: 0.00075630767 | S31: 0.0039219773 | T31: 0.0010931182 | U31: 0.00011865993 | V31: 2.7437095e-09 | W31: 1.8314112e-09 | X31: 1.4534952e-05 | Y31: 1.9514453e-13 | Z31: 6.9437348e-09 | AA31: 0.00043203666 | AB31: 4.3746169e-11 | AC31: 0.00048190886 | AD31: 0.00010014674 | AE31: 6.6846509e-05 | AF31: 7.8568836e-06 | AG31: 0.012982466 | AH31: 1.0766423e-07 | AI31: 2.5657116e-07 | AJ31: 3.1338215e-08 | AK31: 0.00014719996
A32: Activated carbon | B32: kg | C32: 1.2634258 | D32: 0.38453989 | E32: 1.7027155e-05 | F32: 5.1824335e-06 | G32: 1.1804704e-19 | H32: 0.037539918 | I32: 0.47772922 | J32: 0.10027248 | K32: 1.9677838e-05 | L32: 1.1821866e-08 | M32: 1.6797788e-07 | N32: 3.552976e-07 | O32: 1.9853155e-07 | P32: 1.9926703e-10 | Q32: 3.3445848e-09 | R32: 0.022971069 | S32: 0.040682935 | T32: 0.45706972 | U32: 0.049615971 | V32: 4.7965579e-07 | W32: 2.6578996e-07 | X32: 0.0022087376 | Y32: 2.8627356e-11 | Z32: 4.5150881e-06 | AA32: 0.071239533 | AB32: 7.3007938e-09 | AC32: 0.23869151 | AD32: 0.017507683 | AE32: 0.0097013334 | AF32: 0.00024508409 | AG32: 3.173927 | AH32: 2.7878402e-05 | AI32: 3.352016e-06 | AJ32: 4.0942324e-07 | AK32: 0.00046230986
A33: Zeolite | B33: kg | C33: 1.9827624 | D33: 0.60143575 | E33: 2.6721634e-05 | F33: 8.105533e-06 | G33: 1.3097601e-17 | H33: 0.049898833 | I33: 8.8435677 | J33: 0.17100584 | K33: 0.0004896338 | L33: 4.6252072e-08 | M33: 6.2794828e-06 | N33: 1.3863795e-06 | O33: 2.8909316e-06 | P33: 5.018278e-10 | Q33: 8.0697764e-09 | R33: 0.070209896 | S33: 0.11857824 | T33: 0.71575874 | U33: 0.077697233 | V33: 1.7757897e-06 | W33: 2.0566413e-06 | X33: 0.0073018259 | Y33: 1.5803457e-09 | Z33: 5.4700677e-06 | AA33: 0.13034452 | AB33: 1.3195848e-08 | AC33: 0.32466584 | AD33: 0.064937117 | AE33: 0.075067407 | AF33: 0.0007720175 | AG33: 13.234902 | AH33: 5.4280096e-05 | AI33: 2.7484069e-05 | AJ33: 3.3569699e-06 | AK33: 0.00037810453
A34: treatment of wastewater | B34: m3 | C34: 0.092345533 | D34: 0.036271031 | E34: 1.2445382e-06 | F34: 4.8882369e-07 | G34: 1.3270271e-19 | H34: 0.0020338406 | I34: 2.9789716 | J34: 0.006712429 | K34: 0.01275068 | L34: 1.7899238e-08 | M34: 1.1926514e-07 | N34: 8.5934994e-07 | O34: 6.4789762e-07 | P34: 7.8842573e-11 | Q34: 1.5130176e-09 | R34: 0.0045994251 | S34: 0.010311723 | T34: 0.029900955 | U34: 0.0032458105 | V34: 2.6654644e-05 | W34: 1.3034913e-05 | X34: 0.15593723 | Y34: 5.1364404e-12 | Z34: 1.8298016e-07 | AA34: 0.0071055638 | AB34: 7.2009464e-10 | AC34: 0.01562842 | AD34: 0.97289573 | AE34: 0.47577434 | AF34: 5.9002177e-05 | AG34: 4.8045969 | AH34: 3.5612337e-06 | AI34: -1.4397331e-08 | AJ34: -1.7585245e-09 | AK34: 1.3912061e-05
A35: Wood chips | B35: kg | C35: 0.017034246 | D35: 0.0052065342 | E35: 2.2957007e-07 | F35: 7.0168317e-08 | G35: 4.5022236e-20 | H35: 0.00025928245 | I35: 0.0040924082 | J35: 0.00069640851 | K35: 0.00013742829 | L35: 1.3237861e-10 | M35: 1.0765567e-08 | N35: 4.3734986e-09 | O35: 2.8445728e-09 | P35: 5.9988814e-12 | Q35: 1.0531279e-10 | R35: 0.25176696 | S35: 0.001898717 | T35: 0.0062365076 | U35: 0.00067695974 | V35: 9.3271388e-09 | W35: 6.9917796e-09 | X35: 6.4355289e-05 | Y35: 1.3828851e-12 | Z35: 2.4117589e-08 | AA35: 0.0020503153 | AB35: 1.9290481e-10 | AC35: 0.0018745501 | AD35: 0.00034044697 | AE35: 0.00025519996 | AF35: 6.6555555e-06 | AG35: 0.29259982 | AH35: 3.537321e-07 | AI35: 9.3829054e-08 | AJ35: 1.1460505e-08 | AK35: 2.7300618e-06
A37: Mix marginal electricity | B37: kWh | C37: 0.3255785 | D37: 0.09863536 | E37: 4.3878125e-06 | F37: 1.329306e-06 | G37: 0 | H37: 0.0011978365 | I37: 0.0072588893 | J37: 0.0090733214 | K37: 1.3655894e-06 | L37: 3.815994e-10 | M37: 7.5398371e-10 | N37: 1.1130419e-08 | O37: 7.3047472e-09 | P37: 1.6730198e-12 | Q37: 3.5887443e-11 | R37: 0.00090090647 | S37: 0.0041587296 | T37: 0.11786662 | U37: 0.012794711 | V37: 1.085376e-08 | W37: 9.9041347e-09 | X37: 0.0002709758 | Y37: 6.4038625e-11 | Z37: 6.2599247e-08 | AA37: 0.010606122 | AB37: 1.0254708e-09 | AC37: 0.0089289832 | AD37: 0.00039617218 | AE37: 0.00036150091 | AF37: 6.8121332e-06 | AG37: 0.5980444 | AH37: 5.8479029e-06 | AI37: 3.8880035e-07 | AJ37: 4.7489005e-08 | AK37: 7.1891357e-06 | AM37: electricity production, natural gas, conventional power plant
A38: natural gas | B38: m3 | C38: 0.19208701 | D38: 0.077895459 | E38: 2.5887513e-06 | F38: 1.0497949e-06 | G38: 0 | H38: 0.0025264039 | I38: 0.027002481 | J38: 0.031055896 | K38: 4.0494623e-06 | L38: 1.4981608e-09 | M38: 1.2329245e-08 | N38: 4.4427159e-08 | O38: 2.9351524e-08 | P38: 5.7241307e-12 | Q38: 1.2261411e-10 | R38: 0.0034303236 | S38: 0.014342243 | T38: 0.066426259 | U38: 0.0072106913 | V38: 4.8755255e-08 | W38: 4.2659541e-08 | X38: 0.00039935439 | Y38: 2.162732e-10 | Z38: 1.7938466e-07 | AA38: 0.018893856 | AB38: 1.7004089e-09 | AC38: 0.017655913 | AD38: 0.0017796015 | AE38: 0.0015570732 | AF38: 1.7206803e-05 | AG38: 0.46230322 | AH38: 3.9848173e-06 | AI38: 6.3238513e-07 | AJ38: 7.7241032e-08 | AK38: 1.8680467e-05
A39: Mix marginal heat | B39: MJ | C39: 0.036606595 | D39: 0.011027964 | E39: 4.9334608e-07 | F39: 1.4862357e-07 | G39: 1.8355355e-21 | H39: 0.00028862325 | I39: 0.001913816 | J39: 0.00093700432 | K39: 1.4412766e-06 | L39: 1.5012604e-10 | M39: 4.1655245e-09 | N39: 4.0009951e-09 | O39: 2.2101399e-09 | P39: 1.1573822e-12 | Q39: 2.174998e-11 | R39: 0.00012145572 | S39: 0.00099540935 | T39: 0.013271943 | U39: 0.001440703 | V39: 1.9565669e-09 | W39: 1.7764736e-09 | X39: 5.5334525e-05 | Y39: 2.9853225e-12 | Z39: 1.6704189e-08 | AA39: 0.00093625163 | AB39: 8.3728291e-11 | AC39: 0.0018442609 | AD39: 7.1423215e-05 | AE39: 6.4841285e-05 | AF39: 1.039197e-06 | AG39: 0.069578362 | AH39: 6.7176707e-07 | AI39: 2.0123922e-08 | AJ39: 2.4579839e-09 | AK39: 2.3213647e-07 | AM39: heat production, natural gas, at boiler condensing modulating >100kW | heat, district or industrial, natural gas

Sheet LCI_AD-e
A1: AD+combustion+digestate
A2: Process | B2: Flow direction | C2: Flow type | D2: Flow name | E2: Value | F2: Unit
A3: Pretreatment | B3: input | C3: Technosphere flow | D3: Waste | E3: 1 | F3: t
B4: input | C4: Technosphere flow | D4: Electricity | E4: =E3*Parameters!C3 -> 9.98 | F4: kWh
B5: input | C5: Technosphere flow | D5: Water
B6: output | C6: Intermediate flow | D6: Pretreated biowaste | E6: =E3*Parameters!C5 -> 0.77 | F6: t
A7: Incineration | B7: input | C7: Intermediate flow | D7: transported discarded biowaste | E7: =E8*0.001*Parameters!C6 -> 2.3 | F7: tkm
B8: input | C8: Intermediate flow | D8: discarded biowaste | E8: =E3*(1-Parameters!C5)*1000 -> 230 | F8: kg
A9: AD | B9: input | C9: Intermediate flow | D9: Pretreated waste | E9: =E6 -> 0.77 | F9: t
B10: input | C10: Intermediate flow | D10: Electricity | E10: =Parameters!C14*E9 -> 22.33 | F10: kWh
B11: input | C11: Intermediate flow | D11: Heat | E11: =E9*Parameters!C15 -> 227.15 | F11: MJ
B12: output | C12: Elementary flow | D12: Methane | E12: =Parameters!C9*(Parameters!C7*(1-Waste_characteristics!B4))*E9*Parameters!C11*0.001 -> 1.5118454 | F12: kg
B13: output | C13: Intermediate flow | D13: Biogas | E13: =(((Parameters!C7*(1-Waste_characteristics!B4))/Parameters!C10)*0.001)-((E12/Parameters!C11)*(1/Parameters!C10)) -> 223.74985 | F13: m3
B14: output | C14: Technosphere flow | D14: Digestate | E14: =Parameters!C66*E9 -> 0.5558219 | F14: t
A15: Combustion of biogas | B15: input | C15: Intermediate flow | D15: Biogas | E15: =E13 -> 223.74985 | F15: m3
B16: output | C16: Elementary flow | D16: CO2 | E16: =Parameters!C34*E15 -> 449.66648 | F16: kg
B17: output | C17: Elementary flow | D17: CH4 | E17: =$E$15*Parameters!C35 -> 0.0057327997 | F17: kg
B18: output | C18: Elementary flow | D18: N2O | E18: =$E$15*Parameters!C36 -> 0.0057327997 | F18: kg
B19: output | C19: Elementary flow | D19: Sox | E19: =$E$15*Parameters!C37 -> 0.039771298 | F19: kg
B20: output | C20: Elementary flow | D20: PM10 | E20: =$E$15*Parameters!C38 -> 0.029165619 | F20: kg
B21: output | C21: Elementary flow | D21: PM2.5 | E21: =$E$15*Parameters!C39 -> 0.029165619 | F21: kg
B22: output | C22: Elementary flow | D22: Nox | E22: =$E$15*Parameters!C40 -> 0.38338098 | F22: kg
B23: output | C23: Elementary flow | D23: NH3 | E23: =$E$15*Parameters!C41 -> 0.012110539 | F23: kg
B24: output | C24: Elementary flow | D24: CO | E24: =$E$15*Parameters!C42 -> 0.32246998 | F24: kg
B25: output | C25: Elementary flow | D25: VOC | E25: =$E$15*Parameters!C43 -> 0.019276539 | F25: kg
B26: input | C26: Technosphere flow | D26: Electricity | E26: =$E$15*Parameters!C44 -> 0.60859958 | F26: kWh
B27: output | C27: Technosphere flow | D27: Heat | E27: =E15*Parameters!C10*Parameters!C20*Parameters!C33 -> 3876.4661 | F27: MJ
A28: Storage | B28: input | C28: Technosphere flow | D28: Digestate | E28: ='LCI_AD-a'!E26 -> 0.5558219 | F28: t
B29: output | C29: Elementary flow | D29: CH4 | E29: ='LCI_AD-a'!E27 -> 1.338037 | F29: kg
B30: output | C30: Technosphere flow | D30: Digestate after storage | E30: ='LCI_AD-a'!E28 -> 0.55448387 | F30: t
A31: Land application of digestate | B31: input | C31: Technosphere flow | D31: Digestate after storage | E31: ='LCI_AD-a'!E29 -> 0.55448387 | F31: t
B32: output | C32: Elementary flow | D32: N2O | E32: ='LCI_AD-a'!E30 -> 0.069747028 | F32: kg
B33: output | C33: Elementary flow | D33: NH3 | E33: ='LCI_AD-a'!E31 -> 4.329404 | F33: kg
B34: output | C34: Elementary flow | D34: NO3 | E34: ='LCI_AD-a'!E32 -> -1.8937605 | F34: kg
B35: output | C35: Elementary flow | D35: (PO4)3- | E35: ='LCI_AD-a'!E33 -> -0.06209938 | F35: kg
B36: output | C36: Elementary flow | D36: CO2 fossil | E36: ='LCI_AD-a'!E34 -> 0 | F36: kg
A37: Substituted products | E37: ='LCI_AD-a'!E35 -> 0
C38: Technosphere flow | D38: N-fertilizer | E38: ='LCI_AD-a'!E36 -> 18.00888 | F38: kg
C39: Technosphere flow | D39: P-fertilizer | E39: ='LCI_AD-a'!E37 -> 50.217839 | F39: kg
C40: Technosphere flow | D40: K-fertilizer | E40: ='LCI_AD-a'!E38 -> 18.509017 | F40: kg
...

Sheet LCI_AD-f
A1: AD+combustion+composting
A2: Process | B2: Flow direction | C2: Flow type | D2: Flow name | E2: Value | F2: Unit
A3: Pretreatment | B3: input | C3: Technosphere flow | D3: Waste | E3: 1 | F3: t
B4: input | C4: Technosphere flow | D4: Electricity | E4: =E3*Parameters!C3 -> 9.98 | F4: kWh
B5: input | C5: Technosphere flow | D5: Water
B6: output | C6: Intermediate flow | D6: Pretreated biowaste | E6: =E3*Parameters!C5 -> 0.77 | F6: t
A7: Incineration | B7: input | C7: Intermediate flow | D7: transported discarded biowaste | E7: =E8*0.001*Parameters!C6 -> 2.3 | F7: tkm
B8: input | C8: Intermediate flow | D8: discarded biowaste | E8: =E3*(1-Parameters!C5)*1000 -> 230 | F8: kg
A9: AD | B9: input | C9: Intermediate flow | D9: Pretreated waste | E9: =E6 -> 0.77 | F9: t
B10: input | C10: Intermediate flow | D10: Electricity | E10: =Parameters!C14*E9 -> 22.33 | F10: kWh
B11: input | C11: Intermediate flow | D11: Heat | E11: =E9*Parameters!C15 -> 227.15 | F11: MJ
B12: output | C12: Elementary flow | D12: Methane | E12: =Parameters!C9*(Parameters!C7*(1-Waste_characteristics!B4))*E9*Parameters!C11*0.001 -> 1.5118454 | F12: kg
B13: output | C13: Intermediate flow | D13: Biogas | E13: =(((Parameters!C7*(1-Waste_characteristics!B4))/Parameters!C10)*0.001)-((E12/Parameters!C11)*(1/Parameters!C10)) -> 223.74985 | F13: m3
B14: output | C14: Technosphere flow | D14: Digestate | E14: =Parameters!C66*E9 -> 0.5558219 | F14: t
A15: Combustion of biogas | B15: input | C15: Intermediate flow | D15: Biogas | E15: =E13 -> 223.74985 | F15: m3
B16: output | C16: Elementary flow | D16: CO2 | E16: =Parameters!C34*E15 -> 449.66648 | F16: kg
B17: output | C17: Elementary flow | D17: CH4 | E17: =$E$15*Parameters!C35 -> 0.0057327997 | F17: kg
B18: output | C18: Elementary flow | D18: N2O | E18: =$E$15*Parameters!C36 -> 0.0057327997 | F18: kg
B19: output | C19: Elementary flow | D19: Sox | E19: =$E$15*Parameters!C37 -> 0.039771298 | F19: kg
B20: output | C20: Elementary flow | D20: PM10 | E20: =$E$15*Parameters!C38 -> 0.029165619 | F20: kg
B21: output | C21: Elementary flow | D21: PM2.5 | E21: =$E$15*Parameters!C39 -> 0.029165619 | F21: kg
B22: output | C22: Elementary flow | D22: Nox | E22: =$E$15*Parameters!C40 -> 0.38338098 | F22: kg
B23: output | C23: Elementary flow | D23: NH3 | E23: =$E$15*Parameters!C41 -> 0.012110539 | F23: kg
B24: output | C24: Elementary flow | D24: CO | E24: =$E$15*Parameters!C42 -> 0.32246998 | F24: kg
B25: output | C25: Elementary flow | D25: VOC | E25: =$E$15*Parameters!C43 -> 0.019276539 | F25: kg
B26: input | C26: Technosphere flow | D26: Electricity | E26: =$E$15*Parameters!C44 -> 0.60859958 | F26: kWh
B27: output | C27: Technosphere flow | D27: Heat | E27: =E15*Parameters!C10*Parameters!C20*Parameters!C33 -> 3876.4661 | F27: MJ
A28: Dewatering | B28: input | C28: Technosphere flow | D28: Digestate | E28: ='LCI_AD-d'!E24 -> 0.5558219 | F28: t
B29: input | C29: Technosphere flow | D29: electricity | E29: ='LCI_AD-d'!E25 -> 2.0184752 | F29: kWh
B30: output | C30: Technosphere flow | D30: dewatered digestate | E30: ='LCI_AD-d'!E26 -> 0.2970039 | F30: t
B31: output | C31: Technosphere flow | D31: wastewater | E31: ='LCI_AD-d'!E27 -> 0.25911227 | F31: m3
A32: Composting of digestate | B32: input | C32: Technosphere flow | D32: dewatered digestate | E32: ='LCI_AD-d'!E28 -> 0.2970039 | F32: t
B33: output | C33: Elementary flow | D33: CH4 | E33: ='LCI_AD-d'!E29 -> 0.088228561 | F33: kg
B34: output | C34: Elementary flow | D34: N2O | E34: ='LCI_AD-d'!E30 -> 0.062318617 | F34: kg
B35: output | C35: Elementary flow | D35: NH3 | E35: ='LCI_AD-d'!E31 -> 0.20275914 | F35: kg
B36: output | C36: Elementary flow | D36: NMVOC | E36: ='LCI_AD-d'!E32 -> 0.030888406 | F36: kg
B37: output | C37: Elementary flow | D37: CO | E37: ='LCI_AD-d'!E33 -> 0.12509677 | F37: kg
B38: output | C38: Technosphere flow | D38: compost | E38: ='LCI_AD-d'!E34 -> 0.15444203 | F38: t
B39: input | C39: Technosphere flow | D39: electricity | E39: ='LCI_AD-d'!E35 -> 3.1254739 | F39: kWh
B40: input | C40: Technosphere flow | D40: diesel | E40: ='LCI_AD-d'!E36 -> 0.44883056 | F40: kg
...

Sheet Waste_characteristics
C1: Unit
A2: Mass | B2: 1 | C2: t
A3: FW | B3: =B2-B7 -> 1 | C3: t
A4: Moisture content, FW | B4: =[2]mass_composition!$D$99/[2]mass_composition!$C$99 -> 0.63542863 | C4: %FW | D4: 0.72
A5: VS, FW | B5: =[2]mass_composition!$F$99/[2]mass_composition!$E$99 -> 0.96463821 | C5: %TS
A6: VS, FW | B6: =B3*(1-B4)*B5 -> 0.35167947 | C6: t
A7: impurities | B7: 0 | C7: t
A8: Nitrogen content, FW | B8: =[2]mass_composition!$R$99/[2]mass_composition!$E$99 -> 0.032826764 | C8: % of dry mass of FW
A9: Carbon content, FW | B9: =[2]mass_composition!$J$99/[2]mass_composition!$E$99 -> 0.46707763 | C9: % of dry mass of FW
A10: Phosphorus content, FW | B10: =[2]mass_composition!$U$99/[2]mass_composition!$E$99 -> 0.0040243826 | C10: % of dry mass of FW
A11: Potassium content, FW | B11: =[2]mass_composition!$Q$99/[2]mass_composition!$E$99 -> 0.0082642017 | C11: % of dry mass of FW
A13: Nitrogen content, FW | B13: =B8*(1-H2O_FW) -> 0.011967698 | C13: t/t of FW
A14: Carbon content, FW | B14: =B9*(1-H2O_FW) -> 0.17028313 | C14: t/t of FW
A15: Phosphorus content, FW | B15: =B10*(1-H2O_FW) -> 0.0014671747 | C15: t/t of FW
A16: Potassium content, FW | B16: =B8*(1-H2O_FW) -> 0.011967698 | C16: t/t of FW
J35: https://journals.sagepub.com/doi/full/10.1177/0734242X14545374#bibr26-0734242X14545374

Sheet Parameters
B1: Pretreatment
A2: Process | B2: Parameter | C2: Value | D2: Unit | F2: Source
A3: Pretreatment | B3: Electricity requirement | C3: 9.98 | D3: kWh/t | E3: Drum-screen + Shredder + Piston press
B4: Sorting efficiency for impurities | C4: 1 | D4: % of impurities sorted
B5: Sorting efficiency for biowaste | C5: 0.77 | D5: % of biowaste retained
B6: Distance between the industrial plant and the incineration plan | C6: 10 | D6: km
A7: AD | B7: Methane production | C7: =374*1000 -> 374000 | D7: L/dry-t | F7: https://catalog.data.gov/dataset/food-waste-management-life-cycle-inventory-tool-v1-0-0
B8: VS conversion | C8: 0.86 | D8: %VS initial
B9: Fugitive methane loss | C9: 0.02 | F9: https://catalog.data.gov/dataset/food-waste-management-life-cycle-inventory-tool-v1-0-1
B10: Methane volume share in biogas | C10: 0.6 | F10: https://catalog.data.gov/dataset/food-waste-management-life-cycle-inventory-tool-v1-0-2
B11: Methane density | C11: 0.72 | D11: kg/m3 | F11: https://catalog.data.gov/dataset/food-waste-management-life-cycle-inventory-tool-v1-0-3
B12: CO2 density | C12: 1.98 | D12: kg/m3
B13: biogas density | C13: =(C10*C11)+((1-C10)*C12) -> 1.224 | D13: kg/m3
B14: Electricity requirement | C14: 29 | D14: kWh/t | F14: https://catalog.data.gov/dataset/food-waste-management-life-cycle-inventory-tool-v1-0-4
B15: Heat requirement | C15: 295 | D15: MJ/t | F15: https://catalog.data.gov/dataset/food-waste-management-life-cycle-inventory-tool-v1-0-5
B16: Water requriement | C16: 0 | D16: %of Biowaste
A17: CHP | B17: Efficiency | F17: https://catalog.data.gov/dataset/food-waste-management-life-cycle-inventory-tool-v1-0-6
B18: Thermal | C18: 0.46 | F18: https://catalog.data.gov/dataset/food-waste-management-life-cycle-inventory-tool-v1-0-7
B19: Electric | C19: 0.39 | F19: https://catalog.data.gov/dataset/food-waste-management-life-cycle-inventory-tool-v1-0-8
B20: Methane_lhv | C20: 35 | D20: MJ/m3 | F20: https://catalog.data.gov/dataset/food-waste-management-life-cycle-inventory-tool-v1-0-9
B21: Electricity requirement | F21: https://www.sciencedirect.com/science/article/pii/S0013935122009598?casa_token=b-5UAciDODcAAAAA:iPTgJGz224xsnoQdrEctjVyXjbgpRksrTp6NPBa96VQZoPJqxyo5SRxUSGA4QFvLo7qp_-bQrQ
B22: Lubricating oil | C22: 1.54 | D22: g/m3 of biogas | F22: https://www.sciencedirect.com/science/article/pii/S0013935122009598?casa_token=b-5UAciDODcAAAAA:iPTgJGz224xsnoQdrEctjVyXjbgpRksrTp6NPBa96VQZoPJqxyo5SRxUSGA4QFvLo7qp_-bQrQ
B23: Emissions
B24: Nitrogen Oxides (NOx) | C24: 0.00016410454 | D24: kg/m3 biogas combusted | F24: https://catalog.data.gov/dataset/food-waste-management-life-cycle-inventory-tool-v1-0-0
B25: Volatile Organic Compounds (VOCs) | C25: 0.0015816552 | D25: kg/m3 biogas combusted | F25: https://catalog.data.gov/dataset/food-waste-management-life-cycle-inventory-tool-v1-0-1
B26: Sulfur Dioxide (SO2) | C26: 1.4066103e-05 | D26: kg/m3 biogas combusted | F26: https://catalog.data.gov/dataset/food-waste-management-life-cycle-inventory-tool-v1-0-2
B27: Particulate Matter (PM2.5) | C27: 3.4383808e-05 | D27: kg/m3 biogas combusted | F27: https://catalog.data.gov/dataset/food-waste-management-life-cycle-inventory-tool-v1-0-3
B28: Carbon Monoxide (CO) | C28: 0.0010682424 | D28: kg/m3 biogas combusted | F28: https://catalog.data.gov/dataset/food-waste-management-life-cycle-inventory-tool-v1-0-4
B29: Ammonia (NH3) | C29: 6.4078915e-05 | D29: kg/m3 biogas combusted | F29: https://catalog.data.gov/dataset/food-waste-management-life-cycle-inventory-tool-v1-0-5
B30: Methane (CH4) | C30: 0.0043034128 | D30: kg/m3 biogas combusted | F30: https://catalog.data.gov/dataset/food-waste-management-life-cycle-inventory-tool-v1-0-6
B31: Nitrous Oxide (N2O) | C31: 0.00010246221 | D31: kg/m3 biogas combusted | F31: https://catalog.data.gov/dataset/food-waste-management-life-cycle-inventory-tool-v1-0-7
A32: Biogas boiler
B33: Efficiency | C33: 0.825 | F33: https://pureadmin.qub.ac.uk/ws/files/135497181/Document2.pdf
B34: CO2 | C34: =L37*L$48 -> 2.009684 | D34: kg/m3 of biogas | E34: Labutong, 2012
B35: CH4 | C35: =L38*L$48 -> 2.5621469e-05 | D35: kg/m3 of biogas | E35: Labutong, 2012
B36: N2O | C36: =L39*L$48 -> 2.5621469e-05 | D36: kg/m3 of biogas | E36: Labutong, 2012
B37: Sox | C37: =L40*L$48 -> 0.00017774894 | D37: kg/m3 of biogas | E37: Labutong, 2012 | K37: CO2 | L37: =39.1+86.4 -> 125.5 | M37: lb/MCF
B38: PM10 | C38: =L41*L$48 -> 0.00013034922 | D38: kg/m3 of biogas | E38: Labutong, 2012 | K38: CH4 | L38: 0.0016 | M38: lb/MCF
B39: PM2.5 | C39: =L42*L$48 -> 0.00013034922 | D39: kg/m3 of biogas | E39: Labutong, 2012 | K39: N2O | L39: 0.0016 | M39: lb/MCF
B40: Nox | C40: =L43*L$48 -> 0.0017134357 | D40: kg/m3 of biogas | E40: Labutong, 2012 | K40: Sox | L40: 0.0111 | M40: lb/MCF
...

Sheet LCI
A2: Process | B2: Flow direction | C2: Flow type | D2: Flow name | E2: Value | F2: Unit | I2: UF | J2: Treatment of 1t of biowaste
A3: Pretreatment | B3: input | C3: Technosphere flow | D3: Waste | E3: 1 | F3: t
B4: input | C4: Technosphere flow | D4: Electricity | E4: =E3*Parameters!C3 -> 9.98 | F4: kWh
B5: input | C5: Technosphere flow | D5: Water
B6: output | C6: Intermediate flow | D6: Pretreated biowaste | E6: =E3*Parameters!C5 -> 0.77 | F6: t
A7: Incineration | B7: input | C7: Intermediate flow | D7: discarded biowaste | E7: =E3*(1-Parameters!C5)*1000 -> 230 | F7: kg
A9: AD | B9: input | C9: Intermediate flow | D9: Pretreated waste | E9: =E6 -> 0.77 | F9: t
B10: input | C10: Intermediate flow | D10: Electricity | E10: =Parameters!C14*LCI!E9 -> 22.33 | F10: kWh
B11: input | C11: Intermediate flow | D11: Heat | E11: =E9*Parameters!C15 -> 227.15 | F11: MJ
B12: output | C12: Elementary flow | D12: Methane | E12: =Parameters!C9*(Parameters!C7*(1-Waste_characteristics!B4))*LCI!E9*Parameters!C11*0.001 -> 1.5118454 | F12: kg
B13: output | C13: Intermediate flow | D13: Biogas | E13: =(((Parameters!C7*(1-Waste_characteristics!B4))/Parameters!C10)*0.001)-((E12/Parameters!C11)*(1/Parameters!C10)) -> 223.74985 | F13: m3
A14: CHP | B14: input | C14: Intermediate flow | D14: Biogas | E14: =E13 -> 223.74985 | F14: m3
B15: output | C15: Elementary flow | D15: Nitrogen Oxides (NOx) | E15: =E14*Parameters!C24 -> 0.036718365 | F15: kg
B16: output | C16: Elementary flow | D16: Volatile Organic Compounds (VOCs) | E16: =E14*Parameters!C25 -> 0.3538951 | F16: kg
B17: output | C17: Elementary flow | D17: Sulfur Dioxide (SO2) | E17: =E14*Parameters!C26 -> 0.0031472884 | F17: kg
B18: output | C18: Elementary flow | D18: Particulate Matter (PM) | E18: =LCI!E14*Parameters!C27 -> 0.0076933718 | F18: kg
B19: output | C19: Elementary flow | D19: Carbon Monoxide (CO) | E19: =E14*Parameters!C28 -> 0.23901907 | F19: kg
B20: output | C20: Elementary flow | D20: Ammonia (NH3) | E20: =E14*Parameters!C29 -> 0.014337647 | F20: kg
B21: output | C21: Elementary flow | D21: Methane (CH4) | E21: =E14*Parameters!C30 -> 0.96288796 | F21: kg
B22: output | C22: Elementary flow | D22: Nitrous Oxide (N2O) | E22: =LCI!E14*Parameters!C31 -> 0.022925904 | F22: kg
B23: output | C23: Technosphere flow | D23: Electricity | E23: =E14*Parameters!C10*Parameters!C20*Parameters!C19/3.6 -> 509.0309 | F23: kWh
B24: output | C24: Technosphere flow | D24: Heat | E24: =E14*Parameters!C10*Parameters!C20*Parameters!C18 -> 2161.4235 | F24: MJ
A27: Biogas boiler | B27: input | C27: Intermediate flow | D27: Biogas | E27: =E13 -> 223.74985 | F27: m3
B28: output | C28: Elementary flow | D28: CO2 | E28: =$E$27*Parameters!C34 -> 449.66648 | F28: kg
B29: output | C29: Elementary flow | D29: CH4 | E29: =$E$27*Parameters!C35 -> 0.0057327997 | F29: kg
B30: output | C30: Elementary flow | D30: N2O | E30: =$E$27*Parameters!C36 -> 0.0057327997 | F30: kg
B31: output | C31: Elementary flow | D31: Sox | E31: =$E$27*Parameters!C37 -> 0.039771298 | F31: kg
B32: output | C32: Elementary flow | D32: PM10 | E32: =$E$27*Parameters!C38 -> 0.029165619 | F32: kg
B33: output | C33: Elementary flow | D33: PM2.5 | E33: =$E$27*Parameters!C39 -> 0.029165619 | F33: kg
B34: output | C34: Elementary flow | D34: Nox | E34: =$E$27*Parameters!C40 -> 0.38338098 | F34: kg
B35: output | C35: Elementary flow | D35: NH3 | E35: =$E$27*Parameters!C41 -> 0.012110539 | F35: kg
B36: output | C36: Elementary flow | D36: CO | E36: =$E$27*Parameters!C42 -> 0.32246998 | F36: kg
B37: output | C37: Elementary flow | D37: VOC | E37: =$E$27*Parameters!C43 -> 0.019276539 | F37: kg
B38: input | C38: Technosphere flow | D38: Electricity | E38: =Parameters!C44*LCI!E27 -> 0.60859958 | F38: kWh
B39: output | C39: Technosphere flow | D39: Heat | E39: =E27*Parameters!C10*Parameters!C20*Parameters!C33 -> 3876.4661 | F39: MJ
A42: Biogas upgrading | B42: input | C42: Technosphere flow | D42: Biogas | E42: =E13 -> 223.74985 | F42: m3
B43: output | C43: Elementary flow | D43: CO2 | E43: =E42*(1-Parameters!C10)*Parameters!C47*Parameters!C12 -> 174.55173 | F43: kg
B44: output | C44: Elementary flow | D44: CH4 | E44: =E42*Parameters!C10*Parameters!C48*Parameters!C11 -> 1.7398788 | F44: kg
B45: output | C45: Elementary flow | D45: H2S | E45: =Parameters!C49*LCI!E42 -> 0.0013424991 | F45: kg
B46: output | C46: Elementary flow | D46: Sox | E46: =E42*Parameters!C50 -> 0.001476749 | F46: kg
...

Sheet LCI_AD-d
A1: AD+injection+Composting of digestate
A2: Process | B2: Flow direction | C2: Flow type | D2: Flow name | E2: Value | F2: Unit
A3: Pretreatment | B3: input | C3: Technosphere flow | D3: Waste | E3: 1 | F3: t
B4: input | C4: Technosphere flow | D4: Electricity | E4: =E3*Parameters!C3 -> 9.98 | F4: kWh
B5: input | C5: Technosphere flow | D5: Water
B6: output | C6: Intermediate flow | D6: Pretreated biowaste | E6: =E3*Parameters!C5 -> 0.77 | F6: t
A7: Incineration | B7: input | C7: Intermediate flow | D7: transported discarded biowaste | E7: =E8*0.001*Parameters!C6 -> 2.3 | F7: tkm
B8: input | C8: Intermediate flow | D8: discarded biowaste | E8: =E3*(1-Parameters!C5)*1000 -> 230 | F8: kg
A9: AD | B9: input | C9: Intermediate flow | D9: Pretreated waste | E9: =E6 -> 0.77 | F9: t
B10: input | C10: Intermediate flow | D10: Electricity | E10: =Parameters!C14*E9 -> 22.33 | F10: kWh
B11: input | C11: Intermediate flow | D11: Heat | E11: =E9*Parameters!C15 -> 227.15 | F11: MJ
B12: output | C12: Elementary flow | D12: Methane | E12: =Parameters!C9*(Parameters!C7*(1-Waste_characteristics!B4))*E9*Parameters!C11*0.001 -> 1.5118454 | F12: kg
B13: output | C13: Intermediate flow | D13: Biogas | E13: =(((Parameters!C7*(1-Waste_characteristics!B4))/Parameters!C10)*0.001)-((E12/Parameters!C11)*(1/Parameters!C10)) -> 223.74985 | F13: m3
B14: output | C14: Technosphere flow | D14: Digestate | E14: =Parameters!C66*E9 -> 0.5558219 | F14: t
A15: Biogas upgrading | B15: input | C15: Technosphere flow | D15: Biogas | E15: =E13 -> 223.74985 | F15: m3
B16: output | C16: Elementary flow | D16: CO2 | E16: =E15*(1-Parameters!C10)*Parameters!C47*Parameters!C12 -> 174.55173 | F16: kg
B17: output | C17: Elementary flow | D17: CH4 | E17: =E15*Parameters!C10*Parameters!C48*Parameters!C11 -> 1.7398788 | F17: kg
B18: output | C18: Elementary flow | D18: H2S | E18: =Parameters!C49*E15 -> 0.0013424991 | F18: kg
B19: output | C19: Elementary flow | D19: Sox | E19: =E15*Parameters!C50 -> 0.001476749 | F19: kg
B20: input | C20: Technosphere flow | D20: Electricity requirement | E20: =E15*Parameters!C51 -> 76.074947 | F20: kWh
B21: input | C21: Technosphere flow | D21: Activated carbon | E21: =E15*Parameters!C52 -> 0.19913736 | F21: kg
B22: input | C22: Technosphere flow | D22: Zeolite | E22: =E15*Parameters!C53 -> 2.6626232 | F22: kg
B23: output | C23: Technosphere flow | D23: Biomethane | E23: =(E15*Parameters!C10*(1-Parameters!C48)) -> 131.83341 | F23: m3
A24: Dewatering | B24: input | C24: Technosphere flow | D24: Digestate | E24: =E14 -> 0.5558219 | F24: t
B25: input | C25: Technosphere flow | D25: electricity | E25: =E24*Parameters!C90*1000 -> 2.0184752 | F25: kWh
B26: output | C26: Technosphere flow | D26: dewatered digestate | E26: =Parameters!C68*Parameters!C88*(1/Parameters!C89)*E9 -> 0.2970039 | F26: t
B27: output | C27: Technosphere flow | D27: wastewater | E27: =(E24-E26)*1000/Parameters!C70 -> 0.25911227 | F27: m3
A28: Composting of digestate | B28: input | C28: Technosphere flow | D28: dewatered digestate | E28: =E26 -> 0.2970039 | F28: t
B29: output | C29: Elementary flow | D29: CH4 | E29: =(16/12)*Parameters!C98*(1-Parameters!C94)*((E6*1000*(1-Waste_characteristics!B4)*Waste_characteristics!B9)-((E13*(1-Parameters!C10)*Parameters!C12*(12/44)))-((E13*(Parameters!C10)*Parameters!C11*(12/16)))) -> 0.088228561 | F29: kg
B30: output | C30: Elementary flow | D30: N2O | E30: =(E6*1000*(1-Waste_characteristics!B4)*Waste_characteristics!B8)*(1-Parameters!C91)*Parameters!C99*(44/28) -> 0.062318617 | F30: kg
B31: output | C31: Elementary flow | D31: NH3 | E31: =(E6*1000*(1-Waste_characteristics!B4)*Waste_characteristics!B8)*(1-Parameters!C91)*Parameters!C100*(17/14) -> 0.20275914 | F31: kg
B32: output | C32: Elementary flow | D32: NMVOC | E32: =E28*Parameters!C101 -> 0.030888406 | F32: kg
B33: output | C33: Elementary flow | D33: CO | E33: =(44/12)*Parameters!C102*(1-Parameters!C94)*((E6*1000*(1-Waste_characteristics!B4)*Waste_characteristics!B9)-((E14*(1-Parameters!C10)*Parameters!C12*(12/44)))-((E14*(Parameters!C10)*Parameters!C11*(12/16)))) -> 0.12509677 | F33: kg
B34: output | C34: Technosphere flow | D34: compost | E34: =E28*(1-Parameters!C103) -> 0.15444203 | F34: t
B35: input | C35: Technosphere flow | D35: electricity | E35: =E28*Parameters!C104 -> 3.1254739 | F35: kWh
B36: input | C36: Technosphere flow | D36: diesel | E36: =E28*Parameters!C105*Parameters!C106 -> 0.44883056 | F36: kg
A37: Land application of compost
B38: output | C38: Elementary flow | D38: N2O | E38: ='LCI_AD-b'!E40 -> 0.013194214 | F38: kg
B39: output | C39: Elementary flow | D39: NH3 | E39: ='LCI_AD-b'!E41 -> 0.078947678 | F39: kg
B40: output | C40: Elementary flow | D40: NO3 | E40: ='LCI_AD-b'!E42 -> 2.6495849 | F40: kg
...

Sheet params_HC
B2: Technology | I2: Pretratment technology
B3: Pretreatement technology | C3: 1 | D3: (don't select if home composting) | I3: 0 | J3: None
B4: Ratio Biowaste/WC | C4: 8_1 | I4: 1 | J4: Drum-screen + Shredder + Piston press
B5: Aeration mode for industrial composting | C5: Active | D5: (don't select if home composting) | I5: 2 | J5: Shredder + Piston press + Screw press
B6: Distance of biowaste collection | C6: 20 | D6: km | I6: 3 | J6: Separation-mill
B7: Distance of compost transport from composting site to land | C7: 20 | D7: km | I7: 4 | J7: Pulp + Drum-screen

Sheet LCI_AD-a
A1: AD+CHP+Digestate
A2: Process | B2: Flow direction | C2: Flow type | D2: Flow name | E2: Value | F2: Unit
A3: Pretreatment | B3: input | C3: Technosphere flow | D3: Waste | E3: 1 | F3: t
B4: input | C4: Technosphere flow | D4: Electricity | E4: =E3*Parameters!C3 -> 9.98 | F4: kWh
B5: input | C5: Technosphere flow | D5: Water
B6: output | C6: Intermediate flow | D6: Pretreated biowaste | E6: =E3*Parameters!C5 -> 0.77 | F6: t
A7: Incineration | B7: input | C7: Intermediate flow | D7: transported discarded biowaste | E7: =E8*0.001*Parameters!C6 -> 2.3 | F7: tkm
B8: input | C8: Intermediate flow | D8: discarded biowaste | E8: =E3*(1-Parameters!C5)*1000 -> 230 | F8: kg
A9: AD | B9: input | C9: Intermediate flow | D9: Pretreated waste | E9: =E6 -> 0.77 | F9: t
B10: input | C10: Intermediate flow | D10: Electricity | E10: =Parameters!C14*E9 -> 22.33 | F10: kWh
B11: input | C11: Intermediate flow | D11: Heat | E11: =E9*Parameters!C15 -> 227.15 | F11: MJ
B12: output | C12: Elementary flow | D12: Methane | E12: =Parameters!C9*(Parameters!C7*(1-Waste_characteristics!B4))*E9*Parameters!C11*0.001 -> 1.5118454 | F12: kg
B13: output | C13: Intermediate flow | D13: Biogas | E13: =(((Parameters!C7*(1-Waste_characteristics!B4))/Parameters!C10)*0.001)-((E12/Parameters!C11)*(1/Parameters!C10)) -> 223.74985 | F13: m3
B14: output | C14: Technosphere flow | D14: Digestate | E14: =Parameters!C66*E9 -> 0.5558219 | F14: t
A15: CHP | B15: input | C15: Intermediate flow | D15: Biogas | E15: =E13 -> 223.74985 | F15: m3
B16: output | C16: Elementary flow | D16: Nitrogen Oxides (NOx) | E16: =E15*Parameters!C24 -> 0.036718365 | F16: kg
B17: output | C17: Elementary flow | D17: Volatile Organic Compounds (VOCs) | E17: =E15*Parameters!C25 -> 0.3538951 | F17: kg
B18: output | C18: Elementary flow | D18: Sulfur Dioxide (SO2) | E18: =E15*Parameters!C26 -> 0.0031472884 | F18: kg
B19: output | C19: Elementary flow | D19: Particulate Matter (PM) | E19: =LCI!E14*Parameters!C27 -> 0.0076933718 | F19: kg
B20: output | C20: Elementary flow | D20: Carbon Monoxide (CO) | E20: =E15*Parameters!C28 -> 0.23901907 | F20: kg
B21: output | C21: Elementary flow | D21: Ammonia (NH3) | E21: =E15*Parameters!C29 -> 0.014337647 | F21: kg
B22: output | C22: Elementary flow | D22: Methane (CH4) | E22: =E15*Parameters!C30 -> 0.96288796 | F22: kg
B23: output | C23: Elementary flow | D23: Nitrous Oxide (N2O) | E23: =LCI!E14*Parameters!C31 -> 0.022925904 | F23: kg
B24: output | C24: Technosphere flow | D24: Electricity | E24: =E15*Parameters!C10*Parameters!C20*Parameters!C19/3.6 -> 509.0309 | F24: kWh
B25: output | C25: Technosphere flow | D25: Heat | E25: =E15*Parameters!C10*Parameters!C20*Parameters!C18 -> 2161.4235 | F25: MJ
A26: Storage | B26: input | C26: Technosphere flow | D26: Digestate | E26: =E14 -> 0.5558219 | F26: t
B27: output | C27: Elementary flow | D27: CH4 | E27: =Parameters!C75*E9*1000 -> 1.338037 | F27: kg
B28: output | C28: Technosphere flow | D28: Digestate after storage | E28: =E26-(E27*0.001) -> 0.55448387 | F28: t
A29: Land application of digestate | B29: input | C29: Technosphere flow | D29: Digestate after storage | E29: =E28 -> 0.55448387 | F29: t
B30: output | C30: Elementary flow | D30: N2O | E30: =(Parameters!C82*'LCI_AD-a'!E9*1000*Parameters!C79*44/28)-(E36*Parameters!C123*Parameters!C125*44/28) -> 0.069747028 | F30: kg | H30: NET EMISSION TO BE calculated
B31: output | C31: Elementary flow | D31: NH3 | E31: =(Parameters!C82*'LCI_AD-a'!E9*1000*Parameters!C80*17/14)-(E36*Parameters!C123*Parameters!C124*17/14) -> 4.329404 | F31: kg
B32: output | C32: Elementary flow | D32: NO3 | E32: =(Parameters!C82*'LCI_AD-a'!E9*1000*Parameters!C81*62/14)-(E36*Parameters!C123*Parameters!C126*62/14) -> -1.8937605 | F32: kg
B33: output | C33: Elementary flow | D33: (PO4)3- | E33: =-Parameters!C129*'LCI_AD-a'!E37*Parameters!C128*0.001 -> -0.06209938 | F33: kg
B34: output | C34: Elementary flow | D34: CO2 fossil | E34: 0 | F34: kg
A35: Substituted products
C36: Technosphere flow | D36: N-fertilizer | E36: =(Parameters!C83/Parameters!C127)*FW_mass*1000*E6/Parameters!C123 -> 18.00888 | F36: kg | G36: NH4NO3
C37: Technosphere flow | D37: P-fertilizer | E37: =(Parameters!C86/Parameters!C131)*1000*'LCI_AD-a'!E9/Parameters!C128 -> 50.217839 | F37: kg | G37: single superphosphate
C38: Technosphere flow | D38: K-fertilizer | E38: =(Parameters!C85/Parameters!C132)*'LCI_AD-a'!E9*1000 -> 18.509017 | F38: kg
C39: Technosphere flow | D39: Peat | E39: 0 | F39: kg
C40: Technosphere flow | D40: Marginal heat | E40: =E25 -> 2161.4235 | F40: MJ
...

Sheet LCI_AD-c
A1: AD+injection+Digestate
A2: Process | B2: Flow direction | C2: Flow type | D2: Flow name | E2: Value | F2: Unit
A3: Pretreatment | B3: input | C3: Technosphere flow | D3: Waste | E3: 1 | F3: t
B4: input | C4: Technosphere flow | D4: Electricity | E4: =E3*Parameters!C3 -> 9.98 | F4: kWh
B5: input | C5: Technosphere flow | D5: Water
B6: output | C6: Intermediate flow | D6: Pretreated biowaste | E6: =E3*Parameters!C5 -> 0.77 | F6: t
A7: Incineration | B7: input | C7: Intermediate flow | D7: transported discarded biowaste | E7: =E8*0.001*Parameters!C6 -> 2.3 | F7: tkm
B8: input | C8: Intermediate flow | D8: discarded biowaste | E8: =E3*(1-Parameters!C5)*1000 -> 230 | F8: kg
A9: AD | B9: input | C9: Intermediate flow | D9: Pretreated waste | E9: =E6 -> 0.77 | F9: t
B10: input | C10: Intermediate flow | D10: Electricity | E10: =Parameters!C14*E9 -> 22.33 | F10: kWh
B11: input | C11: Intermediate flow | D11: Heat | E11: =E9*Parameters!C15 -> 227.15 | F11: MJ
B12: output | C12: Elementary flow | D12: Methane | E12: =Parameters!C9*(Parameters!C7*(1-Waste_characteristics!B4))*E9*Parameters!C11*0.001 -> 1.5118454 | F12: kg
B13: output | C13: Intermediate flow | D13: Biogas | E13: =(((Parameters!C7*(1-Waste_characteristics!B4))/Parameters!C10)*0.001)-((E12/Parameters!C11)*(1/Parameters!C10)) -> 223.74985 | F13: m3
B14: output | C14: Technosphere flow | D14: Digestate | E14: =Parameters!C66*E9 -> 0.5558219 | F14: t
A15: Biogas upgrading | B15: input | C15: Technosphere flow | D15: Biogas | E15: =E13 -> 223.74985 | F15: m3
B16: output | C16: Elementary flow | D16: CO2 | E16: =E15*(1-Parameters!C10)*Parameters!C47*Parameters!C12 -> 174.55173 | F16: kg
B17: output | C17: Elementary flow | D17: CH4 | E17: =E15*Parameters!C10*Parameters!C48*Parameters!C11 -> 1.7398788 | F17: kg
B18: output | C18: Elementary flow | D18: H2S | E18: =Parameters!C49*E15 -> 0.0013424991 | F18: kg
